Workbook

Sheet 変更履歴
B2: システム名 | H2: 業務分類 | L2: システム分類 | R2: ドキュメント種別 | X2: ドキュメント名 | AK2: 試験対象 | AX2: 作成日 | BB2: 作成者 | BF2: 更新日 | BJ2: 更新者
B3: 受発注システム | H3: =LEFT($X$3,FIND("_",$X$3)-1) -> マスタ | L3: 受発注 | R3: =MID($X$3,FIND("_",$X$3,FIND("_",$X$3)+1)+1,LEN($X$3)-FIND("_",$X$3,FIND("_",$X$3)+1)) -> 結合試験項目 | X3: =REPLACE(LEFT(CELL("filename",$B$2),FIND(".x",CELL("filename",$B$2))-1),1,FIND("[",CELL("filename",$B$2)),) -> マスタ_物件入力_結合試験項目 | AK3: =MID($X$3,FIND("_",$X$3)+1,FIND("_",$X$3,FIND("_",$X$3)+1)-FIND("_",$X$3)-1) -> 物件入力 | AX3: 45636 | BB3: 榎本 | BF3: 45636 | BJ3: 榎本
C7: 変更履歴
C8: 日付 | G8: 版数 | K8: 担当 | O8: 変更箇所 | Y8: 内容
C9: 45636 | G9: 1.0.0 | O9: - | Y9: 新規作成

Sheet 一覧画面
B2: システム名 | H2: 業務分類 | L2: システム分類 | R2: ドキュメント種別 | X2: ドキュメント名 | AK2: 試験対象 | AX2: 作成日 | BB2: 作成者 | BF2: 更新日 | BJ2: 更新者
B3: =変更履歴!B3 -> 受発注システム | H3: =変更履歴!H3 -> マスタ | L3: =変更履歴!L3 -> 受発注 | R3: =変更履歴!R3 -> 結合試験項目 | X3: =変更履歴!X3 -> マスタ_物件入力_結合試験項目 | AK3: =変更履歴!AK3 -> 物件入力 | AX3: =変更履歴!AX3 -> 45636 | BB3: =変更履歴!BB3 -> 榎本 | BF3: =変更履歴!BF3 -> 45636 | BJ3: =変更履歴!BJ3 -> 榎本
BE7: 件数 | BG7: 合計 | BI7: 終了 | BK7: 残
AO8: １回目 | AU8: 2回目 | BG8: =COUNTA(C10:C39) -> 30 | BI8: =COUNTIF(AS10:AT39,"OK")+COUNTIF(AY10:AZ39,"OK") -> 30 | BK8: =BG8-BI8 -> 0
C9: No. | D9: 大項目 | H9: 中項目 | L9: 小項目 | P9: 確認手順 | X9: 確認観点 | AF9: 補足事項(テスト項目補足、テストデータ等) | AO9: 確認日 | AQ9: 確認者 | AS9: 結果 | AU9: 確認日 | AW9: 確認者 | AY9: 結果 | BA9: 試験結果備考
C10: =ROW()-9 -> 1 | D10: 一覧画面 | H10: 初期表示 | L10: 物件番号 | P10: メニューより物件入力を起動する | X10: TD物件情報テーブルの項目と同じ値が表示されていること。 | AO10: 45702 | AQ10: 児玉 | AS10: OK
C11: =ROW()-9 -> 2 | L11: 物件登録日付 | P11: メニューより物件入力を起動する | X11: TD物件情報テーブルの項目と同じ値が表示されていること。 | AO11: 45702 | AQ11: 児玉 | AS11: OK
C12: =ROW()-9 -> 3 | L12: 物件名 | P12: メニューより物件入力を起動する | X12: TD物件情報テーブルの項目と同じ値が表示されていること。 | AO12: 45702 | AQ12: 児玉 | AS12: OK
C13: =ROW()-9 -> 4 | L13: 物件略称 | P13: メニューより物件入力を起動する | X13: TD物件情報テーブルの項目と同じ値が表示されていること。 | AO13: 45702 | AQ13: 児玉 | AS13: OK
C14: =ROW()-9 -> 5 | L14: 得意先CD | P14: メニューより物件入力を起動する | X14: TD物件情報テーブルの項目と同じ値が表示されていること。 | AO14: 45702 | AQ14: 児玉 | AS14: OK
C15: =ROW()-9 -> 6 | L15: 得意先名1 | P15: メニューより物件入力を起動する | X15: TD物件情報テーブルの項目と同じ値が表示されていること。 | AO15: 45702 | AQ15: 児玉 | AS15: OK
C16: =ROW()-9 -> 7 | L16: 得意先名2 | P16: メニューより物件入力を起動する | X16: TD物件情報テーブルの項目と同じ値が表示されていること。 | AO16: 45702 | AQ16: 児玉 | AS16: OK
C17: =ROW()-9 -> 8 | L17: 得TEL | P17: メニューより物件入力を起動する | X17: TD物件情報テーブルの項目と同じ値が表示されていること。 | AO17: 45702 | AQ17: 児玉 | AS17: OK
C18: =ROW()-9 -> 9 | L18: 得FAX | P18: メニューより物件入力を起動する | X18: TD物件情報テーブルの項目と同じ値が表示されていること。 | AO18: 45702 | AQ18: 児玉 | AS18: OK
C19: =ROW()-9 -> 10 | L19: 得意先担当者 | P19: メニューより物件入力を起動する | X19: TD物件情報テーブルの項目と同じ値が表示されていること。 | AO19: 45702 | AQ19: 児玉 | AS19: OK
C20: =ROW()-9 -> 11 | L20: 集計CD | P20: メニューより物件入力を起動する | X20: TD物件情報テーブルの項目と同じ値が表示されていること。 | AO20: 45702 | AQ20: 児玉 | AS20: OK
C21: =ROW()-9 -> 12 | L21: 集計 | P21: メニューより物件入力を起動する | X21: TD物件情報テーブルの項目と同じ値が表示されていること。 | AO21: 45702 | AQ21: 児玉 | AS21: OK
C22: =ROW()-9 -> 13 | L22: 納入得意先CD | P22: メニューより物件入力を起動する | X22: TD物件情報テーブルの項目と同じ値が表示されていること。 | AO22: 45702 | AQ22: 児玉 | AS22: OK
... C48: =ROW()-9 -> 39 | L48: 原価率 | P48: メニューより物件入力を起動する | X48: TD物件情報テーブルの項目と同じ値が表示されていること。 | AO48: 45702 | AQ48: 児玉 | AS48: OK
C49: =ROW()-9 -> 40 | H49: 検索条件 | L49: 物件登録日付 | P49: 検索項目に入力する | X49: レコードに入力された値のフィルタが適応されること | AO49: 45702 | AQ49: 児玉 | AS49: OK
C50: =ROW()-9 -> 41 | L50: 得意先CD | P50: 検索項目に入力する | X50: レコードに入力された値のフィルタが適応されること | AO50: 45702 | AQ50: 児玉 | AS50: OK
C51: =ROW()-9 -> 42 | L51: 納入先CD | P51: 検索項目に入力する | X51: レコードに入力された値のフィルタが適応されること | AO51: 45702 | AQ51: 児玉 | AS51: OK
C52: =ROW()-9 -> 43 | L52: 担当者CD | P52: 検索項目に入力する | X52: レコードに入力された値のフィルタが適応されること | AO52: 45702 | AQ52: 児玉 | AS52: OK
C53: =ROW()-9 -> 44 | L53: 物件番号 | P53: 検索項目に入力する | X53: レコードに入力された値のフィルタが適応されること | AO53: 45702 | AQ53: 児玉 | AS53: OK
C54: =ROW()-9 -> 45 | L54: 物件名 | P54: 検索項目に入力する | X54: レコードに入力された値のフィルタが適応されること | AO54: 45702 | AQ54: 児玉 | AS54: OK
C55: =ROW()-9 -> 46 | H55: 一括削除 | L55: 削除ボタン | P55: 一括削除ボタンを押下する | X55: TD物件情報テーブルの対象レコードが削除されること。 | AO55: 45715 | AQ55: 大谷 | AS55: OK
C56: =ROW()-9 -> 47 | H56: インポート | L56: インポートボタン | P56: インポートボタンを押下する | X56: CSVに入力された値がインポートされること | AO56: 45715 | AQ56: 大谷 | AS56: OK
C57: =ROW()-9 -> 48 | H57: エクスポート | L57: エクスポートボタン | P57: エクスポートボタンを押下する | X57: レコードに入力された値がエクスポートされること | AO57: 45702 | AQ57: 児玉 | AS57: OK

Sheet 新規更新共通
B2: システム名 | H2: 業務分類 | L2: システム分類 | R2: ドキュメント種別 | X2: ドキュメント名 | AK2: 試験対象 | AX2: 作成日 | BB2: 作成者 | BF2: 更新日 | BJ2: 更新者
B3: =変更履歴!B3 -> 受発注システム | H3: =変更履歴!H3 -> マスタ | L3: =変更履歴!L3 -> 受発注 | R3: =変更履歴!R3 -> 結合試験項目 | X3: =変更履歴!X3 -> マスタ_物件入力_結合試験項目 | AK3: =変更履歴!AK3 -> 物件入力 | AX3: =変更履歴!AX3 -> 45636 | BB3: =変更履歴!BB3 -> 榎本 | BF3: =変更履歴!BF3 -> 45636 | BJ3: =変更履歴!BJ3 -> 榎本
BE7: 件数 | BG7: 合計 | BI7: 終了 | BK7: 残
AO8: １回目 | AU8: 2回目 | BG8: =COUNTA(C10:C67) -> 58 | BI8: =COUNTIF(AS10:AT67,"OK")+COUNTIF(AY10:AZ67,"OK") -> 58 | BK8: =BG8-BI8 -> 0
C9: No. | D9: 大項目 | H9: 中項目 | L9: 小項目 | P9: 確認手順 | X9: 確認観点 | AF9: 補足事項(テスト項目補足、テストデータ等) | AO9: 確認日 | AQ9: 確認者 | AS9: 結果 | AU9: 確認日 | AW9: 確認者 | AY9: 結果 | BA9: 試験結果備考
C10: =ROW()-9 -> 1 | D10: 新規登録画面 | H10: 入力制御確認 | L10: 物件登録日付 | P10: 値を入力する | X10: 日付形式でのみ入力できること | AO10: 45684 | AQ10: 児玉 | AS10: OK
C11: =ROW()-9 -> 2 | L11: 物件名 | P11: 値を入力する | X11: 60字まで入力できること | AO11: 45684 | AQ11: 児玉 | AS11: OK
C12: =ROW()-9 -> 3 | L12: 物件略称 | P12: 値を入力する | X12: 24字まで入力できること | AO12: 45684 | AQ12: 児玉 | AS12: OK
C13: =ROW()-9 -> 4 | L13: 得意先名1 | P13: 値を入力する | X13: 28字まで入力できること | AO13: 45684 | AQ13: 児玉 | AS13: OK
C14: =ROW()-9 -> 5 | L14: 得意先名2 | P14: 値を入力する | X14: 28字まで入力できること | AO14: 45684 | AQ14: 児玉 | AS14: OK
C15: =ROW()-9 -> 6 | L15: 得TEL | P15: 値を入力する | X15: 英数字または記号のみで15字まで入力できること | AO15: 45684 | AQ15: 児玉 | AS15: OK
C16: =ROW()-9 -> 7 | L16: 得FAX | P16: 値を入力する | X16: 英数字または記号のみで15字まで入力できること | AO16: 45684 | AQ16: 児玉 | AS16: OK
C17: =ROW()-9 -> 8 | L17: 得意先担当者 | P17: 値を入力する | X17: 40字まで入力できること | AO17: 45684 | AQ17: 児玉 | AS17: OK
C18: =ROW()-9 -> 9 | L18: 納入先名1 | P18: 物件入力より新規作成画面を起動する | X18: 28字まで入力できること | AO18: 45684 | AQ18: 児玉 | AS18: OK
C19: =ROW()-9 -> 10 | L19: 納入先名2 | P19: 物件入力より新規作成画面を起動する | X19: 28字まで入力できること | AO19: 45684 | AQ19: 児玉 | AS19: OK
C20: =ROW()-9 -> 11 | L20: 郵便番号 | P20: 物件入力より新規作成画面を起動する | X20: 英数字または記号のみで8字まで入力できること | AO20: 45684 | AQ20: 児玉 | AS20: OK
C21: =ROW()-9 -> 12 | L21: 住所1 | P21: 物件入力より新規作成画面を起動する | X21: 32字まで入力できること | AO21: 45684 | AQ21: 児玉 | AS21: OK
C22: =ROW()-9 -> 13 | L22: 住所2 | P22: 物件入力より新規作成画面を起動する | X22: 32字まで入力できること | AO22: 45684 | AQ22: 児玉 | AS22: OK
... C31: =ROW()-9 -> 22 | L31: 予定請求予定日付 | P31: 物件入力より新規作成画面を起動する | X31: 日付形式でのみ入力できること | AO31: 45684 | AQ31: 児玉 | AS31: OK
C32: =ROW()-9 -> 23 | H32: 動作確認 | L32: 得意先CD | P32: 得意先CD項目を押下する | X32: 得意先CD検索のダイアログが立ち上がること。 | AO32: 45684 | AQ32: 児玉 | AS32: OK
C33: =ROW()-9 -> 24 | P33: 得意先CD検索画面で得意先CDを検索し、得意先CDを選択する。 | X33: 以下の項目に選択した得意先CDの該当情報が表示されること 得意先CD 得意先名1 得意先名2 得TEL 得FAX 集計CD 集計 | AO33: 45684 | AQ33: 児玉 | AS33: OK
C34: =ROW()-9 -> 25 | X34: 以下の項目が得意先CD選択前と同じであること 物件番号 物件登録日付 物件名 物件略称 得意先担当者 納入得意先CD 納入先CD 納入先1 納入先2 郵便番号 住所1 住所2 納TEL 納FAX 納入先担当者 担当者CD 担当者名 部署CD 部署名 工事担当CD 工事担当者名 予定納期S 予定納期E 予定オープン日 予定業種区分 物件種別 予定受付日付 予定完工日付 予定請求予定日付 売上合計 出精値引き 原価合計 原価率 | AO34: 45684 | AQ34: 児玉 | AS34: OK
C35: =ROW()-9 -> 26 | P35: 得意先CD項目を削除する | X35: 以下の項目に選択した得意先CDの該当情報が削除されること 得意先CD 得意先名1 得意先名2 得TEL 得FAX 集計CD 集計 | AO35: 45684 | AQ35: 児玉 | AS35: OK
C36: =ROW()-9 -> 27 | X36: 以下の項目が得意先CD削除前と同じであること 物件番号 物件登録日付 物件名 物件略称 得意先担当者 納入得意先CD 納入先CD 納入先1 納入先2 郵便番号 住所1 住所2 納TEL 納FAX 納入先担当者 担当者CD 担当者名 部署CD 部署名 工事担当CD 工事担当者名 予定納期S 予定納期E 予定オープン日 予定業種区分 物件種別 予定受付日付 予定完工日付 予定請求予定日付 売上合計 出精値引き 原価合計 原価率 | AO36: 45684 | AQ36: 児玉 | AS36: OK
C37: =ROW()-9 -> 28 | L37: 集計CD | P37: 集計CD項目を押下する | X37: 集計CD検索のダイアログが立ち上がること。 | AO37: 45684 | AQ37: 児玉 | AS37: OK
C38: =ROW()-9 -> 29 | P38: 集計CD検索画面で集計CDを検索し、集計CDを選択する。 | X38: 以下の項目に選択した集計CDの該当情報が表示されること 集計CD 集計 | AO38: 45684 | AQ38: 児玉 | AS38: OK
C39: =ROW()-9 -> 30 | X39: 以下の項目が集計CD選択前と同じであること 物件番号 物件登録日付 物件名 物件略称 得意先CD 得意先名1 得意先名2 得TEL 得FAX 得意先担当者 納入得意先CD 納入先CD 納入先1 納入先2 郵便番号 住所1 住所2 納TEL 納FAX 納入先担当者 担当者CD 担当者名 部署CD 部署名 工事担当CD 工事担当者名 予定納期S 予定納期E 予定オープン日 予定業種区分 物件種別 予定受付日付 予定完工日付 予定請求予定日付 売上合計 出精値引き 原価合計 原価率 | AO39: 45684 | AQ39: 児玉 | AS39: OK
C40: =ROW()-9 -> 31 | P40: 集計CD項目を削除する | X40: 以下の項目に選択した集計CDの該当情報が削除されること 集計CD 集計 | AO40: 45684 | AQ40: 児玉 | AS40: OK
C41: =ROW()-9 -> 32 | X41: 以下の項目が集計CD削除前と同じであること 物件番号 物件登録日付 物件名 物件略称 得意先CD 得意先名1 得意先名2 得TEL 得FAX 得意先担当者 納入得意先CD 納入先CD 納入先1 納入先2 郵便番号 住所1 住所2 納TEL 納FAX 納入先担当者 担当者CD 担当者名 部署CD 部署名 工事担当CD 工事担当者名 予定納期S 予定納期E 予定オープン日 予定業種区分 物件種別 予定受付日付 予定完工日付 予定請求予定日付 売上合計 出精値引き 原価合計 原価率 | AO41: 45684 | AQ41: 児玉 | AS41: OK
C42: =ROW()-9 -> 33 | L42: 納入先CD | P42: 納入先CD項目を押下する | X42: 納入先CD検索のダイアログが立ち上がること。 | AO42: 45684 | AQ42: 児玉 | AS42: OK
C43: =ROW()-9 -> 34 | P43: 納入先CD検索画面で納入先CDを検索し、納入先CDを選択する。 | X43: 以下の項目に選択した納入先CDの該当情報が表示されること 納入先CD 納入先1 納入先2 郵便番号 住所1 住所2 納TEL 納FAX | AO43: 45684 | AQ43: 児玉 | AS43: OK
C44: =ROW()-9 -> 35 | X44: 以下の項目が納入先CD選択前と同じであること 物件番号 物件登録日付 物件名 物件略称 得意先CD 得意先名1 得意先名2 得TEL 得FAX 得意先担当者 集計CD 集計 納入得意先CD 納入先担当者 担当者CD 担当者名 部署CD 部署名 工事担当CD 工事担当者名 予定納期S 予定納期E 予定オープン日 予定業種区分 物件種別 予定受付日付 予定完工日付 予定請求予定日付 売上合計 出精値引き 原価合計 原価率 | AO44: 45684 | AQ44: 児玉 | AS44: OK
C45: =ROW()-9 -> 36 | P45: 納入先CD項目を削除する | X45: 以下の項目に選択した納入先CDの該当情報が削除されること 納入先CD 納入先1 納入先2 郵便番号 住所1 住所2 納TEL 納FAX | AO45: 45684 | AQ45: 児玉 | AS45: OK
C46: =ROW()-9 -> 37 | X46: 以下の項目が納入先CD削除前と同じであること 物件番号 物件登録日付 物件名 物件略称 得意先CD 得意先名1 得意先名2 得TEL 得FAX 得意先担当者 集計CD 集計 納入得意先CD 納入先担当者 担当者CD 担当者名 部署CD 部署名 工事担当CD 工事担当者名 予定納期S 予定納期E 予定オープン日 予定業種区分 物件種別 予定受付日付 予定完工日付 予定請求予定日付 売上合計 出精値引き 原価合計 原価率 | AO46: 45684 | AQ46: 児玉 | AS46: OK
C47: =ROW()-9 -> 38 | L47: 担当者CD | P47: 担当者CD項目を押下する | X47: 担当者CD検索のダイアログが立ち上がること。 | AO47: 45684 | AQ47: 児玉 | AS47: OK
C48: =ROW()-9 -> 39 | P48: 担当者CD検索画面で担当者CDを検索し、担当者CDを選択する。 | X48: 以下の項目に選択した担当者CDの該当情報が表示されること 担当者CD 担当者名 部署CD 部署名 | AO48: 45684 | AQ48: 児玉 | AS48: OK
C49: =ROW()-9 -> 40 | X49: 以下の項目が担当者CD選択前と同じであること 物件番号 物件登録日付 物件名 物件略称 得意先CD 得意先名1 得意先名2 得TEL 得FAX 得意先担当者 集計CD 集計 納入得意先CD 納入先CD 納入先1 納入先2 郵便番号 住所1 住所2 納TEL 納FAX 納入先担当者 工事担当CD 工事担当者名 予定納期S 予定納期E 予定オープン日 予定業種区分 物件種別 予定受付日付 予定完工日付 予定請求予定日付 売上合計 出精値引き 原価合計 原価率 | AO49: 45684 | AQ49: 児玉 | AS49: OK
C50: =ROW()-9 -> 41 | P50: 担当者CD項目を削除する | X50: 以下の項目に選択した担当者CDの該当情報が削除されること 担当者CD 担当者名 部署CD 部署名 | AO50: 45684 | AQ50: 児玉 | AS50: OK
C51: =ROW()-9 -> 42 | X51: 以下の項目が担当者CD削除前と同じであること 物件番号 物件登録日付 物件名 物件略称 得意先CD 得意先名1 得意先名2 得TEL 得FAX 得意先担当者 集計CD 集計 納入得意先CD 納入先CD 納入先1 納入先2 郵便番号 住所1 住所2 納TEL 納FAX 納入先担当者 工事担当CD 工事担当者名 予定納期S 予定納期E 予定オープン日 予定業種区分 物件種別 予定受付日付 予定完工日付 予定請求予定日付 売上合計 出精値引き 原価合計 原価率 | AO51: 45684 | AQ51: 児玉 | AS51: OK
C52: =ROW()-9 -> 43 | L52: 部署CD | P52: 部署CD項目を押下する | X52: 部署CD検索のダイアログが立ち上がること。 | AO52: 45684 | AQ52: 児玉 | AS52: OK
...

Sheet 新規登録画面
B2: システム名 | H2: 業務分類 | L2: システム分類 | R2: ドキュメント種別 | X2: ドキュメント名 | AK2: 試験対象 | AX2: 作成日 | BB2: 作成者 | BF2: 更新日 | BJ2: 更新者
B3: =変更履歴!B3 -> 受発注システム | H3: =変更履歴!H3 -> マスタ | L3: =変更履歴!L3 -> 受発注 | R3: =変更履歴!R3 -> 結合試験項目 | X3: =変更履歴!X3 -> マスタ_物件入力_結合試験項目 | AK3: =変更履歴!AK3 -> 物件入力 | AX3: =変更履歴!AX3 -> 45636 | BB3: =変更履歴!BB3 -> 榎本 | BF3: =変更履歴!BF3 -> 45636 | BJ3: =変更履歴!BJ3 -> 榎本
BE7: 件数 | BG7: 合計 | BI7: 終了 | BK7: 残
AO8: １回目 | AU8: 2回目 | BG8: =COUNTA(C10:C89) -> 80 | BI8: =COUNTIF(AS10:AT89,"OK")+COUNTIF(AY10:AZ89,"OK") -> 80 | BK8: =BG8-BI8 -> 0
C9: No. | D9: 大項目 | H9: 中項目 | L9: 小項目 | P9: 確認手順 | X9: 確認観点 | AF9: 補足事項(テスト項目補足、テストデータ等) | AO9: 確認日 | AQ9: 確認者 | AS9: 結果 | AU9: 確認日 | AW9: 確認者 | AY9: 結果 | BA9: 試験結果備考
C10: =ROW()-9 -> 1 | D10: 新規登録画面 | H10: 初期表示 | L10: 物件番号 | P10: 物件入力より新規作成画面を起動する | X10: 入力欄が非活性、かつ空欄であること。 | AO10: 45684 | AQ10: 児玉 | AS10: OK
C11: =ROW()-9 -> 2 | L11: 物件登録日付 | P11: 物件入力より新規作成画面を起動する | X11: 入力欄が活性、かつ当月の日付が入力されて必須項目であること。 | AO11: 45684 | AQ11: 児玉 | AS11: OK
C12: =ROW()-9 -> 3 | L12: 物件名 | P12: 物件入力より新規作成画面を起動する | X12: 入力欄が活性、かつ空欄であること。 | AO12: 45684 | AQ12: 児玉 | AS12: OK
C13: =ROW()-9 -> 4 | L13: 物件略称 | P13: 物件入力より新規作成画面を起動する | X13: 入力欄が活性、かつ空欄であること。 | AO13: 45684 | AQ13: 児玉 | AS13: OK
C14: =ROW()-9 -> 5 | L14: 得意先CD | P14: 物件入力より新規作成画面を起動する | X14: 入力欄が活性、かつ空欄で必須項目であること。 | AO14: 45684 | AQ14: 児玉 | AS14: OK
C15: =ROW()-9 -> 6 | L15: 得意先名1 | P15: 物件入力より新規作成画面を起動する | X15: 入力欄が活性、かつ空欄であること。 | AO15: 45684 | AQ15: 児玉 | AS15: OK
C16: =ROW()-9 -> 7 | L16: 得意先名2 | P16: 物件入力より新規作成画面を起動する | X16: 入力欄が活性、かつ空欄であること。 | AO16: 45684 | AQ16: 児玉 | AS16: OK
C17: =ROW()-9 -> 8 | L17: 得TEL | P17: 物件入力より新規作成画面を起動する | X17: 入力欄が活性、かつ空欄であること。 | AO17: 45684 | AQ17: 児玉 | AS17: OK
C18: =ROW()-9 -> 9 | L18: 得FAX | P18: 物件入力より新規作成画面を起動する | X18: 入力欄が活性、かつ空欄であること。 | AO18: 45684 | AQ18: 児玉 | AS18: OK
C19: =ROW()-9 -> 10 | L19: 得意先担当者 | P19: 物件入力より新規作成画面を起動する | X19: 入力欄が活性、かつ空欄であること。 | AO19: 45684 | AQ19: 児玉 | AS19: OK
C20: =ROW()-9 -> 11 | L20: 集計CD | P20: 物件入力より新規作成画面を起動する | X20: 入力欄が活性、かつ空欄であること。 | AO20: 45684 | AQ20: 児玉 | AS20: OK
C21: =ROW()-9 -> 12 | L21: 集計 | P21: 物件入力より新規作成画面を起動する | X21: 入力欄が非活性、かつ空欄であること。 | AO21: 45684 | AQ21: 児玉 | AS21: OK
C22: =ROW()-9 -> 13 | L22: 納入得意先CD | P22: 物件入力より新規作成画面を起動する | X22: 入力欄が活性、かつ空欄で必須項目であること。 | AO22: 45684 | AQ22: 児玉 | AS22: OK
... C49: =ROW()-9 -> 40 | L49: 原価率 | P49: 物件入力より新規作成画面を起動する | X49: 入力欄が非活性、かつ0が入力されていること。 | AO49: 45684 | AQ49: 児玉 | AS49: OK
C50: =ROW()-9 -> 41 | H50: 新規登録 | L50: 物件番号 | P50: 値を入力して作成ボタンを押下する | X50: 入力した値がTD物件情報テーブルの項目に反映されること | AO50: 45715 | AQ50: 大谷 | AS50: OK
C51: =ROW()-9 -> 42 | L51: 物件登録日付 | P51: 値を入力して作成ボタンを押下する | X51: 入力した値がTD物件情報テーブルの項目に反映されること | AO51: 45715 | AQ51: 大谷 | AS51: OK
C52: =ROW()-9 -> 43 | L52: 物件名 | P52: 値を入力して作成ボタンを押下する | X52: 入力した値がTD物件情報テーブルの項目に反映されること | AO52: 45715 | AQ52: 大谷 | AS52: OK
C53: =ROW()-9 -> 44 | L53: 物件略称 | P53: 値を入力して作成ボタンを押下する | X53: 入力した値がTD物件情報テーブルの項目に反映されること | AO53: 45715 | AQ53: 大谷 | AS53: OK
C54: =ROW()-9 -> 45 | L54: 得意先CD | P54: 値を入力して作成ボタンを押下する | X54: 入力した値がTD物件情報テーブルの項目に反映されること | AO54: 45715 | AQ54: 大谷 | AS54: OK
C55: =ROW()-9 -> 46 | L55: 得意先名1 | P55: 値を入力して作成ボタンを押下する | X55: 入力した値がTD物件情報テーブルの項目に反映されること | AO55: 45715 | AQ55: 大谷 | AS55: OK
C56: =ROW()-9 -> 47 | L56: 得意先名2 | P56: 値を入力して作成ボタンを押下する | X56: 入力した値がTD物件情報テーブルの項目に反映されること | AO56: 45715 | AQ56: 大谷 | AS56: OK
C57: =ROW()-9 -> 48 | L57: 得TEL | P57: 値を入力して作成ボタンを押下する | X57: 入力した値がTD物件情報テーブルの項目に反映されること | AO57: 45715 | AQ57: 大谷 | AS57: OK
C58: =ROW()-9 -> 49 | L58: 得FAX | P58: 値を入力して作成ボタンを押下する | X58: 入力した値がTD物件情報テーブルの項目に反映されること | AO58: 45715 | AQ58: 大谷 | AS58: OK
C59: =ROW()-9 -> 50 | L59: 得意先担当者 | P59: 値を入力して作成ボタンを押下する | X59: 入力した値がTD物件情報テーブルの項目に反映されること | AO59: 45715 | AQ59: 大谷 | AS59: OK
C60: =ROW()-9 -> 51 | L60: 集計CD | P60: 値を入力して作成ボタンを押下する | X60: 入力した値がTD物件情報テーブルの項目に反映されること | AO60: 45715 | AQ60: 大谷 | AS60: OK
C61: =ROW()-9 -> 52 | L61: 集計 | P61: 値を入力して作成ボタンを押下する | X61: 入力した値がTD物件情報テーブルの項目に反映されること | AO61: 45715 | AQ61: 大谷 | AS61: OK
C62: =ROW()-9 -> 53 | L62: 納入得意先CD | P62: 値を入力して作成ボタンを押下する | X62: 入力した値がTD物件情報テーブルの項目に反映されること | AO62: 45715 | AQ62: 大谷 | AS62: OK
... C89: =ROW()-9 -> 80 | L89: 原価率 | P89: 値を入力して作成ボタンを押下する | X89: 入力した値がTD物件情報テーブルの項目に反映されること | AO89: 45715 | AQ89: 大谷 | AS89: OK

Sheet 更新画面
B2: システム名 | H2: 業務分類 | L2: システム分類 | R2: ドキュメント種別 | X2: ドキュメント名 | AK2: 試験対象 | AX2: 作成日 | BB2: 作成者 | BF2: 更新日 | BJ2: 更新者
B3: =変更履歴!B3 -> 受発注システム | H3: =変更履歴!H3 -> マスタ | L3: =変更履歴!L3 -> 受発注 | R3: =変更履歴!R3 -> 結合試験項目 | X3: =変更履歴!X3 -> マスタ_物件入力_結合試験項目 | AK3: =変更履歴!AK3 -> 物件入力 | AX3: =変更履歴!AX3 -> 45636 | BB3: =変更履歴!BB3 -> 榎本 | BF3: =変更履歴!BF3 -> 45636 | BJ3: =変更履歴!BJ3 -> 榎本
BE7: 件数 | BG7: 合計 | BI7: 終了 | BK7: 残
AO8: １回目 | AU8: 2回目 | BG8: =COUNTA(C10:C90) -> 81 | BI8: =COUNTIF(AS10:AT90,"OK")+COUNTIF(AY10:AZ90,"OK") -> 81 | BK8: =BG8-BI8 -> 0
C9: No. | D9: 大項目 | H9: 中項目 | L9: 小項目 | P9: 確認手順 | X9: 確認観点 | AF9: 補足事項(テスト項目補足、テストデータ等) | AO9: 確認日 | AQ9: 確認者 | AS9: 結果 | AU9: 確認日 | AW9: 確認者 | AY9: 結果 | BA9: 試験結果備考
C10: =ROW()-9 -> 1 | D10: 更新画面 | H10: 初期表示 | L10: 物件番号 | P10: 物件入力より対象のレコードを押下する | X10: TD物件情報テーブルの項目と同じ値が表示されていること。 | AO10: 45684 | AQ10: 児玉 | AS10: OK
C11: =ROW()-9 -> 2 | L11: 物件登録日付 | P11: 物件入力より対象のレコードを押下する | X11: TD物件情報テーブルの項目と同じ値が表示されていること。 | AO11: 45684 | AQ11: 児玉 | AS11: OK
C12: =ROW()-9 -> 3 | L12: 物件名 | P12: 物件入力より対象のレコードを押下する | X12: TD物件情報テーブルの項目と同じ値が表示されていること。 | AO12: 45684 | AQ12: 児玉 | AS12: OK
C13: =ROW()-9 -> 4 | L13: 物件略称 | P13: 物件入力より対象のレコードを押下する | X13: TD物件情報テーブルの項目と同じ値が表示されていること。 | AO13: 45684 | AQ13: 児玉 | AS13: OK
C14: =ROW()-9 -> 5 | L14: 得意先CD | P14: 物件入力より対象のレコードを押下する | X14: TD物件情報テーブルの項目と同じ値が表示されていること。 | AO14: 45684 | AQ14: 児玉 | AS14: OK
C15: =ROW()-9 -> 6 | L15: 得意先名1 | P15: 物件入力より対象のレコードを押下する | X15: TD物件情報テーブルの項目と同じ値が表示されていること。 | AO15: 45684 | AQ15: 児玉 | AS15: OK
C16: =ROW()-9 -> 7 | L16: 得意先名2 | P16: 物件入力より対象のレコードを押下する | X16: TD物件情報テーブルの項目と同じ値が表示されていること。 | AO16: 45684 | AQ16: 児玉 | AS16: OK
C17: =ROW()-9 -> 8 | L17: 得TEL | P17: 物件入力より対象のレコードを押下する | X17: TD物件情報テーブルの項目と同じ値が表示されていること。 | AO17: 45684 | AQ17: 児玉 | AS17: OK
C18: =ROW()-9 -> 9 | L18: 得FAX | P18: 物件入力より対象のレコードを押下する | X18: TD物件情報テーブルの項目と同じ値が表示されていること。 | AO18: 45684 | AQ18: 児玉 | AS18: OK
C19: =ROW()-9 -> 10 | L19: 得意先担当者 | P19: 物件入力より対象のレコードを押下する | X19: TD物件情報テーブルの項目と同じ値が表示されていること。 | AO19: 45684 | AQ19: 児玉 | AS19: OK
C20: =ROW()-9 -> 11 | L20: 集計CD | P20: 物件入力より対象のレコードを押下する | X20: TD物件情報テーブルの項目と同じ値が表示されていること。 | AO20: 45684 | AQ20: 児玉 | AS20: OK
C21: =ROW()-9 -> 12 | L21: 集計 | P21: 物件入力より対象のレコードを押下する | X21: TD物件情報テーブルの項目と同じ値が表示されていること。 | AO21: 45684 | AQ21: 児玉 | AS21: OK
C22: =ROW()-9 -> 13 | L22: 納入得意先CD | P22: 物件入力より対象のレコードを押下する | X22: TD物件情報テーブルの項目と同じ値が表示されていること。 | AO22: 45684 | AQ22: 児玉 | AS22: OK
... C49: =ROW()-9 -> 40 | L49: 原価率 | P49: 物件入力より対象のレコードを押下する | X49: TD物件情報テーブルの項目と同じ値が表示されていること。 | AO49: 45684 | AQ49: 児玉 | AS49: OK
C50: =ROW()-9 -> 41 | H50: 更新 | L50: 物件番号 | P50: 値を入力して更新ボタンを押下する | X50: 入力した値がTD物件情報テーブルの項目に反映されること | AO50: 45715 | AQ50: 大谷 | AS50: OK
C51: =ROW()-9 -> 42 | L51: 物件登録日付 | P51: 値を入力して更新ボタンを押下する | X51: 入力した値がTD物件情報テーブルの項目に反映されること | AO51: 45715 | AQ51: 大谷 | AS51: OK
C52: =ROW()-9 -> 43 | L52: 物件名 | P52: 値を入力して更新ボタンを押下する | X52: 入力した値がTD物件情報テーブルの項目に反映されること | AO52: 45715 | AQ52: 大谷 | AS52: OK
C53: =ROW()-9 -> 44 | L53: 物件略称 | P53: 値を入力して更新ボタンを押下する | X53: 入力した値がTD物件情報テーブルの項目に反映されること | AO53: 45715 | AQ53: 大谷 | AS53: OK
C54: =ROW()-9 -> 45 | L54: 得意先CD | P54: 値を入力して更新ボタンを押下する | X54: 入力した値がTD物件情報テーブルの項目に反映されること | AO54: 45715 | AQ54: 大谷 | AS54: OK
C55: =ROW()-9 -> 46 | L55: 得意先名1 | P55: 値を入力して更新ボタンを押下する | X55: 入力した値がTD物件情報テーブルの項目に反映されること | AO55: 45715 | AQ55: 大谷 | AS55: OK
C56: =ROW()-9 -> 47 | L56: 得意先名2 | P56: 値を入力して更新ボタンを押下する | X56: 入力した値がTD物件情報テーブルの項目に反映されること | AO56: 45715 | AQ56: 大谷 | AS56: OK
C57: =ROW()-9 -> 48 | L57: 得TEL | P57: 値を入力して更新ボタンを押下する | X57: 入力した値がTD物件情報テーブルの項目に反映されること | AO57: 45715 | AQ57: 大谷 | AS57: OK
C58: =ROW()-9 -> 49 | L58: 得FAX | P58: 値を入力して更新ボタンを押下する | X58: 入力した値がTD物件情報テーブルの項目に反映されること | AO58: 45715 | AQ58: 大谷 | AS58: OK
C59: =ROW()-9 -> 50 | L59: 得意先担当者 | P59: 値を入力して更新ボタンを押下する | X59: 入力した値がTD物件情報テーブルの項目に反映されること | AO59: 45715 | AQ59: 大谷 | AS59: OK
C60: =ROW()-9 -> 51 | L60: 集計CD | P60: 値を入力して更新ボタンを押下する | X60: 入力した値がTD物件情報テーブルの項目に反映されること | AO60: 45715 | AQ60: 大谷 | AS60: OK
C61: =ROW()-9 -> 52 | L61: 集計 | P61: 値を入力して更新ボタンを押下する | X61: 入力した値がTD物件情報テーブルの項目に反映されること | AO61: 45715 | AQ61: 大谷 | AS61: OK
C62: =ROW()-9 -> 53 | L62: 納入得意先CD | P62: 値を入力して更新ボタンを押下する | X62: 入力した値がTD物件情報テーブルの項目に反映されること | AO62: 45715 | AQ62: 大谷 | AS62: OK
... C89: =ROW()-9 -> 80 | L89: 原価率 | P89: 値を入力して更新ボタンを押下する | X89: 入力した値がTD物件情報テーブルの項目に反映されること | AO89: 45715 | AQ89: 大谷 | AS89: OK
C90: =ROW()-9 -> 81 | H90: 削除 | L90: 削除ボタン | P90: 削除ボタンを押下する | X90: TD物件情報テーブルの対象レコードが削除されること。 | AO90: 45715 | AQ90: 大谷 | AS90: OK

Sheet 参照
A1: ラベル
A2: インプット
A3: ボタン
A4: ラジオ
