Workbook

Sheet 検針結果
A1: メータ番号 | B1: 管理番号 | C1: メータ名称 | D1: 計量区分 | E1: ハードアドレス | F1: 検針桁数 | G1: 計量乗率 | H1: 計量種別番号 | I1: 計量種別 | J1: 単位 | K1: 用途 | L1: 接点形式 | M1: 補正料金 | N1: 使用量上下限監視有無 | O1: 使用量上限値 | P1: 使用量下限値 | Q1: 前回比上下限監視有無 | R1: 前回比上限値 | S1: 前回比下限値 | T1: テナント番号 | U1: テナント名称 | V1: 計器番号 | W1: 検定有効期限 (検定年月) | X1: 今回指示数 | Y1: 前回指示数 | Z1: 今回使用量 | AA1: 前回使用量 | AB1: 今回検針結果 | AC1: 今回検針日 | AD1: 検針完了フラグ | AE1: 前回比(%) | AF1: 前回比異常有無 | AG1: 使用量異常有無 | AH1: メータ交換の有無 | AI1: 交換検針日 | AJ1: 交換前今回指示数 | AK1: 交換前前回指示数 | AL1: 交換前使用量
A2: 0001 | B2: 1100 | C2: L-1100 | D2: オンライン | E2: 1-1-1---3 | F2: 5 | G2: 1 | H2: 1 | I2: 電灯 | J2: kWh | L2: a接点 | M2: 0 | N2: 監視なし | Q2: 監視なし | T2: 0202 | U2: kate spde new york | V2: 23A038241 | W2: 47788 | X2: 29197 | Y2: 26606 | Z2: 2591 | AA2: 2533 | AB2: 正常 | AC2: 2025年02月01日 | AD2: 実行済み | AE2: 102.29 | AF2: 正常 | AG2: 正常 | AH2: 交換なし | AJ2: 0 | AK2: 0 | AL2: 0
A3: 0002 | B3: 1100 | C3: L-1101 | D3: オンライン | E3: 1-1-1---2 | F3: 5 | G3: 1 | H3: 1 | I3: 電灯 | J3: kWh | L3: a接点 | M3: 0 | N3: 監視なし | Q3: 監視なし | T3: 0202 | U3: kate spde new york | V3: 23A038245 | W3: 47788 | X3: 18363 | Y3: 16800 | Z3: 1563 | AA3: 1544 | AB3: 正常 | AC3: 2025年02月01日 | AD3: 実行済み | AE3: 101.23 | AF3: 正常 | AG3: 正常 | AH3: 交換なし | AJ3: 0 | AK3: 0 | AL3: 0
A4: 0003 | B4: 1110 | C4: L-1102 | D4: オンライン | E4: 1-1-1---1 | F4: 5 | G4: 1 | H4: 1 | I4: 電灯 | J4: kWh | L4: a接点 | M4: 0 | N4: 監視なし | Q4: 監視なし | T4: 0203 | U4: J.PRESS | V4: 23A038248 | W4: 47788 | X4: 19898 | Y4: 18246 | Z4: 1652 | AA4: 1667 | AB4: 正常 | AC4: 2025年02月01日 | AD4: 実行済み | AE4: 99.1 | AF4: 正常 | AG4: 正常 | AH4: 交換なし | AJ4: 0 | AK4: 0 | AL4: 0
A5: 0004 | B5: 1115 | C5: L-1103 | D5: オンライン | E5: 1-1-1---4 | F5: 5 | G5: 1 | H5: 1 | I5: 電灯 | J5: kWh | L5: a接点 | M5: 0 | N5: 監視なし | Q5: 監視なし | T5: 0002 | U5: PETIT BATEAU | V5: 23A038242 | W5: 47788 | X5: 42510 | Y5: 38804 | Z5: 3706 | AA5: 3670 | AB5: 正常 | AC5: 2025年02月01日 | AD5: 実行済み | AE5: 100.98 | AF5: 正常 | AG5: 正常 | AH5: 交換なし | AJ5: 0 | AK5: 0 | AL5: 0
A6: 0005 | B6: 1120 | C6: L-1104 | D6: オンライン | E6: 1-1-1---5 | F6: 5 | G6: 1 | H6: 1 | I6: 電灯 | J6: kWh | L6: a接点 | M6: 0 | N6: 監視なし | Q6: 監視なし | T6: 0003 | U6: ワコール | V6: 23A038249 | W6: 47788 | X6: 25718 | Y6: 23532 | Z6: 2186 | AA6: 2151 | AB6: 正常 | AC6: 2025年02月01日 | AD6: 実行済み | AE6: 101.63 | AF6: 正常 | AG6: 正常 | AH6: 交換なし | AJ6: 0 | AK6: 0 | AL6: 0
A7: 0006 | B7: 1125 | C7: L-1105 | D7: オンライン | E7: 1-1-1---6 | F7: 5 | G7: 1 | H7: 1 | I7: 電灯 | J7: kWh | L7: a接点 | M7: 0 | N7: 監視なし | Q7: 監視なし | T7: 0004 | U7: theory | V7: 23A038244 | W7: 47788 | X7: 12530 | Y7: 11453 | Z7: 1077 | AA7: 1046 | AB7: 正常 | AC7: 2025年02月01日 | AD7: 実行済み | AE7: 102.96 | AF7: 正常 | AG7: 正常 | AH7: 交換なし | AJ7: 0 | AK7: 0 | AL7: 0
A8: 0007 | B8: 1130 | C8: L-1106 | D8: オンライン | E8: 1-1-1---7 | F8: 5 | G8: 1 | H8: 1 | I8: 電灯 | J8: kWh | L8: a接点 | M8: 0 | N8: 監視なし | Q8: 監視なし | T8: 0005 | U8: theory | V8: 23A038258 | W8: 47788 | X8: 16805 | Y8: 15362 | Z8: 1443 | AA8: 1410 | AB8: 正常 | AC8: 2025年02月01日 | AD8: 実行済み | AE8: 102.34 | AF8: 正常 | AG8: 正常 | AH8: 交換なし | AJ8: 0 | AK8: 0 | AL8: 0
A9: 0008 | B9: 1135 | C9: L-1107 | D9: オンライン | E9: 1-1-1---8 | F9: 5 | G9: 1 | H9: 1 | I9: 電灯 | J9: kWh | L9: a接点 | M9: 0 | N9: 監視なし | Q9: 監視なし | T9: 0006 | U9: COACH MEN'S | V9: 23A038252 | W9: 47788 | X9: 19032 | Y9: 17437 | Z9: 1595 | AA9: 1588 | AB9: 正常 | AC9: 2025年02月01日 | AD9: 実行済み | AE9: 100.44 | AF9: 正常 | AG9: 正常 | AH9: 交換なし | AJ9: 0 | AK9: 0 | AL9: 0
A10: 0009 | B10: 1140 | C10: L-1108 | D10: オンライン | E10: 1-1-1---9 | F10: 5 | G10: 1 | H10: 1 | I10: 電灯 | J10: kWh | L10: a接点 | M10: 0 | N10: 監視なし | Q10: 監視なし | T10: 0007 | U10: DIESEL | V10: 23A038255 | W10: 47788 | X10: 13685 | Y10: 12579 | Z10: 1106 | AA10: 1097 | AB10: 正常 | AC10: 2025年02月01日 | AD10: 実行済み | AE10: 100.82 | AF10: 正常 | AG10: 正常 | AH10: 交換なし | AJ10: 0 | AK10: 0 | AL10: 0
A11: 0010 | B11: 1145 | C11: L-1109 | D11: オンライン | E11: 1-1-1---10 | F11: 5 | G11: 1 | H11: 1 | I11: 電灯 | J11: kWh | L11: a接点 | M11: 0 | N11: 監視なし | Q11: 監視なし | T11: 0008 | U11: DIESEL | V11: 23A038253 | W11: 47788 | X11: 39565 | Y11: 36204 | Z11: 3361 | AA11: 3361 | AB11: 正常 | AC11: 2025年02月01日 | AD11: 実行済み | AE11: 100 | AF11: 正常 | AG11: 正常 | AH11: 交換なし | AJ11: 0 | AK11: 0 | AL11: 0
A12: 0011 | B12: 1150 | C12: L-1110 | D12: オンライン | E12: 1-1-1---11 | F12: 5 | G12: 1 | H12: 1 | I12: 電灯 | J12: kWh | L12: a接点 | M12: 0 | N12: 監視なし | Q12: 監視なし | T12: 0009 | U12: NEW YORKER | V12: 23A038239 | W12: 47788 | X12: 19930 | Y12: 18238 | Z12: 1692 | AA12: 1680 | AB12: 正常 | AC12: 2025年02月01日 | AD12: 実行済み | AE12: 100.71 | AF12: 正常 | AG12: 正常 | AH12: 交換なし | AJ12: 0 | AK12: 0 | AL12: 0
A13: 0012 | B13: 2105 | C13: L-2100 | D13: オンライン | E13: 1-1-1---12 | F13: 5 | G13: 1 | H13: 1 | I13: 電灯 | J13: kWh | L13: a接点 | M13: 0 | N13: 監視なし | Q13: 監視なし | T13: 0010 | U13: mezzo piano | V13: 23A038257 | W13: 47788 | X13: 25788 | Y13: 23632 | Z13: 2156 | AA13: 2142 | AB13: 正常 | AC13: 2025年02月01日 | AD13: 実行済み | AE13: 100.65 | AF13: 正常 | AG13: 正常 | AH13: 交換なし | AJ13: 0 | AK13: 0 | AL13: 0
... A96: 0095 | B96: 2600 | C96: L-2604 | D96: オンライン | E96: 1-1-7---6 | F96: 5 | G96: 1 | H96: 1 | I96: 電灯 | J96: kWh | L96: a接点 | M96: 0 | N96: 監視なし | Q96: 監視なし | T96: 0061 | U96: adidas | V96: 23A038312 | W96: 47788 | X96: 28140 | Y96: 26226 | Z96: 1914 | AA96: 2229 | AB96: 正常 | AC96: 2025年02月01日 | AD96: 実行済み | AE96: 85.87 | AF96: 正常 | AG96: 正常 | AH96: 交換なし | AJ96: 0 | AK96: 0 | AL96: 0
A97: 0096 | B97: 2620 | C97: L-2605 | D97: オフライン | E97: 1 | F97: 5 | G97: 1 | H97: 1 | I97: 電灯 | J97: kWh | L97: a接点 | M97: 0 | N97: 監視なし | Q97: 監視なし | V97: 201601521 | W97: 47484 | X97: 25503 | Y97: 25503 | Z97: 0 | AA97: 700 | AB97: 正常 | AD97: 未実行 | AE97: 0 | AF97: 正常 | AG97: 正常 | AH97: 交換なし | AJ97: 0 | AK97: 0 | AL97: 0
A98: 0097 | B98: 2630 | C98: L-2630 | D98: オンライン | E98: 1-1-7---8 | F98: 5 | G98: 1 | H98: 1 | I98: 電灯 | J98: kWh | L98: a接点 | M98: 0 | N98: 監視なし | Q98: 監視なし | T98: 0063 | U98: Folli Follie | V98: 201601515 | W98: 47484 | X98: 80900 | Y98: 79185 | Z98: 1715 | AA98: 1551 | AB98: 正常 | AC98: 2025年02月01日 | AD98: 実行済み | AE98: 110.57 | AF98: 正常 | AG98: 正常 | AH98: 交換なし | AJ98: 0 | AK98: 0 | AL98: 0
A99: 0098 | B99: 2635 | C99: L-2607 | D99: オンライン | E99: 1-1-7---9 | F99: 5 | G99: 1 | H99: 1 | I99: 電灯 | J99: kWh | L99: a接点 | M99: 0 | N99: 監視なし | Q99: 監視なし | T99: 0064 | U99: LEGO CLICK BRICK | V99: 23A038221 | W99: 47788 | X99: 26211 | Y99: 24269 | Z99: 1942 | AA99: 1943 | AB99: 正常 | AC99: 2025年02月01日 | AD99: 実行済み | AE99: 99.95 | AF99: 正常 | AG99: 正常 | AH99: 交換なし | AJ99: 0 | AK99: 0 | AL99: 0
A100: 0099 | B100: 2640 | C100: L-2609 | D100: オンライン | E100: 1-1-7---10 | F100: 5 | G100: 1 | H100: 1 | I100: 電灯 | J100: kWh | L100: a接点 | M100: 0 | N100: 監視なし | Q100: 監視なし | T100: 0063 | U100: Folli Follie | V100: 500101 | W100: 46266 | X100: 86029 | Y100: 86012 | Z100: 17 | AA100: 29 | AB100: 正常 | AC100: 2025年02月01日 | AD100: 実行済み | AE100: 58.62 | AF100: 正常 | AG100: 正常 | AH100: 交換なし | AJ100: 0 | AK100: 0 | AL100: 0
A101: 0100 | B101: 2640 | C101: P-2640 | D101: オンライン | E101: 1-1-7---11 | F101: 5 | G101: 1 | H101: 2 | I101: 動力 | J101: kWh | L101: a接点 | M101: 0 | N101: 監視なし | Q101: 監視なし | T101: 0063 | U101: Folli Follie | V101: 203523 | W101: 46266 | X101: 74030 | Y101: 74030 | Z101: 0 | AA101: 0 | AB101: 正常 | AC101: 2025年02月01日 | AD101: 実行済み | AE101: 0 | AF101: 正常 | AG101: 正常 | AH101: 交換なし | AJ101: 0 | AK101: 0 | AL101: 0
A102: 0101 | B102: 1600 | C102: L-1600 | D102: オンライン | E102: 1-1-8---1 | F102: 5 | G102: 1 | H102: 1 | I102: 電灯 | J102: kWh | L102: a接点 | M102: 0 | N102: 監視なし | Q102: 監視なし | T102: 0066 | U102: adidas | V102: 23A038301 | W102: 47788 | X102: 49492 | Y102: 45623 | Z102: 3869 | AA102: 3825 | AB102: 正常 | AC102: 2025年02月01日 | AD102: 実行済み | AE102: 101.15 | AF102: 正常 | AG102: 正常 | AH102: 交換なし | AJ102: 0 | AK102: 0 | AL102: 0
A103: 0102 | B103: 1605 | C103: L-1601 | D103: オンライン | E103: 1-1-8---2 | F103: 5 | G103: 1 | H103: 1 | I103: 電灯 | J103: kWh | L103: a接点 | M103: 0 | N103: 監視なし | Q103: 監視なし | T103: 0144 | U103: BANANA REPUBLIC | V103: 23A038308 | W103: 47788 | X103: 47098 | Y103: 43532 | Z103: 3566 | AA103: 3558 | AB103: 正常 | AC103: 2025年02月01日 | AD103: 実行済み | AE103: 100.22 | AF103: 正常 | AG103: 正常 | AH103: 交換なし | AJ103: 0 | AK103: 0 | AL103: 0
A104: 0103 | B104: 1600 | C104: L-1602 | D104: オンライン | E104: 1-1-8---3 | F104: 5 | G104: 1 | H104: 1 | I104: 電灯 | J104: kWh | L104: a接点 | M104: 0 | N104: 監視なし | Q104: 監視なし | T104: 0066 | U104: adidas | V104: 23A038309 | W104: 47788 | X104: 37135 | Y104: 34294 | Z104: 2841 | AA104: 2792 | AB104: 正常 | AC104: 2025年02月01日 | AD104: 実行済み | AE104: 101.76 | AF104: 正常 | AG104: 正常 | AH104: 交換なし | AJ104: 0 | AK104: 0 | AL104: 0
A105: 0104 | B105: 1600 | C105: L-1603 | D105: オンライン | E105: 1-1-8---4 | F105: 5 | G105: 1 | H105: 1 | I105: 電灯 | J105: kWh | L105: a接点 | M105: 0 | N105: 監視なし | Q105: 監視なし | T105: 0066 | U105: adidas | V105: 23A038310 | W105: 47788 | X105: 27281 | Y105: 25241 | Z105: 2040 | AA105: 1968 | AB105: 正常 | AC105: 2025年02月01日 | AD105: 実行済み | AE105: 103.66 | AF105: 正常 | AG105: 正常 | AH105: 交換なし | AJ105: 0 | AK105: 0 | AL105: 0
A106: 0105 | B106: 1600 | C106: L-1603 | D106: オンライン | E106: 1-1-8---5 | F106: 5 | G106: 1 | H106: 2 | I106: 動力 | J106: kWh | L106: a接点 | M106: 0 | N106: 監視なし | Q106: 監視なし | T106: 0066 | U106: adidas | V106: 201600679 | W106: 47484 | X106: 2022 | Y106: 1982 | Z106: 40 | AA106: 38 | AB106: 正常 | AC106: 2025年02月01日 | AD106: 実行済み | AE106: 105.26 | AF106: 正常 | AG106: 正常 | AH106: 交換なし | AJ106: 0 | AK106: 0 | AL106: 0
A107: 0106 | B107: 1700 | C107: L-1604 | D107: オンライン | E107: 1-1-8---6 | F107: 5 | G107: 1 | H107: 1 | I107: 電灯 | J107: kWh | L107: a接点 | M107: 0 | N107: 監視なし | Q107: 監視なし | T107: 0067 | U107: WORLD GOURMENT JUNCTION | V107: 201601495 | W107: 47484 | X107: 14183 | Y107: 13857 | Z107: 326 | AA107: 311 | AB107: 正常 | AC107: 2025年02月01日 | AD107: 実行済み | AE107: 104.82 | AF107: 正常 | AG107: 正常 | AH107: 交換なし | AJ107: 0 | AK107: 0 | AL107: 0
A108: 0107 | B108: 1700 | C108: L-1604 | D108: オンライン | E108: 1-1-8---7 | F108: 5 | G108: 1 | H108: 2 | I108: 動力 | J108: kWh | L108: a接点 | M108: 0 | N108: 監視なし | Q108: 監視なし | T108: 0067 | U108: WORLD GOURMENT JUNCTION | V108: 201601617 | W108: 47484 | X108: 11903 | Y108: 8726 | Z108: 3177 | AA108: 3310 | AB108: 正常 | AC108: 2025年02月01日 | AD108: 実行済み | AE108: 95.98 | AF108: 正常 | AG108: 正常 | AH108: 交換なし | AJ108: 0 | AK108: 0 | AL108: 0
A109: 0108 | B109: 1700 | C109: L-1605 | D109: オンライン | E109: 1-1-8---8 | F109: 5 | G109: 1 | H109: 1 | I109: 電灯 | J109: kWh | L109: a接点 | M109: 0 | N109: 監視なし | Q109: 監視なし | T109: 0067 | U109: WORLD GOURMENT JUNCTION | V109: 201601499 | W109: 47484 | X109: 78030 | Y109: 76794 | Z109: 1236 | AA109: 1229 | AB109: 正常 | AC109: 2025年02月01日 | AD109: 実行済み | AE109: 100.57 | AF109: 正常 | AG109: 正常 | AH109: 交換なし | AJ109: 0 | AK109: 0 | AL109: 0
... A121: 0120 | B121: 1630 | C121: L-1611 | D121: オンライン | E121: 1-1-8---20 | F121: 5 | G121: 1 | H121: 2 | I121: 動力 | J121: kWh | L121: a接点 | M121: 0 | N121: 監視なし | Q121: 監視なし | T121: 0070 | U121: St.Cousair | V121: 635360 | W121: 47484 | X121: 38751 | Y121: 38453 | Z121: 298 | AA121: 300 | AB121: 正常 | AC121: 2025年02月01日 | AD121: 実行済み | AE121: 99.33 | AF121: 正常 | AG121: 正常 | AH121: 交換なし | AJ121: 0 | AK121: 0 | AL121: 0
A122: 0121 | C122: L-1611a | D122: オンライン | E122: 1-1-8---21 | F122: 5 | G122: 1 | H122: 1 | I122: 電灯 | J122: kWh | L122: a接点 | M122: 0 | N122: 監視なし | Q122: 監視なし | V122: 2094341 | W122: 40483 | X122: 11336 | Y122: 11336 | Z122: 0 | AA122: 0 | AB122: 正常 | AC122: 2025年02月01日 | AD122: 実行済み | AE122: 0 | AF122: 正常 | AG122: 正常 | AH122: 交換なし | AJ122: 0 | AK122: 0 | AL122: 0
A123: 0122 | C123: L-1611a | D123: オンライン | E123: 1-1-8---22 | F123: 5 | G123: 1 | H123: 2 | I123: 動力 | J123: kWh | L123: a接点 | M123: 0 | N123: 監視なし | Q123: 監視なし | V123: 382499 | W123: 40483 | X123: 1842 | Y123: 1842 | Z123: 0 | AA123: 0 | AB123: 正常 | AC123: 2025年02月01日 | AD123: 実行済み | AE123: 0 | AF123: 正常 | AG123: 正常 | AH123: 交換なし | AJ123: 0 | AK123: 0 | AL123: 0
A124: 0123 | C124: 6L-2 | D124: オンライン | E124: 1-1-3---12 | F124: 5 | G124: 1 | H124: 1 | I124: 電灯 | J124: kWh | L124: a接点 | M124: 0 | N124: 監視なし | Q124: 監視なし | V124: 341023 | W124: 40422 | X124: 18184 | Y124: 18184 | Z124: 0 | AA124: 0 | AB124: 正常 | AC124: 2025年02月01日 | AD124: 実行済み | AE124: 0 | AF124: 正常 | AG124: 正常 | AH124: 交換なし | AJ124: 0 | AK124: 0 | AL124: 0
A125: 0124 | B125: 1530 | C125: L-1700 | D125: オンライン | E125: 1-1-9---1 | F125: 5 | G125: 1 | H125: 1 | I125: 電灯 | J125: kWh | L125: a接点 | M125: 0 | N125: 監視なし | Q125: 監視なし | T125: 0071 | U125: BALLY | V125: 222607222 | W125: 48245 | X125: 31744 | Y125: 30792 | Z125: 952 | AA125: 939 | AB125: 正常 | AC125: 2025年02月01日 | AD125: 実行済み | AE125: 101.38 | AF125: 正常 | AG125: 正常 | AH125: 交換なし | AJ125: 0 | AK125: 0 | AL125: 0
A126: 0125 | B126: 1705 | C126: L-1701 | D126: オンライン | E126: 1-1-9---2 | F126: 5 | G126: 1 | H126: 1 | I126: 電灯 | J126: kWh | L126: a接点 | M126: 0 | N126: 監視なし | Q126: 監視なし | T126: 0072 | U126: Camper | V126: 222607207 | W126: 48245 | X126: 52726 | Y126: 51069 | Z126: 1657 | AA126: 1632 | AB126: 正常 | AC126: 2025年02月01日 | AD126: 実行済み | AE126: 101.53 | AF126: 正常 | AG126: 正常 | AH126: 交換なし | AJ126: 0 | AK126: 0 | AL126: 0
A127: 0126 | B127: 1710 | C127: L-1702 | D127: オンライン | E127: 1-1-9---3 | F127: 5 | G127: 1 | H127: 1 | I127: 電灯 | J127: kWh | L127: a接点 | M127: 0 | N127: 監視なし | Q127: 監視なし | T127: 0073 | U127: LANVIN | V127: 222607212 | W127: 48245 | X127: 32930 | Y127: 31911 | Z127: 1019 | AA127: 1008 | AB127: 正常 | AC127: 2025年02月01日 | AD127: 実行済み | AE127: 101.09 | AF127: 正常 | AG127: 正常 | AH127: 交換なし | AJ127: 0 | AK127: 0 | AL127: 0
A128: 0127 | B128: 1715 | C128: L-1703 | D128: オンライン | E128: 1-1-9---4 | F128: 5 | G128: 1 | H128: 1 | I128: 電灯 | J128: kWh | L128: a接点 | M128: 0 | N128: 監視なし | Q128: 監視なし | T128: 0074 | U128: LE CREUSET | V128: 222607223 | W128: 48245 | X128: 42471 | Y128: 41659 | Z128: 812 | AA128: 785 | AB128: 正常 | AC128: 2025年02月01日 | AD128: 実行済み | AE128: 103.44 | AF128: 正常 | AG128: 正常 | AH128: 交換なし | AJ128: 0 | AK128: 0 | AL128: 0
A129: 0128 | B129: 1720 | C129: L-1704 | D129: オンライン | E129: 1-1-9---5 | F129: 5 | G129: 1 | H129: 1 | I129: 電灯 | J129: kWh | L129: a接点 | M129: 0 | N129: 監視なし | Q129: 監視なし | T129: 0075 | U129: たち吉 | V129: 222607226 | W129: 48245 | X129: 20352 | Y129: 19758 | Z129: 594 | AA129: 565 | AB129: 正常 | AC129: 2025年02月01日 | AD129: 実行済み | AE129: 105.13 | AF129: 正常 | AG129: 正常 | AH129: 交換なし | AJ129: 0 | AK129: 0 | AL129: 0
A130: 0129 | B130: 2700 | C130: L-2700 | D130: オンライン | E130: 1-1-9---6 | F130: 5 | G130: 1 | H130: 1 | I130: 電灯 | J130: kWh | L130: a接点 | M130: 0 | N130: 監視なし | Q130: 監視なし | T130: 0076 | U130: Jill by Jill Stuart | V130: 222607231 | W130: 48245 | X130: 42545 | Y130: 41406 | Z130: 1139 | AA130: 1196 | AB130: 正常 | AC130: 2025年02月01日 | AD130: 実行済み | AE130: 95.23 | AF130: 正常 | AG130: 正常 | AH130: 交換なし | AJ130: 0 | AK130: 0 | AL130: 0
A131: 0130 | B131: 2705 | C131: L-2701 | D131: オンライン | E131: 1-1-9---7 | F131: 5 | G131: 1 | H131: 1 | I131: 電灯 | J131: kWh | L131: a接点 | M131: 0 | N131: 監視なし | Q131: 監視なし | T131: 0077 | U131: AIGLE | V131: 222607218 | W131: 48245 | X131: 80010 | Y131: 77700 | Z131: 2310 | AA131: 2407 | AB131: 正常 | AC131: 2025年02月01日 | AD131: 実行済み | AE131: 95.97 | AF131: 正常 | AG131: 正常 | AH131: 交換なし | AJ131: 0 | AK131: 0 | AL131: 0
A132: 0131 | B132: 2710 | C132: L-2702 | D132: オンライン | E132: 1-1-9---8 | F132: 5 | G132: 1 | H132: 1 | I132: 電灯 | J132: kWh | L132: a接点 | M132: 0 | N132: 監視なし | Q132: 監視なし | T132: 0078 | U132: le coq sportif | V132: 222607263 | W132: 48245 | X132: 25106 | Y132: 24151 | Z132: 955 | AA132: 917 | AB132: 正常 | AC132: 2025年02月01日 | AD132: 実行済み | AE132: 104.14 | AF132: 正常 | AG132: 正常 | AH132: 交換なし | AJ132: 0 | AK132: 0 | AL132: 0
A133: 0132 | B133: 2715 | C133: L-2703 | D133: オンライン | E133: 1-1-9---9 | F133: 5 | G133: 1 | H133: 1 | I133: 電灯 | J133: kWh | L133: a接点 | M133: 0 | N133: 監視なし | Q133: 監視なし | T133: 0079 | U133: Birkenstock | V133: 222500440 | W133: 48245 | X133: 57393 | Y133: 55680 | Z133: 1713 | AA133: 1679 | AB133: 正常 | AC133: 2025年02月01日 | AD133: 実行済み | AE133: 102.03 | AF133: 正常 | AG133: 正常 | AH133: 交換なし | AJ133: 0 | AK133: 0 | AL133: 0
...

Sheet 計量種別
A1: 計量種別番号 | B1: 計量種別名称 | C1: 基本料金 | D1: 基本量 | E1: 単位 | F1: 従量単価１ | G1: 従量単価２ | H1: 従量単価３ | I1: 従量１ | J1: 従量２ | K1: 検針使用量チェック | L1: 検針使用量上限値 | M1: 検針使用量下限値 | N1: 検針前回比チェック | O1: 検針前回比上限比(%) | P1: 検針前回比下限比(%) | Q1: 時間使用量チェック | R1: 時間使用量上限値 | S1: 時間使用量下限値 | T1: 時間使用量異常監視時間帯
A2: 1 | B2: 電灯 | E2: kWh | K2: 0 | N2: 0 | Q2: 0 | T2: 0
A3: 2 | B3: 動力 | E3: kWh | K3: 0 | N3: 0 | Q3: 0 | T3: 0
A4: 3 | B4: 水道 | E4: m3 | K4: 0 | N4: 0 | Q4: 0 | T4: 0
A5: 4 | B5: ガス | E5: m3 | K5: 0 | N5: 0 | Q5: 0 | T5: 0
A6: 5 | B6: 空調動力 | E6: kWh | K6: 0 | N6: 0 | Q6: 0 | T6: 0

Sheet テナント検針
A1: メータ番号 | B1: 管理番号 | C1: 備考 | D1: 製造番号 | E1: 計量種別 | F1: 計量乗率 | G1: 接点形式 | H1: 検針桁数 | I1: 計量区分 | J1: 補正料金 | K1: 検定有効期限 | L1: 今回指示数 | M1: 前回指示数 | N1: 今回使用量 | O1: 前回使用量 | P1: 今回検針日 | Q1: 今回検針結果 | R1: 検針完了ﾌﾗｸﾞ | S1: 交換工程の有無 | T1: 交換時の検針日 | U1: 交換前今回指示数 | V1: 交換前前回指示数 | W1: 交換前使用量
A2: =検針結果!A2 -> 0001 | B2: =検針結果!B2 -> 1100 | C2: =検針結果!C2 -> L-1100 | D2: =検針結果!V2 -> 23A038241 | E2: =検針結果!I2 -> 電灯 | F2: =検針結果!G2 -> 1 | G2: =検針結果!L2 -> a接点 | H2: =検針結果!F2 -> 5 | I2: =検針結果!D2 -> オンライン | J2: =検針結果!M2 -> 0 | K2: =検針結果!W2 -> 47788 | L2: =検針結果!X2 -> 29197 | M2: =検針結果!Y2 -> 26606 | N2: =検針結果!Z2 -> 2591 | O2: =検針結果!AA2 -> 2533 | P2: =検針結果!AC2 -> 2025年02月01日 | Q2: =検針結果!AB2 -> 正常 | R2: =検針結果!AD2 -> 実行済み | S2: =検針結果!AH2 -> 交換なし | T2: =検針結果!AI2 -> 0 | U2: =検針結果!AJ2 -> 0 | V2: =検針結果!AK2 -> 0 | W2: =検針結果!AL2 -> 0
A3: =検針結果!A3 -> 0002 | B3: =検針結果!B3 -> 1100 | C3: =検針結果!C3 -> L-1101 | D3: =検針結果!V3 -> 23A038245 | E3: =検針結果!I3 -> 電灯 | F3: =検針結果!G3 -> 1 | G3: =検針結果!L3 -> a接点 | H3: =検針結果!F3 -> 5 | I3: =検針結果!D3 -> オンライン | J3: =検針結果!M3 -> 0 | K3: =検針結果!W3 -> 47788 | L3: =検針結果!X3 -> 18363 | M3: =検針結果!Y3 -> 16800 | N3: =検針結果!Z3 -> 1563 | O3: =検針結果!AA3 -> 1544 | P3: =検針結果!AC3 -> 2025年02月01日 | Q3: =検針結果!AB3 -> 正常 | R3: =検針結果!AD3 -> 実行済み | S3: =検針結果!AH3 -> 交換なし | T3: =検針結果!AI3 -> 0 | U3: =検針結果!AJ3 -> 0 | V3: =検針結果!AK3 -> 0 | W3: =検針結果!AL3 -> 0
A4: =検針結果!A4 -> 0003 | B4: =検針結果!B4 -> 1110 | C4: =検針結果!C4 -> L-1102 | D4: =検針結果!V4 -> 23A038248 | E4: =検針結果!I4 -> 電灯 | F4: =検針結果!G4 -> 1 | G4: =検針結果!L4 -> a接点 | H4: =検針結果!F4 -> 5 | I4: =検針結果!D4 -> オンライン | J4: =検針結果!M4 -> 0 | K4: =検針結果!W4 -> 47788 | L4: =検針結果!X4 -> 19898 | M4: =検針結果!Y4 -> 18246 | N4: =検針結果!Z4 -> 1652 | O4: =検針結果!AA4 -> 1667 | P4: =検針結果!AC4 -> 2025年02月01日 | Q4: =検針結果!AB4 -> 正常 | R4: =検針結果!AD4 -> 実行済み | S4: =検針結果!AH4 -> 交換なし | T4: =検針結果!AI4 -> 0 | U4: =検針結果!AJ4 -> 0 | V4: =検針結果!AK4 -> 0 | W4: =検針結果!AL4 -> 0
A5: =検針結果!A5 -> 0004 | B5: =検針結果!B5 -> 1115 | C5: =検針結果!C5 -> L-1103 | D5: =検針結果!V5 -> 23A038242 | E5: =検針結果!I5 -> 電灯 | F5: =検針結果!G5 -> 1 | G5: =検針結果!L5 -> a接点 | H5: =検針結果!F5 -> 5 | I5: =検針結果!D5 -> オンライン | J5: =検針結果!M5 -> 0 | K5: =検針結果!W5 -> 47788 | L5: =検針結果!X5 -> 42510 | M5: =検針結果!Y5 -> 38804 | N5: =検針結果!Z5 -> 3706 | O5: =検針結果!AA5 -> 3670 | P5: =検針結果!AC5 -> 2025年02月01日 | Q5: =検針結果!AB5 -> 正常 | R5: =検針結果!AD5 -> 実行済み | S5: =検針結果!AH5 -> 交換なし | T5: =検針結果!AI5 -> 0 | U5: =検針結果!AJ5 -> 0 | V5: =検針結果!AK5 -> 0 | W5: =検針結果!AL5 -> 0
A6: =検針結果!A6 -> 0005 | B6: =検針結果!B6 -> 1120 | C6: =検針結果!C6 -> L-1104 | D6: =検針結果!V6 -> 23A038249 | E6: =検針結果!I6 -> 電灯 | F6: =検針結果!G6 -> 1 | G6: =検針結果!L6 -> a接点 | H6: =検針結果!F6 -> 5 | I6: =検針結果!D6 -> オンライン | J6: =検針結果!M6 -> 0 | K6: =検針結果!W6 -> 47788 | L6: =検針結果!X6 -> 25718 | M6: =検針結果!Y6 -> 23532 | N6: =検針結果!Z6 -> 2186 | O6: =検針結果!AA6 -> 2151 | P6: =検針結果!AC6 -> 2025年02月01日 | Q6: =検針結果!AB6 -> 正常 | R6: =検針結果!AD6 -> 実行済み | S6: =検針結果!AH6 -> 交換なし | T6: =検針結果!AI6 -> 0 | U6: =検針結果!AJ6 -> 0 | V6: =検針結果!AK6 -> 0 | W6: =検針結果!AL6 -> 0
A7: =検針結果!A7 -> 0006 | B7: =検針結果!B7 -> 1125 | C7: =検針結果!C7 -> L-1105 | D7: =検針結果!V7 -> 23A038244 | E7: =検針結果!I7 -> 電灯 | F7: =検針結果!G7 -> 1 | G7: =検針結果!L7 -> a接点 | H7: =検針結果!F7 -> 5 | I7: =検針結果!D7 -> オンライン | J7: =検針結果!M7 -> 0 | K7: =検針結果!W7 -> 47788 | L7: =検針結果!X7 -> 12530 | M7: =検針結果!Y7 -> 11453 | N7: =検針結果!Z7 -> 1077 | O7: =検針結果!AA7 -> 1046 | P7: =検針結果!AC7 -> 2025年02月01日 | Q7: =検針結果!AB7 -> 正常 | R7: =検針結果!AD7 -> 実行済み | S7: =検針結果!AH7 -> 交換なし | T7: =検針結果!AI7 -> 0 | U7: =検針結果!AJ7 -> 0 | V7: =検針結果!AK7 -> 0 | W7: =検針結果!AL7 -> 0
A8: =検針結果!A8 -> 0007 | B8: =検針結果!B8 -> 1130 | C8: =検針結果!C8 -> L-1106 | D8: =検針結果!V8 -> 23A038258 | E8: =検針結果!I8 -> 電灯 | F8: =検針結果!G8 -> 1 | G8: =検針結果!L8 -> a接点 | H8: =検針結果!F8 -> 5 | I8: =検針結果!D8 -> オンライン | J8: =検針結果!M8 -> 0 | K8: =検針結果!W8 -> 47788 | L8: =検針結果!X8 -> 16805 | M8: =検針結果!Y8 -> 15362 | N8: =検針結果!Z8 -> 1443 | O8: =検針結果!AA8 -> 1410 | P8: =検針結果!AC8 -> 2025年02月01日 | Q8: =検針結果!AB8 -> 正常 | R8: =検針結果!AD8 -> 実行済み | S8: =検針結果!AH8 -> 交換なし | T8: =検針結果!AI8 -> 0 | U8: =検針結果!AJ8 -> 0 | V8: =検針結果!AK8 -> 0 | W8: =検針結果!AL8 -> 0
A9: =検針結果!A9 -> 0008 | B9: =検針結果!B9 -> 1135 | C9: =検針結果!C9 -> L-1107 | D9: =検針結果!V9 -> 23A038252 | E9: =検針結果!I9 -> 電灯 | F9: =検針結果!G9 -> 1 | G9: =検針結果!L9 -> a接点 | H9: =検針結果!F9 -> 5 | I9: =検針結果!D9 -> オンライン | J9: =検針結果!M9 -> 0 | K9: =検針結果!W9 -> 47788 | L9: =検針結果!X9 -> 19032 | M9: =検針結果!Y9 -> 17437 | N9: =検針結果!Z9 -> 1595 | O9: =検針結果!AA9 -> 1588 | P9: =検針結果!AC9 -> 2025年02月01日 | Q9: =検針結果!AB9 -> 正常 | R9: =検針結果!AD9 -> 実行済み | S9: =検針結果!AH9 -> 交換なし | T9: =検針結果!AI9 -> 0 | U9: =検針結果!AJ9 -> 0 | V9: =検針結果!AK9 -> 0 | W9: =検針結果!AL9 -> 0
A10: =検針結果!A10 -> 0009 | B10: =検針結果!B10 -> 1140 | C10: =検針結果!C10 -> L-1108 | D10: =検針結果!V10 -> 23A038255 | E10: =検針結果!I10 -> 電灯 | F10: =検針結果!G10 -> 1 | G10: =検針結果!L10 -> a接点 | H10: =検針結果!F10 -> 5 | I10: =検針結果!D10 -> オンライン | J10: =検針結果!M10 -> 0 | K10: =検針結果!W10 -> 47788 | L10: =検針結果!X10 -> 13685 | M10: =検針結果!Y10 -> 12579 | N10: =検針結果!Z10 -> 1106 | O10: =検針結果!AA10 -> 1097 | P10: =検針結果!AC10 -> 2025年02月01日 | Q10: =検針結果!AB10 -> 正常 | R10: =検針結果!AD10 -> 実行済み | S10: =検針結果!AH10 -> 交換なし | T10: =検針結果!AI10 -> 0 | U10: =検針結果!AJ10 -> 0 | V10: =検針結果!AK10 -> 0 | W10: =検針結果!AL10 -> 0
A11: =検針結果!A11 -> 0010 | B11: =検針結果!B11 -> 1145 | C11: =検針結果!C11 -> L-1109 | D11: =検針結果!V11 -> 23A038253 | E11: =検針結果!I11 -> 電灯 | F11: =検針結果!G11 -> 1 | G11: =検針結果!L11 -> a接点 | H11: =検針結果!F11 -> 5 | I11: =検針結果!D11 -> オンライン | J11: =検針結果!M11 -> 0 | K11: =検針結果!W11 -> 47788 | L11: =検針結果!X11 -> 39565 | M11: =検針結果!Y11 -> 36204 | N11: =検針結果!Z11 -> 3361 | O11: =検針結果!AA11 -> 3361 | P11: =検針結果!AC11 -> 2025年02月01日 | Q11: =検針結果!AB11 -> 正常 | R11: =検針結果!AD11 -> 実行済み | S11: =検針結果!AH11 -> 交換なし | T11: =検針結果!AI11 -> 0 | U11: =検針結果!AJ11 -> 0 | V11: =検針結果!AK11 -> 0 | W11: =検針結果!AL11 -> 0
A12: =検針結果!A12 -> 0011 | B12: =検針結果!B12 -> 1150 | C12: =検針結果!C12 -> L-1110 | D12: =検針結果!V12 -> 23A038239 | E12: =検針結果!I12 -> 電灯 | F12: =検針結果!G12 -> 1 | G12: =検針結果!L12 -> a接点 | H12: =検針結果!F12 -> 5 | I12: =検針結果!D12 -> オンライン | J12: =検針結果!M12 -> 0 | K12: =検針結果!W12 -> 47788 | L12: =検針結果!X12 -> 19930 | M12: =検針結果!Y12 -> 18238 | N12: =検針結果!Z12 -> 1692 | O12: =検針結果!AA12 -> 1680 | P12: =検針結果!AC12 -> 2025年02月01日 | Q12: =検針結果!AB12 -> 正常 | R12: =検針結果!AD12 -> 実行済み | S12: =検針結果!AH12 -> 交換なし | T12: =検針結果!AI12 -> 0 | U12: =検針結果!AJ12 -> 0 | V12: =検針結果!AK12 -> 0 | W12: =検針結果!AL12 -> 0
A13: =検針結果!A13 -> 0012 | B13: =検針結果!B13 -> 2105 | C13: =検針結果!C13 -> L-2100 | D13: =検針結果!V13 -> 23A038257 | E13: =検針結果!I13 -> 電灯 | F13: =検針結果!G13 -> 1 | G13: =検針結果!L13 -> a接点 | H13: =検針結果!F13 -> 5 | I13: =検針結果!D13 -> オンライン | J13: =検針結果!M13 -> 0 | K13: =検針結果!W13 -> 47788 | L13: =検針結果!X13 -> 25788 | M13: =検針結果!Y13 -> 23632 | N13: =検針結果!Z13 -> 2156 | O13: =検針結果!AA13 -> 2142 | P13: =検針結果!AC13 -> 2025年02月01日 | Q13: =検針結果!AB13 -> 正常 | R13: =検針結果!AD13 -> 実行済み | S13: =検針結果!AH13 -> 交換なし | T13: =検針結果!AI13 -> 0 | U13: =検針結果!AJ13 -> 0 | V13: =検針結果!AK13 -> 0 | W13: =検針結果!AL13 -> 0
... A265: =検針結果!A265 -> 0275 | B265: =検針結果!B265 -> WC5 | C265: =検針結果!C265 -> 2F女子WC | D265: =検針結果!V265 -> 0 | E265: =検針結果!I265 -> 水道 | F265: =検針結果!G265 -> 1 | G265: =検針結果!L265 -> a接点 | H265: =検針結果!F265 -> 6 | I265: =検針結果!D265 -> オンライン | J265: =検針結果!M265 -> 0 | K265: =検針結果!W265 -> 0 | L265: =検針結果!X265 -> 23095 | M265: =検針結果!Y265 -> 22800 | N265: =検針結果!Z265 -> 295 | O265: =検針結果!AA265 -> 208 | P265: =検針結果!AC265 -> 2025年02月01日 | Q265: =検針結果!AB265 -> 正常 | R265: =検針結果!AD265 -> 実行済み | S265: =検針結果!AH265 -> 交換なし | T265: =検針結果!AI265 -> 0 | U265: =検針結果!AJ265 -> 0 | V265: =検針結果!AK265 -> 0 | W265: =検針結果!AL265 -> 0
A271: =検針結果!A266 -> 0283 | B271: =検針結果!B266 -> 6100 | C271: =検針結果!C266 -> L-6100 | D271: =検針結果!V266 -> 222702659 | E271: =検針結果!I266 -> 電灯 | F271: =検針結果!G266 -> 1 | G271: =検針結果!L266 -> a接点 | H271: =検針結果!F266 -> 5 | I271: =検針結果!D266 -> オンライン | J271: =検針結果!M266 -> 0 | K271: =検針結果!W266 -> 48245 | L271: =検針結果!X266 -> 57943 | M271: =検針結果!Y266 -> 56209 | N271: =検針結果!Z266 -> 1734 | O271: =検針結果!AA266 -> 1693 | P271: =検針結果!AC266 -> 2025年02月01日 | Q271: =検針結果!AB266 -> 正常 | R271: =検針結果!AD266 -> 実行済み | S271: =検針結果!AH266 -> 交換なし | T271: =検針結果!AI266 -> 0 | U271: =検針結果!AJ266 -> 0 | V271: =検針結果!AK266 -> 0 | W271: =検針結果!AL266 -> 0
A272: =検針結果!A267 -> 0284 | B272: =検針結果!B267 -> 6105 | C272: =検針結果!C267 -> L-6105 | D272: =検針結果!V267 -> 222702679 | E272: =検針結果!I267 -> 電灯 | F272: =検針結果!G267 -> 1 | G272: =検針結果!L267 -> a接点 | H272: =検針結果!F267 -> 5 | I272: =検針結果!D267 -> オンライン | J272: =検針結果!M267 -> 0 | K272: =検針結果!W267 -> 48245 | L272: =検針結果!X267 -> 47884 | M272: =検針結果!Y267 -> 46656 | N272: =検針結果!Z267 -> 1228 | O272: =検針結果!AA267 -> 1265 | P272: =検針結果!AC267 -> 2025年02月01日 | Q272: =検針結果!AB267 -> 正常 | R272: =検針結果!AD267 -> 実行済み | S272: =検針結果!AH267 -> 交換なし | T272: =検針結果!AI267 -> 0 | U272: =検針結果!AJ267 -> 0 | V272: =検針結果!AK267 -> 0 | W272: =検針結果!AL267 -> 0
A273: =検針結果!A268 -> 0285 | B273: =検針結果!B268 -> 6110 | C273: =検針結果!C268 -> L-6110 | D273: =検針結果!V268 -> 222702720 | E273: =検針結果!I268 -> 電灯 | F273: =検針結果!G268 -> 1 | G273: =検針結果!L268 -> a接点 | H273: =検針結果!F268 -> 5 | I273: =検針結果!D268 -> オンライン | J273: =検針結果!M268 -> 0 | K273: =検針結果!W268 -> 48245 | L273: =検針結果!X268 -> 61802 | M273: =検針結果!Y268 -> 60118 | N273: =検針結果!Z268 -> 1684 | O273: =検針結果!AA268 -> 1658 | P273: =検針結果!AC268 -> 2025年02月01日 | Q273: =検針結果!AB268 -> 正常 | R273: =検針結果!AD268 -> 実行済み | S273: =検針結果!AH268 -> 交換なし | T273: =検針結果!AI268 -> 0 | U273: =検針結果!AJ268 -> 0 | V273: =検針結果!AK268 -> 0 | W273: =検針結果!AL268 -> 0
A274: =検針結果!A269 -> 0286 | B274: =検針結果!B269 -> 6300 | C274: =検針結果!C269 -> L-6300-1 | D274: =検針結果!V269 -> 221700519 | E274: =検針結果!I269 -> 電灯 | F274: =検針結果!G269 -> 1 | G274: =検針結果!L269 -> a接点 | H274: =検針結果!F269 -> 5 | I274: =検針結果!D269 -> オンライン | J274: =検針結果!M269 -> 0 | K274: =検針結果!W269 -> 48245 | L274: =検針結果!X269 -> 20712 | M274: =検針結果!Y269 -> 20110 | N274: =検針結果!Z269 -> 602 | O274: =検針結果!AA269 -> 610 | P274: =検針結果!AC269 -> 2025年02月01日 | Q274: =検針結果!AB269 -> 正常 | R274: =検針結果!AD269 -> 実行済み | S274: =検針結果!AH269 -> 交換なし | T274: =検針結果!AI269 -> 0 | U274: =検針結果!AJ269 -> 0 | V274: =検針結果!AK269 -> 0 | W274: =検針結果!AL269 -> 0
A275: =検針結果!A270 -> 0287 | B275: =検針結果!B270 -> 6300 | C275: =検針結果!C270 -> L-6300-2 | D275: =検針結果!V270 -> 222702653 | E275: =検針結果!I270 -> 電灯 | F275: =検針結果!G270 -> 1 | G275: =検針結果!L270 -> a接点 | H275: =検針結果!F270 -> 5 | I275: =検針結果!D270 -> オンライン | J275: =検針結果!M270 -> 0 | K275: =検針結果!W270 -> 48245 | L275: =検針結果!X270 -> 43952 | M275: =検針結果!Y270 -> 42537 | N275: =検針結果!Z270 -> 1415 | O275: =検針結果!AA270 -> 1398 | P275: =検針結果!AC270 -> 2025年02月01日 | Q275: =検針結果!AB270 -> 正常 | R275: =検針結果!AD270 -> 実行済み | S275: =検針結果!AH270 -> 交換なし | T275: =検針結果!AI270 -> 0 | U275: =検針結果!AJ270 -> 0 | V275: =検針結果!AK270 -> 0 | W275: =検針結果!AL270 -> 0
A276: =検針結果!A271 -> 0288 | B276: =検針結果!B271 -> 6300 | C276: =検針結果!C271 -> L-6300-3 | D276: =検針結果!V271 -> 222702680 | E276: =検針結果!I271 -> 電灯 | F276: =検針結果!G271 -> 1 | G276: =検針結果!L271 -> a接点 | H276: =検針結果!F271 -> 5 | I276: =検針結果!D271 -> オンライン | J276: =検針結果!M271 -> 0 | K276: =検針結果!W271 -> 48245 | L276: =検針結果!X271 -> 41690 | M276: =検針結果!Y271 -> 40430 | N276: =検針結果!Z271 -> 1260 | O276: =検針結果!AA271 -> 1243 | P276: =検針結果!AC271 -> 2025年02月01日 | Q276: =検針結果!AB271 -> 正常 | R276: =検針結果!AD271 -> 実行済み | S276: =検針結果!AH271 -> 交換なし | T276: =検針結果!AI271 -> 0 | U276: =検針結果!AJ271 -> 0 | V276: =検針結果!AK271 -> 0 | W276: =検針結果!AL271 -> 0
A277: =検針結果!A272 -> 0289 | B277: =検針結果!B272 -> 6313 | C277: =検針結果!C272 -> L-6313 | D277: =検針結果!V272 -> 222702687 | E277: =検針結果!I272 -> 電灯 | F277: =検針結果!G272 -> 1 | G277: =検針結果!L272 -> a接点 | H277: =検針結果!F272 -> 5 | I277: =検針結果!D272 -> オンライン | J277: =検針結果!M272 -> 0 | K277: =検針結果!W272 -> 48245 | L277: =検針結果!X272 -> 50814 | M277: =検針結果!Y272 -> 49406 | N277: =検針結果!Z272 -> 1408 | O277: =検針結果!AA272 -> 1385 | P277: =検針結果!AC272 -> 2025年02月01日 | Q277: =検針結果!AB272 -> 正常 | R277: =検針結果!AD272 -> 実行済み | S277: =検針結果!AH272 -> 交換なし | T277: =検針結果!AI272 -> 0 | U277: =検針結果!AJ272 -> 0 | V277: =検針結果!AK272 -> 0 | W277: =検針結果!AL272 -> 0
A278: =検針結果!A273 -> 0290 | B278: =検針結果!B273 -> 6315 | C278: =検針結果!C273 -> L-6315 | D278: =検針結果!V273 -> 222702694 | E278: =検針結果!I273 -> 電灯 | F278: =検針結果!G273 -> 1 | G278: =検針結果!L273 -> a接点 | H278: =検針結果!F273 -> 5 | I278: =検針結果!D273 -> オンライン | J278: =検針結果!M273 -> 0 | K278: =検針結果!W273 -> 48245 | L278: =検針結果!X273 -> 59110 | M278: =検針結果!Y273 -> 57460 | N278: =検針結果!Z273 -> 1650 | O278: =検針結果!AA273 -> 1647 | P278: =検針結果!AC273 -> 2025年02月01日 | Q278: =検針結果!AB273 -> 正常 | R278: =検針結果!AD273 -> 実行済み | S278: =検針結果!AH273 -> 交換なし | T278: =検針結果!AI273 -> 0 | U278: =検針結果!AJ273 -> 0 | V278: =検針結果!AK273 -> 0 | W278: =検針結果!AL273 -> 0
A279: =検針結果!A274 -> 0291 | B279: =検針結果!B274 -> 6320 | C279: =検針結果!C274 -> L-6320 | D279: =検針結果!V274 -> 222702712 | E279: =検針結果!I274 -> 電灯 | F279: =検針結果!G274 -> 1 | G279: =検針結果!L274 -> a接点 | H279: =検針結果!F274 -> 5 | I279: =検針結果!D274 -> オンライン | J279: =検針結果!M274 -> 0 | K279: =検針結果!W274 -> 48245 | L279: =検針結果!X274 -> 47258 | M279: =検針結果!Y274 -> 45843 | N279: =検針結果!Z274 -> 1415 | O279: =検針結果!AA274 -> 1374 | P279: =検針結果!AC274 -> 2025年02月01日 | Q279: =検針結果!AB274 -> 正常 | R279: =検針結果!AD274 -> 実行済み | S279: =検針結果!AH274 -> 交換なし | T279: =検針結果!AI274 -> 0 | U279: =検針結果!AJ274 -> 0 | V279: =検針結果!AK274 -> 0 | W279: =検針結果!AL274 -> 0
A285: =検針結果!A275 -> 0307 | B285: =検針結果!B275 -> 7300 | C285: =検針結果!C275 -> L-7300 | D285: =検針結果!V275 -> 221700522 | E285: =検針結果!I275 -> 電灯 | F285: =検針結果!G275 -> 1 | G285: =検針結果!L275 -> a接点 | H285: =検針結果!F275 -> 5 | I285: =検針結果!D275 -> オンライン | J285: =検針結果!M275 -> 0 | K285: =検針結果!W275 -> 48245 | L285: =検針結果!X275 -> 36632 | M285: =検針結果!Y275 -> 35469 | N285: =検針結果!Z275 -> 1163 | O285: =検針結果!AA275 -> 1127 | P285: =検針結果!AC275 -> 2025年02月01日 | Q285: =検針結果!AB275 -> 正常 | R285: =検針結果!AD275 -> 実行済み | S285: =検針結果!AH275 -> 交換なし | T285: =検針結果!AI275 -> 0 | U285: =検針結果!AJ275 -> 0 | V285: =検針結果!AK275 -> 0 | W285: =検針結果!AL275 -> 0
A286: =検針結果!A276 -> 0308 | B286: =検針結果!B276 -> 7305 | C286: =検針結果!C276 -> L-7305 | D286: =検針結果!V276 -> 222702684 | E286: =検針結果!I276 -> 電灯 | F286: =検針結果!G276 -> 1 | G286: =検針結果!L276 -> a接点 | H286: =検針結果!F276 -> 5 | I286: =検針結果!D276 -> オンライン | J286: =検針結果!M276 -> 0 | K286: =検針結果!W276 -> 48245 | L286: =検針結果!X276 -> 54206 | M286: =検針結果!Y276 -> 52541 | N286: =検針結果!Z276 -> 1665 | O286: =検針結果!AA276 -> 1669 | P286: =検針結果!AC276 -> 2025年02月01日 | Q286: =検針結果!AB276 -> 正常 | R286: =検針結果!AD276 -> 実行済み | S286: =検針結果!AH276 -> 交換なし | T286: =検針結果!AI276 -> 0 | U286: =検針結果!AJ276 -> 0 | V286: =検針結果!AK276 -> 0 | W286: =検針結果!AL276 -> 0
A287: =検針結果!A277 -> 0309 | B287: =検針結果!B277 -> 7310 | C287: =検針結果!C277 -> L-7310 | D287: =検針結果!V277 -> 222702691 | E287: =検針結果!I277 -> 電灯 | F287: =検針結果!G277 -> 1 | G287: =検針結果!L277 -> a接点 | H287: =検針結果!F277 -> 5 | I287: =検針結果!D277 -> オンライン | J287: =検針結果!M277 -> 0 | K287: =検針結果!W277 -> 48245 | L287: =検針結果!X277 -> 47921 | M287: =検針結果!Y277 -> 46565 | N287: =検針結果!Z277 -> 1356 | O287: =検針結果!AA277 -> 1326 | P287: =検針結果!AC277 -> 2025年02月01日 | Q287: =検針結果!AB277 -> 正常 | R287: =検針結果!AD277 -> 実行済み | S287: =検針結果!AH277 -> 交換なし | T287: =検針結果!AI277 -> 0 | U287: =検針結果!AJ277 -> 0 | V287: =検針結果!AK277 -> 0 | W287: =検針結果!AL277 -> 0
A288: =検針結果!A278 -> 0310 | B288: =検針結果!B278 -> 7315 | C288: =検針結果!C278 -> L-7315 | D288: =検針結果!V278 -> 222702664 | E288: =検針結果!I278 -> 電灯 | F288: =検針結果!G278 -> 1 | G288: =検針結果!L278 -> a接点 | H288: =検針結果!F278 -> 5 | I288: =検針結果!D278 -> オンライン | J288: =検針結果!M278 -> 0 | K288: =検針結果!W278 -> 48245 | L288: =検針結果!X278 -> 49403 | M288: =検針結果!Y278 -> 47922 | N288: =検針結果!Z278 -> 1481 | O288: =検針結果!AA278 -> 1448 | P288: =検針結果!AC278 -> 2025年02月01日 | Q288: =検針結果!AB278 -> 正常 | R288: =検針結果!AD278 -> 実行済み | S288: =検針結果!AH278 -> 交換なし | T288: =検針結果!AI278 -> 0 | U288: =検針結果!AJ278 -> 0 | V288: =検針結果!AK278 -> 0 | W288: =検針結果!AL278 -> 0
A289: =検針結果!A279 -> 0311 | B289: =検針結果!B279 -> 7320 | C289: =検針結果!C279 -> L-7320 | D289: =検針結果!V279 -> 222702715 | E289: =検針結果!I279 -> 電灯 | F289: =検針結果!G279 -> 1 | G289: =検針結果!L279 -> a接点 | H289: =検針結果!F279 -> 5 | I289: =検針結果!D279 -> オンライン | J289: =検針結果!M279 -> 0 | K289: =検針結果!W279 -> 48245 | L289: =検針結果!X279 -> 75848 | M289: =検針結果!Y279 -> 73755 | N289: =検針結果!Z279 -> 2093 | O289: =検針結果!AA279 -> 2062 | P289: =検針結果!AC279 -> 2025年02月01日 | Q289: =検針結果!AB279 -> 正常 | R289: =検針結果!AD279 -> 実行済み | S289: =検針結果!AH279 -> 交換なし | T289: =検針結果!AI279 -> 0 | U289: =検針結果!AJ279 -> 0 | V289: =検針結果!AK279 -> 0 | W289: =検針結果!AL279 -> 0
A300: =検針結果!A280 -> 0350 | B300: =検針結果!B280 -> 6100 | C300: =検針結果!C280 -> PAC-6100 | D300: =検針結果!V280 -> 062165 | E300: =検針結果!I280 -> 空調動力 | F300: =検針結果!G280 -> 1 | G300: =検針結果!L280 -> a接点 | H300: =検針結果!F280 -> 5 | I300: =検針結果!D280 -> オンライン | J300: =検針結果!M280 -> 0 | K300: =検針結果!W280 -> 46235 | L300: =検針結果!X280 -> 3696 | M300: =検針結果!Y280 -> 1473 | N300: =検針結果!Z280 -> 2223 | O300: =検針結果!AA280 -> 1491 | P300: =検針結果!AC280 -> 2025年02月01日 | Q300: =検針結果!AB280 -> 正常 | R300: =検針結果!AD280 -> 実行済み | S300: =検針結果!AH280 -> 交換なし | T300: =検針結果!AI280 -> 0 | U300: =検針結果!AJ280 -> 0 | V300: =検針結果!AK280 -> 0 | W300: =検針結果!AL280 -> 0
A301: =検針結果!A281 -> 0351 | B301: =検針結果!B281 -> 6105 | C301: =検針結果!C281 -> PAC-6105 | D301: =検針結果!V281 -> 062166 | E301: =検針結果!I281 -> 空調動力 | F301: =検針結果!G281 -> 1 | G301: =検針結果!L281 -> a接点 | H301: =検針結果!F281 -> 5 | I301: =検針結果!D281 -> オンライン | J301: =検針結果!M281 -> 0 | K301: =検針結果!W281 -> 46235 | L301: =検針結果!X281 -> 71873 | M301: =検針結果!Y281 -> 70130 | N301: =検針結果!Z281 -> 1743 | O301: =検針結果!AA281 -> 1207 | P301: =検針結果!AC281 -> 2025年02月01日 | Q301: =検針結果!AB281 -> 正常 | R301: =検針結果!AD281 -> 実行済み | S301: =検針結果!AH281 -> 交換なし | T301: =検針結果!AI281 -> 0 | U301: =検針結果!AJ281 -> 0 | V301: =検針結果!AK281 -> 0 | W301: =検針結果!AL281 -> 0
A302: =検針結果!A282 -> 0352 | B302: =検針結果!B282 -> 6110 | C302: =検針結果!C282 -> PAC-6110 | D302: =検針結果!V282 -> 062167 | E302: =検針結果!I282 -> 空調動力 | F302: =検針結果!G282 -> 1 | G302: =検針結果!L282 -> a接点 | H302: =検針結果!F282 -> 5 | I302: =検針結果!D282 -> オンライン | J302: =検針結果!M282 -> 0 | K302: =検針結果!W282 -> 46235 | L302: =検針結果!X282 -> 67392 | M302: =検針結果!Y282 -> 65277 | N302: =検針結果!Z282 -> 2115 | O302: =検針結果!AA282 -> 1699 | P302: =検針結果!AC282 -> 2025年02月01日 | Q302: =検針結果!AB282 -> 正常 | R302: =検針結果!AD282 -> 実行済み | S302: =検針結果!AH282 -> 交換なし | T302: =検針結果!AI282 -> 0 | U302: =検針結果!AJ282 -> 0 | V302: =検針結果!AK282 -> 0 | W302: =検針結果!AL282 -> 0
A303: =検針結果!A283 -> 0353 | B303: =検針結果!B283 -> 6115 | C303: =検針結果!C283 -> PAC-6115 | D303: =検針結果!V283 -> 062168 | E303: =検針結果!I283 -> 空調動力 | F303: =検針結果!G283 -> 1 | G303: =検針結果!L283 -> a接点 | H303: =検針結果!F283 -> 5 | I303: =検針結果!D283 -> オンライン | J303: =検針結果!M283 -> 0 | K303: =検針結果!W283 -> 46235 | L303: =検針結果!X283 -> 65497 | M303: =検針結果!Y283 -> 64211 | N303: =検針結果!Z283 -> 1286 | O303: =検針結果!AA283 -> 758 | P303: =検針結果!AC283 -> 2025年02月01日 | Q303: =検針結果!AB283 -> 正常 | R303: =検針結果!AD283 -> 実行済み | S303: =検針結果!AH283 -> 交換なし | T303: =検針結果!AI283 -> 0 | U303: =検針結果!AJ283 -> 0 | V303: =検針結果!AK283 -> 0 | W303: =検針結果!AL283 -> 0
A304: =検針結果!A284 -> 0354 | B304: =検針結果!B284 -> 6120 | C304: =検針結果!C284 -> PAC-6120 | D304: =検針結果!V284 -> 062169 | E304: =検針結果!I284 -> 空調動力 | F304: =検針結果!G284 -> 1 | G304: =検針結果!L284 -> a接点 | H304: =検針結果!F284 -> 5 | I304: =検針結果!D284 -> オンライン | J304: =検針結果!M284 -> 0 | K304: =検針結果!W284 -> 46235 | L304: =検針結果!X284 -> 75282 | M304: =検針結果!Y284 -> 73375 | N304: =検針結果!Z284 -> 1907 | O304: =検針結果!AA284 -> 1490 | P304: =検針結果!AC284 -> 2025年02月01日 | Q304: =検針結果!AB284 -> 正常 | R304: =検針結果!AD284 -> 実行済み | S304: =検針結果!AH284 -> 交換なし | T304: =検針結果!AI284 -> 0 | U304: =検針結果!AJ284 -> 0 | V304: =検針結果!AK284 -> 0 | W304: =検針結果!AL284 -> 0
A305: =検針結果!A285 -> 0355 | B305: =検針結果!B285 -> 6125 | C305: =検針結果!C285 -> PAC-6125 | D305: =検針結果!V285 -> 062170 | E305: =検針結果!I285 -> 空調動力 | F305: =検針結果!G285 -> 1 | G305: =検針結果!L285 -> a接点 | H305: =検針結果!F285 -> 5 | I305: =検針結果!D285 -> オンライン | J305: =検針結果!M285 -> 0 | K305: =検針結果!W285 -> 46235 | L305: =検針結果!X285 -> 69474 | M305: =検針結果!Y285 -> 68435 | N305: =検針結果!Z285 -> 1039 | O305: =検針結果!AA285 -> 847 | P305: =検針結果!AC285 -> 2025年02月01日 | Q305: =検針結果!AB285 -> 正常 | R305: =検針結果!AD285 -> 実行済み | S305: =検針結果!AH285 -> 交換なし | T305: =検針結果!AI285 -> 0 | U305: =検針結果!AJ285 -> 0 | V305: =検針結果!AK285 -> 0 | W305: =検針結果!AL285 -> 0
A306: =検針結果!A286 -> 0356 | B306: =検針結果!B286 -> 6127 | C306: =検針結果!C286 -> PAC-6127 | D306: =検針結果!V286 -> 062142 | E306: =検針結果!I286 -> 空調動力 | F306: =検針結果!G286 -> 1 | G306: =検針結果!L286 -> a接点 | H306: =検針結果!F286 -> 5 | I306: =検針結果!D286 -> オンライン | J306: =検針結果!M286 -> 0 | K306: =検針結果!W286 -> 46235 | L306: =検針結果!X286 -> 30899 | M306: =検針結果!Y286 -> 30192 | N306: =検針結果!Z286 -> 707 | O306: =検針結果!AA286 -> 629 | P306: =検針結果!AC286 -> 2025年02月01日 | Q306: =検針結果!AB286 -> 正常 | R306: =検針結果!AD286 -> 実行済み | S306: =検針結果!AH286 -> 交換なし | T306: =検針結果!AI286 -> 0 | U306: =検針結果!AJ286 -> 0 | V306: =検針結果!AK286 -> 0 | W306: =検針結果!AL286 -> 0
A307: =検針結果!A287 -> 0357 | B307: =検針結果!B287 -> 6130 | C307: =検針結果!C287 -> PAC-6130 | D307: =検針結果!V287 -> 062163 | E307: =検針結果!I287 -> 空調動力 | F307: =検針結果!G287 -> 1 | G307: =検針結果!L287 -> a接点 | H307: =検針結果!F287 -> 5 | I307: =検針結果!D287 -> オンライン | J307: =検針結果!M287 -> 0 | K307: =検針結果!W287 -> 46235 | L307: =検針結果!X287 -> 27893 | M307: =検針結果!Y287 -> 26256 | N307: =検針結果!Z287 -> 1637 | O307: =検針結果!AA287 -> 1432 | P307: =検針結果!AC287 -> 2025年02月01日 | Q307: =検針結果!AB287 -> 正常 | R307: =検針結果!AD287 -> 実行済み | S307: =検針結果!AH287 -> 交換なし | T307: =検針結果!AI287 -> 0 | U307: =検針結果!AJ287 -> 0 | V307: =検針結果!AK287 -> 0 | W307: =検針結果!AL287 -> 0
A308: =検針結果!A288 -> 0358 | B308: =検針結果!B288 -> 7100 | C308: =検針結果!C288 -> PAC-7100 | D308: =検針結果!V288 -> 062171 | E308: =検針結果!I288 -> 空調動力 | F308: =検針結果!G288 -> 1 | G308: =検針結果!L288 -> a接点 | H308: =検針結果!F288 -> 5 | I308: =検針結果!D288 -> オンライン | J308: =検針結果!M288 -> 0 | K308: =検針結果!W288 -> 46235 | L308: =検針結果!X288 -> 86808 | M308: =検針結果!Y288 -> 86737 | N308: =検針結果!Z288 -> 71 | O308: =検針結果!AA288 -> 91 | P308: =検針結果!AC288 -> 2025年02月01日 | Q308: =検針結果!AB288 -> 正常 | R308: =検針結果!AD288 -> 実行済み | S308: =検針結果!AH288 -> 交換なし | T308: =検針結果!AI288 -> 0 | U308: =検針結果!AJ288 -> 0 | V308: =検針結果!AK288 -> 0 | W308: =検針結果!AL288 -> 0
A309: =検針結果!A289 -> 0359 | B309: =検針結果!B289 -> 7105 | C309: =検針結果!C289 -> PAC-7105 | D309: =検針結果!V289 -> 062172 | E309: =検針結果!I289 -> 空調動力 | F309: =検針結果!G289 -> 1 | G309: =検針結果!L289 -> a接点 | H309: =検針結果!F289 -> 5 | I309: =検針結果!D289 -> オンライン | J309: =検針結果!M289 -> 0 | K309: =検針結果!W289 -> 46235 | L309: =検針結果!X289 -> 84913 | M309: =検針結果!Y289 -> 82568 | N309: =検針結果!Z289 -> 2345 | O309: =検針結果!AA289 -> 1671 | P309: =検針結果!AC289 -> 2025年02月01日 | Q309: =検針結果!AB289 -> 正常 | R309: =検針結果!AD289 -> 実行済み | S309: =検針結果!AH289 -> 交換なし | T309: =検針結果!AI289 -> 0 | U309: =検針結果!AJ289 -> 0 | V309: =検針結果!AK289 -> 0 | W309: =検針結果!AL289 -> 0
A310: =検針結果!A290 -> 0360 | B310: =検針結果!B290 -> 7110 | C310: =検針結果!C290 -> PAC-7110 | D310: =検針結果!V290 -> 062146 | E310: =検針結果!I290 -> 空調動力 | F310: =検針結果!G290 -> 1 | G310: =検針結果!L290 -> a接点 | H310: =検針結果!F290 -> 5 | I310: =検針結果!D290 -> オンライン | J310: =検針結果!M290 -> 0 | K310: =検針結果!W290 -> 46235 | L310: =検針結果!X290 -> 8076 | M310: =検針結果!Y290 -> 5889 | N310: =検針結果!Z290 -> 2187 | O310: =検針結果!AA290 -> 1818 | P310: =検針結果!AC290 -> 2025年02月01日 | Q310: =検針結果!AB290 -> 正常 | R310: =検針結果!AD290 -> 実行済み | S310: =検針結果!AH290 -> 交換なし | T310: =検針結果!AI290 -> 0 | U310: =検針結果!AJ290 -> 0 | V310: =検針結果!AK290 -> 0 | W310: =検針結果!AL290 -> 0
A311: =検針結果!A291 -> 0361 | B311: =検針結果!B291 -> 7115 | C311: =検針結果!C291 -> PAC-7115 | D311: =検針結果!V291 -> 062159 | E311: =検針結果!I291 -> 空調動力 | F311: =検針結果!G291 -> 1 | G311: =検針結果!L291 -> a接点 | H311: =検針結果!F291 -> 5 | I311: =検針結果!D291 -> オンライン | J311: =検針結果!M291 -> 0 | K311: =検針結果!W291 -> 46235 | L311: =検針結果!X291 -> 7820 | M311: =検針結果!Y291 -> 5694 | N311: =検針結果!Z291 -> 2126 | O311: =検針結果!AA291 -> 754 | P311: =検針結果!AC291 -> 2025年02月01日 | Q311: =検針結果!AB291 -> 正常 | R311: =検針結果!AD291 -> 実行済み | S311: =検針結果!AH291 -> 交換なし | T311: =検針結果!AI291 -> 0 | U311: =検針結果!AJ291 -> 0 | V311: =検針結果!AK291 -> 0 | W311: =検針結果!AL291 -> 0
...
