Workbook

Sheet 変更履歴
B2: システム名 | H2: 画面ID | L2: 業務分類 | R2: ドキュメント種別 | X2: ドキュメント名 | AK2: 帳票名 | AX2: 作成日 | BB2: 作成者 | BF2: 更新日 | BJ2: 更新者
B3: 受発注システム | H3: =LEFT($X$3,FIND("_",$X$3)-1) -> 仕入・支払 | L3: 運用自動化 | R3: =MID($X$3,FIND("_",$X$3,FIND("_",$X$3)+1)+1,LEN($X$3)-FIND("_",$X$3,FIND("_",$X$3)+1)) -> ダイアログ画面設計書 | X3: =REPLACE(LEFT(CELL("filename",$B$2),FIND(".x",CELL("filename",$B$2))-1),1,FIND("[",CELL("filename",$B$2)),) -> 仕入・支払_仕入入力_ダイアログ画面設計書 | AK3: =MID($X$3,FIND("_",$X$3)+1,FIND("_",$X$3,FIND("_",$X$3)+1)-FIND("_",$X$3)-1) -> 仕入入力 | AX3: 45720 | BB3: 丹羽 | BF3: 45720 | BJ3: 丹羽
C7: 変更履歴
C8: 日付 | G8: 版数 | K8: 担当 | O8: 変更箇所 | Y8: 内容
C9: 45720 | G9: 1.0.0 | K9: 丹羽 | O9: - | Y9: 新規作成

Sheet 項目一覧1
B2: システム名 | H2: 画面ID | L2: 業務分類 | X2: ドキュメント種別 | AG2: ドキュメント名 | AN2: 帳票名 | BA2: 作成日 | BE2: 作成者 | BI2: 更新日 | BM2: 更新者
B3: =変更履歴!B3 -> 受発注システム | H3: =変更履歴!H3 -> 仕入・支払 | L3: =変更履歴!L3 -> 運用自動化 | X3: =変更履歴!R3 -> ダイアログ画面設計書 | AG3: =変更履歴!X3 -> 仕入・支払_仕入入力_ダイアログ画面設計書 | AN3: =変更履歴!AK3 -> 仕入入力 | BA3: =変更履歴!AX3 -> 45720 | BE3: =変更履歴!BB3 -> 丹羽 | BI3: =変更履歴!BF3 -> 45720 | BM3: =変更履歴!BJ3 -> 丹羽
B7: 項目一覧
C9: 項目
D10: No. | E10: 項目名 | M10: I/O | P10: デフォルト値 | S10: データ型 | V10: 文字数/桁数 | Y10: 条件必須 | AB10: 入力必須 | AE10: 入力方式 | AH10: 備考
D11: 1 | E11: 処理区分CD | M11: IO | P11: 0 | S11: 数値 | V11: 1 | AB11: ○ | AE11: テキストボックス
D12: 2 | E12: 処理区分名 | M12: O | S12: 文字列 | AE12: テキストボックス
D13: 3 | E13: 見積番号 | M13: I | S13: 文字列 | AB13: ○ | AE13: テキストボックス
D14: 4 | E14: 見積件名 | M14: O | S14: 文字列 | AE14: テキストボックス
D15: 5 | E15: 見積番号検索ボタン | M15: - | AE15: ボタン
D16: 6 | E16: 見積番号クリアボタン | M16: - | AE16: ボタン
D17: 7 | E17: 仕入先CD | M17: I | S17: 文字列 | AE17: テキストボックス
D18: 8 | E18: 仕入先名 | M18: O | S18: 文字列 | AE18: テキストボックス
D19: 9 | E19: 仕入先CD検索ボタン | M19: - | AE19: ボタン
D20: 10 | E20: 仕入先CDクリアボタン | M20: - | AE20: ボタン
D21: 11 | E21: 合計金額 | M21: O | S21: 数値 | AE21: テキストボックス
D22: 12 | E22: 一覧
D23: 13 | F23: No | M23: O | S23: 数値 | AE23: テキストボックス
D24: 14 | F24: 仕入先 | M24: O | S24: 文字列 | AE24: テキストボックス
D25: 15 | F25: 仕入先名 | M25: O | S25: 文字列 | AE25: テキストボックス
D26: 16 | F26: 配送先 | M26: O | S26: 文字列 | AE26: テキストボックス
D27: 17 | F27: 配送先名 | M27: O | S27: 文字列 | AE27: テキストボックス
D28: 18 | F28: 仕入金額 | M28: O | S28: 文字列 | AE28: テキストボックス
D29: 19 | F29: 仕入日付 | M29: O | S29: 日付 | AE29: テキストボックス
D30: 20 | F30: 明細内訳 | M30: - | AE30: ボタン
D31: 21 | E31: 終了 | M31: - | AE31: ボタン
D32: 22

Sheet 画面レイアウト1
B2: システム名 | H2: 画面ID | L2: 業務分類 | X2: ドキュメント種別 | AG2: ドキュメント名 | AT2: 帳票名 | BG2: 作成日 | BK2: 作成者 | BO2: 更新日 | BS2: 更新者
B3: =変更履歴!B3 -> 受発注システム | H3: =変更履歴!H3 -> 仕入・支払 | L3: =変更履歴!L3 -> 運用自動化 | X3: =変更履歴!R3 -> ダイアログ画面設計書 | AG3: =変更履歴!X3 -> 仕入・支払_仕入入力_ダイアログ画面設計書 | AT3: =変更履歴!AK3 -> 仕入入力 | BG3: =変更履歴!AX3 -> 45720 | BK3: =変更履歴!BB3 -> 丹羽 | BO3: =変更履歴!BF3 -> 45720 | BS3: =変更履歴!BJ3 -> 丹羽

Sheet 項目一覧2
B2: システム名 | H2: 画面ID | L2: 業務分類 | X2: ドキュメント種別 | AG2: ドキュメント名 | AN2: 帳票名 | BA2: 作成日 | BE2: 作成者 | BI2: 更新日 | BM2: 更新者
B3: =変更履歴!B3 -> 受発注システム | H3: =変更履歴!H3 -> 仕入・支払 | L3: =変更履歴!L3 -> 運用自動化 | X3: =変更履歴!R3 -> ダイアログ画面設計書 | AG3: =変更履歴!X3 -> 仕入・支払_仕入入力_ダイアログ画面設計書 | AN3: =変更履歴!AK3 -> 仕入入力 | BA3: =変更履歴!AX3 -> 45720 | BE3: =変更履歴!BB3 -> 丹羽 | BI3: =変更履歴!BF3 -> 45720 | BM3: =変更履歴!BJ3 -> 丹羽
B7: 項目一覧
C9: 項目
D10: No. | E10: 項目名 | M10: I/O | P10: デフォルト値 | S10: データ型 | V10: 文字数/桁数 | Y10: 条件必須 | AB10: 入力必須 | AE10: 入力方式 | AH10: 備考
D11: 1 | E11: 処理区分CD | M11: O | S11: 数値 | AE11: テキストボックス
D12: 2 | E12: 処理区分名 | M12: O | S12: 文字列 | AE12: テキストボックス
D13: 3 | E13: 見積番号 | M13: O | S13: 文字列 | AE13: テキストボックス
D14: 4 | E14: 見積件名 | M14: O | S14: 文字列 | AE14: テキストボックス
D15: 5 | E15: 仕入先CD | M15: O | S15: 文字列 | AE15: テキストボックス
D16: 6 | E16: 仕入先名 | M16: O | S16: 文字列 | AE16: テキストボックス
D17: 7 | E17: 配送先CD | M17: O | S17: 文字列 | AE17: テキストボックス
D18: 8 | E18: 配送先名 | M18: O | S18: 文字列 | AE18: テキストボックス
D19: 9 | E19: 仕入日付 | M19: IO | S19: 日付 | AB19: ○ | AE19: テキストボックス
D20: 10 | E20: 支払日付 | M20: IO | S20: 日付 | AB20: ○ | AE20: テキストボックス
D21: 11 | E21: 外税対象額 | M21: O | S21: 数値 | AE21: テキストボックス
D22: 12 | E22: 外税 | M22: O | S22: 数値 | AE22: テキストボックス
D23: 13 | E23: 内税対象額 | M23: O | S23: 数値 | AE23: テキストボックス
D24: 14 | E24: 非課税金額 | M24: O | S24: 数値 | AE24: テキストボックス
D25: 15 | E25: 合計金額 | M25: O | S25: 数値 | AE25: テキストボックス
D26: 16 | E26: 売上合計 | M26: O | S26: 数値 | AE26: テキストボックス
D27: 17 | E27: 一覧
D28: 18 | F28: No | M28: O | S28: 数値 | AE28: テキストボックス
D29: 19 | F29: CK | M29: IO | S29: ブール値 | AE29: チェックボックス
D30: 20 | F30: 見積行 | M30: O | S30: 数値 | AE30: テキストボックス
D31: 21 | F31: 伝区 | M31: O | S31: 文字列 | AE31: テキストボックス
D32: 22 | F32: 納品日付しまむら | M32: O | S32: 日付 | AE32: テキストボックス
D33: 23 | F33: 伝票番号しまむら | M33: O | S33: 数値 | AE33: テキストボックス
D34: 24 | F34: SP区分 | M34: O | S34: 文字列 | AE34: テキストボックス
D35: 25 | F35: PC区分 | M35: O | S35: 文字列 | AE35: テキストボックス
D36: 26 | F36: 製品No | M36: O | S36: 文字列 | AE36: テキストボックス
D37: 27 | F37: 仕様No | M37: O | S37: 文字列 | AE37: テキストボックス
D38: 28 | F38: ベース色 | M38: O | S38: 文字列 | AE38: テキストボックス
D39: 29 | F39: 名称 | M39: O | S39: 文字列 | AE39: テキストボックス
... D49: 39 | F49: 単位 | M49: O | S49: 文字列 | AE49: テキストボックス
D50: 40 | F50: U | M50: O | S50: 文字列 | AB50: ○ | AE50: テキストボックス
D51: 41 | F51: 仕入単価 | M51: IO | S51: 数値 | AE51: テキストボックス
D52: 42 | F52: 仕入金額 | M52: O | S52: 数値 | AE52: テキストボックス
D53: 43 | F53: 税区 | M53: O | S53: 文字列 | AE53: テキストボックス
D54: 44 | F54: 税区分名 | M54: O | S54: 文字列 | AE54: テキストボックス
...

Sheet 画面レイアウト2
B2: システム名 | H2: 画面ID | L2: 業務分類 | X2: ドキュメント種別 | AG2: ドキュメント名 | AT2: 帳票名 | BG2: 作成日 | BK2: 作成者 | BO2: 更新日 | BS2: 更新者
B3: =変更履歴!B3 -> 受発注システム | H3: =変更履歴!H3 -> 仕入・支払 | L3: =変更履歴!L3 -> 運用自動化 | X3: =変更履歴!R3 -> ダイアログ画面設計書 | AG3: =変更履歴!X3 -> 仕入・支払_仕入入力_ダイアログ画面設計書 | AT3: =変更履歴!AK3 -> 仕入入力 | BG3: =変更履歴!AX3 -> 45720 | BK3: =変更履歴!BB3 -> 丹羽 | BO3: =変更履歴!BF3 -> 45720 | BS3: =変更履歴!BJ3 -> 丹羽

Sheet 確認事項
B2: 確認事項
B3: No. | C3: シート名 | D3: タイトル | E3: 概要 | F3: 確認済
B4: 1
B5: 2
B6: 3
B7: 4
B8: 5
B9: 6
B10: 7
B11: 8
B12: 9
B13: 10
B14: 11
B15: 12
... B54: 51

Sheet 参照
A1: 数値
A2: ブール値
A3: 文字列
A4: 日付
A5: リスト
A6: 辞書配列
