Workbook
Name TukiNamePos: #REF!
Name TukiNamePos_SS: #REF!
Name TukiRetu_SS: #REF!
Name TukiRetu_zen: #REF!
Name TukiRetu_顧客: 商研!$L:$N
Name TukiRetu_工事: #REF!
Name サービス_営業外費_貨物: DB!$DA$3:$DA$65423
Name サービス_営業外費_物流: DB!$DC$3:$DC$65423
Name サービス_原額_貨物自_サンプラ: DB!$BU$3:$BU$65423
Name サービス_原額_貨物自_その他: DB!$CA$3:$CA$65423
Name サービス_原額_貨物自_トラン: DB!$BY$3:$BY$65423
Name サービス_原額_貨物自_三シャ: DB!$BW$3:$BW$65423
Name サービス_原額_貨物自_三商: DB!$BQ$3:$BQ$65423
Name サービス_原額_貨物自_事故: DB!$CC$3:$CC$65423
Name サービス_原額_貨物自_店装: DB!$BS$3:$BS$65423
Name サービス_原額_貨物庸_サンプラ: DB!$CI$3:$CI$65423
Name サービス_原額_貨物庸_その他: DB!$CO$3:$CO$65423
Name サービス_原額_貨物庸_トラン: DB!$CM$3:$CM$65423
Name サービス_原額_貨物庸_三シャ: DB!$CK$3:$CK$65423
Name サービス_原額_貨物庸_三商: DB!$CE$3:$CE$65423
Name サービス_原額_貨物庸_事故: DB!$CQ$3:$CQ$65423
Name サービス_原額_貨物庸_店装: DB!$CG$3:$CG$65423
Name サービス_原額_物流_その他: DB!$CW$3:$CW$65423
Name サービス_原額_物流_ルート: DB!$CS$3:$CS$65423
Name サービス_原額_物流_丸和: DB!$CU$3:$CU$65423
Name サービス_原額_物流_事故: DB!$CY$3:$CY$65423
Name サービス_人件一般費_貨物: DB!$CZ$3:$CZ$65423
Name サービス_人件一般費_物流: DB!$DB$3:$DB$65423
Name サービス_年月: DB!$BO$3:$BO$65423
Name サービス_売額_貨物自_サンプラ: DB!$BT$3:$BT$65423
Name サービス_売額_貨物自_その他: DB!$BZ$3:$BZ$65423
Name サービス_売額_貨物自_トラン: DB!$BX$3:$BX$65423
Name サービス_売額_貨物自_三シャ: DB!$BV$3:$BV$65423
Name サービス_売額_貨物自_三商: DB!$BP$3:$BP$65423
Name サービス_売額_貨物自_事故: DB!$CB$3:$CB$65423
Name サービス_売額_貨物自_店装: DB!$BR$3:$BR$65423
Name サービス_売額_貨物庸_サンプラ: DB!$CH$3:$CH$65423
Name サービス_売額_貨物庸_その他: DB!$CN$3:$CN$65423
Name サービス_売額_貨物庸_トラン: DB!$CL$3:$CL$65423
Name サービス_売額_貨物庸_三シャ: DB!$CJ$3:$CJ$65423
Name サービス_売額_貨物庸_三商: DB!$CD$3:$CD$65423
Name サービス_売額_貨物庸_事故: DB!$CP$3:$CP$65423
Name サービス_売額_貨物庸_店装: DB!$CF$3:$CF$65423
Name サービス_売額_物流_その他: DB!$CV$3:$CV$65423
Name サービス_売額_物流_ルート: DB!$CR$3:$CR$65423
Name サービス_売額_物流_丸和: DB!$CT$3:$CT$65423
Name サービス_売額_物流_事故: DB!$CX$3:$CX$65423
Name サービス予測_年月: DB!$BA$3:$BA$65423
Name サービス予測_予測原価金額_貨物: DB!$BC$3:$BC$65423
Name サービス予測_予測原価金額_物流: DB!$BE$3:$BE$65423
Name サービス予測_予測売上金額_貨物: DB!$BB$3:$BB$65423
Name サービス予測_予測売上金額_物流: DB!$BD$3:$BD$65423
Name フロント_営業外費: DB!$BL$3:$BL$65423
Name フロント_原価税抜金額: DB!$BJ$3:$BJ$65423
Name フロント_人件一般費: DB!$BK$3:$BK$65423
Name フロント_年月: DB!$BH$3:$BH$65423
Name フロント_売上税抜金額: DB!$BI$3:$BI$65423
Name フロント予測_年月: DB!$AV$3:$AV$65423
Name フロント予測_予測原価金額: DB!$AX$3:$AX$65423
Name フロント予測_予測売上金額: DB!$AW$3:$AW$65423

Sheet DB
A1: 顧客別 売上・原価 | J1: 工事 売上・原価 | Y1: 入出庫 | AE1: 三研 売上（円） | AL1: 2016年 担当別原価埋込 | AQ1: 三研予測(円) | AV1: フロント予測(円) | BA1: サービス予測(円) | BH1: フロント 売上（円） | BO1: サービス 売上（円） | DF1: 営業担当別経費 | DM1: 部署別 売上・原価
A2: 営業担当CD | B2: 番号 | C2: 集計CD | D2: 年月日 | E2: 作業区分CD | F2: 売上税抜金額 | G2: 原価税抜金額 | J2: 工事担当CD | K2: 番号 | L2: 集計CD（未使用） | M2: 年月日 | N2: 作業区分CD | O2: 売上税抜金額 | P2: 原価税抜金額 | Y2: 集計CD | Z2: 年月日 | AA2: 出庫金額 | AB2: 入庫金額 | AE2: 年月日 | AF2: 売上税抜金額 | AG2: 原価税抜金額 | AH2: 人件一般費 | AI2: 営業外費 | AL2: チームCD | AM2: 年月日 | AN2: 原価金額 | AQ2: 年月日 | AR2: 予測売上金額 | AS2: 予測原価金額 | AV2: 年月日 | AW2: 予測売上金額 | AX2: 予測原価金額 | BA2: 年月日 | BB2: 予測売上額_貨物 | BC2: 予測原価額_貨物 | BD2: 予測売上額_物流 | BE2: 予測原価額_物流 | BH2: 年月日 | BI2: 売上税抜金額 | BJ2: 原価税抜金額 | BK2: 人件一般費 | BL2: 営業外費 | BO2: 年月日 | BP2: 売額_貨物自_三商 | BQ2: 原額_貨物自_三商 | BR2: 売額_貨物自_店装 | BS2: 原額_貨物自_店装 | BT2: 売額_貨物自_サンプラ | BU2: 原額_貨物自_サンプラ | BV2: 売額_貨物自_三シャ | BW2: 原額_貨物自_三シャ | BX2: 売額_貨物自_トラン | BY2: 原額_貨物自_トラン | BZ2: 売額_貨物自_その他 | CA2: 原額_貨物自_その他 | CB2: 売額_貨物自_事故 | CC2: 原額_貨物自_事故 | CD2: 売額_貨物庸_三商 | CE2: 原額_貨物庸_三商 | CF2: 売額_貨物庸_店装 | CG2: 原額_貨物庸_店装 | CH2: 売額_貨物庸_サンプラ | CI2: 原額_貨物庸_サンプラ | CJ2: 売額_貨物庸_三シャ | CK2: 原額_貨物庸_三シャ | CL2: 売額_貨物庸_トラン | CM2: 原額_貨物庸_トラン | CN2: 売額_貨物庸_その他 | CO2: 原額_貨物庸_その他 | CP2: 売額_貨物庸_事故 | CQ2: 原額_貨物庸_事故 | CR2: 売額_物流_ルート | CS2: 原額_物流_ルート | CT2: 売額_物流_丸和 | CU2: 原額_物流_丸和 | CV2: 売額_物流_その他 | CW2: 原額_物流_その他 | CX2: 売額_物流_事故 | CY2: 原額_物流_事故 | CZ2: 人件一般費_貨物 | DA2: 営業外費_貨物 | DB2: 人件一般費_物流 | DC2: 営業外費_物流 | DF2: 業種区分 | DG2: 部CD（未使用） | DH2: 年月日 | DI2: 人件費一般費 | DM2: 部署 | DN2: 年月日 | DO2: 作業区分CD | DP2: 売上税抜金額 | DQ2: 原価税抜金額

Sheet 商研
A1: 営業チーム統計
A2: 項目 | F2: =YEAR(I2)-1978+1&"期" -> 46期 | I2: 45170
F3: 原価 | H3: 売上 | I3: 原価 | K3: 売上
A4: 売上 | C4: 0 | F4: =SUM(I4:N4) -> 0 | I4: =SUMIF($C10:$C36,$C4,I10:I36) -> 0 | J4: =SUMIF($C9:$C35,$C4,J9:J35) -> 0 | K4: =SUMIF($C9:$C35,$C4,K9:K35) -> 0
A5: 原価 | C5: 1 | H5: =SUM(I5:N5) -> 0 | K5: =SUMIF($C10:$C36,$C5,K10:K36) -> 0
A6: 売上総利益 | F6: =SUMIF(I$3:N$3,$F$3,I6:N6) -> 0 | H6: =IF(ISERROR(F6/F4),0,F6/F4) -> 0 | I6: =I4-K5 -> 0 | K6: =IF(ISERROR(I6/I4),0,I6/I4) -> 0
A7: 販管費 | C7: 0 | F7: =SUMIF(I$3:N$3,$F$3,I7:N7) -> 0 | H7: =IF(ISERROR(F7/F4),0,F7/F4) -> 0 | I7: =IFERROR(INDEX(DB!統計集計先_人件費一般費,MATCH($C7&"-"&I$2,INDEX(DB!統計集計先_CD&"-"&DB!統計集計先_年月,),0)),0) -> 0 | K7: =IF(ISERROR(I7/I4),0,I7/I4) -> 0
A8: 営業利益 | F8: =SUMIF(I$3:N$3,$F$3,I8:N8) -> 0 | H8: =IF(ISERROR(F8/F4),0,F8/F4) -> 0 | I8: =I6-I7 -> 0 | K8: =IF(ISERROR(I8/I4),0,I8/I4) -> 0
B9: 在庫 | E9: 20 | F9: =SUMIF(I$3:N$3,$F$3,I9:N9) -> 0 | G9: ⇔ | H9: =SUMIF(I$3:N$3,$H$3,I9:N9) -> 0 | I9: =SUMIF($B$37:$B$100,$B9,I$37:I$100) -> 0 | J9: ⇔ | K9: =SUMIF($B$37:$B$100,$B9,K$37:K$100) -> 0
A10: 売上 | C10: 0 | F10: =SUM(H13:H18) -> 0 | I10: =SUM(K13:K18) -> 0
A11: 原価 | C11: 1 | H11: =SUM(I11:N11) -> 0 | K11: =SUM(I13:I18) -> 0
A12: 売上総利益 | F12: =F10-H11 -> 0 | H12: =IF(ISERROR(F12/F10),0,F12/F10) -> 0 | I12: =I10-K11 -> 0 | K12: =IF(ISERROR(I12/I10),0,I12/I10) -> 0
A13: 営業１部 | B13: 営業 | D13: 1 | E13: 0 | F13: =SUMIF(I$3:N$3,$F$3,I13:N13) -> 0 | G13: =IF(ISERROR(F13/H13),0,F13/H13) -> 0 | H13: =SUMIF(I$3:N$3,$H$3,I13:N13) -> 0 | I13: =IFERROR(INDEX(DB!$DQ$3:$DQ$65423,MATCH($D13&"-"&I$2&"-"&$E13,INDEX(DB!$DM$3:$DM$65423&"-"&DB!$DN$3:$DN$65423&"-"&DB!$DO$3:$DO$65423,),0)),0) -> 0 | J13: =IF(ISERROR(I13/K13),0,I13/K13) -> 0 | K13: =IFERROR(INDEX(DB!$DP$3:$DP$65423,MATCH($D13&"-"&I$2&"-"&$E13,INDEX(DB!$DM$3:$DM$65423&"-"&DB!$DN$3:$DN$65423&"-"&DB!$DO$3:$DO$65423,),0)),0) -> 0
B14: 工事 | D14: 1 | E14: 1 | F14: =SUMIF(I$3:N$3,$F$3,I14:N14) -> 0 | G14: =IF(ISERROR(F14/H14),0,F14/H14) -> 0 | H14: =SUMIF(I$3:N$3,$H$3,I14:N14) -> 0 | I14: =IFERROR(INDEX(DB!$DQ$3:$DQ$65423,MATCH($D14&"-"&I$2&"-"&$E14,INDEX(DB!$DM$3:$DM$65423&"-"&DB!$DN$3:$DN$65423&"-"&DB!$DO$3:$DO$65423,),0)),0) -> 0 | J14: =IF(ISERROR(I14/K14),0,I14/K14) -> 0 | K14: =IFERROR(INDEX(DB!$DP$3:$DP$65423,MATCH($D14&"-"&I$2&"-"&$E14,INDEX(DB!$DM$3:$DM$65423&"-"&DB!$DN$3:$DN$65423&"-"&DB!$DO$3:$DO$65423,),0)),0) -> 0
B15: コール | D15: 1 | E15: 2 | F15: =SUMIF(I$3:N$3,$F$3,I15:N15) -> 0 | G15: =IF(ISERROR(F15/H15),0,F15/H15) -> 0 | H15: =SUMIF(I$3:N$3,$H$3,I15:N15) -> 0 | I15: =IFERROR(INDEX(DB!$DQ$3:$DQ$65423,MATCH($D15&"-"&I$2&"-"&$E15,INDEX(DB!$DM$3:$DM$65423&"-"&DB!$DN$3:$DN$65423&"-"&DB!$DO$3:$DO$65423,),0)),0) -> 0 | J15: =IF(ISERROR(I15/K15),0,I15/K15) -> 0 | K15: =IFERROR(INDEX(DB!$DP$3:$DP$65423,MATCH($D15&"-"&I$2&"-"&$E15,INDEX(DB!$DM$3:$DM$65423&"-"&DB!$DN$3:$DN$65423&"-"&DB!$DO$3:$DO$65423,),0)),0) -> 0
B16: 店装 | D16: 1 | E16: 3 | F16: =SUMIF(I$3:N$3,$F$3,I16:N16) -> 0 | G16: =IF(ISERROR(F16/H16),0,F16/H16) -> 0 | H16: =SUMIF(I$3:N$3,$H$3,I16:N16) -> 0 | I16: =IFERROR(INDEX(DB!$DQ$3:$DQ$65423,MATCH($D16&"-"&I$2&"-"&$E16,INDEX(DB!$DM$3:$DM$65423&"-"&DB!$DN$3:$DN$65423&"-"&DB!$DO$3:$DO$65423,),0)),0) -> 0 | J16: =IF(ISERROR(I16/K16),0,I16/K16) -> 0 | K16: =IFERROR(INDEX(DB!$DP$3:$DP$65423,MATCH($D16&"-"&I$2&"-"&$E16,INDEX(DB!$DM$3:$DM$65423&"-"&DB!$DN$3:$DN$65423&"-"&DB!$DO$3:$DO$65423,),0)),0) -> 0
B17: 委託 | D17: 1 | E17: 106 | F17: =SUMIF(I$3:N$3,$F$3,I17:N17) -> 0 | G17: =IF(ISERROR(F17/H17),0,F17/H17) -> 0 | H17: =SUMIF(I$3:N$3,$H$3,I17:N17) -> 0 | I17: =IFERROR(INDEX(DB!$DQ$3:$DQ$65423,MATCH($D17&"-"&I$2&"-"&$E17,INDEX(DB!$DM$3:$DM$65423&"-"&DB!$DN$3:$DN$65423&"-"&DB!$DO$3:$DO$65423,),0)),0) -> 0 | J17: =IF(ISERROR(I17/K17),0,I17/K17) -> 0 | K17: =IFERROR(INDEX(DB!$DP$3:$DP$65423,MATCH($D17&"-"&I$2&"-"&$E17,INDEX(DB!$DM$3:$DM$65423&"-"&DB!$DN$3:$DN$65423&"-"&DB!$DO$3:$DO$65423,),0)),0) -> 0
B18: クレーム | D18: 1 | E18: 4 | F18: =SUMIF(I$3:N$3,$F$3,I18:N18) -> 0 | G18: =IF(ISERROR(F18/H18),0,F18/H18) -> 0 | H18: =SUMIF(I$3:N$3,$H$3,I18:N18) -> 0 | I18: =IFERROR(INDEX(DB!$DQ$3:$DQ$65423,MATCH($D18&"-"&I$2&"-"&$E18,INDEX(DB!$DM$3:$DM$65423&"-"&DB!$DN$3:$DN$65423&"-"&DB!$DO$3:$DO$65423,),0)),0) -> 0 | J18: =IF(ISERROR(I18/K18),0,I18/K18) -> 0 | K18: =IFERROR(INDEX(DB!$DP$3:$DP$65423,MATCH($D18&"-"&I$2&"-"&$E18,INDEX(DB!$DM$3:$DM$65423&"-"&DB!$DN$3:$DN$65423&"-"&DB!$DO$3:$DO$65423,),0)),0) -> 0
A19: 売上 | C19: 0 | F19: =SUM(H22:H27) -> 0 | I19: =SUM(K22:K27) -> 0
A20: 原価 | C20: 1 | H20: =SUM(I20:N20) -> 0 | K20: =SUM(I22:I27) -> 0
A21: 売上総利益 | F21: =F19-H20 -> 0 | H21: =IF(ISERROR(F21/F19),0,F21/F19) -> 0 | I21: =I19-K20 -> 0 | K21: =IF(ISERROR(I21/I19),0,I21/I19) -> 0
A22: 営業２部 | B22: 営業 | D22: 2 | E22: 0 | F22: =SUMIF(I$3:N$3,$F$3,I22:N22) -> 0 | G22: =IF(ISERROR(F22/H22),0,F22/H22) -> 0 | H22: =SUMIF(I$3:N$3,$H$3,I22:N22) -> 0 | I22: =IFERROR(INDEX(DB!$DQ$3:$DQ$65423,MATCH($D22&"-"&I$2&"-"&$E22,INDEX(DB!$DM$3:$DM$65423&"-"&DB!$DN$3:$DN$65423&"-"&DB!$DO$3:$DO$65423,),0)),0) -> 0 | J22: =IF(ISERROR(I22/K22),0,I22/K22) -> 0 | K22: =IFERROR(INDEX(DB!$DP$3:$DP$65423,MATCH($D22&"-"&I$2&"-"&$E22,INDEX(DB!$DM$3:$DM$65423&"-"&DB!$DN$3:$DN$65423&"-"&DB!$DO$3:$DO$65423,),0)),0) -> 0
B23: 工事 | D23: 2 | E23: 1 | F23: =SUMIF(I$3:N$3,$F$3,I23:N23) -> 0 | G23: =IF(ISERROR(F23/H23),0,F23/H23) -> 0 | H23: =SUMIF(I$3:N$3,$H$3,I23:N23) -> 0 | I23: =IFERROR(INDEX(DB!$DQ$3:$DQ$65423,MATCH($D23&"-"&I$2&"-"&$E23,INDEX(DB!$DM$3:$DM$65423&"-"&DB!$DN$3:$DN$65423&"-"&DB!$DO$3:$DO$65423,),0)),0) -> 0 | J23: =IF(ISERROR(I23/K23),0,I23/K23) -> 0 | K23: =IFERROR(INDEX(DB!$DP$3:$DP$65423,MATCH($D23&"-"&I$2&"-"&$E23,INDEX(DB!$DM$3:$DM$65423&"-"&DB!$DN$3:$DN$65423&"-"&DB!$DO$3:$DO$65423,),0)),0) -> 0
B24: コール | D24: 2 | E24: 2 | F24: =SUMIF(I$3:N$3,$F$3,I24:N24) -> 0 | G24: =IF(ISERROR(F24/H24),0,F24/H24) -> 0 | H24: =SUMIF(I$3:N$3,$H$3,I24:N24) -> 0 | I24: =IFERROR(INDEX(DB!$DQ$3:$DQ$65423,MATCH($D24&"-"&I$2&"-"&$E24,INDEX(DB!$DM$3:$DM$65423&"-"&DB!$DN$3:$DN$65423&"-"&DB!$DO$3:$DO$65423,),0)),0) -> 0 | J24: =IF(ISERROR(I24/K24),0,I24/K24) -> 0 | K24: =IFERROR(INDEX(DB!$DP$3:$DP$65423,MATCH($D24&"-"&I$2&"-"&$E24,INDEX(DB!$DM$3:$DM$65423&"-"&DB!$DN$3:$DN$65423&"-"&DB!$DO$3:$DO$65423,),0)),0) -> 0
B25: 店装 | D25: 2 | E25: 3 | F25: =SUMIF(I$3:N$3,$F$3,I25:N25) -> 0 | G25: =IF(ISERROR(F25/H25),0,F25/H25) -> 0 | H25: =SUMIF(I$3:N$3,$H$3,I25:N25) -> 0 | I25: =IFERROR(INDEX(DB!$DQ$3:$DQ$65423,MATCH($D25&"-"&I$2&"-"&$E25,INDEX(DB!$DM$3:$DM$65423&"-"&DB!$DN$3:$DN$65423&"-"&DB!$DO$3:$DO$65423,),0)),0) -> 0 | J25: =IF(ISERROR(I25/K25),0,I25/K25) -> 0 | K25: =IFERROR(INDEX(DB!$DP$3:$DP$65423,MATCH($D25&"-"&I$2&"-"&$E25,INDEX(DB!$DM$3:$DM$65423&"-"&DB!$DN$3:$DN$65423&"-"&DB!$DO$3:$DO$65423,),0)),0) -> 0
B26: 委託 | D26: 2 | E26: 106 | F26: =SUMIF(I$3:N$3,$F$3,I26:N26) -> 0 | G26: =IF(ISERROR(F26/H26),0,F26/H26) -> 0 | H26: =SUMIF(I$3:N$3,$H$3,I26:N26) -> 0 | I26: =IFERROR(INDEX(DB!$DQ$3:$DQ$65423,MATCH($D26&"-"&I$2&"-"&$E26,INDEX(DB!$DM$3:$DM$65423&"-"&DB!$DN$3:$DN$65423&"-"&DB!$DO$3:$DO$65423,),0)),0) -> 0 | J26: =IF(ISERROR(I26/K26),0,I26/K26) -> 0 | K26: =IFERROR(INDEX(DB!$DP$3:$DP$65423,MATCH($D26&"-"&I$2&"-"&$E26,INDEX(DB!$DM$3:$DM$65423&"-"&DB!$DN$3:$DN$65423&"-"&DB!$DO$3:$DO$65423,),0)),0) -> 0
B27: クレーム | D27: 2 | E27: 4 | F27: =SUMIF(I$3:N$3,$F$3,I27:N27) -> 0 | G27: =IF(ISERROR(F27/H27),0,F27/H27) -> 0 | H27: =SUMIF(I$3:N$3,$H$3,I27:N27) -> 0 | I27: =IFERROR(INDEX(DB!$DQ$3:$DQ$65423,MATCH($D27&"-"&I$2&"-"&$E27,INDEX(DB!$DM$3:$DM$65423&"-"&DB!$DN$3:$DN$65423&"-"&DB!$DO$3:$DO$65423,),0)),0) -> 0 | J27: =IF(ISERROR(I27/K27),0,I27/K27) -> 0 | K27: =IFERROR(INDEX(DB!$DP$3:$DP$65423,MATCH($D27&"-"&I$2&"-"&$E27,INDEX(DB!$DM$3:$DM$65423&"-"&DB!$DN$3:$DN$65423&"-"&DB!$DO$3:$DO$65423,),0)),0) -> 0
A28: 売上 | C28: 0 | F28: =SUM(H31:H36) -> 0 | I28: =SUM(K31:K36) -> 0
A29: 原価 | C29: 1 | H29: =SUM(I29:N29) -> 0 | K29: =SUM(I31:I36) -> 0
A30: 売上総利益 | F30: =F28-H29 -> 0 | H30: =IF(ISERROR(F30/F28),0,F30/F28) -> 0 | I30: =I28-K29 -> 0 | K30: =IF(ISERROR(I30/I28),0,I30/I28) -> 0
A31: 営業３部 | B31: 営業 | D31: 3 | E31: 0 | F31: =SUMIF(I$3:N$3,$F$3,I31:N31) -> 0 | G31: =IF(ISERROR(F31/H31),0,F31/H31) -> 0 | H31: =SUMIF(I$3:N$3,$H$3,I31:N31) -> 0 | I31: =IFERROR(INDEX(DB!$DQ$3:$DQ$65423,MATCH($D31&"-"&I$2&"-"&$E31,INDEX(DB!$DM$3:$DM$65423&"-"&DB!$DN$3:$DN$65423&"-"&DB!$DO$3:$DO$65423,),0)),0) -> 0 | J31: =IF(ISERROR(I31/K31),0,I31/K31) -> 0 | K31: =IFERROR(INDEX(DB!$DP$3:$DP$65423,MATCH($D31&"-"&I$2&"-"&$E31,INDEX(DB!$DM$3:$DM$65423&"-"&DB!$DN$3:$DN$65423&"-"&DB!$DO$3:$DO$65423,),0)),0) -> 0
B32: 工事 | D32: 3 | E32: 1 | F32: =SUMIF(I$3:N$3,$F$3,I32:N32) -> 0 | G32: =IF(ISERROR(F32/H32),0,F32/H32) -> 0 | H32: =SUMIF(I$3:N$3,$H$3,I32:N32) -> 0 | I32: =IFERROR(INDEX(DB!$DQ$3:$DQ$65423,MATCH($D32&"-"&I$2&"-"&$E32,INDEX(DB!$DM$3:$DM$65423&"-"&DB!$DN$3:$DN$65423&"-"&DB!$DO$3:$DO$65423,),0)),0) -> 0 | J32: =IF(ISERROR(I32/K32),0,I32/K32) -> 0 | K32: =IFERROR(INDEX(DB!$DP$3:$DP$65423,MATCH($D32&"-"&I$2&"-"&$E32,INDEX(DB!$DM$3:$DM$65423&"-"&DB!$DN$3:$DN$65423&"-"&DB!$DO$3:$DO$65423,),0)),0) -> 0
B33: コール | D33: 3 | E33: 2 | F33: =SUMIF(I$3:N$3,$F$3,I33:N33) -> 0 | G33: =IF(ISERROR(F33/H33),0,F33/H33) -> 0 | H33: =SUMIF(I$3:N$3,$H$3,I33:N33) -> 0 | I33: =IFERROR(INDEX(DB!$DQ$3:$DQ$65423,MATCH($D33&"-"&I$2&"-"&$E33,INDEX(DB!$DM$3:$DM$65423&"-"&DB!$DN$3:$DN$65423&"-"&DB!$DO$3:$DO$65423,),0)),0) -> 0 | J33: =IF(ISERROR(I33/K33),0,I33/K33) -> 0 | K33: =IFERROR(INDEX(DB!$DP$3:$DP$65423,MATCH($D33&"-"&I$2&"-"&$E33,INDEX(DB!$DM$3:$DM$65423&"-"&DB!$DN$3:$DN$65423&"-"&DB!$DO$3:$DO$65423,),0)),0) -> 0
B34: 店装 | D34: 3 | E34: 3 | F34: =SUMIF(I$3:N$3,$F$3,I34:N34) -> 0 | G34: =IF(ISERROR(F34/H34),0,F34/H34) -> 0 | H34: =SUMIF(I$3:N$3,$H$3,I34:N34) -> 0 | I34: =IFERROR(INDEX(DB!$DQ$3:$DQ$65423,MATCH($D34&"-"&I$2&"-"&$E34,INDEX(DB!$DM$3:$DM$65423&"-"&DB!$DN$3:$DN$65423&"-"&DB!$DO$3:$DO$65423,),0)),0) -> 0 | J34: =IF(ISERROR(I34/K34),0,I34/K34) -> 0 | K34: =IFERROR(INDEX(DB!$DP$3:$DP$65423,MATCH($D34&"-"&I$2&"-"&$E34,INDEX(DB!$DM$3:$DM$65423&"-"&DB!$DN$3:$DN$65423&"-"&DB!$DO$3:$DO$65423,),0)),0) -> 0
B35: 委託 | D35: 3 | E35: 106 | F35: =SUMIF(I$3:N$3,$F$3,I35:N35) -> 0 | G35: =IF(ISERROR(F35/H35),0,F35/H35) -> 0 | H35: =SUMIF(I$3:N$3,$H$3,I35:N35) -> 0 | I35: =IFERROR(INDEX(DB!$DQ$3:$DQ$65423,MATCH($D35&"-"&I$2&"-"&$E35,INDEX(DB!$DM$3:$DM$65423&"-"&DB!$DN$3:$DN$65423&"-"&DB!$DO$3:$DO$65423,),0)),0) -> 0 | J35: =IF(ISERROR(I35/K35),0,I35/K35) -> 0 | K35: =IFERROR(INDEX(DB!$DP$3:$DP$65423,MATCH($D35&"-"&I$2&"-"&$E35,INDEX(DB!$DM$3:$DM$65423&"-"&DB!$DN$3:$DN$65423&"-"&DB!$DO$3:$DO$65423,),0)),0) -> 0
B36: クレーム | D36: 3 | E36: 4 | F36: =SUMIF(I$3:N$3,$F$3,I36:N36) -> 0 | G36: =IF(ISERROR(F36/H36),0,F36/H36) -> 0 | H36: =SUMIF(I$3:N$3,$H$3,I36:N36) -> 0 | I36: =IFERROR(INDEX(DB!$DQ$3:$DQ$65423,MATCH($D36&"-"&I$2&"-"&$E36,INDEX(DB!$DM$3:$DM$65423&"-"&DB!$DN$3:$DN$65423&"-"&DB!$DO$3:$DO$65423,),0)),0) -> 0 | J36: =IF(ISERROR(I36/K36),0,I36/K36) -> 0 | K36: =IFERROR(INDEX(DB!$DP$3:$DP$65423,MATCH($D36&"-"&I$2&"-"&$E36,INDEX(DB!$DM$3:$DM$65423&"-"&DB!$DN$3:$DN$65423&"-"&DB!$DO$3:$DO$65423,),0)),0) -> 0
A37: W | B37: 原/売 | D37: 2401 | F37: =SUMIF(I$3:N$3,$F$3,I37:N37) -> 0 | G37: =IF(ISERROR(F37/H37),0,F37/H37) -> 0 | H37: =SUMIF(I$3:N$3,$H$3,I37:N37) -> 0 | I37: =SUMIF($D38:$D43,$D37,I38:I43) -> 0 | J37: =IF(ISERROR(I37/K37),0,I37/K37) -> 0 | K37: =SUM(K38:K43) -> 0
B38: 営業 | C38: 0 | D38: 2401 | E38: 0 | F38: =SUMIF(I$3:N$3,$F$3,I38:N38) -> 0 | G38: =IF(ISERROR(F38/H38),0,F38/H38) -> 0 | H38: =SUMIF(I$3:N$3,$H$3,I38:N38) -> 0 | I38: =IFERROR(INDEX(DB!$G$3:$G$65423,MATCH($C38&"-"&$D38&"-"&I$2&"-"&$E38,INDEX(DB!$A$3:$A$65423&"-"&DB!$C$3:$C$65423&"-"&DB!$D$3:$D$65423&"-"&DB!$E$3:$E$65423,),0)),0) -> 0 | J38: =IF(ISERROR(I38/K38),0,I38/K38) -> 0 | K38: =IFERROR(INDEX(DB!$F$3:$F$65423,MATCH($C38&"-"&$D38&"-"&I$2&"-"&$E38,INDEX(DB!$A$3:$A$65423&"-"&DB!$C$3:$C$65423&"-"&DB!$D$3:$D$65423&"-"&DB!$E$3:$E$65423,),0)),0) -> 0
B39: 工事 | C39: 0 | D39: 2401 | E39: 1 | F39: =SUMIF(I$3:N$3,$F$3,I39:N39) -> 0 | G39: =IF(ISERROR(F39/H39),0,F39/H39) -> 0 | H39: =SUMIF(I$3:N$3,$H$3,I39:N39) -> 0 | I39: =IFERROR(INDEX(DB!$G$3:$G$65423,MATCH($C39&"-"&$D39&"-"&I$2&"-"&$E39,INDEX(DB!$A$3:$A$65423&"-"&DB!$C$3:$C$65423&"-"&DB!$D$3:$D$65423&"-"&DB!$E$3:$E$65423,),0)),0) -> 0 | J39: =IF(ISERROR(I39/K39),0,I39/K39) -> 0 | K39: =IFERROR(INDEX(DB!$F$3:$F$65423,MATCH($C39&"-"&$D39&"-"&I$2&"-"&$E39,INDEX(DB!$A$3:$A$65423&"-"&DB!$C$3:$C$65423&"-"&DB!$D$3:$D$65423&"-"&DB!$E$3:$E$65423,),0)),0) -> 0
B40: コール | C40: 0 | D40: 2401 | E40: 2 | F40: =SUMIF(I$3:N$3,$F$3,I40:N40) -> 0 | G40: =IF(ISERROR(F40/H40),0,F40/H40) -> 0 | H40: =SUMIF(I$3:N$3,$H$3,I40:N40) -> 0 | I40: =IFERROR(INDEX(DB!$G$3:$G$65423,MATCH($C40&"-"&$D40&"-"&I$2&"-"&$E40,INDEX(DB!$A$3:$A$65423&"-"&DB!$C$3:$C$65423&"-"&DB!$D$3:$D$65423&"-"&DB!$E$3:$E$65423,),0)),0) -> 0 | J40: =IF(ISERROR(I40/K40),0,I40/K40) -> 0 | K40: =IFERROR(INDEX(DB!$F$3:$F$65423,MATCH($C40&"-"&$D40&"-"&I$2&"-"&$E40,INDEX(DB!$A$3:$A$65423&"-"&DB!$C$3:$C$65423&"-"&DB!$D$3:$D$65423&"-"&DB!$E$3:$E$65423,),0)),0) -> 0
...
