Workbook

Sheet 変更履歴
B2: システム名 | H2: 業務分類 | L2: システム分類 | R2: ドキュメント種別 | X2: ドキュメント名 | AK2: 画面名 | AX2: 作成日 | BB2: 作成者 | BF2: 更新日 | BJ2: 更新者
B3: 受発注システム | H3: =LEFT($X$3,FIND("_",$X$3)-1) -> 承認 | L3: 受発注 | R3: =MID($X$3,FIND("_",$X$3,FIND("_",$X$3)+1)+1,LEN($X$3)-FIND("_",$X$3,FIND("_",$X$3)+1)) -> 画面設計書 | X3: =REPLACE(LEFT(CELL("filename",$B$2),FIND(".x",CELL("filename",$B$2))-1),1,FIND("[",CELL("filename",$B$2)),) -> 承認_請求書ワークフロー_画面設計書 | AK3: =MID($X$3,FIND("_",$X$3)+1,FIND("_",$X$3,FIND("_",$X$3)+1)-FIND("_",$X$3)-1) -> 請求書ワークフロー | AX3: 45553 | BB3: 人見 | BF3: 45553 | BJ3: 人見
C7: 変更履歴
C8: 日付 | G8: 版数 | K8: 担当 | O8: 変更箇所 | Y8: 内容
C9: 45553 | G9: 1.0.0 | K9: 人見 | O9: - | Y9: 新規作成

Sheet 画面レイアウト(一覧)
B2: システム名 | H2: 業務分類 | L2: システム分類 | X2: ドキュメント種別 | AG2: ドキュメント名 | AT2: 画面名 | BG2: 作成日 | BK2: 作成者 | BO2: 更新日 | BS2: 更新者
B3: =変更履歴!B3 -> 受発注システム | H3: =変更履歴!H3 -> 承認 | L3: =変更履歴!L3 -> 受発注 | X3: =変更履歴!R3 -> 画面設計書 | AG3: =変更履歴!X3 -> 承認_請求書ワークフロー_画面設計書 | AT3: =変更履歴!AK3 -> 請求書ワークフロー | BG3: =変更履歴!AX3 -> 45553 | BK3: =変更履歴!BB3 -> 人見 | BO3: =変更履歴!BF3 -> 45553 | BS3: =変更履歴!BJ3 -> 人見

Sheet 項目一覧(一覧)
B2: システム名 | H2: 業務分類 | L2: システム分類 | X2: ドキュメント種別 | AG2: ドキュメント名 | AT2: 画面名 | BG2: 作成日 | BK2: 作成者 | BO2: 更新日 | BS2: 更新者
B3: =変更履歴!B3 -> 受発注システム | H3: =変更履歴!H3 -> 承認 | L3: =変更履歴!L3 -> 受発注 | X3: =変更履歴!R3 -> 画面設計書 | AG3: =変更履歴!X3 -> 承認_請求書ワークフロー_画面設計書 | AT3: =変更履歴!AK3 -> 請求書ワークフロー | BG3: =変更履歴!AX3 -> 45553 | BK3: =変更履歴!BB3 -> 人見 | BO3: =変更履歴!BF3 -> 45553 | BS3: =変更履歴!BJ3 -> 人見
B7: 項目一覧
C9: 項目
D10: No. | E10: 項目名 | M10: I/O | P10: デフォルト値 | S10: データ型 | V10: 文字数/桁数 | Y10: 条件必須 | AB10: 入力必須 | AE10: 入力方式 | AH10: 備考
D11: 1 | E11: ID | M11: O | S11: ブール値
D12: 2 | E12: タイトル | M12: O | S12: 文字列
D13: 3 | E13: 状況 | M13: O | S13: 文字列
D14: 4 | E14: 申請区分 | M14: O | S14: 文字列
D15: 5 | E15: 申請者 | M15: O | S15: 文字列
D16: 6 | E16: 所属部署 | M16: O | S16: 文字列
D17: 7 | E17: 作成者 | M17: O | S17: 文字列
D18: 8 | E18: 作成日時 | M18: O | S18: 日付
D19: 9 | E19: 更新者 | M19: O | S19: 文字列
D20: 10 | E20: 更新日時 | M20: O | S20: 日付
D21: 11 | E21: 戻る | M21: I | AE21: ボタン
D22: 12
D23: 13
D24: 14
D25: 15
D26: 16
D27: 17
D28: 18

Sheet 画面レイアウト(編集)
B2: システム名 | H2: 業務分類 | L2: システム分類 | X2: ドキュメント種別 | AG2: ドキュメント名 | AT2: 画面名 | BG2: 作成日 | BK2: 作成者 | BO2: 更新日 | BS2: 更新者
B3: =変更履歴!B3 -> 受発注システム | H3: =変更履歴!H3 -> 承認 | L3: =変更履歴!L3 -> 受発注 | X3: =変更履歴!R3 -> 画面設計書 | AG3: =変更履歴!X3 -> 承認_請求書ワークフロー_画面設計書 | AT3: =変更履歴!AK3 -> 請求書ワークフロー | BG3: =変更履歴!AX3 -> 45553 | BK3: =変更履歴!BB3 -> 人見 | BO3: =変更履歴!BF3 -> 45553 | BS3: =変更履歴!BJ3 -> 人見

Sheet 項目一覧(編集)
B2: システム名 | H2: 業務分類 | L2: システム分類 | X2: ドキュメント種別 | AG2: ドキュメント名 | AT2: 画面名 | BG2: 作成日 | BK2: 作成者 | BO2: 更新日 | BS2: 更新者
B3: =変更履歴!B3 -> 受発注システム | H3: =変更履歴!H3 -> 承認 | L3: =変更履歴!L3 -> 受発注 | X3: =変更履歴!R3 -> 画面設計書 | AG3: =変更履歴!X3 -> 承認_請求書ワークフロー_画面設計書 | AT3: =変更履歴!AK3 -> 請求書ワークフロー | BG3: =変更履歴!AX3 -> 45553 | BK3: =変更履歴!BB3 -> 人見 | BO3: =変更履歴!BF3 -> 45553 | BS3: =変更履歴!BJ3 -> 人見
B7: 項目一覧
C9: 項目
D10: No. | E10: 親項目名 | K10: 項目名 | Q10: I/O | T10: デフォルト値 | W10: データ型 | Z10: 文字数/桁数 | AC10: 条件必須 | AF10: 入力必須 | AI10: 入力方式 | AL10: 備考
D11: 1 | K11: ID | Q11: - | W11: 数値
D12: 2 | K12: 状況 | Q12: I | T12: 申請前 | W12: 文字列 | AI12: プルダウン
D13: 3 | E13: 申請者入力エリア | K13: タイトル | Q13: I | W13: 文字列 | AI13: テキストボックス
D14: 4 | E14: 申請者入力エリア | K14: 申請者 | Q14: O | W14: 文字列 | AF14: ○
D15: 5 | E15: 申請者入力エリア | K15: 所属部署 | Q15: O | W15: 数値 | AF15: ○
D16: 6 | E16: 申請者入力エリア | K16: 申請区分 | Q16: I | W16: 文字列 | AF16: ○ | AI16: プルダウン
D17: 7 | E17: 申請者入力エリア | K17: 入金予定日 | Q17: I | W17: 日付 | AI17: テキストボックス
D18: 8 | E18: 申請者入力エリア | K18: 請求担当部署 | Q18: I | W18: 文字列 | AI18: テキストボックス
D19: 9 | E19: 申請者入力エリア | K19: 請求担当者名 | Q19: I | W19: 文字列 | AI19: テキストボックス
D20: 10 | E20: 申請者入力エリア | K20: 請求処理担当 | Q20: I | W20: 文字列 | AI20: プルダウン
D21: 11 | E21: 申請者入力エリア | K21: 申請ファイル | Q21: I | AF21: ○ | AL21: ファイル選択
D22: 12 | E22: 申請者入力エリア | K22: 備考 | Q22: I | W22: 文字列 | AI22: テキストエリア
D23: 13 | E23: グループマネージャ承認時入力エリア | K23: 承認者 | Q23: O | W23: 文字列 | AI23: プルダウン
D24: 14 | E24: グループマネージャ承認時入力エリア | K24: 承認/棄却日時 | Q24: O | W24: 日付
D25: 15 | E25: グループマネージャ承認時入力エリア | K25: コメント① | Q25: I | W25: 文字列 | AI25: テキストエリア
D26: 16 | E26: 部長承認時入力エリア | K26: 承認者 | Q26: O | W26: 文字列 | AI26: プルダウン
D27: 17 | E27: 部長承認時入力エリア | K27: 承認/棄却日時 | Q27: O | W27: 日付
D28: 18 | E28: 部長承認時入力エリア | K28: コメント② | Q28: I | W28: 文字列 | AI28: テキストエリア
D29: 19 | E29: 取締役承認時入力エリア | K29: 承認者 | Q29: O | W29: 文字列 | AI29: プルダウン
D30: 20 | E30: 取締役承認時入力エリア | K30: 承認/棄却日時 | Q30: O | W30: 日付
D31: 21 | E31: 取締役承認時入力エリア | K31: コメント③ | Q31: I | W31: 文字列 | AI31: テキストエリア
D32: 22 | E32: 最終承認時入力エリア | K32: 最終承認者 | Q32: O | W32: 文字列 | AI32: プルダウン
D33: 23 | E33: 最終承認時入力エリア | K33: 最終承認/棄却日時 | Q33: O | W33: 日付
D34: 24 | E34: 最終承認時入力エリア | K34: コメント④ | Q34: I | W34: 文字列 | AI34: テキストエリア
D35: 25
D36: 26
D37: 27
D38: 28
D39: 29
D40: 30
D41: 31
D42: 32
D43: 33
D44: 34
D45: 35
...

Sheet 確認事項
B2: 確認事項
B3: No. | C3: シート名 | D3: タイトル | E3: 概要 | F3: 確認済
B4: 1
B5: 2
B6: 3
B7: 4
B8: 5
B9: 6
B10: 7
B11: 8
B12: 9
B13: 10
B14: 11
B15: 12
... B54: 51

Sheet 参照
A1: 数値
A2: ブール値
A3: 文字列
A4: 日付
A5: リスト
A6: 辞書配列
