Workbook
Name CoreCells: 別紙_テンプレート_新システム!$A$8:$T$8
Name CoreCells: 別紙_テンプレート_現行!$A$8:$V$8
Name SiwaCoreCells: 別紙_テンプレート_新システム!$S$7:$T$8
Name SiwaCoreCells: 別紙_テンプレート_現行!$U$7:$V$8
Name 見積番号: 別紙_テンプレート_新システム!$D$3
Name 見積番号: 別紙_テンプレート_現行!$D$3
Name 見積名称: 別紙_テンプレート_新システム!$G$3
Name 見積名称: 別紙_テンプレート_現行!$F$3
Name 現場名: 別紙_テンプレート_新システム!$D$5
Name 現場名: 別紙_テンプレート_現行!$D$5
Name 作成日: 別紙_テンプレート_新システム!$I$4
Name 作成日: 別紙_テンプレート_現行!$H$4
Name 受注先: 別紙_テンプレート_新システム!$D$4
Name 受注先: 別紙_テンプレート_現行!$D$4
Name 担当者名: 別紙_テンプレート_新システム!$I$5
Name 担当者名: 別紙_テンプレート_現行!$H$5

Sheet 変更履歴
B2: システム名 | H2: 画面ID | L2: システム分類 | R2: ドキュメント種別 | X2: ドキュメント名 | AK2: 帳票名 | AX2: 作成日 | BB2: 作成者 | BF2: 更新日 | BJ2: 更新者
B3: 受発注システム | H3: =LEFT($X$3,FIND("_",$X$3)-1) -> MH0500 | L3: 受発注 | R3: =MID($X$3,FIND("_",$X$3,FIND("_",$X$3)+1)+1,LEN($X$3)-FIND("_",$X$3,FIND("_",$X$3)+1)) -> 帳票設計書 | X3: =REPLACE(LEFT(CELL("filename",$B$2),FIND(".x",CELL("filename",$B$2))-1),1,FIND("[",CELL("filename",$B$2)),) -> MH0500_部材リスト_帳票設計書 | AK3: =MID($X$3,FIND("_",$X$3)+1,FIND("_",$X$3,FIND("_",$X$3)+1)-FIND("_",$X$3)-1) -> 部材リスト | AX3: 45583 | BB3: 大谷 | BF3: 45583 | BJ3: 大谷
C7: 変更履歴
C8: 日付 | G8: 版数 | K8: 担当 | O8: 変更箇所 | Y8: 内容
C9: 45583 | G9: 1.0.0 | K9: 大谷 | O9: - | Y9: 新規作成

Sheet 概要
B2: システム名 | H2: 画面ID | L2: システム分類 | R2: ドキュメント種別 | X2: ドキュメント名 | AK2: 帳票名 | AX2: 作成日 | BB2: 作成者 | BF2: 更新日 | BJ2: 更新者
B3: =変更履歴!B3 -> 受発注システム | H3: =変更履歴!H3 -> MH0500 | L3: =変更履歴!L3 -> 受発注 | R3: =変更履歴!R3 -> 帳票設計書 | X3: =変更履歴!X3 -> MH0500_部材リスト_帳票設計書 | AK3: =変更履歴!AK3 -> 部材リスト | AX3: =変更履歴!AX3 -> 45583 | BB3: =変更履歴!BB3 -> 大谷 | BF3: =変更履歴!BF3 -> 45583 | BJ3: =変更履歴!BJ3 -> 大谷
D7: 帳票の名称 | H7: =AK3 -> 部材リスト
D8: 帳票テンプレート名 | H8: Template_部材リスト.xlsx
D9: ファイル種類 | H9: Excel
D10: ファイル拡張子 | H10: xlsx
D11: 文字コード | H11: -
D12: コーテーション | H12: -
D13: 固定長/可変長 | H13: -
D14: 区切り文字 | H14: -
D15: 用紙サイズ | H15: A3横
D16: 概要

Sheet 帳票レイアウト
B2: システム名 | H2: 画面ID | L2: システム分類 | R2: ドキュメント種別 | X2: ドキュメント名 | AK2: 帳票名 | AX2: 作成日 | BB2: 作成者 | BF2: 更新日 | BJ2: 更新者
B3: =変更履歴!B3 -> 受発注システム | H3: =変更履歴!H3 -> MH0500 | L3: =変更履歴!L3 -> 受発注 | R3: =変更履歴!R3 -> 帳票設計書 | X3: =変更履歴!X3 -> MH0500_部材リスト_帳票設計書 | AK3: =変更履歴!AK3 -> 部材リスト | AX3: =変更履歴!AX3 -> 45583 | BB3: =変更履歴!BB3 -> 大谷 | BF3: =変更履歴!BF3 -> 45583 | BJ3: =変更履歴!BJ3 -> 大谷
B6: ページ１

Sheet 項目一覧
B2: システム名 | H2: 画面ID | L2: システム分類 | R2: ドキュメント種別 | X2: ドキュメント名 | AK2: 帳票名 | AX2: 作成日 | BB2: 作成者 | BF2: 更新日 | BJ2: 更新者
B3: =変更履歴!B3 -> 受発注システム | H3: =変更履歴!H3 -> MH0500 | L3: =変更履歴!L3 -> 受発注 | R3: =変更履歴!R3 -> 帳票設計書 | X3: =変更履歴!X3 -> MH0500_部材リスト_帳票設計書 | AK3: =変更履歴!AK3 -> 部材リスト | AX3: =変更履歴!AX3 -> 45583 | BB3: =変更履歴!BB3 -> 大谷 | BF3: =変更履歴!BF3 -> 45583 | BJ3: =変更履歴!BJ3 -> 大谷
B7: 項目一覧
C9: 項目 | F9: フォントや文字サイズ、セル条件などは「別紙_テンプレート」準拠
D10: No. | E10: 項目名 | M10: データ型 | P10: 全角/半角 | S10: 文字数/桁数 | V10: データ取得元 | AB10: データ整形方法 | AR10: 整形後フォーマット | AX10: 備考
D11: 1 | E11: 見積№ | M11: 数値 | P11: 半角 | S11: 9 | V11: TD見積.見積番号
D12: 2 | E12: 見積名称 | M12: 文字列 | P12: 全角 | S12: 39 | V12: TD見積.見積件名
D13: 3 | E13: 受注先 | M13: 文字列 | P13: 全角 | S13: 28 | V13: TD見積.得意先名1
D14: 4 | E14: 日付 | M14: 日付 | P14: 半角 | S14: 8 | V14: 現在日付
D15: 5 | E15: 現場名 | M15: 文字列 | P15: 全角 | S15: 31 | V15: TD見積.現場名
D16: 6 | E16: 担当者 | M16: 文字列 | P16: 全角 | S16: 13 | V16: TM担当者.担当者名
D17: 7 | E17: 項目 | M17: 数値 | P17: 半角 | S17: 3 | V17: TD見積シートM.行番号
D18: 8 | E18: SP区分 | M18: 文字列 | P18: 半角 | S18: 1 | V18: TD見積シートM.SP区分 | AX18: 不要項目
D19: 9 | E19: PC区分 | M19: 文字列 | P19: 半角 | S19: 1 | V19: TD見積シートM.PC区分 | AX19: 不要項目
D20: 10 | E20: 製品№ | M20: 文字列 | P20: 半角 | S20: 7 | V20: TD見積シートM.製品NO
D21: 11 | E21: 仕様№ | M21: 文字列 | P21: 半角 | S21: 7 | V21: TD見積シートM.仕様NO
D22: 12 | E22: 名称 | M22: 文字列 | P22: 全角 | S22: 縮小して全体表示 | V22: TD見積シートM.漢字名称 | AB22: [TD見積シートM.見積区分]が C or A or S の場合は先頭に半角スペースを2つ付ける
D23: 13 | E23: W | M23: 数値 | P23: 半角 | S23: 縮小して全体表示 | V23: TD見積シートM.W
D24: 14 | E24: D | M24: 数値 | P24: 半角 | S24: 縮小して全体表示 | V24: TD見積シートM.D
D25: 15 | E25: H | M25: 数値 | P25: 半角 | S25: 縮小して全体表示 | V25: TD見積シートM.H
D26: 16 | E26: 備考 | M26: 文字列 | P26: 全角 | S26: 2 | V26: TD見積シートM.明細備考
D27: 17 | E27: 仕入先CD | M27: 文字列 | P27: 半角 | S27: 4 | V27: TD見積シートM.仕入先CD
D28: 18 | E28: 仕入先 | M28: 文字列 | P28: 全角 | S28: 8 | V28: TD見積シートM.仕入先名
D29: 19 | E29: 配送先CD | M29: 文字列 | P29: 半角 | S29: 4 | V29: TD見積シートM.配送先CD
D30: 20 | E30: 配送先 | M30: 文字列 | P30: 全角 | S30: 8 | V30: TD見積シートM.配送先名
D31: 21 | E31: 発注量 | M31: 数値 | P31: 半角 | S31: 縮小して全体表示 | V31: 21.客先在庫数、22.転用、23.使用量合計、28.発注調整数 | AB31: [23.使用量合計]と[28.発注調整数]の合計から[21.客先在庫数]と[22.転用]を引いた数 | AR31: 9.99
D32: 22 | E32: 単位 | M32: 文字列 | P32: 半角 | S32: 6 | V32: TD見積シートM.単位名 | AR32: 9.99
D33: 23 | E33: 客先在庫数 | M33: 数値 | P33: 半角 | S33: 縮小して全体表示 | V33: TD見積シートM.客先在庫数 | AR33: 9.99
D34: 24 | E34: 転用 | M34: 数値 | P34: 半角 | S34: 縮小して全体表示 | V34: TD見積シートM.転用 | AR34: 9.99
D35: 25 | E35: 発注調整数 | M35: 数値 | P35: 半角 | S35: 縮小して全体表示 | V35: TD見積シートM.発注調整数 | AR35: 9.99
D36: 26 | E36: 使用量合計 | M36: 数値 | P36: 半角 | S36: 縮小して全体表示 | V36: 27、28 | AB36: [27.][28.]項目の合計 | AR36: 9.99
D37: 27 | S37: 縮小して全体表示 | AR37: 9.99
D38: 28 | S38: 縮小して全体表示 | AR38: 9.99
D39: 29
D40: 30

Sheet 処理詳細
B2: システム名 | H2: 画面ID | L2: システム分類 | R2: ドキュメント種別 | X2: ドキュメント名 | AK2: 帳票名 | AX2: 作成日 | BB2: 作成者 | BF2: 更新日 | BJ2: 更新者
B3: =変更履歴!B3 -> 受発注システム | H3: =変更履歴!H3 -> MH0500 | L3: =変更履歴!L3 -> 受発注 | R3: =変更履歴!R3 -> 帳票設計書 | X3: =変更履歴!X3 -> MH0500_部材リスト_帳票設計書 | AK3: =変更履歴!AK3 -> 部材リスト | AX3: =変更履歴!AX3 -> 45583 | BB3: =変更履歴!BB3 -> 大谷 | BF3: =変更履歴!BF3 -> 45583 | BJ3: =変更履歴!BJ3 -> 大谷
B6: SQL1 | H6: select | J6: 見積番号 | R6: TD見積.見積番号
J7: 見積日付 | R7: TD見積.見積日付
J8: 物件種別 | R8: TD見積.物件種別
J9: 得意先CD | R9: TD見積.得意先CD
J10: 見積件名 | R10: TD見積.見積件名
J11: 合計金額 | R11: TD見積.合計金額 + TD見積.出精値引 AS 合計金額
J12: 見積書出力日 | R12: TD見積.見積書出力日
J13: 注文発行日 | R13: TD見積.注文発行日
H14: from | J14: FROM TD見積 AS MT
H15: where | J15: WHERE | AK15: WHERE句が存在する場合
K16: and 得意先CD LIKE '画面.得意先CD%' | AK16: 画面.得意先CDが存在する場合
K17: and 納入先CD Like '画面.納入先CD%' | AK17: 画面.納入先CDが存在する場合
K18: and MT.見積番号 >= 画面.開始見積番号 And MT.見積番号 <= 画面.終了見積番号 | AK18: 画面.開始見積番号または画面.終了見積番号が存在する場合
K19: and 見積件名 Like '%画面.見積件名%' | AK19: 画面.見積件名が存在する場合
K20: and MT.合計金額 + MT.出精値引 >= 画面.開始見積金額 And MT.合計金額 + MT.出精値引 <= 画面.終了見積金額 | AK20: 画面.開始見積金額または画面.終了見積金額が存在する場合
K21: and MT.見積日付 >= 画面.開始見積日付 And MT.見積日付 <= 画面.終了見積日付 | AK21: 画面.開始見積日付または画面.終了見積日付が存在する場合
H22: order by | J22: ORDER BY MT.見積日付 DESC, MT.見積番号 DESC | V22: MT.見積日付、MT.見積番号の降順でソート
B23: SQL2 | H23: select | J23: 見積番号 | R23: TD見積.見積番号
J24: 見積件名 | R24: TD見積.見積件名
J25: 得意先名1 | R25: TD見積.得意先名1
J26: 得意先名2 | R26: TD見積.得意先名2
J27: 現場名 | R27: TD見積.現場名
J28: 納期S | R28: TD見積.納期S
J29: 納期E | R29: TD見積.納期E
H30: from | J30: From TD見積
H31: where | J31: WHERE 見積番号 = 画面.見積番号
B32: SQL3 | H32: select | J32: CreateDate | R32: TW見積出力履歴.CreateDate
J33: PCName | R33: TW見積出力履歴.PCName
H34: from | J34: From TW見積出力履歴
H35: where | J35: WHERE ListName = "部材リスト"
K36: AND Number = 画面.見積番号
B37: SQL4 | H37: select | J37: @MAX仕分番号 | R37: MAX(仕分MAX.仕分番号) | AK37: 仕分ＭＡＸ取得 | AP37: @MAX仕分番号は変数
H38: from | J38: FROM
K39: (
K40: SQL5
K41: ) AS 仕分MAX
B42: SQL5 | H42: select | J42: 見積番号 | R42: TD見積シート内訳.見積番号
J43: 仕分番号 | R43: TD見積シート内訳.仕分番号
...

Sheet 処理詳細_書き方
B2: システム名 | H2: 画面ID | L2: 業務分類 | R2: ドキュメント種別 | X2: ドキュメント名 | AK2: 帳票名 | AX2: 作成日 | BB2: 作成者 | BF2: 更新日 | BJ2: 更新者
B3: =変更履歴!B3 -> 受発注システム | H3: =変更履歴!H3 -> MH0500 | L3: =変更履歴!L3 -> 受発注 | R3: =変更履歴!R3 -> 帳票設計書 | X3: =変更履歴!X3 -> MH0500_部材リスト_帳票設計書 | AK3: =変更履歴!AK3 -> 部材リスト | AX3: =変更履歴!AX3 -> 45583 | BB3: =変更履歴!BB3 -> 大谷 | BF3: =変更履歴!BF3 -> 45583 | BJ3: =変更履歴!BJ3 -> 大谷
B7: 1.タイトルを記載 | H7: select | J7: 項目名 | R7: 格納テーブル
J8: 仕入先CD | R8: VM支払予定情報.仕入先CD
J9: 仕入先名1 | R9: VM支払予定情報.仕入先名1
H10: from | J10: 使用するテーブル名を記載
J11: TD売上請求H
J12: TD見積
J13: TM納入先
H14: join | J14: 結合方式
K15: 結合テーブル名
M16: 結合条件
L17: and | M17: 結合条件
L18: or | M18: 結合条件
J19: INNER JOIN
K20: TM納入先
M21: [TD見積.納入得意先CD] = [TM納入先.得意先CD]
L22: and | M22: [TD見積.納入先CD] = [TM納入先.納入先CD]
H23: where | K23: 取得条件 | AK23: パラメータの意味が分かる場合は記載する
J24: and | K24: 取得条件
J25: or | K25: 取得条件
J26: ※可能な限り日本語化する
K27: [TD見積.得意先CD] = '8001' | AK27: 8001'はヤオコーの得意先CD
J28: and | K28: [TD売上請求H.請求日付]が[画面.請求期間From]以降
H32: order by | J32: ソート条件を記載
J33: [画面.iYK物件区分]が1の場合は[TD見積.納入得意先CD],[TD見積.納入先CD],[TD売上請求H.見積番号]を昇順でソート
H36: group byなどほかの条件がある場合は行を追加して記載

Sheet 確認事項
B2: 確認事項
B3: No. | C3: シート名 | D3: タイトル | E3: 概要 | F3: 回答 | G3: 確認済
B4: 1 | C4: 項目一覧 | D4: 項目27,28以降について | E4: 仕分数1～30まで必要な数入れる認識であっているか。その際に罫線とヘッダも追加するか。 | F4: 認識あっている | G4: 〇
B5: 2 | C5: 項目一覧 | D5: 16.備考 | E5: 2文字しか入らないが問題ないか | F5: 問題ない | G5: 〇
B6: 3 | C6: 処理詳細 | D6: ストアド連携待ち | E6: usp_MT0400部材リスト出力_展開_3150が存在しないため連携依頼中 | F6: 不要になった | G6: 〇
B7: 4
B8: 5
B9: 6
B10: 7
B11: 8
B12: 9
B13: 10
B14: 11
B15: 12
B16: 13
B17: 14
B18: 15
... B54: 51

Sheet 別紙_テンプレート_現行
C1: 部門別部材リスト
B3: 見積№ | E3: 見積名称
B4: 受注先 | G4: 日付
B5: 現場名 | G5: 担当者
A7: 項目 | B7: SP 区分 | C7: PC 区分 | D7: 製品№ | E7: 仕様№ | F7: 名称 | G7: Ｗ | H7: Ｄ | I7: Ｈ | J7: 備考 | K7: 仕入先CD | L7: 仕入先 | M7: 配送先CD | N7: 配送先 | O7: 発注量 | P7: 単位 | Q7: 客先 在庫数 | R7: 転用 | S7: 発注 調整数 | T7: 使用量 合計
O8: =IF(ISERROR(T8-Q8-R8+S8),"",T8-Q8-R8+S8) -> 0 | T8: =IF(SUM(U8:V8)=0,0,SUM(U8:V8)) -> 0

Sheet 別紙_テンプレート_新システム
C1: 部門別部材リスト
B3: 見積№ | D3: 見積名称
B4: 受注先 | H4: 日付
B5: 現場名 | H5: 担当者
A7: 項目 | B7: 製品№ | C7: 仕様№ | D7: 名称 | F7: Ｗ | G7: Ｄ | H7: Ｈ | I7: 備考 | J7: 仕入先CD | K7: 仕入先 | L7: 配送先CD | M7: 配送先 | N7: 発注量 | O7: 単位 | P7: 客先 在庫数 | Q7: 転用 | R7: 使用量 合計
N8: =IF(ISERROR(R8-P8-Q8+#REF!),"",R8-P8-Q8+#REF!) | R8: =IF(SUM(S8:T8)=0,0,SUM(S8:T8)) -> 0

Sheet 別紙_印刷レイアウト

Sheet 参照
A1: 数値
A2: ブール値
A3: 文字列
A4: 日付
A5: リスト
A6: 辞書配列
