Workbook

Sheet 変更履歴
B2: システム名 | H2: 画面ID | L2: システム分類 | R2: ドキュメント種別 | X2: ドキュメント名 | AK2: 帳票名 | AX2: 作成日 | BB2: 作成者 | BF2: 更新日 | BJ2: 更新者
B3: 受発注システム | H3: =LEFT($X$3,FIND("_",$X$3)-1) -> MH0800 | L3: 受発注 | R3: =MID($X$3,FIND("_",$X$3,FIND("_",$X$3)+1)+1,LEN($X$3)-FIND("_",$X$3,FIND("_",$X$3)+1)) -> 帳票設計書 | X3: =REPLACE(LEFT(CELL("filename",$B$2),FIND(".x",CELL("filename",$B$2))-1),1,FIND("[",CELL("filename",$B$2)),) -> MH0800_発注一覧表_帳票設計書 | AK3: =MID($X$3,FIND("_",$X$3)+1,FIND("_",$X$3,FIND("_",$X$3)+1)-FIND("_",$X$3)-1) -> 発注一覧表 | AX3: 45583 | BB3: 大谷 | BF3: 45583 | BJ3: 大谷
C7: 変更履歴
C8: 日付 | G8: 版数 | K8: 担当 | O8: 変更箇所 | Y8: 内容
C9: 45583 | G9: 1.0.0 | K9: 大谷 | O9: - | Y9: 新規作成

Sheet 概要
B2: システム名 | H2: 画面ID | L2: システム分類 | R2: ドキュメント種別 | X2: ドキュメント名 | AK2: 帳票名 | AX2: 作成日 | BB2: 作成者 | BF2: 更新日 | BJ2: 更新者
B3: =変更履歴!B3 -> 受発注システム | H3: =変更履歴!H3 -> MH0800 | L3: =変更履歴!L3 -> 受発注 | R3: =変更履歴!R3 -> 帳票設計書 | X3: =変更履歴!X3 -> MH0800_発注一覧表_帳票設計書 | AK3: =変更履歴!AK3 -> 発注一覧表 | AX3: =変更履歴!AX3 -> 45583 | BB3: =変更履歴!BB3 -> 大谷 | BF3: =変更履歴!BF3 -> 45583 | BJ3: =変更履歴!BJ3 -> 大谷
D7: 帳票の名称 | H7: =AK3 -> 発注一覧表
D8: 帳票テンプレート名 | H8: -
D9: ファイル種類 | H9: PDF
D10: ファイル拡張子 | H10: pdf
D11: 文字コード | H11: -
D12: コーテーション | H12: -
D13: 固定長/可変長 | H13: -
D14: 区切り文字 | H14: -
D15: 用紙サイズ | H15: A4横 | J15: コメントB4
D16: 概要

Sheet 帳票レイアウト
B2: システム名 | H2: 画面ID | L2: システム分類 | R2: ドキュメント種別 | X2: ドキュメント名 | AK2: 帳票名 | AX2: 作成日 | BB2: 作成者 | BF2: 更新日 | BJ2: 更新者
B3: =変更履歴!B3 -> 受発注システム | H3: =変更履歴!H3 -> MH0800 | L3: =変更履歴!L3 -> 受発注 | R3: =変更履歴!R3 -> 帳票設計書 | X3: =変更履歴!X3 -> MH0800_発注一覧表_帳票設計書 | AK3: =変更履歴!AK3 -> 発注一覧表 | AX3: =変更履歴!AX3 -> 45583 | BB3: =変更履歴!BB3 -> 大谷 | BF3: =変更履歴!BF3 -> 45583 | BJ3: =変更履歴!BJ3 -> 大谷
B6: ページ１

Sheet 項目一覧
B2: システム名 | H2: 画面ID | L2: システム分類 | R2: ドキュメント種別 | X2: ドキュメント名 | AK2: 帳票名 | AX2: 作成日 | BB2: 作成者 | BF2: 更新日 | BJ2: 更新者
B3: =変更履歴!B3 -> 受発注システム | H3: =変更履歴!H3 -> MH0800 | L3: =変更履歴!L3 -> 受発注 | R3: =変更履歴!R3 -> 帳票設計書 | X3: =変更履歴!X3 -> MH0800_発注一覧表_帳票設計書 | AK3: =変更履歴!AK3 -> 発注一覧表 | AX3: =変更履歴!AX3 -> 45583 | BB3: =変更履歴!BB3 -> 大谷 | BF3: =変更履歴!BF3 -> 45583 | BJ3: =変更履歴!BJ3 -> 大谷
B7: 項目一覧
C9: 項目 | F9: フォントや文字サイズ、セル条件などは「別紙_テンプレート」準拠
D10: No. | E10: 項目名 | M10: データ型 | P10: 全角/半角 | S10: 文字数/桁数 | V10: データ取得元 | AB10: データ整形方法 | AR10: 整形後フォーマット | AX10: 備考
D11: 1 | E11: 作成日 | M11: 日付 | P11: 半角 | V11: 現在日付 | AR11: yyyy年mm月dd日
D12: 2 | E12: 物件名 | M12: 文字列 | P12: 全角 | V12: SQL1.見積件名
D13: 3 | E13: 納入先CD | M13: 数値 | P13: 半角 | V13: SQL1.納入先CD | AR13: [99999]
D14: 4 | E14: 納入先名 | M14: 文字列 | P14: 全角 | V14: SQL1.納入先名1
D15: 5 | E15: 仕入先CD | M15: 数値 | P15: 半角 | V15: SQL1.仕入先CD | AR15: [99999]
D16: 6 | E16: 仕入先名 | M16: 文字列 | P16: 全角 | V16: SQL1.仕入先名1
D17: 7 | E17: 見積番号 | M17: 数値 | P17: 半角 | V17: SQL1.見積番号
D18: 8 | E18: 見積日付 | M18: 日付 | P18: 半角 | V18: SQL1.見積日付 | AR18: yyyy年mm月dd日
D19: 9 | E19: 項目 | M19: 数値 | P19: 半角 | V19: SQL1.行番号,SQL1.見積区分 | AB19: [SQL1.見積区分]が"A","C","S"ではないときのみ[SQL1.行番号]を表示
D20: 10 | E20: 製品No | M20: 数値 | P20: 半角 | V20: SQL1.製品NO
D21: 11 | E21: 仕様No | M21: 数値 | P21: 半角 | V21: SQL1.仕様NO
D22: 12 | E22: 品名 | M22: 文字列 | P22: 全角 | V22: SQL1.漢字名称
D23: 13 | E23: サイズ | M23: 数値 | P23: 半角 | V23: SQL1.製品区分,SQL1.W,SQL1.H,SQL1.H1,SQL1.H2,SQL1.D,SQL1.D1,SQL1.D2 | AB23: [SQL1.W]×[SQL1.D]×[SQL1.H]を表示。 [W]が0の場合は表示しない。 [D]が0の場合はD1/D2を表示。D1,D2どちらも0の場合は表示しない。 [H]が0の場合はH1/H2を表示。H1,H2どちらも0の場合は表示しない。 | AR23: W×D×H
D24: 14 | E24: 数量 | M24: 数値 | P24: 半角 | V24: SQL1.発注数
D25: 15 | E25: 単位 | M25: 数値 | P25: 半角 | V25: SQL1.単位名
D26: 16 | E26: 単価 | M26: 数値 | P26: 半角 | V26: SQL1.仕入単価,SQL1.U区分 | AB26: [U区分]が"U"の場合、[SQL1.仕入単価]+"未"と表示する | AR26: 999999
D27: 17 | E27: 金額 | M27: 数値 | P27: 半角 | V27: SQL1.仕入金額 | AB27: 1レコードごとの[SQL1.仕入金額] | AR27: 999999
D28: 18 | E28: 発注数計 | V28: SQL1.発注数
D29: 19 | E29: 発注数計D
D30: 20 | E30: 仕入金額計 | M30: 数値 | P30: 半角 | V30: SQL1.仕入金額 | AB30: 仕入先ごとの[SQL1.仕入金額]の合計 | AR30: 999999

Sheet 処理詳細
B2: システム名 | H2: 画面ID | L2: システム分類 | R2: ドキュメント種別 | X2: ドキュメント名 | AK2: 帳票名 | AX2: 作成日 | BB2: 作成者 | BF2: 更新日 | BJ2: 更新者
B3: =変更履歴!B3 -> 受発注システム | H3: =変更履歴!H3 -> MH0800 | L3: =変更履歴!L3 -> 受発注 | R3: =変更履歴!R3 -> 帳票設計書 | X3: =変更履歴!X3 -> MH0800_発注一覧表_帳票設計書 | AK3: =変更履歴!AK3 -> 発注一覧表 | AX3: =変更履歴!AX3 -> 45583 | BB3: =変更履歴!BB3 -> 大谷 | BF3: =変更履歴!BF3 -> 45583 | BJ3: =変更履歴!BJ3 -> 大谷
B6: SQL1 | H6: insert | J6: 見積番号 | R6: tmp_sql1.見積番号
J7: 見積件名 | R7: tmp_sql1.見積件名
J8: 納入得意先CD | R8: tmp_sql1.納入得意先CD
J9: 納入先CD | R9: tmp_sql1.納入先CD
J10: 納入先名1 | R10: tmp_sql1.納入先名1
J11: 納入先名2 | R11: tmp_sql1.納入先名2
J12: 行番号 | R12: tmp_sql1.行番号
J13: SP区分 | R13: tmp_sql1.SP区分
J14: PC区分 | R14: tmp_sql1.PC区分
J15: 製品NO | R15: tmp_sql1.製品NO
J16: 仕様NO | R16: tmp_sql1.仕様NO
J17: ベース色 | R17: tmp_sql1.ベース色
J18: 漢字名称 | R18: tmp_sql1.漢字名称
... J28: 仕入単価 | R28: tmp_sql1.仕入単価
J29: 仕入金額 | R29: tmp_sql1.発注数 * tmp_sql1.仕入単価 | AK29: dbo.fn_CutFraction(TM仕入先.仕入端数,発注数 * 仕入単価,@decimalPoint)
J30: 仕入先CD | R30: tmp_sql1.仕入先CD
J31: 仕入先名1 | R31: TM仕入先.仕入先名1
J32: 見積区分 | R32: tmp_sql1.見積区分
J33: 見積日付 | R33: tmp_sql1.見積日付
J34: U区分 | R34: tmp_sql1.U区分
H35: from | J35: (
K36: SQL2
K37: SQL3
K38: SQL4
J39: ) tmp_sql1
J40: TM仕入先
H41: join | J41: (
H42: union | L42: SQL2
K43: union all
L44: SQL3
K45: union all
L46: SQL4
J47: ) tmp_sql1
J48: LEFT JOIN
K49: TM仕入先
M50: tmp_sql1.仕入先CD = TM仕入先.仕入先CD
H51: where | K51: tmp_sql1.仕入先CD >= COALESCE([画面.開始仕入先CD], tmp_sql1.仕入先CD)
J52: AND | K52: tmp_sql1.仕入先CD <= COALESCE([画面.終了仕入先CD], tmp_sql1.仕入先CD)
...

Sheet 処理詳細_書き方
B2: システム名 | H2: 画面ID | L2: 業務分類 | R2: ドキュメント種別 | X2: ドキュメント名 | AK2: 帳票名 | AX2: 作成日 | BB2: 作成者 | BF2: 更新日 | BJ2: 更新者
B3: =変更履歴!B3 -> 受発注システム | H3: =変更履歴!H3 -> MH0800 | L3: =変更履歴!L3 -> 受発注 | R3: =変更履歴!R3 -> 帳票設計書 | X3: =変更履歴!X3 -> MH0800_発注一覧表_帳票設計書 | AK3: =変更履歴!AK3 -> 発注一覧表 | AX3: =変更履歴!AX3 -> 45583 | BB3: =変更履歴!BB3 -> 大谷 | BF3: =変更履歴!BF3 -> 45583 | BJ3: =変更履歴!BJ3 -> 大谷
B7: 1.タイトルを記載 | H7: select | J7: 項目名 | R7: 格納テーブル
J8: 仕入先CD | R8: VM支払予定情報.仕入先CD
J9: 仕入先名1 | R9: VM支払予定情報.仕入先名1
H10: from | J10: 使用するテーブル名を記載
J11: TD売上請求H
J12: TD見積
J13: TM納入先
H14: join | J14: 結合方式
K15: 結合テーブル名
M16: 結合条件
L17: and | M17: 結合条件
L18: or | M18: 結合条件
J19: INNER JOIN
K20: TM納入先
M21: [TD見積.納入得意先CD] = [TM納入先.得意先CD]
L22: and | M22: [TD見積.納入先CD] = [TM納入先.納入先CD]
H23: where | K23: 取得条件 | AK23: パラメータの意味が分かる場合は記載する
J24: and | K24: 取得条件
J25: or | K25: 取得条件
J26: ※可能な限り日本語化する
K27: [TD見積.得意先CD] = '8001' | AK27: 8001'はヤオコーの得意先CD
J28: and | K28: [TD売上請求H.請求日付]が[画面.請求期間From]以降
H32: order by | J32: ソート条件を記載
J33: [画面.iYK物件区分]が1の場合は[TD見積.納入得意先CD],[TD見積.納入先CD],[TD売上請求H.見積番号]を昇順でソート
H36: group byなどほかの条件がある場合は行を追加して記載

Sheet 確認事項
B2: 確認事項
B3: No. | C3: シート名 | D3: タイトル | E3: 概要 | F3: 回答 | G3: 確認済
B4: 1 | C4: 項目一覧 | D4: No18,19 | E4: 18.19項目は何も表示されていないが必要な項目か確認。どのような内容を表示しているのか。 | F4: 表示されていない項目は不要 | G4: 〇
B5: 2
B6: 3
B7: 4
B8: 5
B9: 6
B10: 7
B11: 8
B12: 9
B13: 10
B14: 11
B15: 12
B16: 13
... B54: 51

Sheet 帳票レイアウト確認点

Sheet 別紙_印刷レイアウト

Sheet 参照
A1: 数値
A2: ブール値
A3: 文字列
A4: 日付
A5: リスト
A6: 辞書配列
