Workbook
Name CoreCells: #REF!
Name 見積件名: #REF!
Name 作成日: #REF!
Name 入庫日: #REF!

Sheet 変更履歴
B2: システム名 | H2: 画面ID | L2: システム分類 | R2: ドキュメント種別 | X2: ドキュメント名 | AK2: 帳票名 | AX2: 作成日 | BB2: 作成者 | BF2: 更新日 | BJ2: 更新者
B3: 受発注システム | H3: =LEFT($X$3,FIND("_",$X$3)-1) -> MH0900 | L3: 受発注 | R3: =MID($X$3,FIND("_",$X$3,FIND("_",$X$3)+1)+1,LEN($X$3)-FIND("_",$X$3,FIND("_",$X$3)+1)) -> 帳票設計書 | X3: =REPLACE(LEFT(CELL("filename",$B$2),FIND(".x",CELL("filename",$B$2))-1),1,FIND("[",CELL("filename",$B$2)),) -> MH0900_入庫リスト_帳票設計書 | AK3: =MID($X$3,FIND("_",$X$3)+1,FIND("_",$X$3,FIND("_",$X$3)+1)-FIND("_",$X$3)-1) -> 入庫リスト | AX3: 45581 | BB3: 大谷 | BF3: 45581 | BJ3: 大谷
C7: 変更履歴
C8: 日付 | G8: 版数 | K8: 担当 | O8: 変更箇所 | Y8: 内容
C9: 45581 | G9: 1.0.0 | K9: 大谷 | O9: - | Y9: 新規作成

Sheet 概要
B2: システム名 | H2: 画面ID | L2: システム分類 | R2: ドキュメント種別 | X2: ドキュメント名 | AK2: 帳票名 | AX2: 作成日 | BB2: 作成者 | BF2: 更新日 | BJ2: 更新者
B3: =変更履歴!B3 -> 受発注システム | H3: =変更履歴!H3 -> MH0900 | L3: =変更履歴!L3 -> 受発注 | R3: =変更履歴!R3 -> 帳票設計書 | X3: =変更履歴!X3 -> MH0900_入庫リスト_帳票設計書 | AK3: =変更履歴!AK3 -> 入庫リスト | AX3: =変更履歴!AX3 -> 45581 | BB3: =変更履歴!BB3 -> 大谷 | BF3: =変更履歴!BF3 -> 45581 | BJ3: =変更履歴!BJ3 -> 大谷
D7: 帳票の名称 | H7: =AK3 -> 入庫リスト
D8: 帳票テンプレート名 | H8: Temp社内伝入庫リスト.xlsx
D9: ファイル種類 | H9: Excel
D10: ファイル拡張子 | H10: xlsx
D11: 文字コード | H11: -
D12: コーテーション | H12: -
D13: 固定長/可変長 | H13: -
D14: 区切り文字 | H14: -
D15: 用紙サイズ | H15: A4横
D16: 概要

Sheet 帳票レイアウト
B2: システム名 | H2: 画面ID | L2: システム分類 | R2: ドキュメント種別 | X2: ドキュメント名 | AK2: 帳票名 | AX2: 作成日 | BB2: 作成者 | BF2: 更新日 | BJ2: 更新者
B3: =変更履歴!B3 -> 受発注システム | H3: =変更履歴!H3 -> MH0900 | L3: =変更履歴!L3 -> 受発注 | R3: =変更履歴!R3 -> 帳票設計書 | X3: =変更履歴!X3 -> MH0900_入庫リスト_帳票設計書 | AK3: =変更履歴!AK3 -> 入庫リスト | AX3: =変更履歴!AX3 -> 45581 | BB3: =変更履歴!BB3 -> 大谷 | BF3: =変更履歴!BF3 -> 45581 | BJ3: =変更履歴!BJ3 -> 大谷
B6: ページ１

Sheet 項目一覧
B2: システム名 | H2: 画面ID | L2: システム分類 | R2: ドキュメント種別 | X2: ドキュメント名 | AK2: 帳票名 | AX2: 作成日 | BB2: 作成者 | BF2: 更新日 | BJ2: 更新者
B3: =変更履歴!B3 -> 受発注システム | H3: =変更履歴!H3 -> MH0900 | L3: =変更履歴!L3 -> 受発注 | R3: =変更履歴!R3 -> 帳票設計書 | X3: =変更履歴!X3 -> MH0900_入庫リスト_帳票設計書 | AK3: =変更履歴!AK3 -> 入庫リスト | AX3: =変更履歴!AX3 -> 45581 | BB3: =変更履歴!BB3 -> 大谷 | BF3: =変更履歴!BF3 -> 45581 | BJ3: =変更履歴!BJ3 -> 大谷
B7: 項目一覧
C9: 項目 | F9: フォントや文字サイズ、セル条件などは「別紙_テンプレート」準拠
D10: No. | E10: 項目名 | M10: データ型 | P10: 全角/半角 | S10: 文字数/桁数 | V10: データ取得元 | AB10: データ整形方法 | AR10: 整形後フォーマット | AX10: 備考
D11: 1 | E11: 店舗名 | M11: 文字列 | P11: 全角 | V11: [SQL1.納入先名1],[SQL1.納入先名2] | AB11: [SQL1.納入先名1] + [SQL1.納入先名2]
D12: 2 | E12: 作成日 | M12: 文字列 | P12: 全角 | S12: 14 | V12: 現在日付 | AB12: "作成日：" + [現在日付] | AR12: 作成日：9999/99/99
D13: 3 | E13: 見積件名 | M13: 文字列 | P13: 全角 | S13: 縮小して全体表示 | V13: [SQL1.見積件名],[SQL1.見積番号] | AB13: [SQL1.見積件名] + "No." + [SQL1.見積番号]、[SQL1.見積件名]と[SQL1.見積番号]は空の場合は半角スペース1つを表示
D14: 4 | E14: 入庫日 | M14: 日付 | P14: 全角 | S14: 13 | V14: [SQL1.入庫日] | AB14: "入庫日：" + [SQL1.入庫日] | AR14: 入庫日：9999/99/99
D15: 5 | E15: 積込日 | M15: 日付 | P15: 全角 | S15: 15 | V15: 空
D16: 6 | E16: 保管期限 | M16: 日付 | P16: 全角 | S16: 11 | V16: 空
D17: 7 | E17: 発注者 | M17: 文字列 | P17: 全角 | V17: 出力者の名前 | AX17: 現行はActiveDirectoryのユーザを取得している。新システムでの対応要検討。Pleasanterのユーザ？
D18: 8 | E18: 入庫日付 | M18: 日付 | P18: 半角 | S18: 縮小して全体表示 | V18: [SQL1.入庫日]
D19: 9 | E19: バーコード | M19: 文字列 | P19: 半角 | S19: 縮小して全体表示 | V19: [SQL1.入出庫用CD] | AB19: [SQL1.入出庫用CD]が空の場合は""、空でない場合は"＊" + [SQL1.入出庫用CD] + "＊"
D20: 10 | E20: No | M20: 数値 | P20: 半角 | V20: １から連番
D21: 11 | E21: 棚番 | M21: 文字列 | P21: 半角 | S21: 縮小して全体表示 | V21: [SQL1.棚番名]
D22: 12 | E22: 仕入先CD | M22: 文字列 | P22: 半角 | S22: 縮小して全体表示 | V22: [SQL1.仕入先CD]
D23: 13 | E23: 仕入先名 | M23: 文字列 | P23: 全角 | S23: 縮小して全体表示 | V23: [SQL1.仕入先名]
D24: 14 | E24: 製品No. | M24: 文字列 | P24: 半角 | S24: 縮小して全体表示 | V24: [SQL1.製品NO]
D25: 15 | E25: 仕様No. | M25: 文字列 | P25: 半角 | S25: 縮小して全体表示 | V25: [SQL1.仕様NO]
D26: 16 | E26: 名称 | M26: 文字列 | P26: 全角 | S26: 縮小して全体表示 | V26: [SQL1.漢字名称]
D27: 17 | E27: W | M27: 数値 | P27: 半角 | S27: 縮小して全体表示 | V27: [SQL1.W]
D28: 18 | E28: D | M28: 数値 | P28: 半角 | S28: 縮小して全体表示 | V28: [SQL1.D]
D29: 19 | E29: H | M29: 数値 | P29: 半角 | S29: 縮小して全体表示 | V29: [SQL1.H]
D30: 20 | E30: 発注数 | M30: 数値 | P30: 半角 | S30: 縮小して全体表示 | V30: [SQL1.発注数] | AR30: 9999
D31: 21 | E31: チェック | V31: 空
D32: 22
D33: 23
D34: 24
D35: 25
D36: 26
D37: 27
D38: 28
D39: 29
D40: 30
D41: 31
D42: 32
D43: 33
... D46: 36

Sheet 処理詳細
B2: システム名 | H2: 画面ID | L2: システム分類 | R2: ドキュメント種別 | X2: ドキュメント名 | AK2: 帳票名 | AX2: 作成日 | BB2: 作成者 | BF2: 更新日 | BJ2: 更新者
B3: =変更履歴!B3 -> 受発注システム | H3: =変更履歴!H3 -> MH0900 | L3: =変更履歴!L3 -> 受発注 | R3: =変更履歴!R3 -> 帳票設計書 | X3: =変更履歴!X3 -> MH0900_入庫リスト_帳票設計書 | AK3: =変更履歴!AK3 -> 入庫リスト | AX3: =変更履歴!AX3 -> 45581 | BB3: =変更履歴!BB3 -> 大谷 | BF3: =変更履歴!BF3 -> 45581 | BJ3: =変更履歴!BJ3 -> 大谷
B6: SQL1 | H6: select | J6: 入庫日 | R6: TD見積シートM.入庫日
J7: 出庫日 | R7: TD見積シートM.出庫日
J8: 見積番号 | R8: TD見積.見積番号
J9: 見積日付 | R9: TD見積.見積日付
J10: 見積件名 | R10: TD見積.見積件名
J11: 得意先CD | R11: TD見積.得意先CD
J12: 得意先名1 | R12: TD見積.得意先名1
J13: 仕入業者CD | R13: TD見積シートM.仕入業者CD
J14: 仕入業者名 | R14: TD見積シートM.仕入業者名
J15: 仕入先CD | R15: TD見積シートM.仕入先CD
J16: 仕入先名 | R16: TD見積シートM.仕入先名
J17: 配送先CD | R17: TD見積シートM.配送先CD
J18: 配送先名 | R18: TD見積シートM.配送先名
... J36: 納入先名2 | R36: TD見積.納入先名2
H37: from | J37: TD見積
J38: TD見積シートM
J39: SQL2
J40: TM製品
J41: SQL3
H42: join | J42: INNER
K43: TD見積シートM
L44: [TD見積.見積番号]=[TD見積シートM.見積番号]
J45: LEFT
K46: SQL2
L47: [TD見積シートM.見積明細連番]=[SQL2.見積明細連番]
J48: LEFT
K49: TM製品
L50: [TD見積シートM.製品NO]=[TM製品.製品NO]
K51: AND | L51: [TD見積シートM.仕様NO]=[TM製品.仕様NO]
J52: LEFT
K53: SQL3
L54: [TM製品.製品NO]=[SQL3.製品NO]
K55: AND | L55: [TM製品.仕様NO]=[SQL3.仕様NO]
H56: where | K56: ([TD見積.社内伝票扱い]=1 or [TD見積シートM.配送先CD]="03") | AK56: [TD見積シートM.配送先CD]が"03"のとき、[TD見積シートM.配送先名]が"三和納品"
J57: AND | K57: [TD見積.受注区分]=1
J58: AND | K58: NOT([TD見積シートM.仕入先CD] IN("3150")) | AK58: [TD見積シートM.仕入先CD]が"3150"を含まない
J59: AND | K59: [TD見積シートM.見積区分] NOT IN("A","C","S") | AK59: [TD見積シートM.見積区分]が"A","C","S"を含まない
J60: AND | K60: [TD見積シートM.発注数] <> 0 | AK60: [TD見積シートM.発注数]が0でない
...

Sheet 処理詳細_書き方
B2: システム名 | H2: 画面ID | L2: 業務分類 | R2: ドキュメント種別 | X2: ドキュメント名 | AK2: 帳票名 | AX2: 作成日 | BB2: 作成者 | BF2: 更新日 | BJ2: 更新者
B3: =変更履歴!B3 -> 受発注システム | H3: =変更履歴!H3 -> MH0900 | L3: =変更履歴!L3 -> 受発注 | R3: =変更履歴!R3 -> 帳票設計書 | X3: =変更履歴!X3 -> MH0900_入庫リスト_帳票設計書 | AK3: =変更履歴!AK3 -> 入庫リスト | AX3: =変更履歴!AX3 -> 45581 | BB3: =変更履歴!BB3 -> 大谷 | BF3: =変更履歴!BF3 -> 45581 | BJ3: =変更履歴!BJ3 -> 大谷
B7: 1.タイトルを記載 | H7: select | J7: 項目名 | R7: 格納テーブル
J8: 仕入先CD | R8: VM支払予定情報.仕入先CD
J9: 仕入先名1 | R9: VM支払予定情報.仕入先名1
H10: from | J10: 使用するテーブル名を記載
J11: TD売上請求H
J12: TD見積
J13: TM納入先
H14: join | J14: 結合方式
K15: 結合テーブル名
M16: 結合条件
L17: and | M17: 結合条件
L18: or | M18: 結合条件
J19: INNER JOIN
K20: TM納入先
M21: [TD見積.納入得意先CD] = [TM納入先.得意先CD]
L22: and | M22: [TD見積.納入先CD] = [TM納入先.納入先CD]
H23: where | K23: 取得条件 | AK23: パラメータの意味が分かる場合は記載する
J24: and | K24: 取得条件
J25: or | K25: 取得条件
J26: ※可能な限り日本語化する
K27: [TD見積.得意先CD] = '8001' | AK27: 8001'はヤオコーの得意先CD
J28: and | K28: [TD売上請求H.請求日付]が[画面.請求期間From]以降
H32: order by | J32: ソート条件を記載
J33: [画面.iYK物件区分]が1の場合は[TD見積.納入得意先CD],[TD見積.納入先CD],[TD売上請求H.見積番号]を昇順でソート
H36: group byなどほかの条件がある場合は行を追加して記載

Sheet 確認事項
B2: 確認事項
B3: No. | C3: シート名 | D3: タイトル | E3: 概要 | F3: 回答 | G3: 確認済
B4: 1 | C4: 項目一覧 | D4: ソース上の「店舗名」項目について | E4: ソース上にて「店舗名」にデータを出力している箇所があるが、テンプレートシートに「店舗名」セルがない | F4: 店舗名は不要 | G4: 〇
B5: 2 | C5: 項目一覧 | D5: 新レイアウトにて増えた項目 | E5: 項目一覧の赤文字の箇所に入る値確認。No1、No7、No10、No21 | F5: 店舗名：納入先名１＋２、担当：ActiveDirectoryユーザ、連番：１から連番、チェック：空 | G5: 〇
B6: 3 | C6: 項目一覧 | D6: No5積込日,No6保管期限 | E6: 現行レイアウト上ではデータを入れていないが新レイアウトではデータを入れる必要あるか | F6: 空でよい | G6: 〇
B7: 4 | C7: 別紙_レイアウト案 | E7: コメントの内容確認 | F7: 入庫日の取得元は現行と同じ | G7: 〇
B8: 5
B9: 6
B10: 7
B11: 8
B12: 9
B13: 10
B14: 11
B15: 12
B16: 13
B17: 14
B18: 15
B19: 16
... B54: 51

Sheet 別紙_テンプレート
D1: ｸﾙﾍﾞ竜舞店 | O1: 作成日： 2024/07/11
D2: ｸﾙﾍﾞ竜舞店 あけぼのﾊﾟﾝ用ﾊｺﾏﾙｼｪ No.178262
D3: 入 庫 日 | I3: 積 込 日 | J3: 保管 期限 | N3: 発注者
D4: 8/29 | I4: 8/30 | J4: 10/11 | N4: 中澤
A6: 入庫日付 | B6: バーコード | D6: 棚番 | E6: 仕入先CD | F6: 仕入先名 | G6: 製品№ | H6: 仕様№ | I6: 名称 | J6: Ｗ | K6: Ｄ | L6: Ｈ | M6: 発注数 | N6: チェック
A7: 45486 | B7: *0000000000024375* | C7: 1 | E7: 4603 | F7: 店研創意 | G7: Z015 | I7: ハコマルシェセット黒テント 61-805-5 | J7: 0 | K7: 0 | L7: 0 | M7: 1
C8: 2 | E8: 4604 | F8: 店研創意 | G8: 4000520 | H8: ﾌﾞﾗｯｸ | I8: ハコマルシェセット黒テント 61-805-6 | J8: 0 | K8: 0 | L8: 0 | M8: 5
C9: 3 | E9: 4605 | F9: 店研創意 | G9: 320-32 | H9: ｼﾙｷｰW | I9: ハコマルシェセット黒テント 61-805-7 | J9: 0 | K9: 0 | L9: 0 | M9: 30
C10: 4 | E10: 4606 | F10: 店研創意 | G10: Z016 | I10: ハコマルシェセット黒テント 61-805-8 | J10: 0 | K10: 0 | L10: 0 | M10: 41
C11: 5 | E11: 4607 | F11: 店研創意 | G11: 4000521 | H11: ﾌﾞﾗｯｸ | I11: ハコマルシェセット黒テント 61-805-9 | J11: 0 | K11: 0 | L11: 0 | M11: 55.5
C12: 6 | E12: 4608 | F12: 店研創意 | G12: 320-33 | H12: ｼﾙｷｰW | I12: ハコマルシェセット黒テント 61-805-10 | J12: 0 | K12: 0 | L12: 0 | M12: 70
C13: 7 | E13: 4609 | F13: 店研創意 | G13: Z017 | I13: ハコマルシェセット黒テント 61-805-11 | J13: 0 | K13: 0 | L13: 0 | M13: 84.5
C14: 8 | E14: 4610 | F14: 店研創意 | G14: 4000522 | H14: ﾌﾞﾗｯｸ | I14: ハコマルシェセット黒テント 61-805-12 | J14: 0 | K14: 0 | L14: 0 | M14: 99
C15: 9 | E15: 4611 | F15: 店研創意 | G15: 320-34 | H15: ｼﾙｷｰW | I15: ハコマルシェセット黒テント 61-805-13 | J15: 0 | K15: 0 | L15: 0 | M15: 113.5

Sheet 別紙_レイアウト案
D1: ｸﾙﾍﾞ竜舞店 | O1: 作成日： 2024/07/11
D2: ｸﾙﾍﾞ竜舞店 あけぼのﾊﾟﾝ用ﾊｺﾏﾙｼｪ No.178262
D3: 入 庫 日 | I3: 積 込 日 | J3: 保管 期限 | N3: 発注者
D4: 8/29 | I4: 8/30 | J4: 10/11 | N4: 中澤
A6: 入庫日付 | B6: バーコード | D6: 棚番 | E6: 仕入先CD | F6: 仕入先名 | G6: 製品№ | H6: 仕様№ | I6: 名称 | J6: Ｗ | K6: Ｄ | L6: Ｈ | M6: 発注数 | N6: チェック
A7: 45486 | B7: *0000000000024375* | C7: 1 | E7: 4603 | F7: 店研創意 | G7: Z015 | I7: ハコマルシェセット黒テント 61-805-5 | J7: 0 | K7: 0 | L7: 0 | M7: 1
C8: 2 | E8: 4604 | F8: 店研創意 | G8: 4000520 | H8: ﾌﾞﾗｯｸ | I8: ハコマルシェセット黒テント 61-805-6 | J8: 0 | K8: 0 | L8: 0 | M8: 5
C9: 3 | E9: 4605 | F9: 店研創意 | G9: 320-32 | H9: ｼﾙｷｰW | I9: ハコマルシェセット黒テント 61-805-7 | J9: 0 | K9: 0 | L9: 0 | M9: 30
C10: 4 | E10: 4606 | F10: 店研創意 | G10: Z016 | I10: ハコマルシェセット黒テント 61-805-8 | J10: 0 | K10: 0 | L10: 0 | M10: 41
C11: 5 | E11: 4607 | F11: 店研創意 | G11: 4000521 | H11: ﾌﾞﾗｯｸ | I11: ハコマルシェセット黒テント 61-805-9 | J11: 0 | K11: 0 | L11: 0 | M11: 55.5
C12: 6 | E12: 4608 | F12: 店研創意 | G12: 320-33 | H12: ｼﾙｷｰW | I12: ハコマルシェセット黒テント 61-805-10 | J12: 0 | K12: 0 | L12: 0 | M12: 70
C13: 7 | E13: 4609 | F13: 店研創意 | G13: Z017 | I13: ハコマルシェセット黒テント 61-805-11 | J13: 0 | K13: 0 | L13: 0 | M13: 84.5
C14: 8 | E14: 4610 | F14: 店研創意 | G14: 4000522 | H14: ﾌﾞﾗｯｸ | I14: ハコマルシェセット黒テント 61-805-12 | J14: 0 | K14: 0 | L14: 0 | M14: 99
C15: 9 | E15: 4611 | F15: 店研創意 | G15: 320-34 | H15: ｼﾙｷｰW | I15: ハコマルシェセット黒テント 61-805-13 | J15: 0 | K15: 0 | L15: 0 | M15: 113.5

Sheet 別紙_印刷レイアウト

Sheet 参照
A1: 数値
A2: ブール値
A3: 文字列
A4: 日付
A5: リスト
A6: 辞書配列
