Workbook
Name CoreCells: #REF!
Name 見積番号: #REF!
Name 見積名称: #REF!
Name 現場名: #REF!
Name 受注先TEL: #REF!
Name 受注先zip: #REF!
Name 受注先住所1: #REF!
Name 受注先住所2: #REF!
Name 店番: #REF!

Sheet 変更履歴
B2: システム名 | H2: 画面ID | L2: システム分類 | R2: ドキュメント種別 | X2: ドキュメント名 | AK2: 帳票名 | AX2: 作成日 | BB2: 作成者 | BF2: 更新日 | BJ2: 更新者
B3: 受発注システム | H3: =LEFT($X$3,FIND("_",$X$3)-1) -> MT1400 | L3: 受発注 | R3: =MID($X$3,FIND("_",$X$3,FIND("_",$X$3)+1)+1,LEN($X$3)-FIND("_",$X$3,FIND("_",$X$3)+1)) -> 帳票設計書 | X3: =REPLACE(LEFT(CELL("filename",$B$2),FIND(".x",CELL("filename",$B$2))-1),1,FIND("[",CELL("filename",$B$2)),) -> MT1400_出荷リスト_帳票設計書 | AK3: =MID($X$3,FIND("_",$X$3)+1,FIND("_",$X$3,FIND("_",$X$3)+1)-FIND("_",$X$3)-1) -> 出荷リスト | AX3: 45582 | BB3: 大谷 | BF3: 45582 | BJ3: 大谷
C7: 変更履歴
C8: 日付 | G8: 版数 | K8: 担当 | O8: 変更箇所 | Y8: 内容
C9: 45582 | G9: 1.0.0 | K9: 大谷 | O9: - | Y9: 新規作成

Sheet 概要
B2: システム名 | H2: 画面ID | L2: システム分類 | R2: ドキュメント種別 | X2: ドキュメント名 | AK2: 帳票名 | AX2: 作成日 | BB2: 作成者 | BF2: 更新日 | BJ2: 更新者
B3: =変更履歴!B3 -> 受発注システム | H3: =変更履歴!H3 -> MT1400 | L3: =変更履歴!L3 -> 受発注 | R3: =変更履歴!R3 -> 帳票設計書 | X3: =変更履歴!X3 -> MT1400_出荷リスト_帳票設計書 | AK3: =変更履歴!AK3 -> 出荷リスト | AX3: =変更履歴!AX3 -> 45582 | BB3: =変更履歴!BB3 -> 大谷 | BF3: =変更履歴!BF3 -> 45582 | BJ3: =変更履歴!BJ3 -> 大谷
D7: 帳票の名称 | H7: =AK3 -> 出荷リスト
D8: 帳票テンプレート名 | H8: Temp出荷リスト_梱包出荷用.xlsx
D9: ファイル種類 | H9: Excel
D10: ファイル拡張子 | H10: xlsx
D11: 文字コード | H11: -
D12: コーテーション | H12: -
D13: 固定長/可変長 | H13: -
D14: 区切り文字 | H14: -
D15: 用紙サイズ | H15: A4横
D16: 概要

Sheet 帳票レイアウト
B2: システム名 | H2: 画面ID | L2: システム分類 | R2: ドキュメント種別 | X2: ドキュメント名 | AK2: 帳票名 | AX2: 作成日 | BB2: 作成者 | BF2: 更新日 | BJ2: 更新者
B3: =変更履歴!B3 -> 受発注システム | H3: =変更履歴!H3 -> MT1400 | L3: =変更履歴!L3 -> 受発注 | R3: =変更履歴!R3 -> 帳票設計書 | X3: =変更履歴!X3 -> MT1400_出荷リスト_帳票設計書 | AK3: =変更履歴!AK3 -> 出荷リスト | AX3: =変更履歴!AX3 -> 45582 | BB3: =変更履歴!BB3 -> 大谷 | BF3: =変更履歴!BF3 -> 45582 | BJ3: =変更履歴!BJ3 -> 大谷
B6: ページ１

Sheet 項目一覧
B2: システム名 | H2: 画面ID | L2: システム分類 | R2: ドキュメント種別 | X2: ドキュメント名 | AK2: 帳票名 | AX2: 作成日 | BB2: 作成者 | BF2: 更新日 | BJ2: 更新者
B3: =変更履歴!B3 -> 受発注システム | H3: =変更履歴!H3 -> MT1400 | L3: =変更履歴!L3 -> 受発注 | R3: =変更履歴!R3 -> 帳票設計書 | X3: =変更履歴!X3 -> MT1400_出荷リスト_帳票設計書 | AK3: =変更履歴!AK3 -> 出荷リスト | AX3: =変更履歴!AX3 -> 45582 | BB3: =変更履歴!BB3 -> 大谷 | BF3: =変更履歴!BF3 -> 45582 | BJ3: =変更履歴!BJ3 -> 大谷
B7: 項目一覧
C9: 項目 | F9: フォントや文字サイズ、セル条件などは「別紙_テンプレート」準拠
D10: No. | E10: 項目名 | M10: データ型 | P10: 全角/半角 | S10: 文字数/桁数 | V10: データ取得元 | AB10: データ整形方法 | AR10: 整形後フォーマット | AX10: 備考
D11: 1 | E11: 納品日 | M11: 日付 | P11: 全角 | S11: 8 | V11: SQL1.納期S
D12: 2 | E12: 見積№ | M12: 数値 | P12: 半角 | S12: 11 | V12: SQL1.見積番号 | AR12: m/d（aaa）
D13: 3 | E13: 見積名称 | M13: 文字列 | P13: 全角 | S13: 縮小して全体表示 | V13: SQL1.見積件名
D14: 4 | E14: 現場名 | M14: 文字列 | P14: 全角 | S14: 縮小して全体表示 | V14: SQL1.現場名
D15: 5 | E15: 店番 | M15: 数値 | P15: 半角 | S15: 縮小して全体表示 | V15: SQL1.納入先CD
D16: 6 | E16: 郵便番号 | M16: 数値 | P16: 半角 | S16: 7 | V16: SQL1.郵便番号 | AR16: "〒" + [SQL1.郵便番号]
D17: 7 | E17: TEL | M17: 数値 | P17: 半角 | S17: 10 | V17: SQL1.納TEL | AR17: "TEL:" + [SQL1.納TEL]
D18: 8 | E18: 担当 | M18: 文字列 | P18: 全角 | S18: 縮小して全体表示 | V18: 出力者の名前 | AX18: 現行はActiveDirectoryのユーザを取得している。新システムでの対応要検討。Pleasanterのユーザ？
D19: 9 | E19: 住所1 | M19: 文字列 | P19: 全角 | S19: 縮小して全体表示 | V19: SQL1.住所1
D20: 10 | E20: 住所2 | M20: 文字列 | P20: 全角 | S20: 縮小して全体表示 | V20: SQL1.住所2
D21: 11 | E21: 項目 | M21: 数値 | P21: 半角 | S21: 8 | V21: SQL1.見積区分,SQL1.行番号 | AB21: [SQL1.見積区分]が"C"、"A"、"S"以外の場合[SQL1.行番号]を表示
D22: 12 | E22: 棚番 | M22: 文字列 | P22: 半角 | S22: 縮小して全体表示 | V22: SQL1.棚番名
D23: 13 | E23: 製品№ | M23: 数値 | P23: 半角 | S23: 縮小して全体表示 | V23: SQL1.製品NO
D24: 14 | E24: 仕様№ | M24: 数値 | P24: 半角 | S24: 縮小して全体表示 | V24: SQL1.仕様NO
D25: 15 | E25: 名称 | M25: 文字列 | P25: 全角 | S25: 縮小して全体表示 | V25: SQL1.漢字名称,SQL1.見積区分 | AB25: [SQL1.見積区分]が"C"、"A"、"S"の場合[半角ブランク2つ] ＋ [SQL1.漢字名称]を表示 上記以外の場合は[SQL1.漢字名称]を表示
D26: 16 | E26: W | M26: 数値 | P26: 半角 | S26: 縮小して全体表示 | V26: SQL1.W
D27: 17 | E27: D | M27: 数値 | P27: 半角 | S27: 縮小して全体表示 | V27: SQL1.D,SQL1.D1,SQL1.D2 | AB27: [SQL1.D]が0でない場合は[SQL1.D]を表示 [SQL1.D]が0の場合、 [SQL1.D1],[SQL1.D2]どちらも0の場合は””を表示 [SQL1.D1],[SQL1.D2]どちらかが0でない場合は[SQL1.D1]&”/”&[SQL1.D2]を表示
D28: 18 | E28: H | M28: 数値 | P28: 半角 | S28: 縮小して全体表示 | V28: SQL1.H,SQL1.H1,SQL1.H2 | AB28: [SQL1.H]が0でない場合は[SQL1.H]を表示 [SQL1.H]が0の場合、 [SQL1.H1],[SQL1.H2]どちらも0の場合は””を表示 [SQL1.H1],[SQL1.H2]どちらかが0でない場合は[SQL1.H1]&”/”&[SQL1.H2]を表示
D29: 19 | E29: 発注数 | M29: 数値 | P29: 半角 | S29: 縮小して全体表示 | V29: SQL1.発注数 | AR29: 999999.99
D30: 20 | E30: 単位名 | M30: 文字列 | P30: 全角 | S30: 縮小して全体表示 | V30: SQL1.単位名
D31: 21 | E31: 仕入先 | M31: 文字列 | P31: 全角 | S31: 縮小して全体表示 | V31: SQL1.仕入先CD,SQL1.配送先CD,SQL1.仕入先名,SQL1.配送先名 | AB31: [SQL1.仕入先CD]="3150"かつ[SQL1.配送先CD]="02"の場合は[SQL1.仕入先名] + "-" + [SQL1.配送先名]を表示 上記以外の場合は[SQL1.仕入先名]を表示
D32: 22 | E32: 備考 | M32: 文字列 | P32: 全角 | S32: 縮小して全体表示 | V32: SQL1.明細備考
D33: 23 | E33: 入庫日 | M33: 日付 | P33: 半角 | S33: 8 | V33: SQL1.入庫日 | AR33: "yy/mm/dd"
D34: 24 | E34: チェック | V34: 空
D35: 25

Sheet 処理詳細
B2: システム名 | H2: 画面ID | L2: システム分類 | R2: ドキュメント種別 | X2: ドキュメント名 | AK2: 帳票名 | AX2: 作成日 | BB2: 作成者 | BF2: 更新日 | BJ2: 更新者
B3: =変更履歴!B3 -> 受発注システム | H3: =変更履歴!H3 -> MT1400 | L3: =変更履歴!L3 -> 受発注 | R3: =変更履歴!R3 -> 帳票設計書 | X3: =変更履歴!X3 -> MT1400_出荷リスト_帳票設計書 | AK3: =変更履歴!AK3 -> 出荷リスト | AX3: =変更履歴!AX3 -> 45582 | BB3: =変更履歴!BB3 -> 大谷 | BF3: =変更履歴!BF3 -> 45582 | BJ3: =変更履歴!BJ3 -> 大谷
B6: SQL1 | H6: select | J6: 棚番名 | R6: TB.棚番名
J7: 見積番号 | R7: MH.見積番号
J8: 見積件名 | R8: MH.見積件名
J9: 得意先名1 | R9: H.得意先名1
J10: 得意先名2 | R10: MH.得意先名2
J11: 現場名 | R11: MH.現場名
J12: 担当者名 | R12: MT.担当者名
A13: 45554 | J13: 納入先CD | R13: MH.納入先CD
J14: 販売先納得意先CD | R14: MH.販売先納得意先CD
J15: 販売先納入先CD | R15: MH.販売先納入先CD
J16: 納入先名1 | R16: MH.納入先名1
J17: 納入先名2 | R17: MH.納入先名2
J18: 郵便番号 | R18: MH.郵便番号
J19: 住所1 | R19: MH.住所1
J20: 住所2 | R20: MH.住所2
J21: 納TEL | R21: MH.納TEL
J22: 納FAX | R22: MH.納FAX
J23: 行番号 | R23: MSM.行番号
J24: SP区分 | R24: MSM.SP区分
J25: PC区分 | R25: MSM.PC区分
... J54: 納期S | R54: MH.納期S
H55: from | J55: TD見積 AS MH
J56: VD見積シートM AS MSM
J57: TM担当者 AS MT
J58: TM製品 AS SE(NOLOCK)
J59: SQL4 AS TB
H60: join | J60: INNER JOIN
K61: VD見積シートM
M62: MH.見積番号 = MSM.見積番号
J63: INNER JOIN
K64: TM担当者
M65: MH.担当者CD = MT.担当者CD
J66: LEFT JOIN
K67: TM製品
M68: MSM.製品NO = SE.製品NO
J69: LEFT JOIN
K70: SQL4
M71: MSM.製品NO = TB.製品NO
...

Sheet 処理詳細_書き方
B2: システム名 | H2: 画面ID | L2: 業務分類 | R2: ドキュメント種別 | X2: ドキュメント名 | AK2: 帳票名 | AX2: 作成日 | BB2: 作成者 | BF2: 更新日 | BJ2: 更新者
B3: =変更履歴!B3 -> 受発注システム | H3: =変更履歴!H3 -> MT1400 | L3: =変更履歴!L3 -> 受発注 | R3: =変更履歴!R3 -> 帳票設計書 | X3: =変更履歴!X3 -> MT1400_出荷リスト_帳票設計書 | AK3: =変更履歴!AK3 -> 出荷リスト | AX3: =変更履歴!AX3 -> 45582 | BB3: =変更履歴!BB3 -> 大谷 | BF3: =変更履歴!BF3 -> 45582 | BJ3: =変更履歴!BJ3 -> 大谷
B7: 1.タイトルを記載 | H7: select | J7: 項目名 | R7: 格納テーブル
J8: 仕入先CD | R8: VM支払予定情報.仕入先CD
J9: 仕入先名1 | R9: VM支払予定情報.仕入先名1
H10: from | J10: 使用するテーブル名を記載
J11: TD売上請求H
J12: TD見積
J13: TM納入先
H14: join | J14: 結合方式
K15: 結合テーブル名
M16: 結合条件
L17: and | M17: 結合条件
L18: or | M18: 結合条件
J19: INNER JOIN
K20: TM納入先
M21: [TD見積.納入得意先CD] = [TM納入先.得意先CD]
L22: and | M22: [TD見積.納入先CD] = [TM納入先.納入先CD]
H23: where | K23: 取得条件 | AK23: パラメータの意味が分かる場合は記載する
J24: and | K24: 取得条件
J25: or | K25: 取得条件
J26: ※可能な限り日本語化する
K27: [TD見積.得意先CD] = '8001' | AK27: 8001'はヤオコーの得意先CD
J28: and | K28: [TD売上請求H.請求日付]が[画面.請求期間From]以降
H32: order by | J32: ソート条件を記載
J33: [画面.iYK物件区分]が1の場合は[TD見積.納入得意先CD],[TD見積.納入先CD],[TD売上請求H.見積番号]を昇順でソート
H36: group byなどほかの条件がある場合は行を追加して記載

Sheet 確認事項
B2: 確認事項
B3: No. | C3: シート名 | D3: 概要 | E3: 回答 | F3: 確認済
B4: 1 | C4: 項目一覧 | D4: 新レイアウトで増えた項目の取得元確認。（項目一覧の赤文字の箇所） | E4: 納品日：納期S、担当：ActiveDirectoryユーザ、チェック：空 | F4: 〇
B5: 2 | C5: 帳票レイアウト | D5: 住所の3行目に何かデータが入る想定はあるか | E5: 住所2を表示する。 | F5: 〇
B6: 3 | C6: 別紙_出荷リスト案 | D6: コメント内容の確認 | E6: 「別紙_出荷リスト案」に対応する回答を記載 | F6: 〇
B7: 4
B8: 5
B9: 6
B10: 7
B11: 8
B12: 9
B13: 10
B14: 11
B15: 12
B16: 13
B17: 14
B18: 15
... B54: 51

Sheet 別紙_テンプレート
B1: 出荷リスト （梱包発送） | D1: 納品日 | E1: 7/20（土） | F1: 店着
G2: 送り先 | H2: ﾍﾞﾙｸ広瀬店 | M2: 店番 | N2: 0007 | O2: 担当
B3: 見積№ | C3: 178473 | G3: 住所 | H3: 〒 | I3: 360-0833 | L3: TEL: 048-526-6800 | O3: 時田よ
B4: 見積名称 | C4: ﾍﾞﾙｸ広瀬店 自転車空気入れ 65628 | H4: 埼玉県熊谷市大字広瀬131
A7: 項目 | B7: 棚番 | C7: 製品№ | D7: 仕様№ | E7: 名称 | F7: Ｗ | G7: Ｄ | H7: Ｈ | I7: 発注量 | K7: 仕入先 | L7: 備考 | N7: 入庫日 | O7: ﾁｪｯｸ
A8: 1 | B8: HH-01-01-01-00 | C8: 0000116 | E8: 自転車空気入れ ステンワイヤー1ｍ | I8: 1 | J8: 台 | K8: 三和倉庫
A9: 2 | B9: HH-01-01-02-00 | C9: 0000601 | E9: ﾁｪｰﾝ･ﾆｯｻIW48 30m(空気入れ用) | I9: 1 | J9: ｍ | K9: 三和倉庫 | N9: 45513
A10: 4 | C10: Z012015 | E10: 運搬費 | I10: 1 | J10: 式 | K10: 三和商研
E11: 店長様あて | I11: 0 | K11: 三和商研

Sheet 別紙_出荷リスト案
B1: 出荷リスト （梱包発送） | D1: 納品日 | E1: 7/20（土） | F1: 店着
G2: 送り先 | H2: ﾍﾞﾙｸ広瀬店 | M2: 店番 | N2: 0007 | O2: 担当
B3: 見積№ | C3: 178473 | G3: 住所 | H3: 〒 | I3: 360-0833 | L3: TEL: 048-526-6800 | O3: 時田よ
B4: 見積名称 | C4: ﾍﾞﾙｸ広瀬店 自転車空気入れ 65628 | H4: 埼玉県熊谷市大字広瀬131
A7: 項目 | B7: 棚番 | C7: 製品№ | D7: 仕様№ | E7: 名称 | F7: Ｗ | G7: Ｄ | H7: Ｈ | I7: 発注量 | K7: 仕入先 | L7: 備考 | N7: 入庫日 | O7: ﾁｪｯｸ
A8: 1 | B8: HH-01-01-01-00 | C8: 0000116 | E8: 自転車空気入れ ステンワイヤー1ｍ | I8: 1 | J8: 台 | K8: 三和倉庫
A9: 2 | B9: HH-01-01-02-00 | C9: 0000601 | E9: ﾁｪｰﾝ･ﾆｯｻIW48 30m(空気入れ用) | I9: 1 | J9: ｍ | K9: 三和倉庫 | N9: 45513
A10: 4 | C10: Z012015 | E10: 運搬費 | I10: 1 | J10: 式 | K10: 三和商研
E11: 店長様あて | I11: 0 | K11: 三和商研

Sheet 別紙_印刷レイアウト

Sheet 参照
A1: 数値
A2: ブール値
A3: 文字列
A4: 日付
A5: リスト
A6: 辞書配列
