Workbook

Sheet 変更履歴
B2: システム名 | H2: 画面ID | L2: システム分類 | R2: ドキュメント種別 | X2: ドキュメント名 | AK2: 帳票名 | AX2: 作成日 | BB2: 作成者 | BF2: 更新日 | BJ2: 更新者
B3: 受発注システム | H3: =LEFT($X$3,FIND("_",$X$3)-1) -> SK0100 | L3: 受発注 | R3: =MID($X$3,FIND("_",$X$3,FIND("_",$X$3)+1)+1,LEN($X$3)-FIND("_",$X$3,FIND("_",$X$3)+1)) -> 帳票設計書 | X3: =REPLACE(LEFT(CELL("filename",$B$2),FIND(".x",CELL("filename",$B$2))-1),1,FIND("[",CELL("filename",$B$2)),) -> SK0100_買掛金元帳_帳票設計書 | AK3: =MID($X$3,FIND("_",$X$3)+1,FIND("_",$X$3,FIND("_",$X$3)+1)-FIND("_",$X$3)-1) -> 買掛金元帳 | AX3: 45583 | BB3: 大谷 | BF3: 45583 | BJ3: 大谷
C7: 変更履歴
C8: 日付 | G8: 版数 | K8: 担当 | O8: 変更箇所 | Y8: 内容
C9: 45583 | G9: 1.0.0 | K9: 大谷 | O9: - | Y9: 新規作成

Sheet 概要
B2: システム名 | H2: 画面ID | L2: システム分類 | R2: ドキュメント種別 | X2: ドキュメント名 | AK2: 帳票名 | AX2: 作成日 | BB2: 作成者 | BF2: 更新日 | BJ2: 更新者
B3: =変更履歴!B3 -> 受発注システム | H3: =変更履歴!H3 -> SK0100 | L3: =変更履歴!L3 -> 受発注 | R3: =変更履歴!R3 -> 帳票設計書 | X3: =変更履歴!X3 -> SK0100_買掛金元帳_帳票設計書 | AK3: =変更履歴!AK3 -> 買掛金元帳 | AX3: =変更履歴!AX3 -> 45583 | BB3: =変更履歴!BB3 -> 大谷 | BF3: =変更履歴!BF3 -> 45583 | BJ3: =変更履歴!BJ3 -> 大谷
D7: 帳票の名称 | H7: =AK3 -> 買掛金元帳
D8: 帳票テンプレート名 | H8: -
D9: ファイル種類 | H9: PDF
D10: ファイル拡張子 | H10: pdf
D11: 文字コード | H11: -
D12: コーテーション | H12: -
D13: 固定長/可変長 | H13: -
D14: 区切り文字 | H14: -
D15: 用紙サイズ | H15: A3横
D16: 概要

Sheet 帳票レイアウト
B2: システム名 | H2: 画面ID | L2: システム分類 | R2: ドキュメント種別 | X2: ドキュメント名 | AK2: 帳票名 | AX2: 作成日 | BB2: 作成者 | BF2: 更新日 | BJ2: 更新者
B3: =変更履歴!B3 -> 受発注システム | H3: =変更履歴!H3 -> SK0100 | L3: =変更履歴!L3 -> 受発注 | R3: =変更履歴!R3 -> 帳票設計書 | X3: =変更履歴!X3 -> SK0100_買掛金元帳_帳票設計書 | AK3: =変更履歴!AK3 -> 買掛金元帳 | AX3: =変更履歴!AX3 -> 45583 | BB3: =変更履歴!BB3 -> 大谷 | BF3: =変更履歴!BF3 -> 45583 | BJ3: =変更履歴!BJ3 -> 大谷
B6: ページ１

Sheet 項目一覧
B2: システム名 | H2: 画面ID | L2: システム分類 | R2: ドキュメント種別 | X2: ドキュメント名 | AK2: 帳票名 | AX2: 作成日 | BB2: 作成者 | BF2: 更新日 | BJ2: 更新者
B3: =変更履歴!B3 -> 受発注システム | H3: =変更履歴!H3 -> SK0100 | L3: =変更履歴!L3 -> 受発注 | R3: =変更履歴!R3 -> 帳票設計書 | X3: =変更履歴!X3 -> SK0100_買掛金元帳_帳票設計書 | AK3: =変更履歴!AK3 -> 買掛金元帳 | AX3: =変更履歴!AX3 -> 45583 | BB3: =変更履歴!BB3 -> 大谷 | BF3: =変更履歴!BF3 -> 45583 | BJ3: =変更履歴!BJ3 -> 大谷
B7: 項目一覧
C9: 項目 | F9: フォントや文字サイズ、セル条件などは「別紙_テンプレート」準拠
D10: No. | E10: 項目名 | M10: データ型 | P10: 全角/半角 | S10: 文字数/桁数 | V10: データ取得元 | AB10: データ整形方法 | AR10: 整形後フォーマット | AX10: 備考
D11: 1 | E11: 支払終了日付 | M11: 日付 | P11: 半角 | V11: 画面.支払終了日付 | AR11: yyyy年 mm月 dd日 締
D12: 2 | E12: 仕郵便番号 | M12: 数値 | P12: 半角 | V12: SQL3.郵便番号 | AR12: 000-0000
D13: 3 | E13: 仕住所1 | M13: 文字列 | P13: 全角 | V13: SQL3.住所1
D14: 4 | E14: 仕住所2 | M14: 文字列 | P14: 全角 | V14: SQL3.住所2
D15: 5 | E15: 仕入先名1 | M15: 文字列 | P15: 全角 | V15: SQL3.仕入先名1
D16: 6 | E16: 仕入先名2 | M16: 文字列 | P16: 全角 | V16: SQL3.仕入先名2
D17: 7 | E17: 仕入先CD | M17: 数値 | P17: 半角 | V17: SQL3.得意先CD
D18: 8 | E18: 仕TEL | M18: 数値 | P18: 半角 | V18: SQL3.電話番号 | AR18: 000-000-0000
D19: 9 | E19: 開始日付 | M19: 日付 | P19: 半角 | V19: SQL3.支払開始日付
D20: 10 | E20: 終了日付 | M20: 日付 | P20: 半角 | V20: SQL3.支払終了日付
D21: 11 | E21: 前月残高 | M21: 数値 | P21: 半角 | V21: SQL3.前月残高 | AR21: 9999
D22: 12 | E22: 支払金額 | M22: 数値 | P22: 半角 | V22: SQL3.支払金額 | AR22: 9999
D23: 13 | E23: 調整金額 | M23: 数値 | P23: 半角 | V23: SQL3.調整金額 | AR23: 9999
D24: 14 | E24: 繰越金額 | M24: 数値 | P24: 半角 | V24: SQL3.前月残高、SQL3.支払金額、SQL3.調整金額 | AB24: [SQL3.前月残高] - [SQL3.支払金額] - [SQL3.調整金額] | AR24: 9999
D25: 15 | E25: 仕入金額 | M25: 数値 | P25: 半角 | V25: SQL3.仕入金額 | AR25: 9999
D26: 16 | E26: 返品金額 | M26: 数値 | P26: 半角 | V26: SQL3.返品金額 | AR26: 9999
D27: 17 | E27: 訂正金額 | M27: 数値 | P27: 半角 | V27: SQL3.訂正金額 | AR27: 9999
D28: 18 | E28: 消費税額 | M28: 数値 | P28: 半角 | V28: SQL3.消費税額 | AR28: 9999
D29: 19 | E29: 当月支払 | M29: 数値 | P29: 半角 | V29: SQL3.仕入金額、SQL3.返品金額、SQL3.訂正金額、SQL3.消費税額 | AB29: [SQL3.仕入金額] +[SQL3.返品金額] + [SQL3.訂正金額] + [SQL3.消費税額] | AR29: 9999
D30: 20 | E30: 当月残高 | M30: 数値 | P30: 半角 | V30: SQL3.当月残高 | AR30: 9999
D31: 21 | E31: 日付 | M31: 日付 | P31: 半角 | V31: SQL15.日付 | AR31: yy/mm/dd
D32: 22 | E32: 番号 | M32: 数値 | P32: 半角 | V32: SQL15.見積番号
D33: 23 | E33: 残高名 | M33: 文字列 | P33: 全角 | V33: ソース内 | AB33: 初項目は'繰 越 残 高 'その後は'前 頁 残 高'
D34: 24 | E34: PC区分 | M34: 文字列 | P34: 全角 | V34: SQL15.PC区分
D35: 25 | E35: 製品NO | M35: 文字列 | P35: 全角 | V35: SQL15.製品NO
D36: 26 | E36: 仕様NO | M36: 文字列 | P36: 全角 | V36: SQL15.仕様NO
D37: 27 | E37: 品名 | M37: 文字列 | P37: 全角 | V37: SQL15.品名
D38: 28 | E38: サイズ | M38: 文字列 | P38: 全角 | V38: SQL15.W、SQL15.D、SQL15.H、SQL15.D1、SQL15.D2、SQL15.H1、SQL15.H2 | AR38: [SQL15.W]W×[SQL15.D]/[SQL15.D1]/[SQL15.D2]D×[SQL15.H]×[SQL15.H1]×[SQL15.H2]H | AX38: 例）893W×2D/3D×50H/76H
D39: 29 | E39: 数量 | M39: 数値 | P39: 半角 | V39: SQL15.数量
D40: 30 | E40: 単位 | M40: 文字列 | P40: 全角 | V40: SQL15.単位
D41: 31 | E41: 単価 | M41: 数値 | P41: 半角 | V41: SQL15.単価 | AR41: 9999
D42: 32 | E42: 明細仕入 | M42: 数値 | P42: 半角 | V42: SQL15.金額 | AB42: [SQL15.区分]が1以外のときに入力 | AR42: 9999
D43: 33 | E43: 明細支払 | M43: 数値 | P43: 半角 | V43: SQL15.金額 | AB43: [SQL15.区分]が1のときに入力 | AR43: 9999
D44: 34 | E44: 繰越残高 | M44: 数値 | P44: 半角 | V44: SQL3.前月残高 | AR44: 9999
D45: 35 | E45: 差引残高 | M45: 数値 | P45: 半角 | V45: SQL3.前月残高、SQL15.金額 | AB45: 差引残高（初回は繰越残高） + 明細仕入 - 明細支払 または空 | AR45: 9999 | AX45: [SQL15.見積行番号]が9001のときは空
...

Sheet 処理詳細
B2: システム名 | H2: 画面ID | L2: システム分類 | R2: ドキュメント種別 | X2: ドキュメント名 | AK2: 帳票名 | AX2: 作成日 | BB2: 作成者 | BF2: 更新日 | BJ2: 更新者
B3: =変更履歴!B3 -> 受発注システム | H3: =変更履歴!H3 -> SK0100 | L3: =変更履歴!L3 -> 受発注 | R3: =変更履歴!R3 -> 帳票設計書 | X3: =変更履歴!X3 -> SK0100_買掛金元帳_帳票設計書 | AK3: =変更履歴!AK3 -> 買掛金元帳 | AX3: =変更履歴!AX3 -> 45583 | BB3: =変更履歴!BB3 -> 大谷 | BF3: =変更履歴!BF3 -> 45583 | BJ3: =変更履歴!BJ3 -> 大谷
B6: SQL1 | H6: select | J6: 仕入先CD | R6: TM支払金額.仕入先CD
J7: 仕入先名1 | R7: TM仕入先.仕入先名1
J8: 締日 | R8: TM支払金額.締日
J9: 支払開始日付 | R9: TM支払金額.支払開始日付
J10: 支払終了日付 | R10: TM支払金額.支払終了日付
J11: 処理日 | R11: TM支払金額.処理日
H12: from | J12: FROM TM支払金額 AS SM
H13: join | J13: INNER JOIN (SQL2) AS QR
K14: ON (SM.支払日付 = QR.支払日付)
K15: AND (SM.仕入先CD = QR.仕入先CD)
J16: LEFT JOIN TM仕入先 AS TM ON SM.仕入先CD = TM.仕入先CD
H17: where | J17: SM.仕入先CD >= 画面.開始仕入先CD And SM.仕入先CD <= 画面.終了仕入先CD | AK17: 締日が存在しない場合
J18: SM.締日 = 画面.締日 and SM.仕入先CD >= 画面.開始仕入先CD And SM.仕入先CD <= 画面.終了仕入先CD | AK18: 締日が存在する場合
H19: order by | J19: ORDER BY SM.仕入先CD の昇順でソート
B20: SQL2 | H20: select | J20: 仕入先CD | R20: TM支払金額.仕入先CD
J21: 支払日付 | R21: Max(SK.支払日付)
H22: from | J22: FROM TM支払金額 AS SK
H23: group by | J23: GROUP BY SK.仕入先CD
B24: SQL3 | H24: select | J24: 仕入先CD | R24: TM支払金額.仕入先CD
J25: 支払日付 | R25: TM支払金額.支払日付
J26: 支払開始日付 | R26: TM支払金額.支払開始日付
J27: 支払終了日付 | R27: TM支払金額.支払終了日付
J28: 仕入先名1 | R28: SM.仕入先名1
J29: 仕入先名2 | R29: SM.仕入先名2
J30: 郵便番号 | R30: TM支払金額郵便番号
J31: 住所1 | R31: TM支払金額住所1
J32: 住所2 | R32: TM支払金額住所2
J33: 電話番号 | R33: TM支払金額電話番号
J34: 支払開始日付 | R34: TM支払金額.支払開始日付
J35: 支払終了日付 | R35: TM支払金額.支払終了日付
J36: 前月残高 | R36: TM支払金額.前月残高
... J43: 当月残高 | R43: TM支払金額.当月残高
H44: from | J44: FROM TM支払金額 AS SK
H45: join | J45: LEFT JOIN
K46: (
K47: SQL4
K48: ) AS SM
K49: ON SK.仕入先CD = SM.仕入先CD
...

Sheet 確認事項
B2: 確認事項
B3: No. | C3: シート名 | D3: タイトル | E3: 概要 | F3: 回答 | G3: 確認済
B4: 1 | C4: 項目一覧 | D4: No9.開始日付,No10.終了日付 | E4: No9.開始日付,No10.終了日付は不要の認識で合っているか | F4: 合っている | G4: 〇
B5: 2 | C5: 項目一覧 | D5: No24.PC区分 | E5: No24.PC区分は不要の認識で合っているか | F5: 合っている | G5: 〇
B6: 3
B7: 4
B8: 5
B9: 6
B10: 7
B11: 8
B12: 9
B13: 10
B14: 11
B15: 12
B16: 13
B17: 14
... B54: 51

Sheet 別紙_印刷レイアウト

Sheet 参照
A1: 数値
A2: ブール値
A3: 文字列
A4: 日付
A5: リスト
A6: 辞書配列
