Workbook
Name CoreCells: 別紙_テンプレート!$A$6:$Q$6
Name チーム: 別紙_テンプレート!$A$2
Name 作成日: 別紙_テンプレート!$P$1
Name 仕入先: 別紙_テンプレート!$A$3
Name 日付範囲: 別紙_テンプレート!$D$3

Sheet 概要
B2: システム名 | H2: 画面ID | L2: システム分類 | R2: ドキュメント種別 | X2: ドキュメント名 | AK2: 帳票名 | AX2: 作成日 | BB2: 作成者 | BF2: 更新日 | BJ2: 更新者
B3: =変更履歴!B3 -> 受発注システム | H3: =変更履歴!H3 -> SK0300 | L3: =変更履歴!L3 -> 受発注 | R3: =変更履歴!R3 -> 帳票設計書 | X3: =変更履歴!X3 -> SK0300_仕入先検収明細表_帳票設計書 | AK3: =変更履歴!AK3 -> 仕入先検収明細表 | AX3: =変更履歴!AX3 -> 45623 | BB3: =変更履歴!BB3 -> 大谷 | BF3: =変更履歴!BF3 -> 45623 | BJ3: =変更履歴!BJ3 -> 大谷
D7: 帳票の名称 | H7: =AK3 -> 仕入先検収明細表
D8: 帳票テンプレート名 | H8: Template検収明細表.xlsx
D9: ファイル種類 | H9: Excel
D10: ファイル拡張子 | H10: xlsx
D11: 文字コード | H11: -
D12: コーテーション | H12: -
D13: 固定長/可変長 | H13: -
D14: 区切り文字 | H14: -
D15: 用紙サイズ | H15: A4横
D16: 概要 | H16: 仕入れ先ごとにシートが分かれる

Sheet 変更履歴
B2: システム名 | H2: 画面ID | L2: システム分類 | R2: ドキュメント種別 | X2: ドキュメント名 | AK2: 帳票名 | AX2: 作成日 | BB2: 作成者 | BF2: 更新日 | BJ2: 更新者
B3: 受発注システム | H3: =LEFT($X$3,FIND("_",$X$3)-1) -> SK0300 | L3: 受発注 | R3: =MID($X$3,FIND("_",$X$3,FIND("_",$X$3)+1)+1,LEN($X$3)-FIND("_",$X$3,FIND("_",$X$3)+1)) -> 帳票設計書 | X3: =REPLACE(LEFT(CELL("filename",$B$2),FIND(".x",CELL("filename",$B$2))-1),1,FIND("[",CELL("filename",$B$2)),) -> SK0300_仕入先検収明細表_帳票設計書 | AK3: =MID($X$3,FIND("_",$X$3)+1,FIND("_",$X$3,FIND("_",$X$3)+1)-FIND("_",$X$3)-1) -> 仕入先検収明細表 | AX3: 45623 | BB3: 大谷 | BF3: 45623 | BJ3: 大谷
C7: 変更履歴
C8: 日付 | G8: 版数 | K8: 担当 | O8: 変更箇所 | Y8: 内容
C9: 45623 | G9: 1.0.0 | K9: 大谷 | O9: - | Y9: 新規作成

Sheet 帳票レイアウト
B2: システム名 | H2: 画面ID | L2: システム分類 | R2: ドキュメント種別 | X2: ドキュメント名 | AK2: 帳票名 | AX2: 作成日 | BB2: 作成者 | BF2: 更新日 | BJ2: 更新者
B3: =変更履歴!B3 -> 受発注システム | H3: =変更履歴!H3 -> SK0300 | L3: =変更履歴!L3 -> 受発注 | R3: =変更履歴!R3 -> 帳票設計書 | X3: =変更履歴!X3 -> SK0300_仕入先検収明細表_帳票設計書 | AK3: =変更履歴!AK3 -> 仕入先検収明細表 | AX3: =変更履歴!AX3 -> 45623 | BB3: =変更履歴!BB3 -> 大谷 | BF3: =変更履歴!BF3 -> 45623 | BJ3: =変更履歴!BJ3 -> 大谷
B6: ページ１

Sheet 項目一覧
B2: システム名 | H2: 画面ID | L2: システム分類 | R2: ドキュメント種別 | X2: ドキュメント名 | AK2: 帳票名 | AX2: 作成日 | BB2: 作成者 | BF2: 更新日 | BJ2: 更新者
B3: =変更履歴!B3 -> 受発注システム | H3: =変更履歴!H3 -> SK0300 | L3: =変更履歴!L3 -> 受発注 | R3: =変更履歴!R3 -> 帳票設計書 | X3: =変更履歴!X3 -> SK0300_仕入先検収明細表_帳票設計書 | AK3: =変更履歴!AK3 -> 仕入先検収明細表 | AX3: =変更履歴!AX3 -> 45623 | BB3: =変更履歴!BB3 -> 大谷 | BF3: =変更履歴!BF3 -> 45623 | BJ3: =変更履歴!BJ3 -> 大谷
B7: 項目一覧
C9: 項目 | F9: フォントや文字サイズ、セル条件などは「別紙_テンプレート」準拠
D10: No. | E10: 項目名 | M10: データ型 | P10: 全角/半角 | S10: 文字数/桁数 | V10: データ取得元 | AB10: データ整形方法 | AR10: 整形後フォーマット | AX10: 備考
D11: 1 | E11: 作成日 | M11: 日付 | P11: 半角 | S11: 8 | V11: 現在日付
D12: 2 | E12: チームCD | M12: 文字列 | P12: 半角 | S12: 4 | V12: [SQL1.チームCD] | AX12: 不要
D13: 3 | E13: チーム名 | M13: 文字列 | P13: 全角 | S13: 縮小して全体表示 | V13: TMチーム.チーム名 | AX13: 不要
D14: 4 | E14: 仕入先CD | M14: 文字列 | P14: 半角 | S14: 4 | V14: [SQL1.仕入先CD]
D15: 5 | E15: 略称 | M15: 文字列 | P15: 全角 | S15: 縮小して全体表示 | V15: TM仕入先.略称 | AX15: clsSiiresaki.略称
D16: 6 | E16: 日付範囲from | M16: 日付 | P16: 半角 | S16: 8 | V16: [画面.仕入日付開始日]
D17: 7 | E17: 日付範囲to | M17: 日付 | P17: 半角 | S17: 8 | V17: [画面.仕入日付終了日]
D18: 8 | E18: 仕入日付_1行目 | M18: 日付 | P18: 半角 | V18: 空欄
D19: 9 | E19: 見積番号_1行目 | M19: 文字列 | P19: 半角 | V19: 空欄
D20: 10 | E20: 見積件名_1行目 | M20: 文字列 | P20: 全角 | S20: 1 | V20: [計]
D21: 11 | E21: 得意先名_1行目 | M21: 文字列 | P21: 全角 | V21: 空欄
D22: 12 | E22: 製品NO_1行目 | M22: 文字列 | P22: 半角 | V22: 空欄
D23: 13 | E23: 仕様NO_1行目 | M23: 文字列 | P23: 半角 | V23: 空欄
D24: 14 | E24: 製品名_1行目 | M24: 文字列 | P24: 全角 | V24: 空欄
D25: 15 | E25: W_1行目 | M25: 文字列 | P25: 半角 | V25: 空欄
D26: 16 | E26: D_1行目 | M26: 文字列 | P26: 半角 | V26: 空欄
D27: 17 | E27: H_1行目 | M27: 文字列 | P27: 半角 | V27: 空欄
D28: 18 | E28: D1_1行目 | M28: 文字列 | P28: 半角 | V28: 空欄
D29: 19 | E29: D2_1行目 | M29: 文字列 | P29: 半角 | V29: 空欄
D30: 20 | E30: H1_1行目 | M30: 文字列 | P30: 半角 | V30: 空欄
D31: 21 | E31: H2_1行目 | M31: 文字列 | P31: 半角 | V31: 空欄
D32: 22 | E32: 仕入数量_1行目 | M32: 数値 | P32: 半角 | S32: 縮小して全体表示 | V32: [38.仕入数量] | AB32: [38.仕入数量]の合計 | AR32: 9999
D33: 23 | E33: 仕入単価_1行目 | M33: 数値 | P33: 半角 | V33: 空欄
D34: 24 | E34: 仕入金額_1行目 | M34: 数値 | P34: 半角 | S34: 縮小して全体表示 | V34: [40.仕入金額] | AB34: [40.仕入金額]の合計 | AR34: 9999
D35: 25 | E35: 仕入日付 | M35: 日付 | P35: 半角 | S35: 縮小して全体表示 | V35: [SQL1.仕入日付]
D36: 26 | E36: 見積番号 | M36: 文字列 | P36: 半角 | S36: 縮小して全体表示 | V36: [SQL1.見積番号]
D37: 27 | E37: 見積件名 | M37: 文字列 | P37: 全角 | S37: 縮小して全体表示 | V37: [SQL1.見積件名]
D38: 28 | E38: 得意先名 | M38: 文字列 | P38: 全角 | S38: 縮小して全体表示 | V38: [SQL1.得意先名1]
D39: 29 | E39: 製品NO | M39: 文字列 | P39: 半角 | S39: 7 | V39: [SQL1.製品NO]
D40: 30 | E40: 仕様NO | M40: 文字列 | P40: 半角 | S40: 7 | V40: [SQL1.仕様NO]
D41: 31 | E41: 製品名 | M41: 文字列 | P41: 全角 | S41: 縮小して全体表示 | V41: [SQL1.漢字名称]
D42: 32 | E42: W | M42: 文字列 | P42: 半角 | S42: 縮小して全体表示 | V42: [SQL1.W]
D43: 33 | E43: D | M43: 文字列 | P43: 半角 | S43: 縮小して全体表示 | V43: [SQL1.D]
D44: 34 | E44: H | M44: 文字列 | P44: 半角 | S44: 縮小して全体表示 | V44: [SQL1.H]
D45: 35 | E45: D1 | M45: 文字列 | P45: 半角 | S45: 縮小して全体表示 | V45: [SQL1.D1]
...

Sheet 処理詳細
B2: システム名 | H2: 画面ID | L2: システム分類 | R2: ドキュメント種別 | X2: ドキュメント名 | AK2: 帳票名 | AX2: 作成日 | BB2: 作成者 | BF2: 更新日 | BJ2: 更新者
B3: =変更履歴!B3 -> 受発注システム | H3: =変更履歴!H3 -> SK0300 | L3: =変更履歴!L3 -> 受発注 | R3: =変更履歴!R3 -> 帳票設計書 | X3: =変更履歴!X3 -> SK0300_仕入先検収明細表_帳票設計書 | AK3: =変更履歴!AK3 -> 仕入先検収明細表 | AX3: =変更履歴!AX3 -> 45623 | BB3: =変更履歴!BB3 -> 大谷 | BF3: =変更履歴!BF3 -> 45623 | BJ3: =変更履歴!BJ3 -> 大谷
B6: SQL1 | H6: select | J6: チームCD | R6: TM得意先.チームCD
J7: 仕入先CD | R7: TD仕入明細.仕入先CD
J8: 略称 | R8: TM仕入先.略称
J9: 仕入日付 | R9: TD仕入明細.仕入先CD仕入明細.仕入日付
J10: 見積番号 | R10: TD仕入明細.見積番号
J11: 見積件名 | R11: TD見積.見積件名
J12: 得意先名1 | R12: TD見積.得意先名1
J13: 製品NO | R13: TD仕入明細内訳.製品NO
J14: 仕様NO | R14: TD仕入明細内訳.仕様NO
J15: 漢字名称 | R15: TD仕入明細内訳.漢字名称
J16: W | R16: TD仕入明細内訳.W
J17: D | R17: TD仕入明細内訳.D
J18: H | R18: TD仕入明細内訳.H
... J25: 仕入金額 | R25: TD仕入明細内訳.仕入金額
J26: Count | R26: [TM得意先.チームCD]と[TD仕入明細.仕入先CD]の組み合わせごとの[TM得意先.チームCD]の件数 | AK26: Count = COUNT(TK.チームCD) OVER (PARTITION BY TK.チームCD,SM.仕入先CD)
H27: from | J27: TD仕入明細
J28: TD仕入明細内訳
J29: TD見積
J30: TM得意先
J31: TM仕入先
H32: join | J32: INNER
K33: TD仕入明細内訳
L34: [TD仕入明細.仕入番号]=[TD仕入明細内訳.仕入番号]
J35: INNER
K36: TD見積
L37: [TD仕入明細.見積番号]=[TD見積.見積番号]
J38: INNER
K39: TM得意先
L40: [TD見積.販売先得意先CD]=[TM得意先.得意先CD]
J41: INNER
K42: TM仕入先
L43: [TD仕入明細.仕入先CD]=[TM仕入先.仕入先CD]
H44: where | K44: [TD仕入明細.支払日付]>=[画面.S集計日付]
J45: AND | K45: [TD仕入明細.支払日付]<=[画面.E集計日付]
J46: AND | K46: [TM得意先.チームCD]>=[画面.SチームCD](NULLの場合はTM得意先.チームCD)
J47: AND | K47: [TM得意先.チームCD]<=[画面.EチームCD](NULLの場合はTM得意先.チームCD)
J48: AND | K48: [TD仕入明細.仕入先CD]>=[画面.S仕入先CD](NULLの場合はTD仕入明細.仕入先CD)
J49: AND | K49: [TD仕入明細.仕入先CD]<=[画面.E仕入先CD](NULLの場合はTD仕入明細.仕入先CD)
...

Sheet 処理詳細_書き方
B2: システム名 | H2: 画面ID | L2: 業務分類 | R2: ドキュメント種別 | X2: ドキュメント名 | AK2: 帳票名 | AX2: 作成日 | BB2: 作成者 | BF2: 更新日 | BJ2: 更新者
B3: =変更履歴!B3 -> 受発注システム | H3: =変更履歴!H3 -> SK0300 | L3: =変更履歴!L3 -> 受発注 | R3: =変更履歴!R3 -> 帳票設計書 | X3: =変更履歴!X3 -> SK0300_仕入先検収明細表_帳票設計書 | AK3: =変更履歴!AK3 -> 仕入先検収明細表 | AX3: =変更履歴!AX3 -> 45623 | BB3: =変更履歴!BB3 -> 大谷 | BF3: =変更履歴!BF3 -> 45623 | BJ3: =変更履歴!BJ3 -> 大谷
B7: 1.タイトルを記載 | H7: select | J7: 項目名 | R7: 格納テーブル
J8: 仕入先CD | R8: VM支払予定情報.仕入先CD
J9: 仕入先名1 | R9: VM支払予定情報.仕入先名1
H10: from | J10: 使用するテーブル名を記載
J11: TD売上請求H
J12: TD見積
J13: TM納入先
H14: join | J14: 結合方式
K15: 結合テーブル名
M16: 結合条件
L17: and | M17: 結合条件
L18: or | M18: 結合条件
J19: INNER JOIN
K20: TM納入先
M21: [TD見積.納入得意先CD] = [TM納入先.得意先CD]
L22: and | M22: [TD見積.納入先CD] = [TM納入先.納入先CD]
H23: where | K23: 取得条件 | AK23: パラメータの意味が分かる場合は記載する
J24: and | K24: 取得条件
J25: or | K25: 取得条件
J26: ※可能な限り日本語化する
K27: [TD見積.得意先CD] = '8001' | AK27: 8001'はヤオコーの得意先CD
J28: and | K28: [TD売上請求H.請求日付]が[画面.請求期間From]以降
H32: order by | J32: ソート条件を記載
J33: [画面.iYK物件区分]が1の場合は[TD見積.納入得意先CD],[TD見積.納入先CD],[TD売上請求H.見積番号]を昇順でソート
H36: group byなどほかの条件がある場合は行を追加して記載

Sheet 確認事項
B2: 確認事項
B3: No. | C3: シート名 | D3: タイトル | E3: 概要 | F3: 確認済
B4: 1
B5: 2
B6: 3
B7: 4
B8: 5
B9: 6
B10: 7
B11: 8
B12: 9
B13: 10
B14: 11
B15: 12
... B54: 51

Sheet 別紙_テンプレート
A1: 仕入先検収明細表 | P1: 41366
A3: 仕入先名 | D3: 日付範囲
A4: 仕入日付 | B4: 見積番号 | C4: 見積件名 | D4: 得意先名 | E4: 製品NO | F4: 仕様NO | G4: 製品名 | H4: W | I4: D | J4: H | K4: D1 | L4: D2 | M4: H1 | N4: H2 | O4: 仕入数量 | P4: 仕入単価 | Q4: 仕入金額
C5: 計 | O5: =SUM(O6:O7) -> 0 | Q5: =SUM(Q6:Q7) -> 0

Sheet 別紙_印刷レイアウト

Sheet 参照
A1: 数値
A2: ブール値
A3: 文字列
A4: 日付
A5: リスト
A6: 辞書配列
