Workbook

Sheet 変更履歴
B2: システム名 | H2: 画面ID | L2: システム分類 | R2: ドキュメント種別 | X2: ドキュメント名 | AK2: 帳票名 | AX2: 作成日 | BB2: 作成者 | BF2: 更新日 | BJ2: 更新者
B3: 受発注システム | H3: =LEFT($X$3,FIND("_",$X$3)-1) -> SK0400 | L3: 受発注 | R3: =MID($X$3,FIND("_",$X$3,FIND("_",$X$3)+1)+1,LEN($X$3)-FIND("_",$X$3,FIND("_",$X$3)+1)) -> 帳票設計書 | X3: =REPLACE(LEFT(CELL("filename",$B$2),FIND(".x",CELL("filename",$B$2))-1),1,FIND("[",CELL("filename",$B$2)),) -> SK0400_買掛金集計表(仕分出力)_帳票設計書 | AK3: =MID($X$3,FIND("_",$X$3)+1,FIND("_",$X$3,FIND("_",$X$3)+1)-FIND("_",$X$3)-1) -> 買掛金集計表(仕分出力) | AX3: 45539 | BB3: 大谷 | BF3: 45539 | BJ3: 大谷
C7: 変更履歴
C8: 日付 | G8: 版数 | K8: 担当 | O8: 変更箇所 | Y8: 内容
C9: 45539 | G9: 1.0.0 | K9: 大谷 | O9: - | Y9: 新規作成

Sheet 概要
B2: システム名 | H2: 画面ID | L2: システム分類 | R2: ドキュメント種別 | X2: ドキュメント名 | AK2: 帳票名 | AX2: 作成日 | BB2: 作成者 | BF2: 更新日 | BJ2: 更新者
B3: =変更履歴!B3 -> 受発注システム | H3: =変更履歴!H3 -> SK0400 | L3: =変更履歴!L3 -> 受発注 | R3: =変更履歴!R3 -> 帳票設計書 | X3: =変更履歴!X3 -> SK0400_買掛金集計表(仕分出力)_帳票設計書 | AK3: =変更履歴!AK3 -> 買掛金集計表(仕分出力) | AX3: =変更履歴!AX3 -> 45539 | BB3: =変更履歴!BB3 -> 大谷 | BF3: =変更履歴!BF3 -> 45539 | BJ3: =変更履歴!BJ3 -> 大谷
D7: 帳票の名称 | H7: =AK3 -> 買掛金集計表(仕分出力)
D8: 帳票テンプレート名 | H8: -
D9: ファイル種類 | H9: CSV
D10: ファイル拡張子 | H10: csv
D11: 文字コード | H11: SJIS
D12: コーテーション | H12: ダブルコーテーション
D13: 固定長/可変長 | H13: 可変長
D14: 区切り文字 | H14: カンマ
D15: 用紙サイズ
D16: 概要

Sheet 帳票レイアウト
B2: システム名 | H2: 画面ID | L2: システム分類 | R2: ドキュメント種別 | X2: ドキュメント名 | AK2: 帳票名 | AX2: 作成日 | BB2: 作成者 | BF2: 更新日 | BJ2: 更新者
B3: =変更履歴!B3 -> 受発注システム | H3: =変更履歴!H3 -> SK0400 | L3: =変更履歴!L3 -> 受発注 | R3: =変更履歴!R3 -> 帳票設計書 | X3: =変更履歴!X3 -> SK0400_買掛金集計表(仕分出力)_帳票設計書 | AK3: =変更履歴!AK3 -> 買掛金集計表(仕分出力) | AX3: =変更履歴!AX3 -> 45539 | BB3: =変更履歴!BB3 -> 大谷 | BF3: =変更履歴!BF3 -> 45539 | BJ3: =変更履歴!BJ3 -> 大谷
B6: ページ１

Sheet 項目一覧
B2: システム名 | H2: 画面ID | L2: システム分類 | R2: ドキュメント種別 | X2: ドキュメント名 | AK2: 帳票名 | AX2: 作成日 | BB2: 作成者 | BF2: 更新日 | BJ2: 更新者
B3: =変更履歴!B3 -> 受発注システム | H3: =変更履歴!H3 -> SK0400 | L3: =変更履歴!L3 -> 受発注 | R3: =変更履歴!R3 -> 帳票設計書 | X3: =変更履歴!X3 -> SK0400_買掛金集計表(仕分出力)_帳票設計書 | AK3: =変更履歴!AK3 -> 買掛金集計表(仕分出力) | AX3: =変更履歴!AX3 -> 45539 | BB3: =変更履歴!BB3 -> 大谷 | BF3: =変更履歴!BF3 -> 45539 | BJ3: =変更履歴!BJ3 -> 大谷
B7: 項目一覧
C9: 項目 | F9: フォントや文字サイズ、セル条件などは「別紙_テンプレート」準拠
D10: No. | E10: 項目名 | M10: データ型 | P10: 全角/半角 | S10: 文字数/桁数 | V10: データ取得元 | AB10: データ整形方法 | AR10: 整形後フォーマット | AX10: 備考
D11: 1 | E11: 年 | M11: 日付 | P11: 半角 | V11: SQL7.年 | AR11: yyyy
D12: 2 | E12: 月 | M12: 日付 | P12: 半角 | V12: SQL7.月 | AR12: mm
D13: 3 | E13: 日 | M13: 日付 | P13: 半角 | V13: SQL7.日 | AR13: dd
D14: 4 | E14: 伝票番号 | M14: 数値 | P14: 半角 | V14: SQL7.伝票番号
D15: 5 | E15: 借方金額 | M15: 数値 | P15: 半角 | V15: SQL7.借方金額 | AR15: 9999
D16: 6 | E16: 借方勘定科目CD | M16: 数値 | P16: 半角 | V16: SQL7.借方勘定科目CD
D17: 7 | E17: 借方勘定科目名 | M17: 文字列 | P17: 全角 | V17: SQL7.借方勘定科目名 | AB17: NULL
D18: 8 | E18: 借方消費税CD | M18: 数値 | P18: 半角 | V18: SQL7.借方消費税CD
D19: 9 | E19: 借方消費税率 | M19: 数値 | P19: 半角 | V19: SQL7.借方消費税率 | AB19: 0
D20: 10 | E20: 借方業種 | M20: 数値 | P20: 半角 | V20: SQL7.借方業種 | AB20: NULL
D21: 11 | E21: 借方補助科目CD | M21: 数値 | P21: 半角 | V21: SQL7.借方補助科目CD
D22: 12 | E22: 借方補助科目名 | M22: 文字列 | P22: 全角 | V22: SQL7.借方補助科目名 | AB22: NULL
D23: 13 | E23: 借方部門CD | M23: 数値 | P23: 半角 | V23: SQL7.借方部門CD | AB23: NULL
D24: 14 | E24: 借方部門名 | M24: 文字列 | P24: 全角 | V24: SQL7.借方部門名 | AB24: NULL
D25: 15 | E25: 貸方勘定科目CD | M25: 数値 | P25: 半角 | V25: SQL7.貸方勘定科目CD
D26: 16 | E26: 貸方勘定科目名 | M26: 文字列 | P26: 全角 | V26: SQL7.貸方勘定科目名 | AB26: NULL
D27: 17 | E27: 貸方消費税CD | M27: 数値 | P27: 半角 | V27: SQL7.貸方消費税CD
D28: 18 | E28: 貸方消費税率 | M28: 数値 | P28: 半角 | V28: SQL7.貸方消費税率 | AB28: 0
D29: 19 | E29: 貸方業種 | M29: 数値 | P29: 半角 | V29: SQL7.貸方業種 | AB29: NULL
D30: 20 | E30: 貸方補助科目CD | M30: 数値 | P30: 半角 | V30: SQL7.貸方補助科目CD | AB30: NULL
D31: 21 | E31: 貸方補助科目名 | M31: 文字列 | P31: 全角 | V31: SQL7.貸方補助科目名 | AB31: NULL
D32: 22 | E32: 貸方部門CD | M32: 数値 | P32: 半角 | V32: SQL7.貸方部門CD | AB32: NULL
D33: 23 | E33: 貸方部門名 | M33: 文字列 | P33: 全角 | V33: SQL7.貸方部門名 | AB33: NULL
D34: 24 | E34: 貸方金額 | M34: 数値 | P34: 半角 | V34: SQL7.貸方金額 | AR34: 9999
D35: 25 | E35: 摘要 | M35: 文字列 | P35: 全角 | V35: SQL7.摘要 | AX35: ダブルコーテーションで囲う
D36: 26 | E36: 期日_年 | M36: 日付 | P36: 半角 | V36: SQL7.期日_年 | AB36: NULL
D37: 27 | E37: 期日_月 | M37: 日付 | P37: 半角 | V37: SQL7.期日_月 | AB37: NULL
D38: 28 | E38: 期日_日 | M38: 日付 | P38: 半角 | V38: SQL7.期日_日 | AB38: NULL
D39: 29 | E39: 手形番号 | M39: 数値 | P39: 半角 | V39: SQL7.手形番号 | AB39: NULL

Sheet 処理詳細
B2: システム名 | H2: 画面ID | L2: システム分類 | R2: ドキュメント種別 | X2: ドキュメント名 | AK2: 帳票名 | AX2: 作成日 | BB2: 作成者 | BF2: 更新日 | BJ2: 更新者
B3: =変更履歴!B3 -> 受発注システム | H3: =変更履歴!H3 -> SK0400 | L3: =変更履歴!L3 -> 受発注 | R3: =変更履歴!R3 -> 帳票設計書 | X3: =変更履歴!X3 -> SK0400_買掛金集計表(仕分出力)_帳票設計書 | AK3: =変更履歴!AK3 -> 買掛金集計表(仕分出力) | AX3: =変更履歴!AX3 -> 45539 | BB3: =変更履歴!BB3 -> 大谷 | BF3: =変更履歴!BF3 -> 45539 | BJ3: =変更履歴!BJ3 -> 大谷
B6: SQL1 | H6: insert | J6: 区分 | R6: 0 | AK6: データ抽出（税抜き分・通常仕訳）
J7: 仕入先CD | R7: CONVERT(INT,TM買掛金額.仕入先CD)
J8: 年 | R8: YEAR(画面.仕訳日付)
J9: 月 | R9: MONTH(画面.仕訳日付)
J10: 日 | R10: DAY(画面.仕訳日付)
J11: 伝票番号 | R11: NULL
J12: 借方金額 | R12: ABS(CONVERT(INT,ISNULL(TM買掛金額.仕入金額,0)+ISNULL(TM買掛金額.返品金額,0)+ISNULL(TM買掛金額.訂正金額,0)-ISNULL(TM買掛金額.非課税金額,0)))
J13: 借方勘定科目名CD | R13: 461
J14: 借方勘定科目名 | R14: NULL
J15: 借方消費税CD | R15: TM仕入先.税集計区分が3の場合71、それ以外の場合31
J16: 借方消費税率 | R16: 画面.仕分日付時点の税率
J17: 借方業種 | R17: NULL
J18: 借方補助科目CD | R18: NULL
J19: 借方補助科目名 | R19: NULL
J20: 借方部門CD | R20: NULL
J21: 借方部門名 | R21: NULL
J22: 貸方勘定科目CD | R22: 201
J23: 貸方勘定科目名 | R23: NULL
J24: 貸方消費税CD | R24: 0
J25: 貸方消費税率 | R25: 0
J26: 貸方業種 | R26: NULL
J27: 貸方補助科目CD | R27: CONVERT(INT,TM買掛金額.仕入先CD),
J28: 貸方補助科目名 | R28: NULL
J29: 貸方部門CD | R29: NULL
J30: 貸方部門名 | R30: NULL
J31: 貸方金額 | R31: ABS(CONVERT(INT,ISNULL(TM買掛金額.仕入金額,0)+ISNULL(TM買掛金額.返品金額,0)+ISNULL(TM買掛金額.訂正金額,0)-ISNULL(TM買掛金額.非課税金額,0)))
J32: 摘要 | R32: CONVERT(VARCHAR(96), TM仕入先.仕入先名1)
J33: 期日_年 | R33: NULL
J34: 期日_月 | R34: NULL
J35: 期日_日 | R35: NULL
J36: 手形番号 | R36: NULL
H37: from | J37: FROM TM買掛金額 AS SK
H38: join | J38: LEFT JOIN TM仕入先 AS SI
K39: ON SK.仕入先CD = SI.仕入先CD
H40: where | J40: WHERE SK.買掛日付 = CONVERT(VARCHAR(10),画面.仕分日付,111)
K41: AND SK.仕入先CD >= COALESCE(CONVERT(VARCHAR(4),画面.開始仕入先),SK.仕入先CD)
K42: AND SK.仕入先CD <= COALESCE(CONVERT(VARCHAR(4),画面.終了仕入先),SK.仕入先CD)
K43: AND ISNULL(SK.仕入金額,0)+ISNULL(SK.返品金額,0)+ISNULL(SK.訂正金額,0)-ISNULL(SK.非課税金額,0) <> 0
...

Sheet 処理詳細_書き方
B2: システム名 | H2: 画面ID | L2: 業務分類 | R2: ドキュメント種別 | X2: ドキュメント名 | AK2: 帳票名 | AX2: 作成日 | BB2: 作成者 | BF2: 更新日 | BJ2: 更新者
B3: =変更履歴!B3 -> 受発注システム | H3: =変更履歴!H3 -> SK0400 | L3: =変更履歴!L3 -> 受発注 | R3: =変更履歴!R3 -> 帳票設計書 | X3: =変更履歴!X3 -> SK0400_買掛金集計表(仕分出力)_帳票設計書 | AK3: =変更履歴!AK3 -> 買掛金集計表(仕分出力) | AX3: =変更履歴!AX3 -> 45539 | BB3: =変更履歴!BB3 -> 大谷 | BF3: =変更履歴!BF3 -> 45539 | BJ3: =変更履歴!BJ3 -> 大谷
B7: 1.タイトルを記載 | H7: select | J7: 項目名 | R7: 格納テーブル
J8: 仕入先CD | R8: VM支払予定情報.仕入先CD
J9: 仕入先名1 | R9: VM支払予定情報.仕入先名1
H10: from | J10: 使用するテーブル名を記載
J11: TD売上請求H
J12: TD見積
J13: TM納入先
H14: join | J14: 結合方式
K15: 結合テーブル名
M16: 結合条件
L17: and | M17: 結合条件
L18: or | M18: 結合条件
J19: INNER JOIN
K20: TM納入先
M21: [TD見積.納入得意先CD] = [TM納入先.得意先CD]
L22: and | M22: [TD見積.納入先CD] = [TM納入先.納入先CD]
H23: where | K23: 取得条件 | AK23: パラメータの意味が分かる場合は記載する
J24: and | K24: 取得条件
J25: or | K25: 取得条件
J26: ※可能な限り日本語化する
K27: [TD見積.得意先CD] = '8001' | AK27: 8001'はヤオコーの得意先CD
J28: and | K28: [TD売上請求H.請求日付]が[画面.請求期間From]以降
H32: order by | J32: ソート条件を記載
J33: [画面.iYK物件区分]が1の場合は[TD見積.納入得意先CD],[TD見積.納入先CD],[TD売上請求H.見積番号]を昇順でソート
H36: group byなどほかの条件がある場合は行を追加して記載

Sheet 確認事項
B2: 確認事項
B3: No. | C3: シート名 | D3: タイトル | E3: 概要 | F3: 確認済
B4: 1
B5: 2
B6: 3
B7: 4
B8: 5
B9: 6
B10: 7
B11: 8
B12: 9
B13: 10
B14: 11
B15: 12
... B54: 51

Sheet 参照
A1: 数値
A2: ブール値
A3: 文字列
A4: 日付
A5: リスト
A6: 辞書配列
