Workbook

Sheet 変更履歴
B2: システム名 | H2: 画面ID | L2: システム分類 | R2: ドキュメント種別 | X2: ドキュメント名 | AK2: 帳票名 | AX2: 作成日 | BB2: 作成者 | BF2: 更新日 | BJ2: 更新者
B3: 受発注システム | H3: =LEFT($X$3,FIND("_",$X$3)-1) -> SS0300 | L3: 受発注 | R3: =MID($X$3,FIND("_",$X$3,FIND("_",$X$3)+1)+1,LEN($X$3)-FIND("_",$X$3,FIND("_",$X$3)+1)) -> 帳票設計書 | X3: =REPLACE(LEFT(CELL("filename",$B$2),FIND(".x",CELL("filename",$B$2))-1),1,FIND("[",CELL("filename",$B$2)),) -> SS0300_仕入日計表_帳票設計書 | AK3: =MID($X$3,FIND("_",$X$3)+1,FIND("_",$X$3,FIND("_",$X$3)+1)-FIND("_",$X$3)-1) -> 仕入日計表 | AX3: 45583 | BB3: 大谷 | BF3: 45583 | BJ3: 大谷
C7: 変更履歴
C8: 日付 | G8: 版数 | K8: 担当 | O8: 変更箇所 | Y8: 内容
C9: 45583 | G9: 1.0.0 | K9: 大谷 | O9: - | Y9: 新規作成

Sheet 概要
B2: システム名 | H2: 画面ID | L2: システム分類 | R2: ドキュメント種別 | X2: ドキュメント名 | AK2: 帳票名 | AX2: 作成日 | BB2: 作成者 | BF2: 更新日 | BJ2: 更新者
B3: =変更履歴!B3 -> 受発注システム | H3: =変更履歴!H3 -> SS0300 | L3: =変更履歴!L3 -> 受発注 | R3: =変更履歴!R3 -> 帳票設計書 | X3: =変更履歴!X3 -> SS0300_仕入日計表_帳票設計書 | AK3: =変更履歴!AK3 -> 仕入日計表 | AX3: =変更履歴!AX3 -> 45583 | BB3: =変更履歴!BB3 -> 大谷 | BF3: =変更履歴!BF3 -> 45583 | BJ3: =変更履歴!BJ3 -> 大谷
D7: 帳票の名称 | H7: =AK3 -> 仕入日計表
D8: 帳票テンプレート名 | H8: -
D9: ファイル種類 | H9: PDF
D10: ファイル拡張子 | H10: pdf
D11: 文字コード | H11: -
D12: コーテーション | H12: -
D13: 固定長/可変長 | H13: -
D14: 区切り文字 | H14: -
D15: 用紙サイズ | H15: A3横
D16: 概要

Sheet 帳票レイアウト
B2: システム名 | H2: 画面ID | L2: システム分類 | R2: ドキュメント種別 | X2: ドキュメント名 | AK2: 帳票名 | AX2: 作成日 | BB2: 作成者 | BF2: 更新日 | BJ2: 更新者
B3: =変更履歴!B3 -> 受発注システム | H3: =変更履歴!H3 -> SS0300 | L3: =変更履歴!L3 -> 受発注 | R3: =変更履歴!R3 -> 帳票設計書 | X3: =変更履歴!X3 -> SS0300_仕入日計表_帳票設計書 | AK3: =変更履歴!AK3 -> 仕入日計表 | AX3: =変更履歴!AX3 -> 45583 | BB3: =変更履歴!BB3 -> 大谷 | BF3: =変更履歴!BF3 -> 45583 | BJ3: =変更履歴!BJ3 -> 大谷
B6: ページ１

Sheet 項目一覧
B2: システム名 | H2: 画面ID | L2: システム分類 | R2: ドキュメント種別 | X2: ドキュメント名 | AK2: 帳票名 | AX2: 作成日 | BB2: 作成者 | BF2: 更新日 | BJ2: 更新者
B3: =変更履歴!B3 -> 受発注システム | H3: =変更履歴!H3 -> SS0300 | L3: =変更履歴!L3 -> 受発注 | R3: =変更履歴!R3 -> 帳票設計書 | X3: =変更履歴!X3 -> SS0300_仕入日計表_帳票設計書 | AK3: =変更履歴!AK3 -> 仕入日計表 | AX3: =変更履歴!AX3 -> 45583 | BB3: =変更履歴!BB3 -> 大谷 | BF3: =変更履歴!BF3 -> 45583 | BJ3: =変更履歴!BJ3 -> 大谷
B7: 項目一覧
C9: 項目 | F9: フォントや文字サイズ、セル条件などは「別紙_テンプレート」準拠
D10: No. | E10: 項目名 | M10: データ型 | P10: 全角/半角 | S10: 文字数/桁数 | V10: データ取得元 | AB10: データ整形方法 | AR10: 整形後フォーマット | AX10: 区分1 | AZ10: 区分2 | BB10: 備考
D11: 1 | E11: 作成日 | M11: 日付 | P11: 半角 | V11: 現在日付 | AR11: yyyy年mm月dd日
D12: 2 | E12: 開始仕入先 | M12: 文字列 | P12: 全角 | V12: 画面.開始CD | AB12: 開始仕入先がNullの場合は[最初]を表示 nullでない場合は[開始CD]を表示
D13: 3 | E13: 終了仕入先 | M13: 文字列 | P13: 全角 | V13: 画面.終了CD | AB13: 終了仕入先がNullの場合は[最後]を表示 nullでない場合は[終了CD]を表示
D14: 4 | E14: 開始日付 | M14: 日付 | P14: 半角 | V14: 画面.開始日付 | AR14: yyyy年mm月dd日
D15: 5 | E15: 終了日付 | M15: 日付 | P15: 半角 | V15: 画面.終了日付 | AR15: yyyy年mm月dd日
D16: 6 | E16: 仕入先CD | M16: 数値 | P16: 半角 | V16: SQL1.仕入先CD | BB16: 仕入先ごとの先頭行でのみ表示
D17: 7 | E17: 仕入先名1 | M17: 文字列 | P17: 全角 | V17: SQL1.仕入先名1 | BB17: 仕入先ごとの先頭行でのみ表示
D18: 8 | E18: 仕入先名2 | M18: 文字列 | P18: 全角 | V18: SQL1.仕入先名2 | BB18: 仕入先ごとの先頭行でのみ表示
D19: 9 | E19: 仕入日付 | M19: 日付 | P19: 半角 | V19: SQL1.仕入日付 | AR19: yyyy/mm/dd | BB19: 仕入先と仕入日付ごとの先頭行でのみ表示
D20: 10 | E20: 支払日付 | M20: 日付 | P20: 半角 | V20: SQL1.支払日付 | AR20: yyyy/mm/dd | BB20: 仕入先と支払日付ごとの先頭行でのみ表示
D21: 11 | E21: 伝票番号 | M21: 数値 | P21: 半角 | V21: SQL1.見積番号,SQL1.仕入明細行番号 | AB21: SQL1.見積番号-SQL1.仕入明細行番号の3桁0パディング | AX21: ○ | AZ21: ×
D22: 12 | E22: 製品NO | M22: 文字列 | P22: 半角 | V22: SQL1.製品NO | AX22: ○ | AZ22: ×
D23: 13 | E23: 仕様NO | M23: 文字列 | P23: 半角 | V23: SQL1.仕様NO | AX23: ○ | AZ23: ×
D24: 14 | E24: 製品名 | M24: 文字列 | P24: 全角/半角 | V24: SQL1.漢字名称 | AX24: ○ | AZ24: ×
D25: 15 | E25: W | M25: 数値 | P25: 半角 | V25: SQL1.W | AX25: ○ | AZ25: ×
D26: 16 | E26: D | M26: 数値 | P26: 半角 | V26: SQL1.D | AX26: ○ | AZ26: ×
D27: 17 | E27: H | M27: 数値 | P27: 半角 | V27: SQL1.H | AX27: ○ | AZ27: ×
D28: 18 | E28: 仕入数量 | M28: 数値 | P28: 半角 | V28: SQL1.仕入数量 | AR28: 9,999 or 9,999.00 | AX28: ○ | AZ28: ○ | BB28: 切り捨て前と切り捨て後の値が異なる場合、小数点第2位まで表示
D29: 19 | E29: 単位名 | M29: 文字列 | P29: 全角 | V29: SQL1.単位名 | AX29: ○ | AZ29: ×
D30: 20 | E30: 仕入単価 | M30: 数値 | P30: 半角 | V30: SQL1.仕入単価 | AR30: 99999 | AX30: ○ | AZ30: ○
D31: 21 | E31: 仕入金額 | M31: 数値 | P31: 半角 | V31: SQL1.仕入金額 | AR31: 99999 | AX31: ○ | AZ31: ○
D32: 22 | E32: 伝票区分 | M32: 文字列 | P32: 全角 | V32: SQL1.伝票区分 | AX32: ○ | AZ32: × | BB32: 1の場合"仕入"、2の場合"返品"、3の場合"単価訂正" それ以外は空
D33: 23 | E33: 仕分名称 | BB33: 原稿レイアウトに項目のみ存在→不要
D34: 24 | E34: 締日 | M34: 文字列 | P34: 全角 | V34: SQL1.支払締日 | AX34: ○ | AZ34: ×
D35: 25 | E35: 消費税 | M35: 数値 | P35: 半角 | V35: SQL1.仕入金額 | AB35: 仕入番号ごとの消費税 | AR35: 99999 | AX35: × | AZ35: ○
D36: 26 | E36: 見積件名 | M36: 文字列 | P36: 全角/半角 | V36: SQL1.見積件名
D37: 27 | E37: 合計金額 | M37: 数値 | P37: 半角 | V37: SQL1.仕入金額 | AB37: 仕入番号ごとの仕入金額合計 | AR37: 99999
D38: 28 | E38: 仕入先計 | M38: 数値 | P38: 半角 | V38: SQL1.仕入金額 | AB38: 仕入先CDごとの仕入金額合計 | AR38: 99999

Sheet 処理詳細
B2: システム名 | H2: 画面ID | L2: システム分類 | R2: ドキュメント種別 | X2: ドキュメント名 | AK2: 帳票名 | AX2: 作成日 | BB2: 作成者 | BF2: 更新日 | BJ2: 更新者
B3: =変更履歴!B3 -> 受発注システム | H3: =変更履歴!H3 -> SS0300 | L3: =変更履歴!L3 -> 受発注 | R3: =変更履歴!R3 -> 帳票設計書 | X3: =変更履歴!X3 -> SS0300_仕入日計表_帳票設計書 | AK3: =変更履歴!AK3 -> 仕入日計表 | AX3: =変更履歴!AX3 -> 45583 | BB3: =変更履歴!BB3 -> 大谷 | BF3: =変更履歴!BF3 -> 45583 | BJ3: =変更履歴!BJ3 -> 大谷
B6: SQL1 | H6: select | J6: 区分 | R6: 1 or 2
J7: 仕入先CD | R7: TD仕入明細.仕入先CD
J8: 仕入先名1 | R8: TD仕入明細.仕入先名1
J9: 仕入先名2 | R9: TD仕入明細.仕入先名2
J10: 仕入日付 | R10: TD仕入明細.仕入日付
J11: 支払日付 | R11: TD仕入明細.支払日付
J12: 見積件名 | R12: TD仕入.見積件名
J13: 見積番号 | R13: TD仕入明細.見積番号
J14: 仕入番号 | R14: TD仕入明細.仕入番号
J15: 仕入明細行番号 | R15: TD仕入明細内訳.仕入明細行番号 or '' AS 仕入明細行番号
J16: 製品NO | R16: TD仕入明細内訳.製品NO or '' AS 製品NO
J17: 仕様NO | R17: TD仕入明細内訳.仕様NO or '' AS 仕様NO
J18: 漢字名称 | R18: TD仕入明細内訳.漢字名称 or '' AS 漢字名称
... J31: 支払締日 | R31: TD仕入明細.支払締日が99の場合'月末'、 0の場合'都度' 、それ以外の場合,TD仕入明細.支払締日 + '日' or NULL AS 支払締日
H32: from | J32: FROM
J33: SQL2
J34: SQL3
J35: UNIION ALL
J36: AS DT
H37: order by | J37: DT.仕入先CD,DT.仕入日付,DT.見積番号,DT.仕入番号,DT.区分,DT.仕入明細行番号 を昇順でソート
B38: SQL2 | H38: select | J38: 区分 | R38: 1 AS 区分 | AK38: 明細用
J39: 仕入先CD | R39: TD仕入明細.仕入先CD
J40: 仕入先名1 | R40: TD仕入明細.仕入先名1
J41: 仕入先名2 | R41: TD仕入明細.仕入先名2
J42: 仕入日付 | R42: TD仕入明細.仕入日付
J43: 支払日付 | R43: TD仕入明細.支払日付
J44: 見積件名 | R44: TD仕入.見積件名
J45: 見積番号 | R45: TD仕入明細.見積番号
J46: 仕入番号 | R46: TD仕入明細.仕入番号
J47: 仕入明細行番号 | R47: TD仕入明細内訳.仕入明細行番号
J48: 製品NO | R48: TD仕入明細内訳.製品NO
J49: 仕様NO | R49: TD仕入明細内訳.仕様NO
J50: 漢字名称 | R50: TD仕入明細内訳.漢字名称
... J63: 支払締日 | R63: TD仕入明細.支払締日が99の場合'月末'、 0の場合'都度' 、それ以外の場合,TD仕入明細.支払締日 + '日'
H64: from | J64: FROM
J65: TD仕入明細
J66: AS SD
H67: join | J67: LEFT JOIN TD仕入 AS SR
...

Sheet 処理詳細_書き方
B2: システム名 | H2: 画面ID | L2: 業務分類 | R2: ドキュメント種別 | X2: ドキュメント名 | AK2: 帳票名 | AX2: 作成日 | BB2: 作成者 | BF2: 更新日 | BJ2: 更新者
B3: =変更履歴!B3 -> 受発注システム | H3: =変更履歴!H3 -> SS0300 | L3: =変更履歴!L3 -> 受発注 | R3: =変更履歴!R3 -> 帳票設計書 | X3: =変更履歴!X3 -> SS0300_仕入日計表_帳票設計書 | AK3: =変更履歴!AK3 -> 仕入日計表 | AX3: =変更履歴!AX3 -> 45583 | BB3: =変更履歴!BB3 -> 大谷 | BF3: =変更履歴!BF3 -> 45583 | BJ3: =変更履歴!BJ3 -> 大谷
B7: 1.タイトルを記載 | H7: select | J7: 項目名 | R7: 格納テーブル
J8: 仕入先CD | R8: VM支払予定情報.仕入先CD
J9: 仕入先名1 | R9: VM支払予定情報.仕入先名1
H10: from | J10: 使用するテーブル名を記載
J11: TD売上請求H
J12: TD見積
J13: TM納入先
H14: join | J14: 結合方式
K15: 結合テーブル名
M16: 結合条件
L17: and | M17: 結合条件
L18: or | M18: 結合条件
J19: INNER JOIN
K20: TM納入先
M21: [TD見積.納入得意先CD] = [TM納入先.得意先CD]
L22: and | M22: [TD見積.納入先CD] = [TM納入先.納入先CD]
H23: where | K23: 取得条件 | AK23: パラメータの意味が分かる場合は記載する
J24: and | K24: 取得条件
J25: or | K25: 取得条件
J26: ※可能な限り日本語化する
K27: [TD見積.得意先CD] = '8001' | AK27: 8001'はヤオコーの得意先CD
J28: and | K28: [TD売上請求H.請求日付]が[画面.請求期間From]以降
H32: order by | J32: ソート条件を記載
J33: [画面.iYK物件区分]が1の場合は[TD見積.納入得意先CD],[TD見積.納入先CD],[TD売上請求H.見積番号]を昇順でソート
H36: group byなどほかの条件がある場合は行を追加して記載

Sheet 確認事項
B2: 確認事項
B3: No. | C3: シート名 | D3: タイトル | E3: 概要 | F3: 回答 | G3: 確認済
B4: 1 | C4: 項目一覧 | D4: 開始CD、終了CD、開始日付、終了日付の取得先確認 | E4: フォームから取得している認識で間違いないか確認 | F4: 認識合っている | G4: 〇
B5: 2 | C5: 現行レイアウト | D5: 仕分名称を使用しているか確認 | E5: 項目は存在しているが使用していない認識で間違いないか確認 | F5: 使っていない | G5: 〇
B6: 3 | C6: 項目一覧 | D6: 消費税 | E6: 仕入番号ごとの消費税で間違いないか確認 | F6: 認識合っている | G6: 〇
B7: 4 | C7: 項目一覧 | D7: 合計金額 | E7: 仕入番号ごとの仕入金額合計で間違いないか確認 | F7: 認識合っている | G7: 〇
B8: 5 | C8: 項目一覧 | D8: 仕入先計 | E8: 仕入先CDごとの仕入金額合計で間違いないか確認 | F8: 認識合っている | G8: 〇
B9: 6
B10: 7
B11: 8
B12: 9
B13: 10
B14: 11
B15: 12
B16: 13
B17: 14
B18: 15
B19: 16
B20: 17
... B54: 51

Sheet 現行レイアウト

Sheet 別紙_印刷レイアウト

Sheet 参照
A1: 数値
A2: ブール値
A3: 文字列
A4: 日付
A5: リスト
A6: 辞書配列
