Workbook
Name CoreCells: 別紙_テンプレート1!$A$3:$O$3
Name CoreCells: 別紙_テンプレート2!#REF!
Name CoreCells: #REF!
Name CoreGroups: 別紙_テンプレート2!#REF!
Name CoreGroups: 別紙_テンプレート1!$1:$5
Name TotalRows: 別紙_テンプレート2!$3:$4
Name TotalRows: 別紙_テンプレート1!#REF!
Name 合計名称: #REF!
Name 作成日: 別紙_テンプレート2!#REF!
Name 作成日: 別紙_テンプレート1!$K$1
Name 締切: 別紙_テンプレート1!$D$1
Name 締切: 別紙_テンプレート2!#REF!
Name 締切: #REF!

Sheet 変更履歴
B2: システム名 | H2: 画面ID | L2: システム分類 | R2: ドキュメント種別 | X2: ドキュメント名 | AK2: 帳票名 | AX2: 作成日 | BB2: 作成者 | BF2: 更新日 | BJ2: 更新者
B3: 受発注システム | H3: =LEFT($X$3,FIND("_",$X$3)-1) -> SU1100 | L3: 受発注 | R3: =MID($X$3,FIND("_",$X$3,FIND("_",$X$3)+1)+1,LEN($X$3)-FIND("_",$X$3,FIND("_",$X$3)+1)) -> 帳票設計書 | X3: =REPLACE(LEFT(CELL("filename",$B$2),FIND(".x",CELL("filename",$B$2))-1),1,FIND("[",CELL("filename",$B$2)),) -> SU1100_ウエルシア請求明細_帳票設計書 | AK3: =MID($X$3,FIND("_",$X$3)+1,FIND("_",$X$3,FIND("_",$X$3)+1)-FIND("_",$X$3)-1) -> ウエルシア請求明細 | AX3: 45581 | BB3: 大谷 | BF3: 45581 | BJ3: 大谷
C7: 変更履歴
C8: 日付 | G8: 版数 | K8: 担当 | O8: 変更箇所 | Y8: 内容
C9: 45581 | G9: 1.0.0 | K9: 大谷 | O9: - | Y9: 新規作成

Sheet 概要
B2: システム名 | H2: 画面ID | L2: システム分類 | R2: ドキュメント種別 | X2: ドキュメント名 | AK2: 帳票名 | AX2: 作成日 | BB2: 作成者 | BF2: 更新日 | BJ2: 更新者
B3: =変更履歴!B3 -> 受発注システム | H3: =変更履歴!H3 -> SU1100 | L3: =変更履歴!L3 -> 受発注 | R3: =変更履歴!R3 -> 帳票設計書 | X3: =変更履歴!X3 -> SU1100_ウエルシア請求明細_帳票設計書 | AK3: =変更履歴!AK3 -> ウエルシア請求明細 | AX3: 45456 | BB3: =変更履歴!BB3 -> 大谷 | BF3: =変更履歴!BF3 -> 45581 | BJ3: =変更履歴!BJ3 -> 大谷
D7: 帳票の名称 | H7: =AK3 -> ウエルシア請求明細
D8: 帳票テンプレート名 | H8: TemplateWel請求明細
D9: ファイル種類 | H9: Excel
D10: ファイル拡張子 | H10: xlsx
D11: 文字コード | H11: -
D12: コーテーション | H12: -
D13: 固定長/可変長 | H13: -
D14: 区切り文字 | H14: -
D15: 用紙サイズ | H15: A4横
D16: 概要 | H16: 通常、リース、その他の3シートに分かれる

Sheet 帳票レイアウト
B2: システム名 | H2: 画面ID | L2: システム分類 | R2: ドキュメント種別 | X2: ドキュメント名 | AK2: 帳票名 | AX2: 作成日 | BB2: 作成者 | BF2: 更新日 | BJ2: 更新者
B3: =変更履歴!B3 -> 受発注システム | H3: =変更履歴!H3 -> SU1100 | L3: =変更履歴!L3 -> 受発注 | R3: =変更履歴!R3 -> 帳票設計書 | X3: =変更履歴!X3 -> SU1100_ウエルシア請求明細_帳票設計書 | AK3: =変更履歴!AK3 -> ウエルシア請求明細 | AX3: =変更履歴!AX3 -> 45581 | BB3: =変更履歴!BB3 -> 大谷 | BF3: =変更履歴!BF3 -> 45581 | BJ3: =変更履歴!BJ3 -> 大谷
B6: ページ１
B49: ページ2

Sheet 項目一覧
B2: システム名 | H2: 画面ID | L2: システム分類 | R2: ドキュメント種別 | X2: ドキュメント名 | AK2: 帳票名 | AX2: 作成日 | BB2: 作成者 | BF2: 更新日 | BJ2: 更新者
B3: =変更履歴!B3 -> 受発注システム | H3: =変更履歴!H3 -> SU1100 | L3: =変更履歴!L3 -> 受発注 | R3: =変更履歴!R3 -> 帳票設計書 | X3: =変更履歴!X3 -> SU1100_ウエルシア請求明細_帳票設計書 | AK3: =変更履歴!AK3 -> ウエルシア請求明細 | AX3: =変更履歴!AX3 -> 45581 | BB3: =変更履歴!BB3 -> 大谷 | BF3: =変更履歴!BF3 -> 45581 | BJ3: =変更履歴!BJ3 -> 大谷
B7: 項目一覧
C9: 項目 | F9: フォントや文字サイズ、セル条件などは「別紙_テンプレート」準拠
D10: No. | E10: 項目名 | M10: データ型 | P10: 全角/半角 | S10: 文字数/桁数 | V10: データ取得元 | AB10: データ整形方法 | AR10: 整形後フォーマット | AX10: 備考
D11: 1 | E11: 締切 | M11: 日付 | P11: 全角 | S11: 4 | V11: 画面.請求日付To | AR11: mm月締切
D12: 2 | E12: 作成日 | M12: 日付 | P12: 半角 | S12: 8 | V12: 現在日付
D13: 3 | E13: No. | M13: 数値 | P13: 半角 | S13: 縮小して全体表示 | V13: -
D14: 4 | E14: リース | M14: 数値 | P14: 半角 | S14: 5 | V14: TD見積.ウエルシアリース区分
D15: 5 | E15: 物件区分 | M15: 数値 | P15: 半角 | S15: 7 | V15: TD見積.ウエルシア物件区分CD
D16: 6 | E16: 日付 | M16: 日付 | P16: 半角 | S16: 8 | V16: TD見積.納期S
D17: 7 | E17: 店舗番号 | M17: 文字列 | P17: 半角 | S17: 縮小して全体表示 | V17: TD見積.納入先CD
D18: 8 | E18: 伝票番号 | M18: 数値 | P18: 半角 | S18: 縮小して全体表示 | V18: TD売上請求H.見積番号
D19: 9 | E19: 店舗名 | M19: 文字列 | P19: 全角 | S19: 縮小して全体表示 | V19: TD見積.納入先名1
D20: 10 | E20: 内容 | M20: 文字列 | P20: 全角 | S20: 縮小して全体表示 | V20: TD見積.ウエルシア物件内容名
D21: 11 | E21: 部材金額 | M21: 数値 | P21: 半角 | S21: 縮小して全体表示 | V21: TM製品.費用区分,TD売上明細v2.売上金額 | AB21: [TM製品.費用区分]が0の[TD売上明細v2.売上金額]の合計 | AR21: 999999
D22: 12 | E22: 労務金額 | M22: 数値 | P22: 半角 | S22: 縮小して全体表示 | V22: TM製品.費用区分,TD売上明細v2.売上金額,TD売上明細v2.製品NO | AB22: [TM製品.費用区分]が0 && [TD売上明細v2.製品NO]が「z019,z101,z103」でない場合の[TM売上明細v2.売上金額]の合計 | AR22: 999999
D23: 13 | E23: 販売割戻金 | M23: 数値 | P23: 半角 | S23: 縮小して全体表示 | V23: TD売上v2.売上金額 | AB23: [TM製品.製品NO]が'z103'の時の[TD売上明細v2.売上金額]の合計 | AR23: 999999
D24: 14 | E24: 消費税 | M24: 数値 | P24: 半角 | S24: 縮小して全体表示 | V24: TD売上請求H.外税額 | AR24: 999999
D25: 15 | E25: 特別出精値引 | M25: 数値 | P25: 半角 | S25: 縮小して全体表示 | V25: TM製品.費用区分,TD売上明細v2.売上金額,TD売上明細v2.製品NO | AB25: [TM製品.製品NO]が'z101','z019'の時の[TD売上明細v2.売上金額]の合計 | AR25: 999999
D26: 16 | E26: 請求金額（税抜） | M26: 数値 | P26: 半角 | S26: 縮小して全体表示 | V26: TD売上請求H.合計金額 | AR26: 999999
D27: 17 | E27: 請求金額（税込） | M27: 数値 | P27: 半角 | S27: 縮小して全体表示 | V27: TD売上請求H.合計金額,TD売上請求H.外税額 | AB27: [TD売上請求H.合計金額]と[TD売上請求H.外税額]を足した値 | AR27: 999999
D28: 18 | E28: 請求書合計件数_部材金額 | M28: 数値 | P28: 半角 | S28: 縮小して全体表示 | V28: 部材金額 | AB28: カラムの合計 | AR28: 999999
D29: 19 | E29: 請求書合計件数_労務金額 | M29: 数値 | P29: 半角 | S29: 縮小して全体表示 | V29: 労務金額 | AB29: カラムの合計 | AR29: 999999
D30: 20 | E30: 請求書合計件数_販売割戻金 | M30: 数値 | P30: 半角 | S30: 縮小して全体表示 | V30: 販売割戻金 | AB30: カラムの合計 | AR30: 999999
D31: 21 | E31: 請求書合計件数_消費税 | M31: 数値 | P31: 半角 | S31: 縮小して全体表示 | V31: 消費税 | AB31: カラムの合計 | AR31: 999999
D32: 22 | E32: 請求書合計件数_特別出精値引 | M32: 数値 | P32: 半角 | S32: 縮小して全体表示 | V32: 特別出精値引き | AB32: カラムの合計 | AR32: 999999
D33: 23 | E33: 請求書合計件数_請求金額（税抜） | M33: 数値 | P33: 半角 | S33: 縮小して全体表示 | V33: 請求金額（税抜） | AB33: カラムの合計 | AR33: 999999
D34: 24 | E34: 請求書合計件数_請求金額（税込） | M34: 数値 | P34: 半角 | S34: 縮小して全体表示 | V34: 請求金額（税込） | AB34: TD売上請求H.合計金額とTD売上請求H.外税額を足した値の合計 | AR34: 999999
D35: 25 | E35: タイトル | M35: 文字列 | P35: 全角 | S35: 縮小して全体表示 | V35: TD見積.ウエルシアリース区分 | AB35: ウエルシアリース区分が2の場合は「m月リース合計」、それ以外の場合は「m月支払合計」 | AR35: 999999
D36: 26 | E36: 部材金額 | M36: 数値 | P36: 半角 | S36: 縮小して全体表示 | V36: 請求書合計件数_部材金額 | AB36: [請求書合計件数_部材金額]の値 | AR36: 999999
D37: 27 | E37: 施工金額 | M37: 数値 | P37: 半角 | S37: 縮小して全体表示 | V37: 請求書合計件数_労務金額 | AB37: [請求書合計件数_労務金額]の値 | AR37: 999999
D38: 28 | E38: 販売割戻金 | M38: 数値 | P38: 半角 | S38: 縮小して全体表示 | V38: 請求書合計件数_販売割戻金 | AB38: [請求書合計件数_販売割戻金]の値 | AR38: 999999
... D42: 32 | E42: 請求金額（税込） | M42: 数値 | P42: 半角 | S42: 縮小して全体表示 | V42: 請求書合計件数_請求金額（税込） | AB42: [請求書合計件数_請求金額（税込）]の値 | AR42: 999999
D43: 33

Sheet 処理詳細
B2: システム名 | H2: 画面ID | L2: システム分類 | R2: ドキュメント種別 | X2: ドキュメント名 | AK2: 帳票名 | AX2: 作成日 | BB2: 作成者 | BF2: 更新日 | BJ2: 更新者
B3: =変更履歴!B3 -> 受発注システム | H3: =変更履歴!H3 -> SU1100 | L3: =変更履歴!L3 -> 受発注 | R3: =変更履歴!R3 -> 帳票設計書 | X3: =変更履歴!X3 -> SU1100_ウエルシア請求明細_帳票設計書 | AK3: =変更履歴!AK3 -> ウエルシア請求明細 | AX3: =変更履歴!AX3 -> 45581 | BB3: =変更履歴!BB3 -> 大谷 | BF3: =変更履歴!BF3 -> 45581 | BJ3: =変更履歴!BJ3 -> 大谷
B6: 1 | H6: select | J6: ウエルシアリース区分 | R6: TD見積
J7: ウエルシア物件区分CD | R7: TD見積
J8: ウエルシア物件区分名 | R8: TMウエルシア物件区分
J9: 納期S | R9: TD見積
J10: 納入先CD | R10: TD見積
J11: 見積番号 | R11: TD売上請求H
J12: 納入先名1 | R12: TD見積
J13: ウエルシア物件内容名 | R13: TD見積
J14: 合計金額 | R14: TD売上請求H
J15: 外税額 | R15: TD売上請求H
J16: 税込金額 | R16: [TD売上請求H.合計金額] + [TD売上請求H.外税額]
J17: 部材費 | R17: sql2
J18: 施工費 | R18: sql2
... J20: 特別出精値引 | R20: sql2
H24: from | J24: TD売上請求H
H26: join | J26: INNER JOIN
K27: sql2
J29: INNER JOIN
K30: TD見積
L31: [TD見積.見積番号] = [TD売上請求H.見積番号]
J33: LEFT JOIN
K34: [TD見積.ウエルシア物件区分CD] = [TMウエルシア物件区分.ウエルシア物件区分CD]
H36: where | K36: [TD売上請求H.請求日付] >= [画面.集計日付From]
J37: and | K37: [TD売上請求H.請求日付] <= [画面.集計日付To]
J38: and | K38: [TD見積.得意先CD] = '2401'
H40: order by | J40: [TD見積.ウエルシアリース区分],[TD見積.ウエルシア物件区分CD],[TD見積.納期S],[TD見積.見積番号]を昇順でソート
B41: 2.sql2 | H41: select | J41: 見積番号 | R41: TD売上v2
J42: 部材費 | R42: [TM製品.製品区分]が0の場合の[TD売上明細v2.売上金額]の合計
J43: 施工費 | R43: [TM製品.製品区分]が1の場合かつ[TD売上明細v2.製品NO]の値が「'Z019','Z101','Z103'」以外の場合の[TD売上明細v2.売上金額]の合計
J44: 販売割戻金 | R44: [TD売上明細v2.製品NO]が'Z103'の場合の[TD売上明細v2.売上金額]の合計
J45: 特別出精値引き | R45: [TD売上明細v2.製品NO]が「'Z101','Z019'」の場合の[TD売上明細v2.売上金額]の合計
H46: from | J46: TD売上v2
H48: join | J48: INNER JOIN
K49: TD売上明細v2
L50: [TD売上v2.売上番号] = [TD売上明細v2.売上番号]
J52: LEFT JOIN
K53: TM製品
M54: [TD売上明細v2.製品NO] = [TM製品.製品NO]
...

Sheet 処理詳細_書き方
B2: システム名 | H2: 画面ID | L2: 業務分類 | R2: ドキュメント種別 | X2: ドキュメント名 | AK2: 帳票名 | AX2: 作成日 | BB2: 作成者 | BF2: 更新日 | BJ2: 更新者
B3: =変更履歴!B3 -> 受発注システム | H3: =変更履歴!H3 -> SU1100 | L3: =変更履歴!L3 -> 受発注 | R3: =変更履歴!R3 -> 帳票設計書 | X3: =変更履歴!X3 -> SU1100_ウエルシア請求明細_帳票設計書 | AK3: =変更履歴!AK3 -> ウエルシア請求明細 | AX3: =変更履歴!AX3 -> 45581 | BB3: =変更履歴!BB3 -> 大谷 | BF3: =変更履歴!BF3 -> 45581 | BJ3: =変更履歴!BJ3 -> 大谷
B7: 1.タイトルを記載 | H7: select | J7: 項目名 | R7: 格納テーブル
J8: 仕入先CD | R8: VM支払予定情報.仕入先CD
J9: 仕入先名1 | R9: VM支払予定情報.仕入先名1
H10: from | J10: 使用するテーブル名を記載
J11: TD売上請求H
J12: TD見積
J13: TM納入先
H14: join | J14: 結合方式
K15: 結合テーブル名
M16: 結合条件
L17: and | M17: 結合条件
L18: or | M18: 結合条件
J19: INNER JOIN
K20: TM納入先
M21: [TD見積.納入得意先CD] = [TM納入先.得意先CD]
L22: and | M22: [TD見積.納入先CD] = [TM納入先.納入先CD]
H23: where | K23: 取得条件 | AK23: パラメータの意味が分かる場合は記載する
J24: and | K24: 取得条件
J25: or | K25: 取得条件
J26: ※可能な限り日本語化する
K27: [TD見積.得意先CD] = '8001' | AK27: 8001'はヤオコーの得意先CD
J28: and | K28: [TD売上請求H.請求日付]が[画面.請求期間From]以降
H32: order by | J32: ソート条件を記載
J33: [画面.iYK物件区分]が1の場合は[TD見積.納入得意先CD],[TD見積.納入先CD],[TD売上請求H.見積番号]を昇順でソート
H36: group byなどほかの条件がある場合は行を追加して記載

Sheet 確認事項
B2: 確認事項
B3: No. | C3: シート名 | D3: タイトル | E3: 概要 | F3: 確認済
B4: 1
B5: 2
B6: 3
B7: 4
B8: 5
B9: 6
B10: 7
B11: 8
B12: 9
B13: 10
B14: 11
B15: 12
... B54: 51

Sheet 別紙_テンプレート1
G1: 請求明細一覧 | K1: 42170
A2: No. | B2: リース | C2: 物件区分 | D2: 日付 | E2: 店舗番号 | F2: 伝票番号 | G2: 店 舗 名 | H2: 内容 | I2: 部材金額 | J2: 労務金額 | K2: 販売割戻金 | L2: 消費税 | M2: 特別出精値引 | N2: 請求金額(税抜) | O2: 請求金額(税込)
A5: 請求書合計件数 | I5: =SUM(I3:I4) -> 0 | J5: =SUM(J3:J4) -> 0 | K5: =SUM(K3:K4) -> 0 | L5: =SUM(L3:L4) -> 0 | M5: =SUM(M3:M4) -> 0 | N5: =SUM(N3:N4) -> 0 | O5: =SUM(O3:O4) -> 0

Sheet 別紙_テンプレート2
E3: 10月支払合計 | I3: 部材金額 | J3: 施工金額 | K3: 販売割戻金 | L3: 消費税 | M3: 特別出精値引 | N3: 請求金額(税抜) | O3: 請求金額(税込)

Sheet 別紙_印刷レイアウト

Sheet 参照
A1: 数値
A2: ブール値
A3: 文字列
A4: 日付
A5: リスト
A6: 辞書配列
