Workbook
Name CoreCells: 別紙_テンプレート!$A$43:$P$43
Name CoreCellsRow: 別紙_テンプレート!$39:$73
Name インボイス登録番号: 別紙_テンプレート!$K$9
Name 会社担当者: 別紙_テンプレート!$K$16
Name 会社担当者E_mail: 別紙_テンプレート!$K$17
Name 見積金額: 別紙_テンプレート!$D$8
Name 見積件名: 別紙_テンプレート!$D$13
Name 見積日: [1]別紙_テンプレート!#REF!
Name 見積日: 別紙_テンプレート!#REF!
Name 見積番号: 別紙_テンプレート!$A$1
Name 見積有効期限: [1]別紙_テンプレート!#REF!
Name 見積有効期限: 別紙_テンプレート!#REF!
Name 現場名: [1]別紙_テンプレート!#REF!
Name 現場名: 別紙_テンプレート!#REF!
Name 合計金額: 別紙_テンプレート!$D$11
Name 作成日: 別紙_テンプレート!$O$1
Name 支払条件: 別紙_テンプレート!$D$17
Name 受注区分: [1]別紙_テンプレート!#REF!
Name 受注区分: 別紙_テンプレート!#REF!
Name 受注先1: [1]別紙_テンプレート!#REF!
Name 受注先1: 別紙_テンプレート!#REF!
Name 受渡地: 別紙_テンプレート!$D$16
Name 消費税額: 別紙_テンプレート!$D$10
Name 消費税見出し: 別紙_テンプレート!$A$10
Name 担当者: [1]別紙_テンプレート!#REF!
Name 担当者: 別紙_テンプレート!#REF!
Name 担当者名: 別紙_テンプレート!$K$16
Name 店番: 別紙_テンプレート!$F$16
Name 得意先名1: 別紙_テンプレート!$A$3
Name 得意先名2: 別紙_テンプレート!$A$4
Name 納期: 別紙_テンプレート!$D$15
Name 納入先1: [1]別紙_テンプレート!#REF!
Name 納入先1: 別紙_テンプレート!#REF!
Name 納入先住所1: [1]別紙_テンプレート!#REF!
Name 納入先住所1: 別紙_テンプレート!#REF!
Name 非課税金額: 別紙_テンプレート!$D$9
Name 備考: 別紙_テンプレート!$D$18

Sheet 変更履歴
B2: システム名 | H2: 画面ID | L2: システム分類 | R2: ドキュメント種別 | X2: ドキュメント名 | AK2: 帳票名 | AX2: 作成日 | BB2: 作成者 | BF2: 更新日 | BJ2: 更新者
B3: 受発注システム | H3: =LEFT($X$3,FIND("_",$X$3)-1) -> SU1300 | L3: 受発注 | R3: =MID($X$3,FIND("_",$X$3,FIND("_",$X$3)+1)+1,LEN($X$3)-FIND("_",$X$3,FIND("_",$X$3)+1)) -> 帳票設計書 | X3: =REPLACE(LEFT(CELL("filename",$B$2),FIND(".x",CELL("filename",$B$2))-1),1,FIND("[",CELL("filename",$B$2)),) -> SU1300_請求書(屋外広告物専用)_帳票設計書 | AK3: =MID($X$3,FIND("_",$X$3)+1,FIND("_",$X$3,FIND("_",$X$3)+1)-FIND("_",$X$3)-1) -> 請求書(屋外広告物専用) | AX3: 45581 | BB3: 大谷 | BF3: 45581 | BJ3: 大谷
C7: 変更履歴
C8: 日付 | G8: 版数 | K8: 担当 | O8: 変更箇所 | Y8: 内容
C9: 45581 | G9: 1.0.0 | K9: 大谷 | O9: - | Y9: 新規作成

Sheet 概要
B2: システム名 | H2: 画面ID | L2: システム分類 | R2: ドキュメント種別 | X2: ドキュメント名 | AK2: 帳票名 | AX2: 作成日 | BB2: 作成者 | BF2: 更新日 | BJ2: 更新者
B3: =変更履歴!B3 -> 受発注システム | H3: =変更履歴!H3 -> SU1300 | L3: =変更履歴!L3 -> 受発注 | R3: =変更履歴!R3 -> 帳票設計書 | X3: =変更履歴!X3 -> SU1300_請求書(屋外広告物専用)_帳票設計書 | AK3: =変更履歴!AK3 -> 請求書(屋外広告物専用) | AX3: =変更履歴!AX3 -> 45581 | BB3: =変更履歴!BB3 -> 大谷 | BF3: =変更履歴!BF3 -> 45581 | BJ3: =変更履歴!BJ3 -> 大谷
D7: 帳票の名称 | H7: =AK3 -> 請求書(屋外広告物専用)
D8: 帳票テンプレート名 | H8: Temp_請求書_屋外広告物.xlsx
D9: ファイル種類 | H9: Excel,PDF
D10: ファイル拡張子 | H10: xlsx,pdf
D11: 文字コード | H11: -
D12: コーテーション | H12: -
D13: 固定長/可変長 | H13: -
D14: 区切り文字 | H14: -
D15: 用紙サイズ | H15: A4横
D16: 概要

Sheet 帳票レイアウト
B2: システム名 | H2: 画面ID | L2: システム分類 | R2: ドキュメント種別 | X2: ドキュメント名 | AK2: 帳票名 | AX2: 作成日 | BB2: 作成者 | BF2: 更新日 | BJ2: 更新者
B3: =変更履歴!B3 -> 受発注システム | H3: =変更履歴!H3 -> SU1300 | L3: =変更履歴!L3 -> 受発注 | R3: =変更履歴!R3 -> 帳票設計書 | X3: =変更履歴!X3 -> SU1300_請求書(屋外広告物専用)_帳票設計書 | AK3: =変更履歴!AK3 -> 請求書(屋外広告物専用) | AX3: =変更履歴!AX3 -> 45581 | BB3: =変更履歴!BB3 -> 大谷 | BF3: =変更履歴!BF3 -> 45581 | BJ3: =変更履歴!BJ3 -> 大谷
B6: ページ１

Sheet 項目一覧
B2: システム名 | H2: 画面ID | L2: システム分類 | R2: ドキュメント種別 | X2: ドキュメント名 | AK2: 帳票名 | AX2: 作成日 | BB2: 作成者 | BF2: 更新日 | BJ2: 更新者
B3: =変更履歴!B3 -> 受発注システム | H3: =変更履歴!H3 -> SU1300 | L3: =変更履歴!L3 -> 受発注 | R3: =変更履歴!R3 -> 帳票設計書 | X3: =変更履歴!X3 -> SU1300_請求書(屋外広告物専用)_帳票設計書 | AK3: =変更履歴!AK3 -> 請求書(屋外広告物専用) | AX3: =変更履歴!AX3 -> 45581 | BB3: =変更履歴!BB3 -> 大谷 | BF3: =変更履歴!BF3 -> 45581 | BJ3: =変更履歴!BJ3 -> 大谷
B7: 項目一覧
C9: 項目 | F9: フォントや文字サイズ、セル条件などは「別紙_テンプレート」準拠
D10: No. | E10: 項目名 | M10: データ型 | P10: 全角/半角 | S10: 文字数/桁数 | V10: データ取得元 | AB10: データ整形方法 | AR10: 整形後フォーマット | AX10: 備考
D11: 1 | E11: 見積番号 | M11: 数値 | P11: 半角 | S11: 46 | V11: SQL19.見積番号 | AB11: "No." + [SQL19.見積番号]
D12: 2 | E12: 作成日 | M12: 日付 | P12: 半角 | S12: 8 | V12: 画面.請求書発行日付 | AR12: yyyy年mm月dd日
D13: 3 | E13: 得意先名1 | M13: 文字列 | P13: 全角 | S13: 16 | V13: SQL19.得意先名1 | AB13: [SQL19.得意先名2]が空出ない場合は[SQL19.得意先名1]、からの場合は""を表示
D14: 4 | E14: 得意先名2 | M14: 文字列 | P14: 全角 | S14: 縮小して全体表示 | V14: TD見積.得意先名1,TD見積.得意先名2 | AB14: [SQL19.得意先名2]が空出ない場合は[SQL19.得意先名2]、からの場合は[SQL19.得意先名1]を表示
D15: 5 | E15: 御請求金額 | M15: 数値 | P15: 半角 | S15: 14 | V15: SQL19.合計金額 | AR15: \999,999-
D16: 6 | E16: 御見積金額(非課税)
D17: 7 | E17: 消費税見出し | M17: 文字列 | P17: 全角 | S17: 10 | V17: SQL19.請求日付,SQL19.切替日付,SQL19.税率,SQL19.旧税率 | AB17: [SQL19.請求日付]>=[SQL19.切替日付]の場合は[SQL19.税率]、 [SQL19.請求日付]<[SQL19.切替日付]の場合は[SQL19.旧税率]を[税率]とする。 "消費税等(" & [税率] & "%)"を表示する
D18: 8 | E18: 消費税等 | M18: 数値 | P18: 半角 | S18: 14 | V18: SQL19.外税額 | AR18: \999,999-
D19: 9 | E19: 合計 | M19: 数値 | P19: 半角 | S19: 14 | V19: 5.御請求金額,6.消費税等 | AB19: [5.御請求金額]と[6.消費税等]の合計。 | AR19: \999,999-
D20: 10 | E20: 件名 | M20: 文字列 | P20: 全角 | S20: 縮小して全体表示 | V20: SQL19.見積件名
D21: 11 | E21: 納期 | M21: 文字列 | P21: 全角 | S21: 縮小して全体表示 | V21: SQL19.納期S,SQL19.納期E | AB21: [SQL19.納期S]と[SQL19.納期E]のどちらもnullでない場合、[SQL19.納期S]~[SQL19.納期E]を表示する。 [SQL19.納期S]がnullの場合、[SQL19.納期E]を表示する。 それ以外の場合、[SQL19.納期S]を表示する。 | AR21: yyyy年mm月dd日
D22: 12 | E22: 受渡地 | M22: 文字列 | P22: 全角 | S22: 縮小して全体表示 | V22: SQL19.現場名,SQL19.納入先CD,SQL19.納入得意先CD | AB22: [SQL19.納入得意先CD]が"2401", "8001"の場合は[SQL19.現場名]に対して[SQL19.納入先CD]文字を””に置き換えた値
D23: 13 | E23: 店番 | M23: 文字列 | P23: 半角 | S23: 11 | V23: SQL19.納入先CD,SQL19.納入得意先CD | AB23: [SQL19.納入得意先CD]が"2401", "8001"の場合は[SQL19.納入先CD]、それ以外の場合は""を表示
D24: 14 | E24: 御支払条件 | M24: 文字列 | P24: 全角 | S24: 縮小して全体表示 | V24: SQL19.支払条件,SQL19.支払条件その他 | AB24: [SQL19.支払条件]が0の場合は"別途御打ち合せによる"、[SQL19.支払条件]が1の場合は[SQL19.支払条件その他]を表示
D25: 15 | E25: 備考 | M25: 文字列 | P25: 全角 | S25: 縮小して全体表示 | V25: SQL19.備考
D26: 16 | E26: 売場面積 | M26: 文字列 | P26: 全角 | S26: 9 | V26: SQL19.ウエルシア売場面積 | AB26: [SQL19.ウエルシア売場面積]が0出ない場合、"売 場 面 積 ："を表示
D27: 17 | E27: ウエルシア売場面積 | M27: 数値 | P27: 半角 | S27: 22 | V27: SQL19.ウエルシア売場面積 | AB27: [SQL19.ウエルシア売場面積]が0出ない場合、[SQL19.ウエルシア売場面積]を表示 | AR27: [TD見積.ウエルシア売場面積] & "坪"
D28: 18 | E28: インボイス登録番号 | M28: 数値 | P28: 全角 | S28: 9 | V28: TM会社.インボイス登録番号 | AB28: [TM会社.インボイス登録番号]が空の場合は何も表示しない | AR28: "登録番号 " & [TM会社.インボイス登録番号] | AX28: clsKaisya.cls
D29: 19 | E29: 会社郵便番号 | M29: 数値 | P29: 半角 | S29: 9 | V29: [TM会社.郵便番号]
D30: 20 | E30: 会社住所 | M30: 文字列 | P30: 全角 | S30: 22 | V30: [TM会社.住所1]
D31: 21 | E31: 会社電話番号 | M31: 数値 | P31: 半角 | S31: 17 | V31: [TM会社.電話番号]
D32: 22 | E32: 会社FAX番号 | M32: 数値 | P32: 半角 | S32: 16 | V32: [TM会社.FAX番号]
D33: 23 | E33: 銀行名 | M33: 文字列 | P33: 全角 | S33: 22 | V33: 空
D34: 24 | E34: 会社担当者 | M34: 文字列 | P34: 全角 | S34: 22 | V34: TM担当者.問い合わせ先 | AB34: [TM担当者.問い合わせ先]が空の場合は何も表示しない | AR34: 担当：[TM担当者.問い合わせ先]
D35: 25 | E35: 会社担当者E_mail | M35: 文字列 | P35: 半角 | S35: 45 | V35: 空 | AX35: 空
D36: 26 | E36: 通貨名 | M36: 文字列 | P36: 全角 | S36: 7 | V36: "(単位：円)"
D37: 27 | E37: SEQ | M37: 数値 | P37: 半角 | S37: 3 | V37: SQL21.仕分番号 | AB37: [SQL21.仕分番号]のゼロ埋め2桁
D38: 28 | E38: 項目 | M38: 文字列 | P38: 半角 | S38: 3 | V38: SQL21.伝票区分,SQL21.行番号 | AB38: [SQL21.伝票区分]が"C"か"A"か"S"の場合””、それ以外の場合[TD見積シートM.行番号]を表示
D39: 29 | E39: 品名 | M39: 文字列 | P39: 全角 | S39: 18 | V39: SQL21.伝票区分,SQL21.漢字名称 | AB39: [SQL21.伝票区分]が"C"か"A"か"S"の場合" "&[SQL21.漢字名称]、それ以外の場合[SQL21.漢字名称]を表示
D40: 30 | E40: 製品 | M40: 文字列 | P40: 全角 | S40: 5 | V40: SQL21.PC区分,SQL21.製品NO | AR40: [SQL21.PC区分]&[SQL21.製品NO]
D41: 31 | E41: 仕様 | M41: 文字列 | P41: 全角 | S41: 5 | V41: SQL21.仕様NO
D42: 32 | E42: W | M42: 数値 | P42: 半角 | S42: 8 | V42: SQL21.W
D43: 33 | E43: D | M43: 数値 | P43: 半角 | S43: 8 | V43: SQL21.D,SQL21.D1,SQL21.D2 | AB43: [SQL21.D]が0でない場合は[SQL21.D]を表示 [SQL21.D]が0の場合、 [SQL21.D1],[SQL21.D2]どちらも0の場合は””を表示 [SQL21.D1],[SQL21.D2]どちらかが0でない場合は[SQL21.D1]&”/”&[SQL21.D2]を表示
D44: 34 | E44: H | M44: 数値 | P44: 半角 | S44: 8 | V44: SQL21.H,SQL21.H1,SQL21.H2 | AB44: [SQL21.H]が0でない場合は[SQL21.H]を表示 [SQL21.H]が0の場合、 [SQL21.H1],[SQL21.H2]どちらも0の場合は””を表示 [SQL21.H1],[SQL21.H2]どちらかが0でない場合は[SQL21.H1]&”/”&[SQL21.H2]を表示
D45: 35 | E45: 売上数量 | M45: 数値 | P45: 半角 | S45: 1 | V45: SQL21.数量
...

Sheet 処理詳細_書き方
B2: システム名 | H2: 画面ID | L2: 業務分類 | R2: ドキュメント種別 | X2: ドキュメント名 | AK2: 帳票名 | AX2: 作成日 | BB2: 作成者 | BF2: 更新日 | BJ2: 更新者
B3: =変更履歴!B3 -> 受発注システム | H3: =変更履歴!H3 -> SU1300 | L3: =変更履歴!L3 -> 受発注 | R3: =変更履歴!R3 -> 帳票設計書 | X3: =変更履歴!X3 -> SU1300_請求書(屋外広告物専用)_帳票設計書 | AK3: =変更履歴!AK3 -> 請求書(屋外広告物専用) | AX3: =変更履歴!AX3 -> 45581 | BB3: =変更履歴!BB3 -> 大谷 | BF3: =変更履歴!BF3 -> 45581 | BJ3: =変更履歴!BJ3 -> 大谷
B7: 1.タイトルを記載 | H7: select | J7: 項目名 | R7: 格納テーブル
J8: 仕入先CD | R8: VM支払予定情報.仕入先CD
J9: 仕入先名1 | R9: VM支払予定情報.仕入先名1
H10: from | J10: 使用するテーブル名を記載
J11: TD売上請求H
J12: TD見積
J13: TM納入先
H14: join | J14: 結合方式
K15: 結合テーブル名
M16: 結合条件
L17: and | M17: 結合条件
L18: or | M18: 結合条件
J19: INNER JOIN
K20: TM納入先
M21: [TD見積.納入得意先CD] = [TM納入先.得意先CD]
L22: and | M22: [TD見積.納入先CD] = [TM納入先.納入先CD]
H23: where | K23: 取得条件 | AK23: パラメータの意味が分かる場合は記載する
J24: and | K24: 取得条件
J25: or | K25: 取得条件
J26: ※可能な限り日本語化する
K27: [TD見積.得意先CD] = '8001' | AK27: 8001'はヤオコーの得意先CD
J28: and | K28: [TD売上請求H.請求日付]が[画面.請求期間From]以降
H32: order by | J32: ソート条件を記載
J33: [画面.iYK物件区分]が1の場合は[TD見積.納入得意先CD],[TD見積.納入先CD],[TD売上請求H.見積番号]を昇順でソート
H36: group byなどほかの条件がある場合は行を追加して記載

Sheet 処理詳細
B2: システム名 | H2: 画面ID | L2: システム分類 | R2: ドキュメント種別 | X2: ドキュメント名 | AK2: 帳票名 | AX2: 作成日 | BB2: 作成者 | BF2: 更新日 | BJ2: 更新者
B3: =変更履歴!B3 -> 受発注システム | H3: =[3]変更履歴!H3 -> 27 | L3: =[3]変更履歴!L3 -> 運用自動化 | R3: =[3]変更履歴!R3 -> 帳票設計書 | X3: =[3]変更履歴!X3 -> 27_ヤオコー請求明細表_帳票設計書 | AK3: =[3]変更履歴!AK3 -> ヤオコー請求明細表 | AX3: =[3]変更履歴!AX3 -> 0 | BB3: =[3]変更履歴!BB3 -> 0 | BF3: =[3]変更履歴!BF3 -> 0 | BJ3: =[3]変更履歴!BJ3 -> 0
B6: INSERT SQL | H6: into | J6: #WK見積明細
H7: from | J7: SQL1 AS AS 見積明細
B8: SQL1.見積出力用データ作成 | H8: select | J8: 見積番号 | R8: UNION_SQL.見積番号
J9: 仕分番号 | R9: UNION_SQL.仕分番号
J10: 仕分名称 | R10: UNION_SQL.仕分名称
J11: 行番号 | R11: UNION_SQL.行番号
J12: SP区分 | R12: UNION_SQL.SP区分
J13: PC区分 | R13: UNION_SQL.PC区分
J14: 製品NO | R14: UNION_SQL.製品NO
J15: 仕様NO | R15: UNION_SQL.仕様NO
J16: 漢字名称 | R16: UNION_SQL.漢字名称
J17: W | R17: UNION_SQL.W
J18: D | R18: UNION_SQL.D
J19: H | R19: UNION_SQL.H
J20: D1 | R20: UNION_SQL.D1
... J42: 伝票区分 | R42: UNION_SQL.伝票区分
H43: from | J43: 2.コメントでないもの
J44: 3.コメントAのもの
J45: 4.コメントCのもの
J46: 5.附属部材でコメントでないもの
J47: 6.附属部材でコメントAのもの
J48: 7.附属部材でコメントCのもの
J49: 8.出精値引
H50: union | J50: (
L51: 2.コメントでないもの
K52: union all
L53: 3.コメントAのもの
K54: union all
L55: 4.コメントCのもの
K56: union all
L57: 5.客先在庫・転用数があるもの
K58: union all
L59: 6.客先在庫・転用数があるものでコメントAのもの
K60: union all
L61: 7.客先在庫・転用数があるものでコメントCのもの
K62: union all
L63: 8.出精値引
J64: ) AS UNION_SQL
...

Sheet 確認事項
B2: 確認事項
B3: No. | C3: シート名 | D3: タイトル | E3: 概要 | F3: 確認済
B4: 1 | C4: 項目一覧 | D4: No18~25 | E4: 中国用の判定を行っている[COUNTRY_CODE]の設定元が不明。 | F4: 〇
B5: 2 | D5: No18~25 | E5: 中国用のテキストの設定欄がK7～K12となっているが最新のテンプレートに合わせてK10~K15変更する必要あるか | F5: 〇
B6: 3
B7: 4
B8: 5
B9: 6
B10: 7
B11: 8
B12: 9
B13: 10
B14: 11
B15: 12
B16: 13
B17: 14
... B54: 51

Sheet 別紙_テンプレート
E1: 御 請 求 書
A6: 下記の通り御請求申し上げます。
A8: 御請求金額
A9: 御請求金額(非課税)
A10: 消費税等(10%)
A11: 合計 | D11: =SUM(D8+D10) -> 0 | K11: 〒360-0012
K12: 埼玉県熊谷市上之2919-5
A13: 件 名 ： | K13: TEL 048-525-1171㈹
K14: FAX 048-525-0008
A15: 納 期 ：
A16: 受 渡 地 ： | K16: 担当：蓮見 明
A17: 御支払条件 ： | K17: E-mail：xxx@sanwashouken.co.jp
A18: 備 考 ：
G19: 振込先 | H19: 埼玉りそな銀行 熊谷支店
H20: 当座№0113747 ㈱三和商研 | O20: (単位：円)
A21: SEC | B21: 項目 | C21: 品名 | E21: 製品 | F21: 仕様 | G21: Ｗ | H21: Ｄ | I21: Ｈ | K21: 数量 | L21: 単位 | N21: 単価 | O21: 金額
K22: =IF(MOD(J22,1)=0,TEXT(J22,"#,###"),TEXT(J22,"#,##0.##")) | N22: =IF(MOD(M22,1)=0,TEXT(M22,"#,###"),TEXT(M22,"#,##0.##"))
K23: =IF(MOD(J23,1)=0,TEXT(J23,"#,###"),TEXT(J23,"#,##0.##")) | N23: =IF(MOD(M23,1)=0,TEXT(M23,"#,###"),TEXT(M23,"#,##0.##"))
K24: =IF(MOD(J24,1)=0,TEXT(J24,"#,###"),TEXT(J24,"#,##0.##")) | N24: =IF(MOD(M24,1)=0,TEXT(M24,"#,###"),TEXT(M24,"#,##0.##"))
K25: =IF(MOD(J25,1)=0,TEXT(J25,"#,###"),TEXT(J25,"#,##0.##")) | N25: =IF(MOD(M25,1)=0,TEXT(M25,"#,###"),TEXT(M25,"#,##0.##"))
K26: =IF(MOD(J26,1)=0,TEXT(J26,"#,###"),TEXT(J26,"#,##0.##")) | N26: =IF(MOD(M26,1)=0,TEXT(M26,"#,###"),TEXT(M26,"#,##0.##"))
K27: =IF(MOD(J27,1)=0,TEXT(J27,"#,###"),TEXT(J27,"#,##0.##")) | N27: =IF(MOD(M27,1)=0,TEXT(M27,"#,###"),TEXT(M27,"#,##0.##"))
K28: =IF(MOD(J28,1)=0,TEXT(J28,"#,###"),TEXT(J28,"#,##0.##")) | N28: =IF(MOD(M28,1)=0,TEXT(M28,"#,###"),TEXT(M28,"#,##0.##"))
K29: =IF(MOD(J29,1)=0,TEXT(J29,"#,###"),TEXT(J29,"#,##0.##")) | N29: =IF(MOD(M29,1)=0,TEXT(M29,"#,###"),TEXT(M29,"#,##0.##"))
K30: =IF(MOD(J30,1)=0,TEXT(J30,"#,###"),TEXT(J30,"#,##0.##")) | N30: =IF(MOD(M30,1)=0,TEXT(M30,"#,###"),TEXT(M30,"#,##0.##"))
K31: =IF(MOD(J31,1)=0,TEXT(J31,"#,###"),TEXT(J31,"#,##0.##")) | N31: =IF(MOD(M31,1)=0,TEXT(M31,"#,###"),TEXT(M31,"#,##0.##"))
K32: =IF(MOD(J32,1)=0,TEXT(J32,"#,###"),TEXT(J32,"#,##0.##")) | N32: =IF(MOD(M32,1)=0,TEXT(M32,"#,###"),TEXT(M32,"#,##0.##"))
K33: =IF(MOD(J33,1)=0,TEXT(J33,"#,###"),TEXT(J33,"#,##0.##")) | N33: =IF(MOD(M33,1)=0,TEXT(M33,"#,###"),TEXT(M33,"#,##0.##"))
... K38: =IF(MOD(J38,1)=0,TEXT(J38,"#,###"),TEXT(J38,"#,##0.##")) | N38: =IF(MOD(M38,1)=0,TEXT(M38,"#,###"),TEXT(M38,"#,##0.##"))
O40: (単位：円)
A41: SEC | B41: 項目 | C41: 品名 | E41: 製品 | F41: 仕様 | G41: Ｗ | H41: Ｄ | I41: Ｈ | K41: 数量 | L41: 単位 | N41: 単価 | O41: 金額
K42: =IF(MOD(J42,1)=0,TEXT(J42,"#,###"),TEXT(J42,"#,##0.##")) | N42: =IF(MOD(M42,1)=0,TEXT(M42,"#,###"),TEXT(M42,"#,##0.##"))
K43: =IF(MOD(J43,1)=0,TEXT(J43,"#,###"),TEXT(J43,"#,##0.##")) | N43: =IF(MOD(M43,1)=0,TEXT(M43,"#,###"),TEXT(M43,"#,##0.##"))
K44: =IF(MOD(J44,1)=0,TEXT(J44,"#,###"),TEXT(J44,"#,##0.##")) | N44: =IF(MOD(M44,1)=0,TEXT(M44,"#,###"),TEXT(M44,"#,##0.##"))
K45: =IF(MOD(J45,1)=0,TEXT(J45,"#,###"),TEXT(J45,"#,##0.##")) | N45: =IF(MOD(M45,1)=0,TEXT(M45,"#,###"),TEXT(M45,"#,##0.##"))
K46: =IF(MOD(J46,1)=0,TEXT(J46,"#,###"),TEXT(J46,"#,##0.##")) | N46: =IF(MOD(M46,1)=0,TEXT(M46,"#,###"),TEXT(M46,"#,##0.##"))
K47: =IF(MOD(J47,1)=0,TEXT(J47,"#,###"),TEXT(J47,"#,##0.##")) | N47: =IF(MOD(M47,1)=0,TEXT(M47,"#,###"),TEXT(M47,"#,##0.##"))
K48: =IF(MOD(J48,1)=0,TEXT(J48,"#,###"),TEXT(J48,"#,##0.##")) | N48: =IF(MOD(M48,1)=0,TEXT(M48,"#,###"),TEXT(M48,"#,##0.##"))
K49: =IF(MOD(J49,1)=0,TEXT(J49,"#,###"),TEXT(J49,"#,##0.##")) | N49: =IF(MOD(M49,1)=0,TEXT(M49,"#,###"),TEXT(M49,"#,##0.##"))
K50: =IF(MOD(J50,1)=0,TEXT(J50,"#,###"),TEXT(J50,"#,##0.##")) | N50: =IF(MOD(M50,1)=0,TEXT(M50,"#,###"),TEXT(M50,"#,##0.##"))
...

Sheet 別紙_印刷レイアウト

Sheet 参照
A1: 数値
A2: ブール値
A3: 文字列
A4: 日付
A5: リスト
A6: 辞書配列
