Workbook
Name CoreCells: 別紙_テンプレート!$A$6:$I$6
Name NenRetu: 別紙_テンプレート!$D:$I
Name SumCore: 別紙_テンプレート!#REF!
Name YearNamePos: 別紙_テンプレート!$D$3
Name 集計範囲: 別紙_テンプレート!$C$1

Sheet 変更履歴
B2: システム名 | H2: 画面ID | L2: システム分類 | R2: ドキュメント種別 | X2: ドキュメント名 | AK2: 帳票名 | AX2: 作成日 | BB2: 作成者 | BF2: 更新日 | BJ2: 更新者
B3: 受発注システム | H3: =LEFT($X$3,FIND("_",$X$3)-1) -> TK0100 | L3: 受発注 | R3: =MID($X$3,FIND("_",$X$3,FIND("_",$X$3)+1)+1,LEN($X$3)-FIND("_",$X$3,FIND("_",$X$3)+1)) -> 帳票設計書 | X3: =REPLACE(LEFT(CELL("filename",$B$2),FIND(".x",CELL("filename",$B$2))-1),1,FIND("[",CELL("filename",$B$2)),) -> TK0100_得意先別年間売上順位推移表_帳票設計書 | AK3: =MID($X$3,FIND("_",$X$3)+1,FIND("_",$X$3,FIND("_",$X$3)+1)-FIND("_",$X$3)-1) -> 得意先別年間売上順位推移表 | AX3: 45581 | BB3: 大谷 | BF3: 45581 | BJ3: 大谷
C7: 変更履歴
C8: 日付 | G8: 版数 | K8: 担当 | O8: 変更箇所 | Y8: 内容
C9: 45581 | G9: 1.0.0 | K9: 大谷 | O9: - | Y9: 新規作成

Sheet 概要
B2: システム名 | H2: 画面ID | L2: システム分類 | R2: ドキュメント種別 | X2: ドキュメント名 | AK2: 帳票名 | AX2: 作成日 | BB2: 作成者 | BF2: 更新日 | BJ2: 更新者
B3: =変更履歴!B3 -> 受発注システム | H3: =変更履歴!H3 -> TK0100 | L3: =変更履歴!L3 -> 受発注 | R3: =変更履歴!R3 -> 帳票設計書 | X3: =変更履歴!X3 -> TK0100_得意先別年間売上順位推移表_帳票設計書 | AK3: =変更履歴!AK3 -> 得意先別年間売上順位推移表 | AX3: =変更履歴!AX3 -> 45581 | BB3: =変更履歴!BB3 -> 大谷 | BF3: =変更履歴!BF3 -> 45581 | BJ3: =変更履歴!BJ3 -> 大谷
D7: 帳票の名称 | H7: =AK3 -> 得意先別年間売上順位推移表
D8: 帳票テンプレート名 | H8: Template得意先別年間売上順位推移表.xlsx
D9: ファイル種類 | H9: Excel
D10: ファイル拡張子 | H10: xlsx
D11: 文字コード | H11: -
D12: コーテーション | H12: -
D13: 固定長/可変長 | H13: -
D14: 区切り文字 | H14: -
D15: 用紙サイズ
D16: 概要 | H16: 年が古い順に左から並ぶ

Sheet 帳票レイアウト
B2: システム名 | H2: 画面ID | L2: システム分類 | R2: ドキュメント種別 | X2: ドキュメント名 | AK2: 帳票名 | AX2: 作成日 | BB2: 作成者 | BF2: 更新日 | BJ2: 更新者
B3: =変更履歴!B3 -> 受発注システム | H3: =変更履歴!H3 -> TK0100 | L3: =変更履歴!L3 -> 受発注 | R3: =変更履歴!R3 -> 帳票設計書 | X3: =変更履歴!X3 -> TK0100_得意先別年間売上順位推移表_帳票設計書 | AK3: =変更履歴!AK3 -> 得意先別年間売上順位推移表 | AX3: =変更履歴!AX3 -> 45581 | BB3: =変更履歴!BB3 -> 大谷 | BF3: =変更履歴!BF3 -> 45581 | BJ3: =変更履歴!BJ3 -> 大谷
B6: ページ１

Sheet 項目一覧
B2: システム名 | H2: 画面ID | L2: システム分類 | R2: ドキュメント種別 | X2: ドキュメント名 | AK2: 帳票名 | AX2: 作成日 | BB2: 作成者 | BF2: 更新日 | BJ2: 更新者
B3: =変更履歴!B3 -> 受発注システム | H3: =変更履歴!H3 -> TK0100 | L3: =変更履歴!L3 -> 受発注 | R3: =変更履歴!R3 -> 帳票設計書 | X3: =変更履歴!X3 -> TK0100_得意先別年間売上順位推移表_帳票設計書 | AK3: =変更履歴!AK3 -> 得意先別年間売上順位推移表 | AX3: =変更履歴!AX3 -> 45581 | BB3: =変更履歴!BB3 -> 大谷 | BF3: =変更履歴!BF3 -> 45581 | BJ3: =変更履歴!BJ3 -> 大谷
B7: 項目一覧
C9: 項目 | F9: フォントや文字サイズ、セル条件などは「別紙_テンプレート」準拠
D10: No. | E10: 項目名 | M10: データ型 | P10: 全角/半角 | S10: 文字数/桁数 | V10: データ取得元 | AB10: データ整形方法 | AR10: 整形後フォーマット | AX10: 備考
D11: 1 | E11: 期間from | M11: 日付 | P11: 半角 | S11: 4 | V11: 画面.集計年開始日 | AB11: "yyyy年4月" | AR11: "yyyy年4月"
D12: 2 | E12: 期間to | M12: 日付 | P12: 半角 | S12: 4 | V12: 画面.集計年終了日 | AB12: "yyyy年3月" | AR12: "yyyy年3月"
D13: 3 | E13: 集計年 | M13: 日付 | P13: 半角 | S13: 4 | V13: 画面.集計年開始日 | AB13: [画面.集計年開始日]+1+i | AR13: "yyyy年"
D14: 4 | E14: 原価金額合計 | M14: 数値 | P14: 半角 | S14: 6 | V14: 12.原価金額 | AB14: [12.原価金額]の合計 | AR14: 9999
D15: 5 | E15: 原価率合計 | M15: 数値 | P15: 半角 | S15: 10 | V15: 4.原価金額合計,6.純売上金額合計 | AB15: [4.原価金額合計]から[6.純売上金額合計]を割って100を掛けた値 | AR15: 9.99
D16: 6 | E16: 純売上金額合計 | M16: 数値 | P16: 半角 | S16: 10 | V16: 14.純売上金額 | AB16: [14.純売上金額]の合計 | AR16: 9999
D17: 7 | E17: 得意先CD | M17: 数値 | P17: 半角 | S17: 8 | V17: SQL17.得意先CD
D18: 8 | E18: 得意先名1 | M18: 文字列 | P18: 全角 | S18: 7 | V18: SQL17.得意先名1
D19: 9 | E19: 得意先名2 | M19: 文字列 | P19: 全角 | S19: 5 | V19: SQL17.得意先名2
D20: 10 | E20: 順位 | M20: 数値 | P20: 半角 | S20: 4 | V20: SQL17.順位i+1
D21: 11 | E21: 前対比 | M21: 数値 | P21: 半角 | S21: 4 | V21: 14.純売上金額 | AB21: 前年の純売上金額がある場合は[14.純売上金額]に100をかけて前年の[純売上金額]で割った値、ない場合は0 | AR21: 99.9
D22: 12 | E22: 原価金額 | M22: 数値 | P22: 半角 | S22: 6 | V22: SQL17.原価金額i+1 | AR22: 999999
D23: 13 | E23: 原価率 | M23: 数値 | P23: 半角 | S23: 5 | V23: SQL17.原価金額i+1,SQL17.税抜金額i+1 | AB23: [SQL17.税抜金額i+1]が０の場合、[SQL17.原価金額i+1]を表示 それ以外の場合、[SQL17.原価金額i+1]/[SQL17.税抜金額i+1]*100を表示 | AR23: 99.99
D24: 14 | E24: 純売上金額 | M24: 数値 | P24: 半角 | S24: 10 | V24: SQL17.税抜金額i+1 | AR24: 999999
D25: 15 | E25: パーセント | M25: 数値 | P25: 半角 | S25: 4 | V25: 14.純売上金額,6.純売上金額合計 | AB25: [14.純売上金額]から[6.純売上金額合計]を割って100を掛けた値 | AR25: 99.9

Sheet 処理詳細
B2: システム名 | H2: 画面ID | L2: システム分類 | R2: ドキュメント種別 | X2: ドキュメント名 | AK2: 帳票名 | AX2: 作成日 | BB2: 作成者 | BF2: 更新日 | BJ2: 更新者
B3: =変更履歴!B3 -> 受発注システム | H3: =変更履歴!H3 -> TK0100 | L3: =変更履歴!L3 -> 受発注 | R3: =変更履歴!R3 -> 帳票設計書 | X3: =変更履歴!X3 -> TK0100_得意先別年間売上順位推移表_帳票設計書 | AK3: =変更履歴!AK3 -> 得意先別年間売上順位推移表 | AX3: =変更履歴!AX3 -> 45581 | BB3: =変更履歴!BB3 -> 大谷 | BF3: =変更履歴!BF3 -> 45581 | BJ3: =変更履歴!BJ3 -> 大谷
B6: IF | J6: IF [画面.集計区分] = 0
K7: SQL1
K8: SQL5
K9: SQL6
J10: ELSE
K11: SQL8
K12: SQL12
K13: SQL13
B14: INSERT SQL1 | H14: insert | J14: #TMP
H15: select | J15: 得意先CD | R15: SQL2.得意先CD
J16: 年 | R16: SQL2.年
J17: 順位 | R17: NULL
J18: 原価金額 | R18: NULL
J19: 税抜金額 | R19: SQL2.税抜金額
J20: 比率 | R20: NULL
J21: トータル税抜金額 | R21: SQL2.トータル税抜金額
H22: from | J22: SQL2
B23: SQL2 | H23: select | J23: 得意先CD | R23: U.得意先CD
J24: 年 | R24: U.年
J25: 税抜金額 | R25: U.税抜金額
J26: トータル税抜金額 | R26: TOTAL.トータル税抜金額
H27: from | J27: SQL3 AS U
J28: SQL4 AS TOTAL
H29: join | J29: LEFT JOIN
K30: SQL4
M31: U.年 = TOTAL.年
B32: SQL3 | H32: select | J32: 得意先CD | R32: MH.得意先CD
J33: 年 | R33: CASE WHEN MONTH(UH.売上日付) <= 3 THEN YEAR(UH.売上日付) - 1 ELSE YEAR(UH.売上日付) END
J34: 税抜金額 | R34: SUM(CASE WHEN UM.売上税区分 = 1 THEN (UM.売上金額-UM.消費税額) ELSE UM.売上金額 END)
H35: from | J35: TD売上v2 AS UH
J36: TD見積 AS MH
J37: TD売上明細v2 AS UM
H38: join | J38: INNER JOIN
K39: TD見積
M40: UH.見積番号 = MH.見積番号
J41: INNER JOIN
K42: TD売上明細v2
M43: UH.売上番号 = UM.売上番号
...

Sheet 処理詳細_書き方
B2: システム名 | H2: 画面ID | L2: 業務分類 | R2: ドキュメント種別 | X2: ドキュメント名 | AK2: 帳票名 | AX2: 作成日 | BB2: 作成者 | BF2: 更新日 | BJ2: 更新者
B3: =変更履歴!B3 -> 受発注システム | H3: =変更履歴!H3 -> TK0100 | L3: =変更履歴!L3 -> 受発注 | R3: =変更履歴!R3 -> 帳票設計書 | X3: =変更履歴!X3 -> TK0100_得意先別年間売上順位推移表_帳票設計書 | AK3: =変更履歴!AK3 -> 得意先別年間売上順位推移表 | AX3: =変更履歴!AX3 -> 45581 | BB3: =変更履歴!BB3 -> 大谷 | BF3: =変更履歴!BF3 -> 45581 | BJ3: =変更履歴!BJ3 -> 大谷
B7: 1.タイトルを記載 | H7: select | J7: 項目名 | R7: 格納テーブル
J8: 仕入先CD | R8: VM支払予定情報.仕入先CD
J9: 仕入先名1 | R9: VM支払予定情報.仕入先名1
H10: from | J10: 使用するテーブル名を記載
J11: TD売上請求H
J12: TD見積
J13: TM納入先
H14: join | J14: 結合方式
K15: 結合テーブル名
M16: 結合条件
L17: and | M17: 結合条件
L18: or | M18: 結合条件
J19: INNER JOIN
K20: TM納入先
M21: [TD見積.納入得意先CD] = [TM納入先.得意先CD]
L22: and | M22: [TD見積.納入先CD] = [TM納入先.納入先CD]
H23: where | K23: 取得条件 | AK23: パラメータの意味が分かる場合は記載する
J24: and | K24: 取得条件
J25: or | K25: 取得条件
J26: ※可能な限り日本語化する
K27: [TD見積.得意先CD] = '8001' | AK27: 8001'はヤオコーの得意先CD
J28: and | K28: [TD売上請求H.請求日付]が[画面.請求期間From]以降
H32: order by | J32: ソート条件を記載
J33: [画面.iYK物件区分]が1の場合は[TD見積.納入得意先CD],[TD見積.納入先CD],[TD売上請求H.見積番号]を昇順でソート
H36: group byなどほかの条件がある場合は行を追加して記載

Sheet 確認事項
B2: 確認事項
B3: No. | C3: シート名 | D3: タイトル | E3: 概要 | F3: 確認済
B4: 1
B5: 2
B6: 3
B7: 4
B8: 5
B9: 6
B10: 7
B11: 8
B12: 9
B13: 10
B14: 11
B15: 12
... B54: 51

Sheet 別紙_テンプレート
C1: 2012年～2012年
A2: 得意先別年間売上順位推移表
D4: 計 | F4: =SUM(F6:F7) -> 0 | G4: =IF(ISERROR(F4*100/H4),0,F4*100/H4) -> 0 | H4: =SUM(H6:H7) -> 0 | J4: 計 | L4: =SUM(L6:L7) -> 0 | M4: =IF(ISERROR(L4*100/N4),0,L4*100/N4) -> 0 | N4: =SUM(N6:N7) -> 0
A5: 得意先CD | B5: 得意先名1 | C5: 得意先名2 | D5: 順位 | E5: 前対比 | F5: 原価金額 | G5: 原価率 | H5: 純売上金額 | I5: ﾊﾟｰｾﾝﾄ | J5: 順位 | K5: 前対比 | M5: 原価率 | N5: 純売上金額 | O5: ﾊﾟｰｾﾝﾄ
E6: =IF(ISERROR(H6*100/OFFSET(H6,0,-6)),0,IF(OFFSET(H6,0,-6)=0,0,H6*100/OFFSET(H6,0,-6))) -> 0 | I6: =IF(H6=0,0,H6*100/H$4) -> 0 | K6: =IF(ISERROR(N6*100/OFFSET(N6,0,-6)),0,IF(OFFSET(N6,0,-6)=0,0,N6*100/OFFSET(N6,0,-6))) -> 0 | O6: =IF(N6=0,0,N6*100/N$4) -> 0
E7: =IF(ISERROR(H7*100/OFFSET(H7,0,-6)),0,IF(OFFSET(H7,0,-6)=0,0,H7*100/OFFSET(H7,0,-6))) -> 0 | I7: =IF(H7=0,0,H7*100/H$4) -> 0 | K7: =IF(ISERROR(N7*100/OFFSET(N7,0,-6)),0,IF(OFFSET(N7,0,-6)=0,0,N7*100/OFFSET(N7,0,-6))) -> 0 | O7: =IF(N7=0,0,N7*100/N$4) -> 0

Sheet 別紙_印刷レイアウト

Sheet 参照
A1: 数値
A2: ブール値
A3: 文字列
A4: 日付
A5: リスト
A6: 辞書配列
