Workbook
Name TukiNamePos: #REF!
Name TukiNamePos_SS: #REF!
Name TukiRetu_SS: #REF!
Name TukiRetu_zen: #REF!
Name TukiRetu_顧客: #REF!
Name TukiRetu_工事: #REF!
Name サービス_営業外費_貨物: 別紙_テンプレート_DB!$DA$3:$DA$65423
Name サービス_営業外費_物流: 別紙_テンプレート_DB!$DC$3:$DC$65423
Name サービス_原額_貨物自_サンプラ: 別紙_テンプレート_DB!$BU$3:$BU$65423
Name サービス_原額_貨物自_その他: 別紙_テンプレート_DB!$CA$3:$CA$65423
Name サービス_原額_貨物自_トラン: 別紙_テンプレート_DB!$BY$3:$BY$65423
Name サービス_原額_貨物自_三シャ: 別紙_テンプレート_DB!$BW$3:$BW$65423
Name サービス_原額_貨物自_三商: 別紙_テンプレート_DB!$BQ$3:$BQ$65423
Name サービス_原額_貨物自_事故: 別紙_テンプレート_DB!$CC$3:$CC$65423
Name サービス_原額_貨物自_店装: 別紙_テンプレート_DB!$BS$3:$BS$65423
Name サービス_原額_貨物庸_サンプラ: 別紙_テンプレート_DB!$CI$3:$CI$65423
Name サービス_原額_貨物庸_その他: 別紙_テンプレート_DB!$CO$3:$CO$65423
Name サービス_原額_貨物庸_トラン: 別紙_テンプレート_DB!$CM$3:$CM$65423
Name サービス_原額_貨物庸_三シャ: 別紙_テンプレート_DB!$CK$3:$CK$65423
Name サービス_原額_貨物庸_三商: 別紙_テンプレート_DB!$CE$3:$CE$65423
Name サービス_原額_貨物庸_事故: 別紙_テンプレート_DB!$CQ$3:$CQ$65423
Name サービス_原額_貨物庸_店装: 別紙_テンプレート_DB!$CG$3:$CG$65423
Name サービス_原額_物流_その他: 別紙_テンプレート_DB!$CW$3:$CW$65423
Name サービス_原額_物流_ルート: 別紙_テンプレート_DB!$CS$3:$CS$65423
Name サービス_原額_物流_丸和: 別紙_テンプレート_DB!$CU$3:$CU$65423
Name サービス_原額_物流_事故: 別紙_テンプレート_DB!$CY$3:$CY$65423
Name サービス_人件一般費_貨物: 別紙_テンプレート_DB!$CZ$3:$CZ$65423
Name サービス_人件一般費_物流: 別紙_テンプレート_DB!$DB$3:$DB$65423
Name サービス_年月: 別紙_テンプレート_DB!$BO$3:$BO$65423
Name サービス_売額_貨物自_サンプラ: 別紙_テンプレート_DB!$BT$3:$BT$65423
Name サービス_売額_貨物自_その他: 別紙_テンプレート_DB!$BZ$3:$BZ$65423
Name サービス_売額_貨物自_トラン: 別紙_テンプレート_DB!$BX$3:$BX$65423
Name サービス_売額_貨物自_三シャ: 別紙_テンプレート_DB!$BV$3:$BV$65423
Name サービス_売額_貨物自_三商: 別紙_テンプレート_DB!$BP$3:$BP$65423
Name サービス_売額_貨物自_事故: 別紙_テンプレート_DB!$CB$3:$CB$65423
Name サービス_売額_貨物自_店装: 別紙_テンプレート_DB!$BR$3:$BR$65423
Name サービス_売額_貨物庸_サンプラ: 別紙_テンプレート_DB!$CH$3:$CH$65423
Name サービス_売額_貨物庸_その他: 別紙_テンプレート_DB!$CN$3:$CN$65423
Name サービス_売額_貨物庸_トラン: 別紙_テンプレート_DB!$CL$3:$CL$65423
Name サービス_売額_貨物庸_三シャ: 別紙_テンプレート_DB!$CJ$3:$CJ$65423
Name サービス_売額_貨物庸_三商: 別紙_テンプレート_DB!$CD$3:$CD$65423
Name サービス_売額_貨物庸_事故: 別紙_テンプレート_DB!$CP$3:$CP$65423
Name サービス_売額_貨物庸_店装: 別紙_テンプレート_DB!$CF$3:$CF$65423
Name サービス_売額_物流_その他: 別紙_テンプレート_DB!$CV$3:$CV$65423
Name サービス_売額_物流_ルート: 別紙_テンプレート_DB!$CR$3:$CR$65423
Name サービス_売額_物流_丸和: 別紙_テンプレート_DB!$CT$3:$CT$65423
Name サービス_売額_物流_事故: 別紙_テンプレート_DB!$CX$3:$CX$65423
Name サービス予測_年月: 別紙_テンプレート_DB!$BA$3:$BA$65423
Name サービス予測_予測原価金額_貨物: 別紙_テンプレート_DB!$BC$3:$BC$65423
Name サービス予測_予測原価金額_物流: 別紙_テンプレート_DB!$BE$3:$BE$65423
Name サービス予測_予測売上金額_貨物: 別紙_テンプレート_DB!$BB$3:$BB$65423
Name サービス予測_予測売上金額_物流: 別紙_テンプレート_DB!$BD$3:$BD$65423
Name フロント_営業外費: 別紙_テンプレート_DB!$BL$3:$BL$65423
Name フロント_原価税抜金額: 別紙_テンプレート_DB!$BJ$3:$BJ$65423
Name フロント_人件一般費: 別紙_テンプレート_DB!$BK$3:$BK$65423
Name フロント_年月: 別紙_テンプレート_DB!$BH$3:$BH$65423
Name フロント_売上税抜金額: 別紙_テンプレート_DB!$BI$3:$BI$65423
Name フロント予測_年月: 別紙_テンプレート_DB!$AV$3:$AV$65423
Name フロント予測_予測原価金額: 別紙_テンプレート_DB!$AX$3:$AX$65423
Name フロント予測_予測売上金額: 別紙_テンプレート_DB!$AW$3:$AW$65423

Sheet 変更履歴
B2: システム名 | H2: 画面ID | L2: システム分類 | R2: ドキュメント種別 | X2: ドキュメント名 | AK2: 帳票名 | AX2: 作成日 | BB2: 作成者 | BF2: 更新日 | BJ2: 更新者
B3: 受発注システム | H3: =LEFT($X$3,FIND("_",$X$3)-1) -> TK0300 | L3: 受発注 | R3: =MID($X$3,FIND("_",$X$3,FIND("_",$X$3)+1)+1,LEN($X$3)-FIND("_",$X$3,FIND("_",$X$3)+1)) -> 帳票設計書 | X3: =REPLACE(LEFT(CELL("filename",$B$2),FIND(".x",CELL("filename",$B$2))-1),1,FIND("[",CELL("filename",$B$2)),) -> TK0300_統計推移表(日単位)_帳票設計書 | AK3: =MID($X$3,FIND("_",$X$3)+1,FIND("_",$X$3,FIND("_",$X$3)+1)-FIND("_",$X$3)-1) -> 統計推移表(日単位) | AX3: 45581 | BB3: 大谷 | BF3: 45581 | BJ3: 大谷
C7: 変更履歴
C8: 日付 | G8: 版数 | K8: 担当 | O8: 変更箇所 | Y8: 内容
C9: 45581 | G9: 1.0.0 | K9: 大谷 | O9: - | Y9: 新規作成

Sheet 概要
B2: システム名 | H2: 画面ID | L2: システム分類 | R2: ドキュメント種別 | X2: ドキュメント名 | AK2: 帳票名 | AX2: 作成日 | BB2: 作成者 | BF2: 更新日 | BJ2: 更新者
B3: =変更履歴!B3 -> 受発注システム | H3: =変更履歴!H3 -> TK0300 | L3: =変更履歴!L3 -> 受発注 | R3: =変更履歴!R3 -> 帳票設計書 | X3: =変更履歴!X3 -> TK0300_統計推移表(日単位)_帳票設計書 | AK3: =変更履歴!AK3 -> 統計推移表(日単位) | AX3: =変更履歴!AX3 -> 45581 | BB3: =変更履歴!BB3 -> 大谷 | BF3: =変更履歴!BF3 -> 45581 | BJ3: =変更履歴!BJ3 -> 大谷
D7: 帳票の名称 | H7: =AK3 -> 統計推移表(日単位)
D8: 帳票テンプレート名 | H8: Temp統計推移表v13
D9: ファイル種類 | H9: Excel
D10: ファイル拡張子 | H10: xlsx
D11: 文字コード | H11: -
D12: コーテーション | H12: -
D13: 固定長/可変長 | H13: -
D14: 区切り文字 | H14: -
D15: 用紙サイズ | H15: A4横
D16: 概要

Sheet 帳票レイアウト(グループ)
B2: システム名 | H2: 画面ID | L2: 業務分類 | R2: ドキュメント種別 | X2: ドキュメント名 | AK2: 帳票名 | AX2: 作成日 | BB2: 作成者 | BF2: 更新日 | BJ2: 更新者
B3: =変更履歴!B3 -> 受発注システム | H3: =変更履歴!H3 -> TK0300 | L3: =変更履歴!L3 -> 受発注 | R3: =変更履歴!R3 -> 帳票設計書 | X3: =変更履歴!X3 -> TK0300_統計推移表(日単位)_帳票設計書 | AK3: =変更履歴!AK3 -> 統計推移表(日単位) | AX3: =変更履歴!AX3 -> 45581 | BB3: =変更履歴!BB3 -> 大谷 | BF3: =変更履歴!BF3 -> 45581 | BJ3: =変更履歴!BJ3 -> 大谷
B6: ページ１

Sheet 帳票レイアウト(商研)
B2: システム名 | H2: 画面ID | L2: システム分類 | R2: ドキュメント種別 | X2: ドキュメント名 | AK2: 帳票名 | AX2: 作成日 | BB2: 作成者 | BF2: 更新日 | BJ2: 更新者
B3: =変更履歴!B3 -> 受発注システム | H3: =変更履歴!H3 -> TK0300 | L3: =変更履歴!L3 -> 受発注 | R3: =変更履歴!R3 -> 帳票設計書 | X3: =変更履歴!X3 -> TK0300_統計推移表(日単位)_帳票設計書 | AK3: =変更履歴!AK3 -> 統計推移表(日単位) | AX3: =変更履歴!AX3 -> 45581 | BB3: =変更履歴!BB3 -> 大谷 | BF3: =変更履歴!BF3 -> 45581 | BJ3: =変更履歴!BJ3 -> 大谷
B6: ページ１
B49: ページ２
B92: ページ３

Sheet 帳票レイアウト(工事)
B2: システム名 | H2: 画面ID | L2: 業務分類 | R2: ドキュメント種別 | X2: ドキュメント名 | AK2: 帳票名 | AX2: 作成日 | BB2: 作成者 | BF2: 更新日 | BJ2: 更新者
B3: =変更履歴!B3 -> 受発注システム | H3: =変更履歴!H3 -> TK0300 | L3: =変更履歴!L3 -> 受発注 | R3: =変更履歴!R3 -> 帳票設計書 | X3: =変更履歴!X3 -> TK0300_統計推移表(日単位)_帳票設計書 | AK3: =変更履歴!AK3 -> 統計推移表(日単位) | AX3: =変更履歴!AX3 -> 45581 | BB3: =変更履歴!BB3 -> 大谷 | BF3: =変更履歴!BF3 -> 45581 | BJ3: =変更履歴!BJ3 -> 大谷
B6: ページ１

Sheet 帳票レイアウト(三和サービス)
B2: システム名 | H2: 画面ID | L2: 業務分類 | R2: ドキュメント種別 | X2: ドキュメント名 | AK2: 帳票名 | AX2: 作成日 | BB2: 作成者 | BF2: 更新日 | BJ2: 更新者
B3: =変更履歴!B3 -> 受発注システム | H3: =変更履歴!H3 -> TK0300 | L3: =変更履歴!L3 -> 受発注 | R3: =変更履歴!R3 -> 帳票設計書 | X3: =変更履歴!X3 -> TK0300_統計推移表(日単位)_帳票設計書 | AK3: =変更履歴!AK3 -> 統計推移表(日単位) | AX3: =変更履歴!AX3 -> 45581 | BB3: =変更履歴!BB3 -> 大谷 | BF3: =変更履歴!BF3 -> 45581 | BJ3: =変更履歴!BJ3 -> 大谷
B6: ページ１

Sheet 項目一覧
B2: システム名 | H2: 画面ID | L2: システム分類 | R2: ドキュメント種別 | X2: ドキュメント名 | AK2: 帳票名 | AX2: 作成日 | BB2: 作成者 | BF2: 更新日 | BJ2: 更新者
B3: =変更履歴!B3 -> 受発注システム | H3: =変更履歴!H3 -> TK0300 | L3: =変更履歴!L3 -> 受発注 | R3: =変更履歴!R3 -> 帳票設計書 | X3: =変更履歴!X3 -> TK0300_統計推移表(日単位)_帳票設計書 | AK3: =変更履歴!AK3 -> 統計推移表(日単位) | AX3: =変更履歴!AX3 -> 45581 | BB3: =変更履歴!BB3 -> 大谷 | BF3: =変更履歴!BF3 -> 45581 | BJ3: =変更履歴!BJ3 -> 大谷
B7: 項目一覧
C9: 項目 | F9: フォントや文字サイズ、セル条件などは「別紙_テンプレート」準拠
D10: No. | E10: 項目名 | M10: データ型 | P10: 全角/半角 | S10: 文字数/桁数 | V10: データ取得元 | AB10: データ整形方法 | AR10: 整形後フォーマット | AX10: 備考
D11: 1 | E11: 売上・原価_営業担当CD | M11: 数値 | P11: 半角 | S11: 7 | V11: - | AX11: 固定値で0
D12: 2 | E12: 売上・原価_番号 | M12: 数値 | P12: 半角 | S12: 4 | V12: - | AX12: 固定値で0
D13: 3 | E13: 売上・原価_集計CD | M13: 文字列 | P13: 半角 | S13: 8 | V13: TD見積.集計CD
D14: 4 | E14: 売上・原価_年月日 | M14: 日付 | P14: 半角 | S14: 10 | V14: TD売上v2.売上日付 | AB14: [TD売上v2.売上日付]の月初（例：2024/12/31 → 2024/12/1） | AR14: yyyy/m/d
D15: 5 | E15: 売上・原価_作業区分CD | M15: 数値 | P15: 半角 | S15: 7 | V15: TD見積.物件種別,TD見積.業種区分,TD見積シートM.作業区分CD | AB15: [TD見積.物件種別]が6の場合は106, 106以外かつ[TD見積.業種区分]が1の場合は3, 106以外かつ[TD見積.業種区分]が1以外の場合は[TD見積.業種区分]の値（Nullは0に置換）
D16: 6 | E16: 売上・原価_売上税抜金額 | M16: 数値 | P16: 半角 | S16: 9 | V16: TD売上明細V2.売上税区分,TD売上明細V2.売上金額,TD売上明細V2.消費税額 | AB16: [TD売上明細V2.売上税区分]が1の場合は[TD売上明細V2.売上金額]から[TD売上明細V2.消費税額]を引いた値、 それ以外の場合は[TD売上明細V2.売上金額] | AR16: 999999
D17: 7 | E17: 売上・原価_原価税抜金額 | M17: 数値 | P17: 半角 | S17: 9 | V17: TD仕入明細内訳.仕入税区分,TD仕入明細内訳.仕入金額,TD仕入明細内訳.消費税額 | AB17: [TD仕入明細内訳.売上税区分]が1の場合は[TD仕入明細内訳.仕入金額]から[TD仕入明細内訳.消費税額]を引いた値、 それ以外の場合は[TD仕入明細内訳.売上金額][TD仕入明細内訳.売上税区分]が1の場合は[TD仕入明細内訳.売上金額]から[TD仕入明細内訳.消費税額]を引いた値、 それ以外の場合は[TD仕入明細内訳.売上金額] | AR17: 999999
D18: 8 | E18: 工事・売上・原価_工事担当CD | M18: 数値 | P18: 半角 | S18: 8 | V18: TD見積.工事担当CD
D19: 9 | E19: 工事・売上・原価_番号 | M19: 数値 | P19: 半角 | S19: 4 | V19: - | AX19: 固定値で0
D20: 10 | E20: 工事・売上・原価_集計CD（未使用） | M20: 数値 | P20: 半角 | S20: 6 | V20: - | AX20: 固定値で0
D21: 11 | E21: 工事・売上・原価_年月日 | M21: 日付 | P21: 半角 | S21: 10 | V21: TD売上v2.売上日付 | AB21: [TD売上v2.売上日付]の月初（例：2024/12/31 → 2024/12/1） | AR21: yyyy/m/d
D22: 12 | E22: 工事・売上・原価_作業区分CD | M22: 数値 | P22: 半角 | S22: 9 | V22: TD見積.物件種別,TD見積もり.業種区分,TD見積シートM.作業区分CD | AB22: [TD見積.物件種別]が6の場合は106, 106以外かつ[TD見積.業種区分]が1の場合は3, 106以外かつ[TD見積.業種区分]が1以外の場合は[TD見積.業種区分]の値（Nullは0に置換）
D23: 13 | E23: 工事・売上・原価_売上税抜金額 | M23: 数値 | P23: 半角 | S23: 10 | V23: TD売上明細V2.売上税区分,TD売上明細V2.売上金額,TD売上明細V2.消費税額 | AB23: [TD売上明細V2.売上税区分]が1の場合は[TD売上明細V2.売上金額]から[TD売上明細V2.消費税額]を引いた値、 それ以外の場合は[TD売上明細V2.売上金額] | AR23: 999999
D24: 14 | E24: 工事・売上・原価_原価税抜金額 | M24: 数値 | P24: 半角 | S24: 10 | V24: TD仕入明細内訳.仕入税区分,TD仕入明細内訳.仕入金額,TD仕入明細内訳.消費税額 | AB24: [TD仕入明細内訳.売上税区分]が1の場合は[TD仕入明細内訳.仕入金額]から[TD仕入明細内訳.消費税額]を引いた値、 それ以外の場合は[TD仕入明細内訳.売上金額][TD仕入明細内訳.売上税区分]が1の場合は[TD仕入明細内訳.売上金額]から[TD仕入明細内訳.消費税額]を引いた値、 それ以外の場合は[TD仕入明細内訳.売上金額] | AR24: 999999
D25: 15 | E25: 入出庫_集計CD | M25: 文字列 | P25: 半角 | S25: 7 | V25: TD見積.集計CD
D26: 16 | E26: 入出庫_年月日 | M26: 日付 | P26: 半角 | S26: 10 | V26: TD仕入明細.仕入日付 | AB26: [TD仕入明細.仕入日付]の月初（例：2024/12/31 → 2024/12/1） | AR26: yyyy/m/d
D27: 17 | E27: 入出庫_出庫金額 | M27: 数値 | P27: 半角 | S27: 7 | V27: TD仕入明細内訳.仕入税区分,TD仕入明細内訳.消費税額,TD在庫調整明細.仕入税区分,TD在庫調整明細.調整金額,TD在庫調整明細.消費税額 | AB27: 出庫合計金額 = [TD仕入明細内訳.仕入税区分]が1の場合は[TD仕入明細内訳.仕入金額] - [TD仕入明細内訳.消費税額]、1以外の場合は[TD仕入明細内訳.仕入金額]の合計 調整出庫合計金額 = [TD在庫調整明細.仕入税区分]が1の場合は[TD在庫調整明細.調整金額]-[TD在庫調整明細.消費税額]、1以外の場合は[TD在庫調整明細.調整金額]の合計 出庫合計金額 + 調整出庫合計金額の合計 | AR27: 999999
D28: 18 | E28: 入出庫_入庫金額 | M28: 数値 | P28: 半角 | S28: 7 | V28: TD仕入明細内訳.仕入税区分,TD仕入明細内訳.消費税額,TD在庫調整明細.仕入税区分,TD在庫調整明細.調整金額,TD在庫調整明細.消費税額 | AB28: 入庫合計金額 = [TD仕入明細内訳.仕入税区分]が1の場合は[TD仕入明細内訳.仕入金額] - [TD仕入明細内訳.消費税額]、1以外の場合は[TD仕入明細内訳.仕入金額]の合計 調整入庫合計金額 = [TD在庫調整明細.仕入税区分]が1の場合は[TD在庫調整明細.調整金額]-[TD在庫調整明細.消費税額]、1以外の場合は[TD在庫調整明細.調整金額]の合計 入庫合計金額 + 調整入庫合計金額の合計 | AR28: 999999
D29: 19 | E29: 三研 売上（円）_年月日 | M29: 日付 | P29: 半角 | S29: 10 | V29: TM三研情報.年月 | AR29: yyyy/m/d
D30: 20 | E30: 三研 売上（円）_売上税抜金額 | M30: 数値 | P30: 半角 | S30: 7 | V30: TM三研情報.売上税抜金額_円
D31: 21 | E31: 三研 売上（円）_原価税抜金額 | M31: 数値 | P31: 半角 | S31: 7 | V31: TM三研情報.原価税抜金額_円
D32: 22 | E32: 三研 売上（円）_人件一般費 | M32: 数値 | P32: 半角 | S32: 7 | V32: TM三研情報.人件一般費_円
D33: 23 | E33: 三研 売上（円）_営業外費 | M33: 数値 | P33: 半角 | S33: 7 | V33: TM三研情報.営業外費_円
D34: 24 | E34: サービス 売上（円）_年月日 | M34: 日付 | P34: 半角 | S34: 10 | V34: TMサービス実績情報.年月 | AR34: yyyy/m/d
D35: 25 | E35: サービス 売上（円）_売額_貨物自_三商 | M35: 数値 | P35: 半角 | S35: 15 | V35: TMサービス実績情報.売額_貨物自_三商
D36: 26 | E36: サービス 売上（円）_原額_貨物自_三商 | M36: 数値 | P36: 半角 | S36: 15 | V36: TMサービス実績情報.原額_貨物自_三商
D37: 27 | E37: サービス 売上（円）_売額_貨物自_店装 | M37: 数値 | P37: 半角 | S37: 15 | V37: TMサービス実績情報.売額_貨物自_店装
D38: 28 | E38: サービス 売上（円）_原額_貨物自_店装 | M38: 数値 | P38: 半角 | S38: 15 | V38: TMサービス実績情報.原額_貨物自_店装
D39: 29 | E39: サービス 売上（円）_売額_貨物自_サンプラ | M39: 数値 | P39: 半角 | S39: 15 | V39: TMサービス実績情報.売額_貨物自_サンプラ
D40: 30 | E40: サービス 売上（円）_原額_貨物自_サンプラ | M40: 数値 | P40: 半角 | S40: 15 | V40: TMサービス実績情報.原額_貨物自_サンプラ
D41: 31 | E41: サービス 売上（円）_売額_貨物自_三シャ | M41: 数値 | P41: 半角 | S41: 15 | V41: TMサービス実績情報.売額_貨物自_三シャ
D42: 32 | E42: サービス 売上（円）_原額_貨物自_三シャ | M42: 数値 | P42: 半角 | S42: 15 | V42: TMサービス実績情報.原額_貨物自_三シャ
D43: 33 | E43: サービス 売上（円）_売額_貨物自_トラン | M43: 数値 | P43: 半角 | S43: 15 | V43: TMサービス実績情報.売額_貨物自_トラン
D44: 34 | E44: サービス 売上（円）_原額_貨物自_トラン | M44: 数値 | P44: 半角 | S44: 15 | V44: TMサービス実績情報.原額_貨物自_トラン
D45: 35 | E45: サービス 売上（円）_売額_貨物自_その他 | M45: 数値 | P45: 半角 | S45: 15 | V45: TMサービス実績情報.売額_貨物自_その他
...

Sheet 処理詳細_書き方
B2: システム名 | H2: 画面ID | L2: 業務分類 | R2: ドキュメント種別 | X2: ドキュメント名 | AK2: 帳票名 | AX2: 作成日 | BB2: 作成者 | BF2: 更新日 | BJ2: 更新者
B3: =変更履歴!B3 -> 受発注システム | H3: =変更履歴!H3 -> TK0300 | L3: =変更履歴!L3 -> 受発注 | R3: =変更履歴!R3 -> 帳票設計書 | X3: =変更履歴!X3 -> TK0300_統計推移表(日単位)_帳票設計書 | AK3: =変更履歴!AK3 -> 統計推移表(日単位) | AX3: =変更履歴!AX3 -> 45581 | BB3: =変更履歴!BB3 -> 大谷 | BF3: =変更履歴!BF3 -> 45581 | BJ3: =変更履歴!BJ3 -> 大谷
B7: 1.タイトルを記載 | H7: select | J7: 項目名 | R7: 格納テーブル
J8: 仕入先CD | R8: VM支払予定情報.仕入先CD
J9: 仕入先名1 | R9: VM支払予定情報.仕入先名1
H10: from | J10: 使用するテーブル名を記載
J11: TD売上請求H
J12: TD見積
J13: TM納入先
H14: join | J14: 結合方式
K15: 結合テーブル名
M16: 結合条件
L17: and | M17: 結合条件
L18: or | M18: 結合条件
J19: INNER JOIN
K20: TM納入先
M21: [TD見積.納入得意先CD] = [TM納入先.得意先CD]
L22: and | M22: [TD見積.納入先CD] = [TM納入先.納入先CD]
H23: where | K23: 取得条件 | AK23: パラメータの意味が分かる場合は記載する
J24: and | K24: 取得条件
J25: or | K25: 取得条件
J26: ※可能な限り日本語化する
K27: [TD見積.得意先CD] = '8001' | AK27: 8001'はヤオコーの得意先CD
J28: and | K28: [TD売上請求H.請求日付]が[画面.請求期間From]以降
H32: order by | J32: ソート条件を記載
J33: [画面.iYK物件区分]が1の場合は[TD見積.納入得意先CD],[TD見積.納入先CD],[TD売上請求H.見積番号]を昇順でソート
H36: group byなどほかの条件がある場合は行を追加して記載

Sheet 処理詳細
B2: システム名 | H2: 画面ID | L2: システム分類 | R2: ドキュメント種別 | X2: ドキュメント名 | AK2: 帳票名 | AX2: 作成日 | BB2: 作成者 | BF2: 更新日 | BJ2: 更新者
B3: =[1]変更履歴!B3 -> XXXXXXXX | H3: =[1]変更履歴!H3 -> TK0300 | L3: =[1]変更履歴!L3 -> 運用自動化 | R3: =[1]変更履歴!R3 -> 帳票設計書 | X3: =[1]変更履歴!X3 -> TK0300_統計推移表_帳票設計書 | AK3: =[1]変更履歴!AK3 -> 統計推移表 | AX3: =[1]変更履歴!AX3 -> 45474 | BB3: =[1]変更履歴!BB3 -> 丹羽 | BF3: =[1]変更履歴!BF3 -> 0 | BJ3: =[1]変更履歴!BJ3 -> 0
B6: SQL1 MERGE INTO | H6: merge into | J6: #TMP_TOTAL AS A
H7: using | J7: SQL2 AS B
H8: on | K8: A.部署CD = B.部署CD
J9: AND | K9: A.工事担当CD = B.工事担当CD
J10: AND | K10: A.番号 = B.番号
J11: AND | K11: A.集計CD = B.集計CD
J12: AND | K12: A.年月日 = B.年月日
J13: AND | K13: A.作業区分CD = B.作業区分CD
H14: matched | J14: WHEN MATCHED THEN
K15: UPDATE
L16: SET A.売上税抜金額 = A.売上税抜金額 + B.税抜金額
J17: WHEN NOT MATCHED THEN
K18: INSERT
J19: 部署CD | R19: B.部署CD
J20: 工事担当CD | R20: B.工事担当CD
J21: 番号 | R21: B.番号
J22: 集計CD | R22: B.集計CD
J23: 年月日 | R23: B.年月日
J24: 作業区分CD | R24: B.作業区分CD
J25: 売上税抜金額 | R25: B.税抜金額
B26: SQL2 | H26: select | J26: 部署CD | R26: MH.部署CD
J27: 工事担当CD | R27: MH.工事担当CD
J28: 番号 | R28: 0
J29: 集計CD | R29: MH.集計CD
J30: 年月日 | R30: CONVERT(DATETIME, CONVERT(CHAR (7), UH.売上日付, 111) + '/1')
J31: 作業区分CD | R31: CASE WHEN MH.物件種別 = 6 THEN 106 ELSE CASE WHEN (MH.業種区分 = 1) THEN 3 ELSE ISNULL(MSM.作業区分CD, 0) END END
J32: 税抜金額 | R32: SUM(CASE WHEN UM.売上税区分 = 1 THEN (UM.売上金額 - UM.消費税額) ELSE UM.売上金額 END)
H33: from | J33: TD売上v2 AS UH
J34: TD見積 AS MH
J35: TD売上明細V2 AS UM
J36: TD見積シートM AS MSM
J37: TM得意先 AS TM
J38: TD物件情報 AS BK
J39: TM製品 AS SE
H40: join | J40: INNER JOIN
K41: TD見積
M42: UH.見積番号 = MH.見積番号
J43: INNER JOIN
...

Sheet 確認事項
B2: 確認事項
B3: No. | C3: シート名 | D3: タイトル | E3: 概要 | F3: 確認済
B4: 1
B5: 2
B6: 3
B7: 4
B8: 5
B9: 6
B10: 7
B11: 8
B12: 9
B13: 10
B14: 11
B15: 12
... B54: 51

Sheet 別紙_テンプレート_DB
A1: 顧客別 売上・原価 | J1: 工事 売上・原価 | Y1: 入出庫 | AE1: 三研 売上（円） | AL1: 2016年 担当別原価埋込 | AQ1: 三研予測(円) | AV1: フロント予測(円) | BA1: サービス予測(円) | BH1: フロント 売上（円） | BO1: サービス 売上（円） | DF1: 営業担当別経費 | DM1: 部署別 売上・原価
A2: 営業担当CD | B2: 番号 | C2: 集計CD | D2: 年月日 | E2: 作業区分CD | F2: 売上税抜金額 | G2: 原価税抜金額 | J2: 工事担当CD | K2: 番号 | L2: 集計CD（未使用） | M2: 年月日 | N2: 作業区分CD | O2: 売上税抜金額 | P2: 原価税抜金額 | Y2: 集計CD | Z2: 年月日 | AA2: 出庫金額 | AB2: 入庫金額 | AE2: 年月日 | AF2: 売上税抜金額 | AG2: 原価税抜金額 | AH2: 人件一般費 | AI2: 営業外費 | AL2: チームCD | AM2: 年月 | AN2: 原価金額 | AQ2: 年月 | AR2: 予測売上金額 | AS2: 予測原価金額 | AV2: 年月 | AW2: 予測売上金額 | AX2: 予測原価金額 | BA2: 年月 | BB2: 予測売上額_貨物 | BC2: 予測原価額_貨物 | BD2: 予測売上額_物流 | BE2: 予測原価額_物流 | BH2: 年月 | BI2: 売上税抜金額 | BJ2: 原価税抜金額 | BK2: 人件一般費 | BL2: 営業外費 | BO2: 年月日 | BP2: 売額_貨物自_三商 | BQ2: 原額_貨物自_三商 | BR2: 売額_貨物自_店装 | BS2: 原額_貨物自_店装 | BT2: 売額_貨物自_サンプラ | BU2: 原額_貨物自_サンプラ | BV2: 売額_貨物自_三シャ | BW2: 原額_貨物自_三シャ | BX2: 売額_貨物自_トラン | BY2: 原額_貨物自_トラン | BZ2: 売額_貨物自_その他 | CA2: 原額_貨物自_その他 | CB2: 売額_貨物自_事故 | CC2: 原額_貨物自_事故 | CD2: 売額_貨物庸_三商 | CE2: 原額_貨物庸_三商 | CF2: 売額_貨物庸_店装 | CG2: 原額_貨物庸_店装 | CH2: 売額_貨物庸_サンプラ | CI2: 原額_貨物庸_サンプラ | CJ2: 売額_貨物庸_三シャ | CK2: 原額_貨物庸_三シャ | CL2: 売額_貨物庸_トラン | CM2: 原額_貨物庸_トラン | CN2: 売額_貨物庸_その他 | CO2: 原額_貨物庸_その他 | CP2: 売額_貨物庸_事故 | CQ2: 原額_貨物庸_事故 | CR2: 売額_物流_ルート | CS2: 原額_物流_ルート | CT2: 売額_物流_丸和 | CU2: 原額_物流_丸和 | CV2: 売額_物流_その他 | CW2: 原額_物流_その他 | CX2: 売額_物流_事故 | CY2: 原額_物流_事故 | CZ2: 人件一般費_貨物 | DA2: 営業外費_貨物 | DB2: 人件一般費_物流 | DC2: 営業外費_物流 | DF2: 業種区分 | DG2: 部CD（未使用） | DH2: 年月日 | DI2: 人件費一般費 | DM2: 部署 | DN2: 年月日 | DO2: 作業区分CD | DP2: 売上税抜金額 | DQ2: 原価税抜金額

Sheet 別紙_テンプレート_グループ
B1: 三和グループ統計
B2: 項目 | F2: =IF(MONTH(I2)<4,YEAR(I2)-1&"年度",YEAR(I2)&"年度") -> 2020年度 | I2: 44227 | L2: 44226
F3: 原価 | H3: 売上 | I3: 原価 | K3: 売上 | L3: 原価 | N3: 売上
B4: 原価 | F4: =SUMIF(I$3:N$3,$F$3,I4:N4) -> 0 | G4: =IF(ISERROR(F4/H4),0,F4/H4) -> 0 | H4: =SUMIF(I$3:N$3,$H$3,I4:N4) -> 0 | I4: =SUM(I10,I16,I22) -> 0 | J4: =IF(ISERROR(I4/K4),0,I4/K4) -> 0 | K4: =SUM(K10,K16,K22) -> 0 | L4: =SUM(L10,L16,L22) -> 0 | M4: =IF(ISERROR(L4/N4),0,L4/N4) -> 0 | N4: =SUM(N10,N16,N22) -> 0
B5: 営利 | F5: =SUMIF(I$3:N$3,$F$3,I5:N5) -> #REF! | G5: =IF(ISERROR(F5/H4),0,F5/H4) -> 0 | I5: =SUM(I11,I17,I23) -> #REF! | J5: =IF(ISERROR(I5/K4),0,I5/K4) -> 0 | L5: =SUM(L11,L17,L23) -> #REF! | M5: =IF(ISERROR(L5/N4),0,L5/N4) -> 0
B6: 債務 差引 | F6: =OFFSET(F6,,3) -> 0 | G6: 借入 | H6: =OFFSET(H6,,5) -> 0 | I6: =SUM(I12,I18,I24,I30) -> 0 | K6: =SUM(K12,K18,K24,K30) -> 0 | L6: =SUM(L12,L18,L24,L30) -> 0 | N6: =SUM(N12,N18,N24,N30) -> 0
F7: =OFFSET(F7,,3) -> 0 | G7: 現預金 | H7: =OFFSET(H7,,5) -> 0 | I7: =SUM(I13,I19,I25,I35) -> 0 | K7: =SUM(K13,K19,K25,K35) -> 0 | L7: =SUM(L13,L19,L25,L35) -> 0 | N7: =SUM(N13,N19,N25,N35) -> 0
B8: 株式会社 三和商研
B9: 項目 | F9: =YEAR(I9)-1978+1&"期" -> 44期 | I9: =I2 -> 44227 | L9: =L2 -> 44226
B10: 原価 | F10: =SUMIF(I$3:N$3,$F$3,I10:N10) -> 0 | G10: =IF(ISERROR(F10/H10),0,F10/H10) -> 0 | H10: =SUMIF(I$3:N$3,$H$3,I10:N10) -> 0 | I10: =別紙_テンプレート_商研!K5 -> 0 | J10: =IF(ISERROR(I10/K10),0,I10/K10) -> 0 | K10: =別紙_テンプレート_商研!I4 -> 0 | L10: =別紙_テンプレート_商研!N5 -> 0 | M10: =IF(ISERROR(L10/N10),0,L10/N10) -> 0 | N10: =別紙_テンプレート_商研!L4 -> 0
B11: 営利 | F11: =SUMIF(I$3:N$3,$F$3,I11:N11) -> #REF! | G11: =IF(ISERROR(F11/H10),0,F11/H10) -> 0 | I11: =別紙_テンプレート_商研!#REF! -> #REF! | J11: =IF(ISERROR(I11/K10),0,I11/K10) -> 0 | L11: =別紙_テンプレート_商研!#REF! -> #REF! | M11: =IF(ISERROR(L11/N10),0,L11/N10) -> 0
B12: 債務 差引 | F12: =OFFSET(F12,,3) -> 0 | G12: 借入 | H12: =OFFSET(H12,,5) -> 0 | I12: =K13-K12 -> 0 | L12: =N13-N12 -> 0
F13: =OFFSET(F13,,3) -> 0 | G13: 現預金 | H13: =OFFSET(H13,,5) -> 0 | I13: =SUM(I12-OFFSET(I12,,3)) -> 0 | L13: =SUM(L12-OFFSET(L12,,3)) -> 0
B14: 三研(上海)商貿有限公司
B15: 項目 | F15: =YEAR(I15)-2014+1&"期" -> 8期 | I15: =I2 -> 44227 | L15: =L2 -> 44226
B16: 原価 | F16: =SUMIF(I$3:N$3,$F$3,I16:N16) -> 0 | G16: =IF(ISERROR(F16/H16),0,F16/H16) -> 0 | H16: =SUMIF(I$3:N$3,$H$3,I16:N16) -> 0 | I16: =IFERROR(INDEX(別紙_テンプレート_DB!三研_原価税抜金額,MATCH(I$2,INDEX(別紙_テンプレート_DB!三研_年月,),0)),0) -> 0 | J16: =IF(ISERROR(I16/K16),0,I16/K16) -> 0 | K16: =IFERROR(INDEX(別紙_テンプレート_DB!三研_売上税抜金額,MATCH(I$2,INDEX(別紙_テンプレート_DB!三研_年月,),0)),0) -> 0 | L16: =IFERROR(INDEX(別紙_テンプレート_DB!三研_原価税抜金額,MATCH(L$2,INDEX(別紙_テンプレート_DB!三研_年月,),0)),0) -> 0 | M16: =IF(ISERROR(L16/N16),0,L16/N16) -> 0 | N16: =IFERROR(INDEX(別紙_テンプレート_DB!三研_売上税抜金額,MATCH(L$2,INDEX(別紙_テンプレート_DB!三研_年月,),0)),0) -> 0
B17: 営利 | F17: =SUMIF(I$3:N$3,$F$3,I17:N17) -> 0 | G17: =IF(ISERROR(F17/H16),0,F17/H16) -> 0 | I17: =K16-I16-(IFERROR(INDEX(別紙_テンプレート_DB!三研_人件一般費,MATCH(I$2,INDEX(別紙_テンプレート_DB!三研_年月,),0)),0)) -> 0 | J17: =IF(ISERROR(I17/K16),0,I17/K16) -> 0 | L17: =N16-L16-(IFERROR(INDEX(別紙_テンプレート_DB!三研_人件一般費,MATCH(L$2,INDEX(別紙_テンプレート_DB!三研_年月,),0)),0)) -> 0 | M17: =IF(ISERROR(L17/N16),0,L17/N16) -> 0
B18: 債務 差引 | F18: =OFFSET(F18,,3) -> 0 | G18: 借入 | H18: =OFFSET(H18,,5) -> 0 | I18: =K19-K18 -> 0 | L18: =N19-N18 -> 0
F19: =OFFSET(F19,,3) -> 0 | G19: 現預金 | H19: =OFFSET(H19,,5) -> 0 | I19: =SUM(I18-OFFSET(I18,,3)) -> 0 | L19: =SUM(L18-OFFSET(L18,,3)) -> 0
B20: 株式会社 三和サービス
B21: 項目 | F21: =YEAR(I21)-1980+1&"期" -> 42期 | I21: =I2 -> 44227 | L21: =L2 -> 44226
B22: 原価 | F22: =SUMIF(I$3:N$3,$F$3,I22:N22) -> 0 | G22: =IF(ISERROR(F22/H22),0,F22/H22) -> 0 | H22: =SUMIF(I$3:N$3,$H$3,I22:N22) -> 0 | I22: =別紙_テンプレート_三和サービス!H4 -> 0 | J22: =IF(ISERROR(I22/K22),0,I22/K22) -> 0 | K22: =別紙_テンプレート_三和サービス!J4 -> 0 | L22: =別紙_テンプレート_三和サービス!K4 -> 0 | M22: =IF(ISERROR(L22/N22),0,L22/N22) -> 0 | N22: =別紙_テンプレート_三和サービス!M4 -> 0
B23: 営利 | F23: =SUMIF(I$3:N$3,$F$3,I23:N23) -> 0 | G23: =IF(ISERROR(F23/H22),0,F23/H22) -> 0 | I23: =別紙_テンプレート_三和サービス!H6 -> 0 | J23: =IF(ISERROR(I23/K22),0,I23/K22) -> 0 | L23: =別紙_テンプレート_三和サービス!K6 -> 0 | M23: =IF(ISERROR(L23/N22),0,L23/N22) -> 0
B24: 債務 差引 | F24: =OFFSET(F24,,3) -> 0 | G24: 借入 | H24: =OFFSET(H24,,5) -> 0 | I24: =K25-K24 -> 0 | L24: =N25-N24 -> 0
F25: =OFFSET(F25,,3) -> 0 | G25: 現預金 | H25: =OFFSET(H25,,5) -> 0 | I25: =SUM(I24-OFFSET(I24,,3)) -> 0 | L25: =SUM(L24-OFFSET(L24,,3)) -> 0
B26: 株式会社 三和
B27: 項目 | F27: =YEAR(I27)-1985+1&"期" -> 37期 | I27: =I2 -> 44227 | L27: =L2 -> 44226
B28: 原価 | F28: =SUMIF(I$3:N$3,$F$3,I28:N28) -> 0 | G28: =IF(ISERROR(F28/H28),0,F28/H28) -> 0 | H28: =SUMIF(I$3:N$3,$H$3,I28:N28) -> 0 | J28: =IF(ISERROR(I28/K28),0,I28/K28) -> 0 | M28: =IF(ISERROR(L28/N28),0,L28/N28) -> 0
B29: 営利 | F29: =SUMIF(I$3:N$3,$F$3,I29:N29) -> 0 | G29: =IF(ISERROR(F29/H28),0,F29/H28) -> 0 | J29: =IF(ISERROR(I29/K28),0,I29/K28) -> 0 | M29: =IF(ISERROR(L29/N28),0,L29/N28) -> 0
B30: 債務 差引 | F30: =H35-SUM(H30:H34) -> 0 | G30: 長期借入 | I30: =K35-SUM(K30:K34) -> 0 | L30: =N35-SUM(N30:N34) -> 0
G31: Ｇｒ借入
G32: 役員借入
G33: 長期未払
G34: リース債務 | H34: =OFFSET(H34,,5) -> 0
F35: =OFFSET(F35,,3) -> 0 | G35: 現預金 | H35: =OFFSET(H35,,3) -> 0 | I35: =SUM(I30-OFFSET(I30,,3)) -> 0 | L35: =SUM(L30-OFFSET(L30,,3)) -> 0

Sheet 別紙_テンプレート_商研
A1: 営業チーム統計
A2: 項目 | F2: =YEAR(I2)-1978+1&"期" -> 46期 | I2: 45199 | L2: 45198
F3: 原価 | H3: 売上 | I3: 原価 | K3: 売上 | L3: 原価 | N3: 売上
A4: 売上 | C4: 0 | F4: =SUM(I4:N4) -> 0 | I4: =SUMIF($C8:$C34,$C4,I8:I34) -> 0 | J4: =SUMIF($C7:$C33,$C4,J7:J33) -> 0 | K4: =SUMIF($C7:$C33,$C4,K7:K33) -> 0 | L4: =SUMIF($C8:$C34,$C4,L8:L34) -> 0 | M4: =SUMIF($C7:$C33,$C4,M7:M33) -> 0 | N4: =SUMIF($C7:$C33,$C4,N7:N33) -> 0
A5: 原価 | C5: 1 | H5: =SUM(I5:N5) -> 0 | K5: =SUMIF($C8:$C34,$C5,K8:K34) -> 0 | N5: =SUMIF($C8:$C34,$C5,N8:N34) -> 0
A6: 売上総利益 | F6: =SUMIF(I$3:N$3,$F$3,I6:N6) -> 0 | H6: =IF(ISERROR(F6/F4),0,F6/F4) -> 0 | I6: =I4-K5 -> 0 | K6: =IF(ISERROR(I6/I4),0,I6/I4) -> 0 | L6: =L4-N5 -> 0 | N6: =IF(ISERROR(L6/L4),0,L6/L4) -> 0
B7: 在庫 | E7: 20 | F7: =SUMIF(I$3:N$3,$F$3,I7:N7) -> 0 | G7: ⇔ | H7: =SUMIF(I$3:N$3,$H$3,I7:N7) -> 0 | I7: =SUMIF($B$35:$B$98,$B7,I$35:I$98) -> 0 | J7: ⇔ | K7: =SUMIF($B$35:$B$98,$B7,K$35:K$98) -> 0 | L7: =SUMIF($B$35:$B$98,$B7,L$35:L$98) -> 0 | M7: ⇔ | N7: =SUMIF($B$35:$B$98,$B7,N$35:N$98) -> 0
A8: 売上 | C8: 0 | F8: =SUM(H11:H16) -> 0 | I8: =SUM(K11:K16) -> 0 | L8: =SUM(N11:N16) -> 0
A9: 原価 | C9: 1 | H9: =SUM(I9:N9) -> 0 | K9: =SUM(I11:I16) -> 0 | N9: =SUM(L11:L16) -> 0
A10: 売上総利益 | F10: =F8-H9 -> 0 | H10: =IF(ISERROR(F10/F8),0,F10/F8) -> 0 | I10: =I8-K9 -> 0 | K10: =IF(ISERROR(I10/I8),0,I10/I8) -> 0 | L10: =L8-N9 -> 0 | N10: =IF(ISERROR(L10/L8),0,L10/L8) -> 0
A11: 営業１部 | B11: 営業 | D11: 1 | E11: 0 | F11: =SUMIF(I$3:N$3,$F$3,I11:N11) -> 0 | G11: =IF(ISERROR(F11/H11),0,F11/H11) -> 0 | H11: =SUMIF(I$3:N$3,$H$3,I11:N11) -> 0 | I11: =IFERROR(INDEX(別紙_テンプレート_DB!$DQ$3:$DQ$65423,MATCH($D11&"-"&I$2&"-"&$E11,INDEX(別紙_テンプレート_DB!$DM$3:$DM$65423&"-"&別紙_テンプレート_DB!$DN$3:$DN$65423&"-"&別紙_テンプレート_DB!$DO$3:$DO$65423,),0)),0) -> 0 | J11: =IF(ISERROR(I11/K11),0,I11/K11) -> 0 | K11: =IFERROR(INDEX(別紙_テンプレート_DB!$DP$3:$DP$65423,MATCH($D11&"-"&I$2&"-"&$E11,INDEX(別紙_テンプレート_DB!$DM$3:$DM$65423&"-"&別紙_テンプレート_DB!$DN$3:$DN$65423&"-"&別紙_テンプレート_DB!$DO$3:$DO$65423,),0)),0) -> 0 | L11: =IFERROR(INDEX(別紙_テンプレート_DB!$DQ$3:$DQ$65423,MATCH($D11&"-"&L$2&"-"&$E11,INDEX(別紙_テンプレート_DB!$DM$3:$DM$65423&"-"&別紙_テンプレート_DB!$DN$3:$DN$65423&"-"&別紙_テンプレート_DB!$DO$3:$DO$65423,),0)),0) -> 0 | M11: =IF(ISERROR(L11/N11),0,L11/N11) -> 0 | N11: =IFERROR(INDEX(別紙_テンプレート_DB!$DP$3:$DP$65423,MATCH($D11&"-"&L$2&"-"&$E11,INDEX(別紙_テンプレート_DB!$DM$3:$DM$65423&"-"&別紙_テンプレート_DB!$DN$3:$DN$65423&"-"&別紙_テンプレート_DB!$DO$3:$DO$65423,),0)),0) -> 0
B12: 工事 | D12: 1 | E12: 1 | F12: =SUMIF(I$3:N$3,$F$3,I12:N12) -> 0 | G12: =IF(ISERROR(F12/H12),0,F12/H12) -> 0 | H12: =SUMIF(I$3:N$3,$H$3,I12:N12) -> 0 | I12: =IFERROR(INDEX(別紙_テンプレート_DB!$DQ$3:$DQ$65423,MATCH($D12&"-"&I$2&"-"&$E12,INDEX(別紙_テンプレート_DB!$DM$3:$DM$65423&"-"&別紙_テンプレート_DB!$DN$3:$DN$65423&"-"&別紙_テンプレート_DB!$DO$3:$DO$65423,),0)),0) -> 0 | J12: =IF(ISERROR(I12/K12),0,I12/K12) -> 0 | K12: =IFERROR(INDEX(別紙_テンプレート_DB!$DP$3:$DP$65423,MATCH($D12&"-"&I$2&"-"&$E12,INDEX(別紙_テンプレート_DB!$DM$3:$DM$65423&"-"&別紙_テンプレート_DB!$DN$3:$DN$65423&"-"&別紙_テンプレート_DB!$DO$3:$DO$65423,),0)),0) -> 0 | L12: =IFERROR(INDEX(別紙_テンプレート_DB!$DQ$3:$DQ$65423,MATCH($D12&"-"&L$2&"-"&$E12,INDEX(別紙_テンプレート_DB!$DM$3:$DM$65423&"-"&別紙_テンプレート_DB!$DN$3:$DN$65423&"-"&別紙_テンプレート_DB!$DO$3:$DO$65423,),0)),0) -> 0 | M12: =IF(ISERROR(L12/N12),0,L12/N12) -> 0 | N12: =IFERROR(INDEX(別紙_テンプレート_DB!$DP$3:$DP$65423,MATCH($D12&"-"&L$2&"-"&$E12,INDEX(別紙_テンプレート_DB!$DM$3:$DM$65423&"-"&別紙_テンプレート_DB!$DN$3:$DN$65423&"-"&別紙_テンプレート_DB!$DO$3:$DO$65423,),0)),0) -> 0
B13: コール | D13: 1 | E13: 2 | F13: =SUMIF(I$3:N$3,$F$3,I13:N13) -> 0 | G13: =IF(ISERROR(F13/H13),0,F13/H13) -> 0 | H13: =SUMIF(I$3:N$3,$H$3,I13:N13) -> 0 | I13: =IFERROR(INDEX(別紙_テンプレート_DB!$DQ$3:$DQ$65423,MATCH($D13&"-"&I$2&"-"&$E13,INDEX(別紙_テンプレート_DB!$DM$3:$DM$65423&"-"&別紙_テンプレート_DB!$DN$3:$DN$65423&"-"&別紙_テンプレート_DB!$DO$3:$DO$65423,),0)),0) -> 0 | J13: =IF(ISERROR(I13/K13),0,I13/K13) -> 0 | K13: =IFERROR(INDEX(別紙_テンプレート_DB!$DP$3:$DP$65423,MATCH($D13&"-"&I$2&"-"&$E13,INDEX(別紙_テンプレート_DB!$DM$3:$DM$65423&"-"&別紙_テンプレート_DB!$DN$3:$DN$65423&"-"&別紙_テンプレート_DB!$DO$3:$DO$65423,),0)),0) -> 0 | L13: =IFERROR(INDEX(別紙_テンプレート_DB!$DQ$3:$DQ$65423,MATCH($D13&"-"&L$2&"-"&$E13,INDEX(別紙_テンプレート_DB!$DM$3:$DM$65423&"-"&別紙_テンプレート_DB!$DN$3:$DN$65423&"-"&別紙_テンプレート_DB!$DO$3:$DO$65423,),0)),0) -> 0 | M13: =IF(ISERROR(L13/N13),0,L13/N13) -> 0 | N13: =IFERROR(INDEX(別紙_テンプレート_DB!$DP$3:$DP$65423,MATCH($D13&"-"&L$2&"-"&$E13,INDEX(別紙_テンプレート_DB!$DM$3:$DM$65423&"-"&別紙_テンプレート_DB!$DN$3:$DN$65423&"-"&別紙_テンプレート_DB!$DO$3:$DO$65423,),0)),0) -> 0
B14: 店装 | D14: 1 | E14: 3 | F14: =SUMIF(I$3:N$3,$F$3,I14:N14) -> 0 | G14: =IF(ISERROR(F14/H14),0,F14/H14) -> 0 | H14: =SUMIF(I$3:N$3,$H$3,I14:N14) -> 0 | I14: =IFERROR(INDEX(別紙_テンプレート_DB!$DQ$3:$DQ$65423,MATCH($D14&"-"&I$2&"-"&$E14,INDEX(別紙_テンプレート_DB!$DM$3:$DM$65423&"-"&別紙_テンプレート_DB!$DN$3:$DN$65423&"-"&別紙_テンプレート_DB!$DO$3:$DO$65423,),0)),0) -> 0 | J14: =IF(ISERROR(I14/K14),0,I14/K14) -> 0 | K14: =IFERROR(INDEX(別紙_テンプレート_DB!$DP$3:$DP$65423,MATCH($D14&"-"&I$2&"-"&$E14,INDEX(別紙_テンプレート_DB!$DM$3:$DM$65423&"-"&別紙_テンプレート_DB!$DN$3:$DN$65423&"-"&別紙_テンプレート_DB!$DO$3:$DO$65423,),0)),0) -> 0 | L14: =IFERROR(INDEX(別紙_テンプレート_DB!$DQ$3:$DQ$65423,MATCH($D14&"-"&L$2&"-"&$E14,INDEX(別紙_テンプレート_DB!$DM$3:$DM$65423&"-"&別紙_テンプレート_DB!$DN$3:$DN$65423&"-"&別紙_テンプレート_DB!$DO$3:$DO$65423,),0)),0) -> 0 | M14: =IF(ISERROR(L14/N14),0,L14/N14) -> 0 | N14: =IFERROR(INDEX(別紙_テンプレート_DB!$DP$3:$DP$65423,MATCH($D14&"-"&L$2&"-"&$E14,INDEX(別紙_テンプレート_DB!$DM$3:$DM$65423&"-"&別紙_テンプレート_DB!$DN$3:$DN$65423&"-"&別紙_テンプレート_DB!$DO$3:$DO$65423,),0)),0) -> 0
B15: 委託 | D15: 1 | E15: 106 | F15: =SUMIF(I$3:N$3,$F$3,I15:N15) -> 0 | G15: =IF(ISERROR(F15/H15),0,F15/H15) -> 0 | H15: =SUMIF(I$3:N$3,$H$3,I15:N15) -> 0 | I15: =IFERROR(INDEX(別紙_テンプレート_DB!$DQ$3:$DQ$65423,MATCH($D15&"-"&I$2&"-"&$E15,INDEX(別紙_テンプレート_DB!$DM$3:$DM$65423&"-"&別紙_テンプレート_DB!$DN$3:$DN$65423&"-"&別紙_テンプレート_DB!$DO$3:$DO$65423,),0)),0) -> 0 | J15: =IF(ISERROR(I15/K15),0,I15/K15) -> 0 | K15: =IFERROR(INDEX(別紙_テンプレート_DB!$DP$3:$DP$65423,MATCH($D15&"-"&I$2&"-"&$E15,INDEX(別紙_テンプレート_DB!$DM$3:$DM$65423&"-"&別紙_テンプレート_DB!$DN$3:$DN$65423&"-"&別紙_テンプレート_DB!$DO$3:$DO$65423,),0)),0) -> 0 | L15: =IFERROR(INDEX(別紙_テンプレート_DB!$DQ$3:$DQ$65423,MATCH($D15&"-"&L$2&"-"&$E15,INDEX(別紙_テンプレート_DB!$DM$3:$DM$65423&"-"&別紙_テンプレート_DB!$DN$3:$DN$65423&"-"&別紙_テンプレート_DB!$DO$3:$DO$65423,),0)),0) -> 0 | M15: =IF(ISERROR(L15/N15),0,L15/N15) -> 0 | N15: =IFERROR(INDEX(別紙_テンプレート_DB!$DP$3:$DP$65423,MATCH($D15&"-"&L$2&"-"&$E15,INDEX(別紙_テンプレート_DB!$DM$3:$DM$65423&"-"&別紙_テンプレート_DB!$DN$3:$DN$65423&"-"&別紙_テンプレート_DB!$DO$3:$DO$65423,),0)),0) -> 0
B16: クレーム | D16: 1 | E16: 4 | F16: =SUMIF(I$3:N$3,$F$3,I16:N16) -> 0 | G16: =IF(ISERROR(F16/H16),0,F16/H16) -> 0 | H16: =SUMIF(I$3:N$3,$H$3,I16:N16) -> 0 | I16: =IFERROR(INDEX(別紙_テンプレート_DB!$DQ$3:$DQ$65423,MATCH($D16&"-"&I$2&"-"&$E16,INDEX(別紙_テンプレート_DB!$DM$3:$DM$65423&"-"&別紙_テンプレート_DB!$DN$3:$DN$65423&"-"&別紙_テンプレート_DB!$DO$3:$DO$65423,),0)),0) -> 0 | J16: =IF(ISERROR(I16/K16),0,I16/K16) -> 0 | K16: =IFERROR(INDEX(別紙_テンプレート_DB!$DP$3:$DP$65423,MATCH($D16&"-"&I$2&"-"&$E16,INDEX(別紙_テンプレート_DB!$DM$3:$DM$65423&"-"&別紙_テンプレート_DB!$DN$3:$DN$65423&"-"&別紙_テンプレート_DB!$DO$3:$DO$65423,),0)),0) -> 0 | L16: =IFERROR(INDEX(別紙_テンプレート_DB!$DQ$3:$DQ$65423,MATCH($D16&"-"&L$2&"-"&$E16,INDEX(別紙_テンプレート_DB!$DM$3:$DM$65423&"-"&別紙_テンプレート_DB!$DN$3:$DN$65423&"-"&別紙_テンプレート_DB!$DO$3:$DO$65423,),0)),0) -> 0 | M16: =IF(ISERROR(L16/N16),0,L16/N16) -> 0 | N16: =IFERROR(INDEX(別紙_テンプレート_DB!$DP$3:$DP$65423,MATCH($D16&"-"&L$2&"-"&$E16,INDEX(別紙_テンプレート_DB!$DM$3:$DM$65423&"-"&別紙_テンプレート_DB!$DN$3:$DN$65423&"-"&別紙_テンプレート_DB!$DO$3:$DO$65423,),0)),0) -> 0
A17: 売上 | C17: 0 | F17: =SUM(H20:H25) -> 0 | I17: =SUM(K20:K25) -> 0 | L17: =SUM(N20:N25) -> 0
A18: 原価 | C18: 1 | H18: =SUM(I18:N18) -> 0 | K18: =SUM(I20:I25) -> 0 | N18: =SUM(L20:L25) -> 0
A19: 売上総利益 | F19: =F17-H18 -> 0 | H19: =IF(ISERROR(F19/F17),0,F19/F17) -> 0 | I19: =I17-K18 -> 0 | K19: =IF(ISERROR(I19/I17),0,I19/I17) -> 0 | L19: =L17-N18 -> 0 | N19: =IF(ISERROR(L19/L17),0,L19/L17) -> 0
A20: 営業２部 | B20: 営業 | D20: 2 | E20: 0 | F20: =SUMIF(I$3:N$3,$F$3,I20:N20) -> 0 | G20: =IF(ISERROR(F20/H20),0,F20/H20) -> 0 | H20: =SUMIF(I$3:N$3,$H$3,I20:N20) -> 0 | I20: =IFERROR(INDEX(別紙_テンプレート_DB!$DQ$3:$DQ$65423,MATCH($D20&"-"&I$2&"-"&$E20,INDEX(別紙_テンプレート_DB!$DM$3:$DM$65423&"-"&別紙_テンプレート_DB!$DN$3:$DN$65423&"-"&別紙_テンプレート_DB!$DO$3:$DO$65423,),0)),0) -> 0 | J20: =IF(ISERROR(I20/K20),0,I20/K20) -> 0 | K20: =IFERROR(INDEX(別紙_テンプレート_DB!$DP$3:$DP$65423,MATCH($D20&"-"&I$2&"-"&$E20,INDEX(別紙_テンプレート_DB!$DM$3:$DM$65423&"-"&別紙_テンプレート_DB!$DN$3:$DN$65423&"-"&別紙_テンプレート_DB!$DO$3:$DO$65423,),0)),0) -> 0 | L20: =IFERROR(INDEX(別紙_テンプレート_DB!$DQ$3:$DQ$65423,MATCH($D20&"-"&L$2&"-"&$E20,INDEX(別紙_テンプレート_DB!$DM$3:$DM$65423&"-"&別紙_テンプレート_DB!$DN$3:$DN$65423&"-"&別紙_テンプレート_DB!$DO$3:$DO$65423,),0)),0) -> 0 | M20: =IF(ISERROR(L20/N20),0,L20/N20) -> 0 | N20: =IFERROR(INDEX(別紙_テンプレート_DB!$DP$3:$DP$65423,MATCH($D20&"-"&L$2&"-"&$E20,INDEX(別紙_テンプレート_DB!$DM$3:$DM$65423&"-"&別紙_テンプレート_DB!$DN$3:$DN$65423&"-"&別紙_テンプレート_DB!$DO$3:$DO$65423,),0)),0) -> 0
B21: 工事 | D21: 2 | E21: 1 | F21: =SUMIF(I$3:N$3,$F$3,I21:N21) -> 0 | G21: =IF(ISERROR(F21/H21),0,F21/H21) -> 0 | H21: =SUMIF(I$3:N$3,$H$3,I21:N21) -> 0 | I21: =IFERROR(INDEX(別紙_テンプレート_DB!$DQ$3:$DQ$65423,MATCH($D21&"-"&I$2&"-"&$E21,INDEX(別紙_テンプレート_DB!$DM$3:$DM$65423&"-"&別紙_テンプレート_DB!$DN$3:$DN$65423&"-"&別紙_テンプレート_DB!$DO$3:$DO$65423,),0)),0) -> 0 | J21: =IF(ISERROR(I21/K21),0,I21/K21) -> 0 | K21: =IFERROR(INDEX(別紙_テンプレート_DB!$DP$3:$DP$65423,MATCH($D21&"-"&I$2&"-"&$E21,INDEX(別紙_テンプレート_DB!$DM$3:$DM$65423&"-"&別紙_テンプレート_DB!$DN$3:$DN$65423&"-"&別紙_テンプレート_DB!$DO$3:$DO$65423,),0)),0) -> 0 | L21: =IFERROR(INDEX(別紙_テンプレート_DB!$DQ$3:$DQ$65423,MATCH($D21&"-"&L$2&"-"&$E21,INDEX(別紙_テンプレート_DB!$DM$3:$DM$65423&"-"&別紙_テンプレート_DB!$DN$3:$DN$65423&"-"&別紙_テンプレート_DB!$DO$3:$DO$65423,),0)),0) -> 0 | M21: =IF(ISERROR(L21/N21),0,L21/N21) -> 0 | N21: =IFERROR(INDEX(別紙_テンプレート_DB!$DP$3:$DP$65423,MATCH($D21&"-"&L$2&"-"&$E21,INDEX(別紙_テンプレート_DB!$DM$3:$DM$65423&"-"&別紙_テンプレート_DB!$DN$3:$DN$65423&"-"&別紙_テンプレート_DB!$DO$3:$DO$65423,),0)),0) -> 0
B22: コール | D22: 2 | E22: 2 | F22: =SUMIF(I$3:N$3,$F$3,I22:N22) -> 0 | G22: =IF(ISERROR(F22/H22),0,F22/H22) -> 0 | H22: =SUMIF(I$3:N$3,$H$3,I22:N22) -> 0 | I22: =IFERROR(INDEX(別紙_テンプレート_DB!$DQ$3:$DQ$65423,MATCH($D22&"-"&I$2&"-"&$E22,INDEX(別紙_テンプレート_DB!$DM$3:$DM$65423&"-"&別紙_テンプレート_DB!$DN$3:$DN$65423&"-"&別紙_テンプレート_DB!$DO$3:$DO$65423,),0)),0) -> 0 | J22: =IF(ISERROR(I22/K22),0,I22/K22) -> 0 | K22: =IFERROR(INDEX(別紙_テンプレート_DB!$DP$3:$DP$65423,MATCH($D22&"-"&I$2&"-"&$E22,INDEX(別紙_テンプレート_DB!$DM$3:$DM$65423&"-"&別紙_テンプレート_DB!$DN$3:$DN$65423&"-"&別紙_テンプレート_DB!$DO$3:$DO$65423,),0)),0) -> 0 | L22: =IFERROR(INDEX(別紙_テンプレート_DB!$DQ$3:$DQ$65423,MATCH($D22&"-"&L$2&"-"&$E22,INDEX(別紙_テンプレート_DB!$DM$3:$DM$65423&"-"&別紙_テンプレート_DB!$DN$3:$DN$65423&"-"&別紙_テンプレート_DB!$DO$3:$DO$65423,),0)),0) -> 0 | M22: =IF(ISERROR(L22/N22),0,L22/N22) -> 0 | N22: =IFERROR(INDEX(別紙_テンプレート_DB!$DP$3:$DP$65423,MATCH($D22&"-"&L$2&"-"&$E22,INDEX(別紙_テンプレート_DB!$DM$3:$DM$65423&"-"&別紙_テンプレート_DB!$DN$3:$DN$65423&"-"&別紙_テンプレート_DB!$DO$3:$DO$65423,),0)),0) -> 0
B23: 店装 | D23: 2 | E23: 3 | F23: =SUMIF(I$3:N$3,$F$3,I23:N23) -> 0 | G23: =IF(ISERROR(F23/H23),0,F23/H23) -> 0 | H23: =SUMIF(I$3:N$3,$H$3,I23:N23) -> 0 | I23: =IFERROR(INDEX(別紙_テンプレート_DB!$DQ$3:$DQ$65423,MATCH($D23&"-"&I$2&"-"&$E23,INDEX(別紙_テンプレート_DB!$DM$3:$DM$65423&"-"&別紙_テンプレート_DB!$DN$3:$DN$65423&"-"&別紙_テンプレート_DB!$DO$3:$DO$65423,),0)),0) -> 0 | J23: =IF(ISERROR(I23/K23),0,I23/K23) -> 0 | K23: =IFERROR(INDEX(別紙_テンプレート_DB!$DP$3:$DP$65423,MATCH($D23&"-"&I$2&"-"&$E23,INDEX(別紙_テンプレート_DB!$DM$3:$DM$65423&"-"&別紙_テンプレート_DB!$DN$3:$DN$65423&"-"&別紙_テンプレート_DB!$DO$3:$DO$65423,),0)),0) -> 0 | L23: =IFERROR(INDEX(別紙_テンプレート_DB!$DQ$3:$DQ$65423,MATCH($D23&"-"&L$2&"-"&$E23,INDEX(別紙_テンプレート_DB!$DM$3:$DM$65423&"-"&別紙_テンプレート_DB!$DN$3:$DN$65423&"-"&別紙_テンプレート_DB!$DO$3:$DO$65423,),0)),0) -> 0 | M23: =IF(ISERROR(L23/N23),0,L23/N23) -> 0 | N23: =IFERROR(INDEX(別紙_テンプレート_DB!$DP$3:$DP$65423,MATCH($D23&"-"&L$2&"-"&$E23,INDEX(別紙_テンプレート_DB!$DM$3:$DM$65423&"-"&別紙_テンプレート_DB!$DN$3:$DN$65423&"-"&別紙_テンプレート_DB!$DO$3:$DO$65423,),0)),0) -> 0
B24: 委託 | D24: 2 | E24: 106 | F24: =SUMIF(I$3:N$3,$F$3,I24:N24) -> 0 | G24: =IF(ISERROR(F24/H24),0,F24/H24) -> 0 | H24: =SUMIF(I$3:N$3,$H$3,I24:N24) -> 0 | I24: =IFERROR(INDEX(別紙_テンプレート_DB!$DQ$3:$DQ$65423,MATCH($D24&"-"&I$2&"-"&$E24,INDEX(別紙_テンプレート_DB!$DM$3:$DM$65423&"-"&別紙_テンプレート_DB!$DN$3:$DN$65423&"-"&別紙_テンプレート_DB!$DO$3:$DO$65423,),0)),0) -> 0 | J24: =IF(ISERROR(I24/K24),0,I24/K24) -> 0 | K24: =IFERROR(INDEX(別紙_テンプレート_DB!$DP$3:$DP$65423,MATCH($D24&"-"&I$2&"-"&$E24,INDEX(別紙_テンプレート_DB!$DM$3:$DM$65423&"-"&別紙_テンプレート_DB!$DN$3:$DN$65423&"-"&別紙_テンプレート_DB!$DO$3:$DO$65423,),0)),0) -> 0 | L24: =IFERROR(INDEX(別紙_テンプレート_DB!$DQ$3:$DQ$65423,MATCH($D24&"-"&L$2&"-"&$E24,INDEX(別紙_テンプレート_DB!$DM$3:$DM$65423&"-"&別紙_テンプレート_DB!$DN$3:$DN$65423&"-"&別紙_テンプレート_DB!$DO$3:$DO$65423,),0)),0) -> 0 | M24: =IF(ISERROR(L24/N24),0,L24/N24) -> 0 | N24: =IFERROR(INDEX(別紙_テンプレート_DB!$DP$3:$DP$65423,MATCH($D24&"-"&L$2&"-"&$E24,INDEX(別紙_テンプレート_DB!$DM$3:$DM$65423&"-"&別紙_テンプレート_DB!$DN$3:$DN$65423&"-"&別紙_テンプレート_DB!$DO$3:$DO$65423,),0)),0) -> 0
B25: クレーム | D25: 2 | E25: 4 | F25: =SUMIF(I$3:N$3,$F$3,I25:N25) -> 0 | G25: =IF(ISERROR(F25/H25),0,F25/H25) -> 0 | H25: =SUMIF(I$3:N$3,$H$3,I25:N25) -> 0 | I25: =IFERROR(INDEX(別紙_テンプレート_DB!$DQ$3:$DQ$65423,MATCH($D25&"-"&I$2&"-"&$E25,INDEX(別紙_テンプレート_DB!$DM$3:$DM$65423&"-"&別紙_テンプレート_DB!$DN$3:$DN$65423&"-"&別紙_テンプレート_DB!$DO$3:$DO$65423,),0)),0) -> 0 | J25: =IF(ISERROR(I25/K25),0,I25/K25) -> 0 | K25: =IFERROR(INDEX(別紙_テンプレート_DB!$DP$3:$DP$65423,MATCH($D25&"-"&I$2&"-"&$E25,INDEX(別紙_テンプレート_DB!$DM$3:$DM$65423&"-"&別紙_テンプレート_DB!$DN$3:$DN$65423&"-"&別紙_テンプレート_DB!$DO$3:$DO$65423,),0)),0) -> 0 | L25: =IFERROR(INDEX(別紙_テンプレート_DB!$DQ$3:$DQ$65423,MATCH($D25&"-"&L$2&"-"&$E25,INDEX(別紙_テンプレート_DB!$DM$3:$DM$65423&"-"&別紙_テンプレート_DB!$DN$3:$DN$65423&"-"&別紙_テンプレート_DB!$DO$3:$DO$65423,),0)),0) -> 0 | M25: =IF(ISERROR(L25/N25),0,L25/N25) -> 0 | N25: =IFERROR(INDEX(別紙_テンプレート_DB!$DP$3:$DP$65423,MATCH($D25&"-"&L$2&"-"&$E25,INDEX(別紙_テンプレート_DB!$DM$3:$DM$65423&"-"&別紙_テンプレート_DB!$DN$3:$DN$65423&"-"&別紙_テンプレート_DB!$DO$3:$DO$65423,),0)),0) -> 0
A26: 売上 | C26: 0 | F26: =SUM(H29:H34) -> 0 | I26: =SUM(K29:K34) -> 0 | L26: =SUM(N29:N34) -> 0
A27: 原価 | C27: 1 | H27: =SUM(I27:N27) -> 0 | K27: =SUM(I29:I34) -> 0 | N27: =SUM(L29:L34) -> 0
A28: 売上総利益 | F28: =F26-H27 -> 0 | H28: =IF(ISERROR(F28/F26),0,F28/F26) -> 0 | I28: =I26-K27 -> 0 | K28: =IF(ISERROR(I28/I26),0,I28/I26) -> 0 | L28: =L26-N27 -> 0 | N28: =IF(ISERROR(L28/L26),0,L28/L26) -> 0
A29: 営業３部 | B29: 営業 | D29: 3 | E29: 0 | F29: =SUMIF(I$3:N$3,$F$3,I29:N29) -> 0 | G29: =IF(ISERROR(F29/H29),0,F29/H29) -> 0 | H29: =SUMIF(I$3:N$3,$H$3,I29:N29) -> 0 | I29: =IFERROR(INDEX(別紙_テンプレート_DB!$DQ$3:$DQ$65423,MATCH($D29&"-"&I$2&"-"&$E29,INDEX(別紙_テンプレート_DB!$DM$3:$DM$65423&"-"&別紙_テンプレート_DB!$DN$3:$DN$65423&"-"&別紙_テンプレート_DB!$DO$3:$DO$65423,),0)),0) -> 0 | J29: =IF(ISERROR(I29/K29),0,I29/K29) -> 0 | K29: =IFERROR(INDEX(別紙_テンプレート_DB!$DP$3:$DP$65423,MATCH($D29&"-"&I$2&"-"&$E29,INDEX(別紙_テンプレート_DB!$DM$3:$DM$65423&"-"&別紙_テンプレート_DB!$DN$3:$DN$65423&"-"&別紙_テンプレート_DB!$DO$3:$DO$65423,),0)),0) -> 0 | L29: =IFERROR(INDEX(別紙_テンプレート_DB!$DQ$3:$DQ$65423,MATCH($D29&"-"&L$2&"-"&$E29,INDEX(別紙_テンプレート_DB!$DM$3:$DM$65423&"-"&別紙_テンプレート_DB!$DN$3:$DN$65423&"-"&別紙_テンプレート_DB!$DO$3:$DO$65423,),0)),0) -> 0 | M29: =IF(ISERROR(L29/N29),0,L29/N29) -> 0 | N29: =IFERROR(INDEX(別紙_テンプレート_DB!$DP$3:$DP$65423,MATCH($D29&"-"&L$2&"-"&$E29,INDEX(別紙_テンプレート_DB!$DM$3:$DM$65423&"-"&別紙_テンプレート_DB!$DN$3:$DN$65423&"-"&別紙_テンプレート_DB!$DO$3:$DO$65423,),0)),0) -> 0
B30: 工事 | D30: 3 | E30: 1 | F30: =SUMIF(I$3:N$3,$F$3,I30:N30) -> 0 | G30: =IF(ISERROR(F30/H30),0,F30/H30) -> 0 | H30: =SUMIF(I$3:N$3,$H$3,I30:N30) -> 0 | I30: =IFERROR(INDEX(別紙_テンプレート_DB!$DQ$3:$DQ$65423,MATCH($D30&"-"&I$2&"-"&$E30,INDEX(別紙_テンプレート_DB!$DM$3:$DM$65423&"-"&別紙_テンプレート_DB!$DN$3:$DN$65423&"-"&別紙_テンプレート_DB!$DO$3:$DO$65423,),0)),0) -> 0 | J30: =IF(ISERROR(I30/K30),0,I30/K30) -> 0 | K30: =IFERROR(INDEX(別紙_テンプレート_DB!$DP$3:$DP$65423,MATCH($D30&"-"&I$2&"-"&$E30,INDEX(別紙_テンプレート_DB!$DM$3:$DM$65423&"-"&別紙_テンプレート_DB!$DN$3:$DN$65423&"-"&別紙_テンプレート_DB!$DO$3:$DO$65423,),0)),0) -> 0 | L30: =IFERROR(INDEX(別紙_テンプレート_DB!$DQ$3:$DQ$65423,MATCH($D30&"-"&L$2&"-"&$E30,INDEX(別紙_テンプレート_DB!$DM$3:$DM$65423&"-"&別紙_テンプレート_DB!$DN$3:$DN$65423&"-"&別紙_テンプレート_DB!$DO$3:$DO$65423,),0)),0) -> 0 | M30: =IF(ISERROR(L30/N30),0,L30/N30) -> 0 | N30: =IFERROR(INDEX(別紙_テンプレート_DB!$DP$3:$DP$65423,MATCH($D30&"-"&L$2&"-"&$E30,INDEX(別紙_テンプレート_DB!$DM$3:$DM$65423&"-"&別紙_テンプレート_DB!$DN$3:$DN$65423&"-"&別紙_テンプレート_DB!$DO$3:$DO$65423,),0)),0) -> 0
B31: コール | D31: 3 | E31: 2 | F31: =SUMIF(I$3:N$3,$F$3,I31:N31) -> 0 | G31: =IF(ISERROR(F31/H31),0,F31/H31) -> 0 | H31: =SUMIF(I$3:N$3,$H$3,I31:N31) -> 0 | I31: =IFERROR(INDEX(別紙_テンプレート_DB!$DQ$3:$DQ$65423,MATCH($D31&"-"&I$2&"-"&$E31,INDEX(別紙_テンプレート_DB!$DM$3:$DM$65423&"-"&別紙_テンプレート_DB!$DN$3:$DN$65423&"-"&別紙_テンプレート_DB!$DO$3:$DO$65423,),0)),0) -> 0 | J31: =IF(ISERROR(I31/K31),0,I31/K31) -> 0 | K31: =IFERROR(INDEX(別紙_テンプレート_DB!$DP$3:$DP$65423,MATCH($D31&"-"&I$2&"-"&$E31,INDEX(別紙_テンプレート_DB!$DM$3:$DM$65423&"-"&別紙_テンプレート_DB!$DN$3:$DN$65423&"-"&別紙_テンプレート_DB!$DO$3:$DO$65423,),0)),0) -> 0 | L31: =IFERROR(INDEX(別紙_テンプレート_DB!$DQ$3:$DQ$65423,MATCH($D31&"-"&L$2&"-"&$E31,INDEX(別紙_テンプレート_DB!$DM$3:$DM$65423&"-"&別紙_テンプレート_DB!$DN$3:$DN$65423&"-"&別紙_テンプレート_DB!$DO$3:$DO$65423,),0)),0) -> 0 | M31: =IF(ISERROR(L31/N31),0,L31/N31) -> 0 | N31: =IFERROR(INDEX(別紙_テンプレート_DB!$DP$3:$DP$65423,MATCH($D31&"-"&L$2&"-"&$E31,INDEX(別紙_テンプレート_DB!$DM$3:$DM$65423&"-"&別紙_テンプレート_DB!$DN$3:$DN$65423&"-"&別紙_テンプレート_DB!$DO$3:$DO$65423,),0)),0) -> 0
B32: 店装 | D32: 3 | E32: 3 | F32: =SUMIF(I$3:N$3,$F$3,I32:N32) -> 0 | G32: =IF(ISERROR(F32/H32),0,F32/H32) -> 0 | H32: =SUMIF(I$3:N$3,$H$3,I32:N32) -> 0 | I32: =IFERROR(INDEX(別紙_テンプレート_DB!$DQ$3:$DQ$65423,MATCH($D32&"-"&I$2&"-"&$E32,INDEX(別紙_テンプレート_DB!$DM$3:$DM$65423&"-"&別紙_テンプレート_DB!$DN$3:$DN$65423&"-"&別紙_テンプレート_DB!$DO$3:$DO$65423,),0)),0) -> 0 | J32: =IF(ISERROR(I32/K32),0,I32/K32) -> 0 | K32: =IFERROR(INDEX(別紙_テンプレート_DB!$DP$3:$DP$65423,MATCH($D32&"-"&I$2&"-"&$E32,INDEX(別紙_テンプレート_DB!$DM$3:$DM$65423&"-"&別紙_テンプレート_DB!$DN$3:$DN$65423&"-"&別紙_テンプレート_DB!$DO$3:$DO$65423,),0)),0) -> 0 | L32: =IFERROR(INDEX(別紙_テンプレート_DB!$DQ$3:$DQ$65423,MATCH($D32&"-"&L$2&"-"&$E32,INDEX(別紙_テンプレート_DB!$DM$3:$DM$65423&"-"&別紙_テンプレート_DB!$DN$3:$DN$65423&"-"&別紙_テンプレート_DB!$DO$3:$DO$65423,),0)),0) -> 0 | M32: =IF(ISERROR(L32/N32),0,L32/N32) -> 0 | N32: =IFERROR(INDEX(別紙_テンプレート_DB!$DP$3:$DP$65423,MATCH($D32&"-"&L$2&"-"&$E32,INDEX(別紙_テンプレート_DB!$DM$3:$DM$65423&"-"&別紙_テンプレート_DB!$DN$3:$DN$65423&"-"&別紙_テンプレート_DB!$DO$3:$DO$65423,),0)),0) -> 0
B33: 委託 | D33: 3 | E33: 106 | F33: =SUMIF(I$3:N$3,$F$3,I33:N33) -> 0 | G33: =IF(ISERROR(F33/H33),0,F33/H33) -> 0 | H33: =SUMIF(I$3:N$3,$H$3,I33:N33) -> 0 | I33: =IFERROR(INDEX(別紙_テンプレート_DB!$DQ$3:$DQ$65423,MATCH($D33&"-"&I$2&"-"&$E33,INDEX(別紙_テンプレート_DB!$DM$3:$DM$65423&"-"&別紙_テンプレート_DB!$DN$3:$DN$65423&"-"&別紙_テンプレート_DB!$DO$3:$DO$65423,),0)),0) -> 0 | J33: =IF(ISERROR(I33/K33),0,I33/K33) -> 0 | K33: =IFERROR(INDEX(別紙_テンプレート_DB!$DP$3:$DP$65423,MATCH($D33&"-"&I$2&"-"&$E33,INDEX(別紙_テンプレート_DB!$DM$3:$DM$65423&"-"&別紙_テンプレート_DB!$DN$3:$DN$65423&"-"&別紙_テンプレート_DB!$DO$3:$DO$65423,),0)),0) -> 0 | L33: =IFERROR(INDEX(別紙_テンプレート_DB!$DQ$3:$DQ$65423,MATCH($D33&"-"&L$2&"-"&$E33,INDEX(別紙_テンプレート_DB!$DM$3:$DM$65423&"-"&別紙_テンプレート_DB!$DN$3:$DN$65423&"-"&別紙_テンプレート_DB!$DO$3:$DO$65423,),0)),0) -> 0 | M33: =IF(ISERROR(L33/N33),0,L33/N33) -> 0 | N33: =IFERROR(INDEX(別紙_テンプレート_DB!$DP$3:$DP$65423,MATCH($D33&"-"&L$2&"-"&$E33,INDEX(別紙_テンプレート_DB!$DM$3:$DM$65423&"-"&別紙_テンプレート_DB!$DN$3:$DN$65423&"-"&別紙_テンプレート_DB!$DO$3:$DO$65423,),0)),0) -> 0
B34: クレーム | D34: 3 | E34: 4 | F34: =SUMIF(I$3:N$3,$F$3,I34:N34) -> 0 | G34: =IF(ISERROR(F34/H34),0,F34/H34) -> 0 | H34: =SUMIF(I$3:N$3,$H$3,I34:N34) -> 0 | I34: =IFERROR(INDEX(別紙_テンプレート_DB!$DQ$3:$DQ$65423,MATCH($D34&"-"&I$2&"-"&$E34,INDEX(別紙_テンプレート_DB!$DM$3:$DM$65423&"-"&別紙_テンプレート_DB!$DN$3:$DN$65423&"-"&別紙_テンプレート_DB!$DO$3:$DO$65423,),0)),0) -> 0 | J34: =IF(ISERROR(I34/K34),0,I34/K34) -> 0 | K34: =IFERROR(INDEX(別紙_テンプレート_DB!$DP$3:$DP$65423,MATCH($D34&"-"&I$2&"-"&$E34,INDEX(別紙_テンプレート_DB!$DM$3:$DM$65423&"-"&別紙_テンプレート_DB!$DN$3:$DN$65423&"-"&別紙_テンプレート_DB!$DO$3:$DO$65423,),0)),0) -> 0 | L34: =IFERROR(INDEX(別紙_テンプレート_DB!$DQ$3:$DQ$65423,MATCH($D34&"-"&L$2&"-"&$E34,INDEX(別紙_テンプレート_DB!$DM$3:$DM$65423&"-"&別紙_テンプレート_DB!$DN$3:$DN$65423&"-"&別紙_テンプレート_DB!$DO$3:$DO$65423,),0)),0) -> 0 | M34: =IF(ISERROR(L34/N34),0,L34/N34) -> 0 | N34: =IFERROR(INDEX(別紙_テンプレート_DB!$DP$3:$DP$65423,MATCH($D34&"-"&L$2&"-"&$E34,INDEX(別紙_テンプレート_DB!$DM$3:$DM$65423&"-"&別紙_テンプレート_DB!$DN$3:$DN$65423&"-"&別紙_テンプレート_DB!$DO$3:$DO$65423,),0)),0) -> 0
A35: W | B35: 原/売 | D35: 2401 | F35: =SUMIF(I$3:N$3,$F$3,I35:N35) -> 0 | G35: =IF(ISERROR(F35/H35),0,F35/H35) -> 0 | H35: =SUMIF(I$3:N$3,$H$3,I35:N35) -> 0 | I35: =SUMIF($D36:$D41,$D35,I36:I41) -> 0 | J35: =IF(ISERROR(I35/K35),0,I35/K35) -> 0 | K35: =SUM(K36:K41) -> 0 | L35: =SUMIF($D36:$D41,$D35,L36:L41) -> 0 | M35: =IF(ISERROR(L35/N35),0,L35/N35) -> 0 | N35: =SUM(N36:N41) -> 0
B36: 営業 | C36: 0 | D36: 2401 | E36: 0 | F36: =SUMIF(I$3:N$3,$F$3,I36:N36) -> 0 | G36: =IF(ISERROR(F36/H36),0,F36/H36) -> 0 | H36: =SUMIF(I$3:N$3,$H$3,I36:N36) -> 0 | I36: =IFERROR(INDEX(別紙_テンプレート_DB!$G$3:$G$65423,MATCH($C36&"-"&$D36&"-"&I$2&"-"&$E36,INDEX(別紙_テンプレート_DB!$A$3:$A$65423&"-"&別紙_テンプレート_DB!$C$3:$C$65423&"-"&別紙_テンプレート_DB!$D$3:$D$65423&"-"&別紙_テンプレート_DB!$E$3:$E$65423,),0)),0) -> 0 | J36: =IF(ISERROR(I36/K36),0,I36/K36) -> 0 | K36: =IFERROR(INDEX(別紙_テンプレート_DB!$F$3:$F$65423,MATCH($C36&"-"&$D36&"-"&I$2&"-"&$E36,INDEX(別紙_テンプレート_DB!$A$3:$A$65423&"-"&別紙_テンプレート_DB!$C$3:$C$65423&"-"&別紙_テンプレート_DB!$D$3:$D$65423&"-"&別紙_テンプレート_DB!$E$3:$E$65423,),0)),0) -> 0 | L36: =IFERROR(INDEX(別紙_テンプレート_DB!$G$3:$G$65423,MATCH($C36&"-"&$D36&"-"&L$2&"-"&$E36,INDEX(別紙_テンプレート_DB!$A$3:$A$65423&"-"&別紙_テンプレート_DB!$C$3:$C$65423&"-"&別紙_テンプレート_DB!$D$3:$D$65423&"-"&別紙_テンプレート_DB!$E$3:$E$65423,),0)),0) -> 0 | M36: =IF(ISERROR(L36/N36),0,L36/N36) -> 0 | N36: =IFERROR(INDEX(別紙_テンプレート_DB!$F$3:$F$65423,MATCH($C36&"-"&$D36&"-"&L$2&"-"&$E36,INDEX(別紙_テンプレート_DB!$A$3:$A$65423&"-"&別紙_テンプレート_DB!$C$3:$C$65423&"-"&別紙_テンプレート_DB!$D$3:$D$65423&"-"&別紙_テンプレート_DB!$E$3:$E$65423,),0)),0) -> 0
B37: 工事 | C37: 0 | D37: 2401 | E37: 1 | F37: =SUMIF(I$3:N$3,$F$3,I37:N37) -> 0 | G37: =IF(ISERROR(F37/H37),0,F37/H37) -> 0 | H37: =SUMIF(I$3:N$3,$H$3,I37:N37) -> 0 | I37: =IFERROR(INDEX(別紙_テンプレート_DB!$G$3:$G$65423,MATCH($C37&"-"&$D37&"-"&I$2&"-"&$E37,INDEX(別紙_テンプレート_DB!$A$3:$A$65423&"-"&別紙_テンプレート_DB!$C$3:$C$65423&"-"&別紙_テンプレート_DB!$D$3:$D$65423&"-"&別紙_テンプレート_DB!$E$3:$E$65423,),0)),0) -> 0 | J37: =IF(ISERROR(I37/K37),0,I37/K37) -> 0 | K37: =IFERROR(INDEX(別紙_テンプレート_DB!$F$3:$F$65423,MATCH($C37&"-"&$D37&"-"&I$2&"-"&$E37,INDEX(別紙_テンプレート_DB!$A$3:$A$65423&"-"&別紙_テンプレート_DB!$C$3:$C$65423&"-"&別紙_テンプレート_DB!$D$3:$D$65423&"-"&別紙_テンプレート_DB!$E$3:$E$65423,),0)),0) -> 0 | L37: =IFERROR(INDEX(別紙_テンプレート_DB!$G$3:$G$65423,MATCH($C37&"-"&$D37&"-"&L$2&"-"&$E37,INDEX(別紙_テンプレート_DB!$A$3:$A$65423&"-"&別紙_テンプレート_DB!$C$3:$C$65423&"-"&別紙_テンプレート_DB!$D$3:$D$65423&"-"&別紙_テンプレート_DB!$E$3:$E$65423,),0)),0) -> 0 | M37: =IF(ISERROR(L37/N37),0,L37/N37) -> 0 | N37: =IFERROR(INDEX(別紙_テンプレート_DB!$F$3:$F$65423,MATCH($C37&"-"&$D37&"-"&L$2&"-"&$E37,INDEX(別紙_テンプレート_DB!$A$3:$A$65423&"-"&別紙_テンプレート_DB!$C$3:$C$65423&"-"&別紙_テンプレート_DB!$D$3:$D$65423&"-"&別紙_テンプレート_DB!$E$3:$E$65423,),0)),0) -> 0
B38: コール | C38: 0 | D38: 2401 | E38: 2 | F38: =SUMIF(I$3:N$3,$F$3,I38:N38) -> 0 | G38: =IF(ISERROR(F38/H38),0,F38/H38) -> 0 | H38: =SUMIF(I$3:N$3,$H$3,I38:N38) -> 0 | I38: =IFERROR(INDEX(別紙_テンプレート_DB!$G$3:$G$65423,MATCH($C38&"-"&$D38&"-"&I$2&"-"&$E38,INDEX(別紙_テンプレート_DB!$A$3:$A$65423&"-"&別紙_テンプレート_DB!$C$3:$C$65423&"-"&別紙_テンプレート_DB!$D$3:$D$65423&"-"&別紙_テンプレート_DB!$E$3:$E$65423,),0)),0) -> 0 | J38: =IF(ISERROR(I38/K38),0,I38/K38) -> 0 | K38: =IFERROR(INDEX(別紙_テンプレート_DB!$F$3:$F$65423,MATCH($C38&"-"&$D38&"-"&I$2&"-"&$E38,INDEX(別紙_テンプレート_DB!$A$3:$A$65423&"-"&別紙_テンプレート_DB!$C$3:$C$65423&"-"&別紙_テンプレート_DB!$D$3:$D$65423&"-"&別紙_テンプレート_DB!$E$3:$E$65423,),0)),0) -> 0 | L38: =IFERROR(INDEX(別紙_テンプレート_DB!$G$3:$G$65423,MATCH($C38&"-"&$D38&"-"&L$2&"-"&$E38,INDEX(別紙_テンプレート_DB!$A$3:$A$65423&"-"&別紙_テンプレート_DB!$C$3:$C$65423&"-"&別紙_テンプレート_DB!$D$3:$D$65423&"-"&別紙_テンプレート_DB!$E$3:$E$65423,),0)),0) -> 0 | M38: =IF(ISERROR(L38/N38),0,L38/N38) -> 0 | N38: =IFERROR(INDEX(別紙_テンプレート_DB!$F$3:$F$65423,MATCH($C38&"-"&$D38&"-"&L$2&"-"&$E38,INDEX(別紙_テンプレート_DB!$A$3:$A$65423&"-"&別紙_テンプレート_DB!$C$3:$C$65423&"-"&別紙_テンプレート_DB!$D$3:$D$65423&"-"&別紙_テンプレート_DB!$E$3:$E$65423,),0)),0) -> 0
B39: 店装 | C39: 0 | D39: 2401 | E39: 3 | F39: =SUMIF(I$3:N$3,$F$3,I39:N39) -> 0 | G39: =IF(ISERROR(F39/H39),0,F39/H39) -> 0 | H39: =SUMIF(I$3:N$3,$H$3,I39:N39) -> 0 | I39: =IFERROR(INDEX(別紙_テンプレート_DB!$G$3:$G$65423,MATCH($C39&"-"&$D39&"-"&I$2&"-"&$E39,INDEX(別紙_テンプレート_DB!$A$3:$A$65423&"-"&別紙_テンプレート_DB!$C$3:$C$65423&"-"&別紙_テンプレート_DB!$D$3:$D$65423&"-"&別紙_テンプレート_DB!$E$3:$E$65423,),0)),0) -> 0 | J39: =IF(ISERROR(I39/K39),0,I39/K39) -> 0 | K39: =IFERROR(INDEX(別紙_テンプレート_DB!$F$3:$F$65423,MATCH($C39&"-"&$D39&"-"&I$2&"-"&$E39,INDEX(別紙_テンプレート_DB!$A$3:$A$65423&"-"&別紙_テンプレート_DB!$C$3:$C$65423&"-"&別紙_テンプレート_DB!$D$3:$D$65423&"-"&別紙_テンプレート_DB!$E$3:$E$65423,),0)),0) -> 0 | L39: =IFERROR(INDEX(別紙_テンプレート_DB!$G$3:$G$65423,MATCH($C39&"-"&$D39&"-"&L$2&"-"&$E39,INDEX(別紙_テンプレート_DB!$A$3:$A$65423&"-"&別紙_テンプレート_DB!$C$3:$C$65423&"-"&別紙_テンプレート_DB!$D$3:$D$65423&"-"&別紙_テンプレート_DB!$E$3:$E$65423,),0)),0) -> 0 | M39: =IF(ISERROR(L39/N39),0,L39/N39) -> 0 | N39: =IFERROR(INDEX(別紙_テンプレート_DB!$F$3:$F$65423,MATCH($C39&"-"&$D39&"-"&L$2&"-"&$E39,INDEX(別紙_テンプレート_DB!$A$3:$A$65423&"-"&別紙_テンプレート_DB!$C$3:$C$65423&"-"&別紙_テンプレート_DB!$D$3:$D$65423&"-"&別紙_テンプレート_DB!$E$3:$E$65423,),0)),0) -> 0
B40: 委託 | C40: 0 | D40: 2401 | E40: 106 | F40: =SUMIF(I$3:N$3,$F$3,I40:N40) -> 0 | G40: =IF(ISERROR(F40/H40),0,F40/H40) -> 0 | H40: =SUMIF(I$3:N$3,$H$3,I40:N40) -> 0 | I40: =IFERROR(INDEX(別紙_テンプレート_DB!$G$3:$G$65423,MATCH($C40&"-"&$D40&"-"&I$2&"-"&$E40,INDEX(別紙_テンプレート_DB!$A$3:$A$65423&"-"&別紙_テンプレート_DB!$C$3:$C$65423&"-"&別紙_テンプレート_DB!$D$3:$D$65423&"-"&別紙_テンプレート_DB!$E$3:$E$65423,),0)),0) -> 0 | J40: =IF(ISERROR(I40/K40),0,I40/K40) -> 0 | K40: =IFERROR(INDEX(別紙_テンプレート_DB!$F$3:$F$65423,MATCH($C40&"-"&$D40&"-"&I$2&"-"&$E40,INDEX(別紙_テンプレート_DB!$A$3:$A$65423&"-"&別紙_テンプレート_DB!$C$3:$C$65423&"-"&別紙_テンプレート_DB!$D$3:$D$65423&"-"&別紙_テンプレート_DB!$E$3:$E$65423,),0)),0) -> 0 | L40: =IFERROR(INDEX(別紙_テンプレート_DB!$G$3:$G$65423,MATCH($C40&"-"&$D40&"-"&L$2&"-"&$E40,INDEX(別紙_テンプレート_DB!$A$3:$A$65423&"-"&別紙_テンプレート_DB!$C$3:$C$65423&"-"&別紙_テンプレート_DB!$D$3:$D$65423&"-"&別紙_テンプレート_DB!$E$3:$E$65423,),0)),0) -> 0 | M40: =IF(ISERROR(L40/N40),0,L40/N40) -> 0 | N40: =IFERROR(INDEX(別紙_テンプレート_DB!$F$3:$F$65423,MATCH($C40&"-"&$D40&"-"&L$2&"-"&$E40,INDEX(別紙_テンプレート_DB!$A$3:$A$65423&"-"&別紙_テンプレート_DB!$C$3:$C$65423&"-"&別紙_テンプレート_DB!$D$3:$D$65423&"-"&別紙_テンプレート_DB!$E$3:$E$65423,),0)),0) -> 0
...

Sheet 別紙_印刷レイアウト

Sheet 別紙_テンプレート_工事
A1: 工事チーム統計
A2: 項目 | F2: =IF(MONTH(I2)<4,YEAR(I2)-1&"年度",YEAR(I2)&"年度") -> 2022年度 | I2: 44773 | L2: 44772
F3: 原価 | H3: 売上 | I3: 原価 | K3: 売上 | L3: 原価 | N3: 売上
A4: 売上総利益 | D4: 0 | F4: =SUMIF(I$3:N$3,$F$3,I4:N4) -> 0 | G4: =IF(ISERROR(F4/H4),0,F4/H4) -> 0 | H4: =SUMIF(I$3:N$3,$H$3,I4:N4) -> 0 | I4: =SUMIF($D6:$D12,$D4,I6:I12) -> 0 | J4: =IF(ISERROR(I4/K4),0,I4/K4) -> 0 | K4: =SUM(K6:K12) -> 0 | L4: =SUMIF($D6:$D12,$D4,L6:L12) -> 0 | M4: =IF(ISERROR(L4/N4),0,L4/N4) -> 0 | N4: =SUM(N6:N12) -> 0
A5: 粗利益 | F5: =SUMIF(I$3:N$3,$F$3,I5:N5) -> 0 | G5: =IF(ISERROR(F5/H4),0,F5/H4) -> 0 | I5: =K4-I4-(I7) -> 0 | J5: =IF(ISERROR(I5/K4),0,I5/K4) -> 0 | L5: =N4-L4-(L7) -> 0 | M5: =IF(ISERROR(L5/N4),0,L5/N4) -> 0
A6: 科目計 | B6: 営業 | D6: 0 | E6: 0 | F6: =SUMIF(I$3:N$3,$F$3,I6:N6) -> 0 | G6: =IF(ISERROR(F6/H6),0,F6/H6) -> 0 | H6: =SUMIF(I$3:N$3,$H$3,I6:N6) -> 0 | I6: =SUMIF($B$13:$B$75,$B6,I$13:I$75) -> 0 | J6: =IF(ISERROR(I6/K6),0,I6/K6) -> 0 | K6: =SUMIF($B$13:$B$75,$B6,K$13:K$75) -> 0 | L6: =SUMIF($B$13:$B$75,$B6,L$13:L$75) -> 0 | M6: =IF(ISERROR(L6/N6),0,L6/N6) -> 0 | N6: =SUMIF($B$13:$B$75,$B6,N$13:N$75) -> 0
B7: 営業経費 | I7: =SUMIF($B$13:$B$75,$B7,I$13:I$75) -> 0 | L7: =SUMIF($B$13:$B$75,$B7,L$13:L$75) -> 0
B8: 工事 | D8: 0 | E8: 1 | F8: =SUMIF(I$3:N$3,$F$3,I8:N8) -> 0 | G8: =IF(ISERROR(F8/H8),0,F8/H8) -> 0 | H8: =SUMIF(I$3:N$3,$H$3,I8:N8) -> 0 | I8: =SUMIF($B$13:$B$75,$B8,I$13:I$75) -> 0 | J8: =IF(ISERROR(I8/K8),0,I8/K8) -> 0 | K8: =SUMIF($B$13:$B$75,$B8,K$13:K$75) -> 0 | L8: =SUMIF($B$13:$B$75,$B8,L$13:L$75) -> 0 | M8: =IF(ISERROR(L8/N8),0,L8/N8) -> 0 | N8: =SUMIF($B$13:$B$75,$B8,N$13:N$75) -> 0
B9: コール | D9: 0 | E9: 2 | F9: =SUMIF(I$3:N$3,$F$3,I9:N9) -> 0 | G9: =IF(ISERROR(F9/H9),0,F9/H9) -> 0 | H9: =SUMIF(I$3:N$3,$H$3,I9:N9) -> 0 | I9: =SUMIF($B$13:$B$75,$B9,I$13:I$75) -> 0 | J9: =IF(ISERROR(I9/K9),0,I9/K9) -> 0 | K9: =SUMIF($B$13:$B$75,$B9,K$13:K$75) -> 0 | L9: =SUMIF($B$13:$B$75,$B9,L$13:L$75) -> 0 | M9: =IF(ISERROR(L9/N9),0,L9/N9) -> 0 | N9: =SUMIF($B$13:$B$75,$B9,N$13:N$75) -> 0
B10: 内装 | D10: 0 | E10: 3 | F10: =SUMIF(I$3:N$3,$F$3,I10:N10) -> 0 | G10: =IF(ISERROR(F10/H10),0,F10/H10) -> 0 | H10: =SUMIF(I$3:N$3,$H$3,I10:N10) -> 0 | I10: =SUMIF($B$13:$B$75,$B10,I$13:I$75) -> 0 | J10: =IF(ISERROR(I10/K10),0,I10/K10) -> 0 | K10: =SUMIF($B$13:$B$75,$B10,K$13:K$75) -> 0 | L10: =SUMIF($B$13:$B$75,$B10,L$13:L$75) -> 0 | M10: =IF(ISERROR(L10/N10),0,L10/N10) -> 0 | N10: =SUMIF($B$13:$B$75,$B10,N$13:N$75) -> 0
B11: 委託 | D11: 0 | E11: 106 | F11: =SUMIF(I$3:N$3,$F$3,I11:N11) -> 0 | G11: =IF(ISERROR(F11/H11),0,F11/H11) -> 0 | H11: =SUMIF(I$3:N$3,$H$3,I11:N11) -> 0 | I11: =SUMIF($B$13:$B$75,$B11,I$13:I$75) -> 0 | J11: =IF(ISERROR(I11/K11),0,I11/K11) -> 0 | K11: =SUMIF($B$13:$B$75,$B11,K$13:K$75) -> 0 | L11: =SUMIF($B$13:$B$75,$B11,L$13:L$75) -> 0 | M11: =IF(ISERROR(L11/N11),0,L11/N11) -> 0 | N11: =SUMIF($B$13:$B$75,$B11,N$13:N$75) -> 0
B12: クレーム | D12: 0 | E12: 4 | F12: =SUMIF(I$3:N$3,$F$3,I12:N12) -> 0 | G12: =IF(ISERROR(F12/H12),0,F12/H12) -> 0 | H12: =SUMIF(I$3:N$3,$H$3,I12:N12) -> 0 | I12: =SUMIF($B$13:$B$75,$B12,I$13:I$75) -> 0 | J12: =IF(ISERROR(I12/K12),0,I12/K12) -> 0 | K12: =SUMIF($B$13:$B$75,$B12,K$13:K$75) -> 0 | L12: =SUMIF($B$13:$B$75,$B12,L$13:L$75) -> 0 | M12: =IF(ISERROR(L12/N12),0,L12/N12) -> 0 | N12: =SUMIF($B$13:$B$75,$B12,N$13:N$75) -> 0
A13: 原価 ／ 売価 | C13: 工事担当 | D13: 119 | F13: =SUMIF(I$3:N$3,$F$3,I13:N13) -> 0 | G13: =IF(ISERROR(F13/H13),0,F13/H13) -> 0 | H13: =SUMIF(I$3:N$3,$H$3,I13:N13) -> 0 | I13: =SUMIF($D15:$D21,$D13,I15:I21) -> 0 | J13: =IF(ISERROR(I13/K13),0,I13/K13) -> 0 | K13: =SUM(K15:K21) -> 0 | L13: =SUMIF($D15:$D21,$D13,L15:L21) -> 0 | M13: =IF(ISERROR(L13/N13),0,L13/N13) -> 0 | N13: =SUM(N15:N21) -> 0
A14: 粗利益 | F14: =SUMIF(I$3:N$3,$F$3,I14:N14) -> 0 | I14: =K13-I13-(I16) -> 0 | L14: =N13-L13-(L16) -> 0
A15: 高橋 | B15: 営業 | D15: 119 | E15: 0 | F15: =SUMIF(I$3:N$3,$F$3,I15:N15) -> 0 | G15: =IF(ISERROR(F15/H15),0,F15/H15) -> 0 | H15: =SUMIF(I$3:N$3,$H$3,I15:N15) -> 0 | I15: =IFERROR(INDEX(別紙_テンプレート_DB!$P$3:$P$65423,MATCH($D15&"-"&I$2&"-"&$E15,INDEX(別紙_テンプレート_DB!$J$3:$J$65423&"-"&別紙_テンプレート_DB!$M$3:$M$65423&"-"&別紙_テンプレート_DB!$N$3:$N$65423,),0)),0) -> 0 | J15: =IF(ISERROR(I15/K15),0,I15/K15) -> 0 | K15: =IFERROR(INDEX(別紙_テンプレート_DB!$O$3:$O$65423,MATCH($D15&"-"&I$2&"-"&$E15,INDEX(別紙_テンプレート_DB!$J$3:$J$65423&"-"&別紙_テンプレート_DB!$M$3:$M$65423&"-"&別紙_テンプレート_DB!$N$3:$N$65423,),0)),0) -> 0 | L15: =IFERROR(INDEX(別紙_テンプレート_DB!$P$3:$P$65423,MATCH($D15&"-"&L$2&"-"&$E15,INDEX(別紙_テンプレート_DB!$J$3:$J$65423&"-"&別紙_テンプレート_DB!$M$3:$M$65423&"-"&別紙_テンプレート_DB!$N$3:$N$65423,),0)),0) -> 0 | M15: =IF(ISERROR(L15/N15),0,L15/N15) -> 0 | N15: =IFERROR(INDEX(別紙_テンプレート_DB!$O$3:$O$65423,MATCH($D15&"-"&L$2&"-"&$E15,INDEX(別紙_テンプレート_DB!$J$3:$J$65423&"-"&別紙_テンプレート_DB!$M$3:$M$65423&"-"&別紙_テンプレート_DB!$N$3:$N$65423,),0)),0) -> 0
B16: 営業経費 | I16: =IFERROR(INDEX(別紙_テンプレート_DB!$DP$3:$DP$65423,MATCH($C16&"-"&I$2,INDEX(別紙_テンプレート_DB!$DM$3:$DM$65423&"-"&別紙_テンプレート_DB!$DN$3:$DN$65423,),0)),0) -> 0 | L16: =IFERROR(INDEX(別紙_テンプレート_DB!$DP$3:$DP$65423,MATCH($C16&"-"&L$2,INDEX(別紙_テンプレート_DB!$DM$3:$DM$65423&"-"&別紙_テンプレート_DB!$DN$3:$DN$65423,),0)),0) -> 0
B17: 工事 | D17: 119 | E17: 1 | F17: =SUMIF(I$3:N$3,$F$3,I17:N17) -> 0 | G17: =IF(ISERROR(F17/H17),0,F17/H17) -> 0 | H17: =SUMIF(I$3:N$3,$H$3,I17:N17) -> 0 | I17: =IFERROR(INDEX(別紙_テンプレート_DB!$P$3:$P$65423,MATCH($D17&"-"&I$2&"-"&$E17,INDEX(別紙_テンプレート_DB!$J$3:$J$65423&"-"&別紙_テンプレート_DB!$M$3:$M$65423&"-"&別紙_テンプレート_DB!$N$3:$N$65423,),0)),0) -> 0 | J17: =IF(ISERROR(I17/K17),0,I17/K17) -> 0 | K17: =IFERROR(INDEX(別紙_テンプレート_DB!$O$3:$O$65423,MATCH($D17&"-"&I$2&"-"&$E17,INDEX(別紙_テンプレート_DB!$J$3:$J$65423&"-"&別紙_テンプレート_DB!$M$3:$M$65423&"-"&別紙_テンプレート_DB!$N$3:$N$65423,),0)),0) -> 0 | L17: =IFERROR(INDEX(別紙_テンプレート_DB!$P$3:$P$65423,MATCH($D17&"-"&L$2&"-"&$E17,INDEX(別紙_テンプレート_DB!$J$3:$J$65423&"-"&別紙_テンプレート_DB!$M$3:$M$65423&"-"&別紙_テンプレート_DB!$N$3:$N$65423,),0)),0) -> 0 | M17: =IF(ISERROR(L17/N17),0,L17/N17) -> 0 | N17: =IFERROR(INDEX(別紙_テンプレート_DB!$O$3:$O$65423,MATCH($D17&"-"&L$2&"-"&$E17,INDEX(別紙_テンプレート_DB!$J$3:$J$65423&"-"&別紙_テンプレート_DB!$M$3:$M$65423&"-"&別紙_テンプレート_DB!$N$3:$N$65423,),0)),0) -> 0
B18: コール | D18: 119 | E18: 2 | F18: =SUMIF(I$3:N$3,$F$3,I18:N18) -> 0 | G18: =IF(ISERROR(F18/H18),0,F18/H18) -> 0 | H18: =SUMIF(I$3:N$3,$H$3,I18:N18) -> 0 | I18: =IFERROR(INDEX(別紙_テンプレート_DB!$P$3:$P$65423,MATCH($D18&"-"&I$2&"-"&$E18,INDEX(別紙_テンプレート_DB!$J$3:$J$65423&"-"&別紙_テンプレート_DB!$M$3:$M$65423&"-"&別紙_テンプレート_DB!$N$3:$N$65423,),0)),0) -> 0 | J18: =IF(ISERROR(I18/K18),0,I18/K18) -> 0 | K18: =IFERROR(INDEX(別紙_テンプレート_DB!$O$3:$O$65423,MATCH($D18&"-"&I$2&"-"&$E18,INDEX(別紙_テンプレート_DB!$J$3:$J$65423&"-"&別紙_テンプレート_DB!$M$3:$M$65423&"-"&別紙_テンプレート_DB!$N$3:$N$65423,),0)),0) -> 0 | L18: =IFERROR(INDEX(別紙_テンプレート_DB!$P$3:$P$65423,MATCH($D18&"-"&L$2&"-"&$E18,INDEX(別紙_テンプレート_DB!$J$3:$J$65423&"-"&別紙_テンプレート_DB!$M$3:$M$65423&"-"&別紙_テンプレート_DB!$N$3:$N$65423,),0)),0) -> 0 | M18: =IF(ISERROR(L18/N18),0,L18/N18) -> 0 | N18: =IFERROR(INDEX(別紙_テンプレート_DB!$O$3:$O$65423,MATCH($D18&"-"&L$2&"-"&$E18,INDEX(別紙_テンプレート_DB!$J$3:$J$65423&"-"&別紙_テンプレート_DB!$M$3:$M$65423&"-"&別紙_テンプレート_DB!$N$3:$N$65423,),0)),0) -> 0
B19: 内装 | D19: 119 | E19: 3 | F19: =SUMIF(I$3:N$3,$F$3,I19:N19) -> 0 | G19: =IF(ISERROR(F19/H19),0,F19/H19) -> 0 | H19: =SUMIF(I$3:N$3,$H$3,I19:N19) -> 0 | I19: =IFERROR(INDEX(別紙_テンプレート_DB!$P$3:$P$65423,MATCH($D19&"-"&I$2&"-"&$E19,INDEX(別紙_テンプレート_DB!$J$3:$J$65423&"-"&別紙_テンプレート_DB!$M$3:$M$65423&"-"&別紙_テンプレート_DB!$N$3:$N$65423,),0)),0) -> 0 | J19: =IF(ISERROR(I19/K19),0,I19/K19) -> 0 | K19: =IFERROR(INDEX(別紙_テンプレート_DB!$O$3:$O$65423,MATCH($D19&"-"&I$2&"-"&$E19,INDEX(別紙_テンプレート_DB!$J$3:$J$65423&"-"&別紙_テンプレート_DB!$M$3:$M$65423&"-"&別紙_テンプレート_DB!$N$3:$N$65423,),0)),0) -> 0 | L19: =IFERROR(INDEX(別紙_テンプレート_DB!$P$3:$P$65423,MATCH($D19&"-"&L$2&"-"&$E19,INDEX(別紙_テンプレート_DB!$J$3:$J$65423&"-"&別紙_テンプレート_DB!$M$3:$M$65423&"-"&別紙_テンプレート_DB!$N$3:$N$65423,),0)),0) -> 0 | M19: =IF(ISERROR(L19/N19),0,L19/N19) -> 0 | N19: =IFERROR(INDEX(別紙_テンプレート_DB!$O$3:$O$65423,MATCH($D19&"-"&L$2&"-"&$E19,INDEX(別紙_テンプレート_DB!$J$3:$J$65423&"-"&別紙_テンプレート_DB!$M$3:$M$65423&"-"&別紙_テンプレート_DB!$N$3:$N$65423,),0)),0) -> 0
B20: 委託 | D20: 119 | E20: 106 | F20: =SUMIF(I$3:N$3,$F$3,I20:N20) -> 0 | G20: =IF(ISERROR(F20/H20),0,F20/H20) -> 0 | H20: =SUMIF(I$3:N$3,$H$3,I20:N20) -> 0 | I20: =IFERROR(INDEX(別紙_テンプレート_DB!$P$3:$P$65423,MATCH($D20&"-"&I$2&"-"&$E20,INDEX(別紙_テンプレート_DB!$J$3:$J$65423&"-"&別紙_テンプレート_DB!$M$3:$M$65423&"-"&別紙_テンプレート_DB!$N$3:$N$65423,),0)),0) -> 0 | J20: =IF(ISERROR(I20/K20),0,I20/K20) -> 0 | K20: =IFERROR(INDEX(別紙_テンプレート_DB!$O$3:$O$65423,MATCH($D20&"-"&I$2&"-"&$E20,INDEX(別紙_テンプレート_DB!$J$3:$J$65423&"-"&別紙_テンプレート_DB!$M$3:$M$65423&"-"&別紙_テンプレート_DB!$N$3:$N$65423,),0)),0) -> 0 | L20: =IFERROR(INDEX(別紙_テンプレート_DB!$P$3:$P$65423,MATCH($D20&"-"&L$2&"-"&$E20,INDEX(別紙_テンプレート_DB!$J$3:$J$65423&"-"&別紙_テンプレート_DB!$M$3:$M$65423&"-"&別紙_テンプレート_DB!$N$3:$N$65423,),0)),0) -> 0 | M20: =IF(ISERROR(L20/N20),0,L20/N20) -> 0 | N20: =IFERROR(INDEX(別紙_テンプレート_DB!$O$3:$O$65423,MATCH($D20&"-"&L$2&"-"&$E20,INDEX(別紙_テンプレート_DB!$J$3:$J$65423&"-"&別紙_テンプレート_DB!$M$3:$M$65423&"-"&別紙_テンプレート_DB!$N$3:$N$65423,),0)),0) -> 0
B21: クレーム | D21: 119 | E21: 4 | F21: =SUMIF(I$3:N$3,$F$3,I21:N21) -> 0 | I21: =IFERROR(INDEX(別紙_テンプレート_DB!$P$3:$P$65423,MATCH($D21&"-"&I$2&"-"&$E21,INDEX(別紙_テンプレート_DB!$J$3:$J$65423&"-"&別紙_テンプレート_DB!$M$3:$M$65423&"-"&別紙_テンプレート_DB!$N$3:$N$65423,),0)),0) -> 0 | L21: =IFERROR(INDEX(別紙_テンプレート_DB!$P$3:$P$65423,MATCH($D21&"-"&L$2&"-"&$E21,INDEX(別紙_テンプレート_DB!$J$3:$J$65423&"-"&別紙_テンプレート_DB!$M$3:$M$65423&"-"&別紙_テンプレート_DB!$N$3:$N$65423,),0)),0) -> 0
A22: 原価 ／ 売価 | C22: 工事担当 | D22: 120 | F22: =SUMIF(I$3:N$3,$F$3,I22:N22) -> 0 | G22: =IF(ISERROR(F22/H22),0,F22/H22) -> 0 | H22: =SUMIF(I$3:N$3,$H$3,I22:N22) -> 0 | I22: =SUMIF($D24:$D30,$D22,I24:I30) -> 0 | J22: =IF(ISERROR(I22/K22),0,I22/K22) -> 0 | K22: =SUM(K24:K30) -> 0 | L22: =SUMIF($D24:$D30,$D22,L24:L30) -> 0 | M22: =IF(ISERROR(L22/N22),0,L22/N22) -> 0 | N22: =SUM(N24:N30) -> 0
A23: 粗利益 | F23: =SUMIF(I$3:N$3,$F$3,I23:N23) -> 0 | I23: =K22-I22-(I25) -> 0 | L23: =N22-L22-(L25) -> 0
A24: 小林 | B24: 営業 | D24: 120 | E24: 0 | F24: =SUMIF(I$3:N$3,$F$3,I24:N24) -> 0 | G24: =IF(ISERROR(F24/H24),0,F24/H24) -> 0 | H24: =SUMIF(I$3:N$3,$H$3,I24:N24) -> 0 | I24: =IFERROR(INDEX(別紙_テンプレート_DB!$P$3:$P$65423,MATCH($D24&"-"&I$2&"-"&$E24,INDEX(別紙_テンプレート_DB!$J$3:$J$65423&"-"&別紙_テンプレート_DB!$M$3:$M$65423&"-"&別紙_テンプレート_DB!$N$3:$N$65423,),0)),0) -> 0 | J24: =IF(ISERROR(I24/K24),0,I24/K24) -> 0 | K24: =IFERROR(INDEX(別紙_テンプレート_DB!$O$3:$O$65423,MATCH($D24&"-"&I$2&"-"&$E24,INDEX(別紙_テンプレート_DB!$J$3:$J$65423&"-"&別紙_テンプレート_DB!$M$3:$M$65423&"-"&別紙_テンプレート_DB!$N$3:$N$65423,),0)),0) -> 0 | L24: =IFERROR(INDEX(別紙_テンプレート_DB!$P$3:$P$65423,MATCH($D24&"-"&L$2&"-"&$E24,INDEX(別紙_テンプレート_DB!$J$3:$J$65423&"-"&別紙_テンプレート_DB!$M$3:$M$65423&"-"&別紙_テンプレート_DB!$N$3:$N$65423,),0)),0) -> 0 | M24: =IF(ISERROR(L24/N24),0,L24/N24) -> 0 | N24: =IFERROR(INDEX(別紙_テンプレート_DB!$O$3:$O$65423,MATCH($D24&"-"&L$2&"-"&$E24,INDEX(別紙_テンプレート_DB!$J$3:$J$65423&"-"&別紙_テンプレート_DB!$M$3:$M$65423&"-"&別紙_テンプレート_DB!$N$3:$N$65423,),0)),0) -> 0
B25: 営業経費 | I25: =IFERROR(INDEX(別紙_テンプレート_DB!$DP$3:$DP$65423,MATCH($C25&"-"&I$2,INDEX(別紙_テンプレート_DB!$DM$3:$DM$65423&"-"&別紙_テンプレート_DB!$DN$3:$DN$65423,),0)),0) -> 0 | L25: =IFERROR(INDEX(別紙_テンプレート_DB!$DP$3:$DP$65423,MATCH($C25&"-"&L$2,INDEX(別紙_テンプレート_DB!$DM$3:$DM$65423&"-"&別紙_テンプレート_DB!$DN$3:$DN$65423,),0)),0) -> 0
B26: 工事 | D26: 120 | E26: 1 | F26: =SUMIF(I$3:N$3,$F$3,I26:N26) -> 0 | G26: =IF(ISERROR(F26/H26),0,F26/H26) -> 0 | H26: =SUMIF(I$3:N$3,$H$3,I26:N26) -> 0 | I26: =IFERROR(INDEX(別紙_テンプレート_DB!$P$3:$P$65423,MATCH($D26&"-"&I$2&"-"&$E26,INDEX(別紙_テンプレート_DB!$J$3:$J$65423&"-"&別紙_テンプレート_DB!$M$3:$M$65423&"-"&別紙_テンプレート_DB!$N$3:$N$65423,),0)),0) -> 0 | J26: =IF(ISERROR(I26/K26),0,I26/K26) -> 0 | K26: =IFERROR(INDEX(別紙_テンプレート_DB!$O$3:$O$65423,MATCH($D26&"-"&I$2&"-"&$E26,INDEX(別紙_テンプレート_DB!$J$3:$J$65423&"-"&別紙_テンプレート_DB!$M$3:$M$65423&"-"&別紙_テンプレート_DB!$N$3:$N$65423,),0)),0) -> 0 | L26: =IFERROR(INDEX(別紙_テンプレート_DB!$P$3:$P$65423,MATCH($D26&"-"&L$2&"-"&$E26,INDEX(別紙_テンプレート_DB!$J$3:$J$65423&"-"&別紙_テンプレート_DB!$M$3:$M$65423&"-"&別紙_テンプレート_DB!$N$3:$N$65423,),0)),0) -> 0 | M26: =IF(ISERROR(L26/N26),0,L26/N26) -> 0 | N26: =IFERROR(INDEX(別紙_テンプレート_DB!$O$3:$O$65423,MATCH($D26&"-"&L$2&"-"&$E26,INDEX(別紙_テンプレート_DB!$J$3:$J$65423&"-"&別紙_テンプレート_DB!$M$3:$M$65423&"-"&別紙_テンプレート_DB!$N$3:$N$65423,),0)),0) -> 0
