Workbook
Name 原価_見出し: [1]別紙_テンプレート!#REF!
Name 施工仕入金額: [1]別紙_テンプレート!#REF!
Name 施工売上金額: [1]別紙_テンプレート!#REF!

Sheet 変更履歴
B2: システム名 | H2: 画面ID | L2: システム分類 | R2: ドキュメント種別 | X2: ドキュメント名 | AK2: 帳票名 | AX2: 作成日 | BB2: 作成者 | BF2: 更新日 | BJ2: 更新者
B3: 受発注システム | H3: =LEFT($X$3,FIND("_",$X$3)-1) -> UN0200 | L3: 受発注 | R3: =MID($X$3,FIND("_",$X$3,FIND("_",$X$3)+1)+1,LEN($X$3)-FIND("_",$X$3,FIND("_",$X$3)+1)) -> 帳票設計書 | X3: =REPLACE(LEFT(CELL("filename",$B$2),FIND(".x",CELL("filename",$B$2))-1),1,FIND("[",CELL("filename",$B$2)),) -> UN0200_納品書_帳票設計書 | AK3: =MID($X$3,FIND("_",$X$3)+1,FIND("_",$X$3,FIND("_",$X$3)+1)-FIND("_",$X$3)-1) -> 納品書 | AX3: 45581 | BB3: 大谷 | BF3: 45581 | BJ3: 大谷
C7: 変更履歴
C8: 日付 | G8: 版数 | K8: 担当 | O8: 変更箇所 | Y8: 内容
C9: 45581 | G9: 1.0.0 | K9: 大谷 | O9: - | Y9: 新規作成

Sheet 概要
B2: システム名 | H2: 画面ID | L2: システム分類 | R2: ドキュメント種別 | X2: ドキュメント名 | AK2: 帳票名 | AX2: 作成日 | BB2: 作成者 | BF2: 更新日 | BJ2: 更新者
B3: =変更履歴!B3 -> 受発注システム | H3: =変更履歴!H3 -> UN0200 | L3: =変更履歴!L3 -> 受発注 | R3: =変更履歴!R3 -> 帳票設計書 | X3: =変更履歴!X3 -> UN0200_納品書_帳票設計書 | AK3: =変更履歴!AK3 -> 納品書 | AX3: =変更履歴!AX3 -> 45581 | BB3: =変更履歴!BB3 -> 大谷 | BF3: =変更履歴!BF3 -> 45581 | BJ3: =変更履歴!BJ3 -> 大谷
D7: 帳票の名称 | H7: =AK3 -> 納品書
D8: 帳票テンプレート名 | H8: Template_納品書.xlsx
D9: ファイル種類 | H9: Excel,PDF
D10: ファイル拡張子 | H10: xlsx,pdf
D11: 文字コード | H11: -
D12: コーテーション | H12: -
D13: 固定長/可変長 | H13: -
D14: 区切り文字 | H14: -
D15: 用紙サイズ | H15: A4横
D16: 概要

Sheet 帳票レイアウト
B2: システム名 | H2: 画面ID | L2: システム分類 | R2: ドキュメント種別 | X2: ドキュメント名 | AK2: 帳票名 | AX2: 作成日 | BB2: 作成者 | BF2: 更新日 | BJ2: 更新者
B3: =変更履歴!B3 -> 受発注システム | H3: =変更履歴!H3 -> UN0200 | L3: =変更履歴!L3 -> 受発注 | R3: =変更履歴!R3 -> 帳票設計書 | X3: =変更履歴!X3 -> UN0200_納品書_帳票設計書 | AK3: =変更履歴!AK3 -> 納品書 | AX3: =変更履歴!AX3 -> 45581 | BB3: =変更履歴!BB3 -> 大谷 | BF3: =変更履歴!BF3 -> 45581 | BJ3: =変更履歴!BJ3 -> 大谷
B6: ページ１

Sheet 項目一覧
B2: システム名 | H2: 画面ID | L2: システム分類 | R2: ドキュメント種別 | X2: ドキュメント名 | AK2: 帳票名 | AX2: 作成日 | BB2: 作成者 | BF2: 更新日 | BJ2: 更新者
B3: =変更履歴!B3 -> 受発注システム | H3: =変更履歴!H3 -> UN0200 | L3: =変更履歴!L3 -> 受発注 | R3: =変更履歴!R3 -> 帳票設計書 | X3: =変更履歴!X3 -> UN0200_納品書_帳票設計書 | AK3: =変更履歴!AK3 -> 納品書 | AX3: =変更履歴!AX3 -> 45581 | BB3: =変更履歴!BB3 -> 大谷 | BF3: =変更履歴!BF3 -> 45581 | BJ3: =変更履歴!BJ3 -> 大谷
B7: 項目一覧
C9: 項目 | F9: フォントや文字サイズ、セル条件などは「別紙_テンプレート」準拠
D10: No. | E10: 項目名 | M10: データ型 | P10: 全角/半角 | S10: 文字数/桁数 | V10: データ取得元 | AB10: データ整形方法 | AR10: 整形後フォーマット | AX10: 備考
D11: 1 | E11: 見積番号_見出し | M11: 文字列 | P11: 半角 | S11: 4 | V11: [SQL29.見積番号] | AB11: "No." + [SQL29.見積番号]
D12: 2 | E12: 作成日 | M12: 日付 | P12: 半角 | S12: 8 | V12: [SQL29.見積日出力],[SQL29.見積日付] | AB12: [SQL29.見積日出力]が1の場合[SQL29.見積日付]を表示 | AR12: 9999年99月99日
D13: 3 | E13: 得意先名1 | M13: 文字列 | P13: 全角 | S13: 17 | V13: [SQL29.得意先名1],[SQL29.得意先名2] | AB13: [SQL29.得意先名2]が空の場合は何も表示しない、空でない場合は[SQL29.得意先名1]を表示。
D14: 4 | E14: 得意先名2 | M14: 文字列 | P14: 全角 | S14: 縮小して全体表示 | V14: [SQL29.得意先名1],[SQL29.得意先名2] | AB14: [SQL29.得意先名2]が空の場合は[SQL29.得意先名1]、空でない場合は[SQL29.得意先名2]を表示。
D15: 5 | E15: 御見積金額 | M15: 数値 | P15: 半角 | S15: 13 | V15: [SQL29.合計金額],[SQL29.出精値引] | AB15: [SQL29.合計金額]と[SQL29.出精値引]の合計。 | AR15: \9,999-
D16: 6 | E16: 消費税等 | M16: 文字列 | P16: 全角 | S16: 8 | V16: [SQL29.見積日付],[SQL34.切替日付],[SQL34.税率],[SQL34.旧税率] | AB16: [SQL29.見積日付] >= [SQL34.切替日付]の場合は[SQL34.税率]、 [SQL29.見積日付] < [SQL34.切替日付]の場合は[SQL34.旧税率]を[税率]とする。 "消費税等(" + [税率] + "%)"で表示。 | AX16: cZeiritsu.GetbyDate
D17: 7 | E17: 消費税額 | M17: 数値 | P17: 半角 | S17: 13 | V17: [SQL29.外税額] | AR17: \9,999-
D18: 8 | E18: 合計 | M18: 数値 | P18: 半角 | S18: 13 | V18: [5.御見積金額],[7.消費税額] | AB18: [5.御見積金額]と[7.消費税額]の合計。 | AR18: \9,999-
D19: 9 | E19: 件名 | M19: 文字列 | P19: 全角 | S19: 縮小して全体表示 | V19: [SQL29.見積件名]
D20: 10 | E20: 納期 | M20: 文字列 | P20: 全角 | S20: 縮小して全体表示 | V20: [SQL29.納期表示],[SQL29.納期S],[SQL29.納期E],[SQL29.納期その他] | AB20: [SQL29.納期表示]が0のとき[SQL29.納期S]と[SQL29.納期E]がどちらもnullでない場合は[SQL29.納期S] + "～" + [SQL29.納期E]を表示、どちらか片方がnullでない場合はnullでないものを表示、どちらもnullの場合は何も表示しない。 [SQL29.納期表示]が1の場合は"別途御打ち合せによる"、2の場合は[SQL29.納期その他]を表示。
D21: 11 | E21: 御支払条件 | M21: 文字列 | P21: 全角 | S21: 縮小して全体表示 | V21: [SQL29.支払条件],[SQL29.支払条件その他] | AB21: [SQL29.支払条件]が0の場合は"別途御打ち合せによる"、1の場合は[SQL29.支払条件その他]
D22: 12 | E22: 備考 | M22: 文字列 | P22: 全角 | S22: 縮小して全体表示 | V22: [SQL29.備考]
D23: 13 | E23: 郵便番号 | M23: 数値 | P23: 半角 | S23: 7 | V23: [TM会社.郵便番号]
D24: 14 | E24: 住所 | M24: 文字列 | P24: 全角 | S24: 41 | V24: [TM会社.住所1]
D25: 15 | E25: TEL | M25: 数値 | P25: 半角 | S25: 11 | V25: [TM会社.電話番号]
D26: 16 | E26: FAX | M26: 数値 | P26: 半角 | S26: 11 | V26: [TM会社.FAX番号]
D27: 17 | E27: コールセンター | M27: 数値 | P27: 半角 | S27: 11 | V27: [TM会社.コールセンター番号]
D28: 18 | E28: 会社担当者 | M28: 文字列 | P28: 全角 | S28: 20 | V28: [SQL35.問い合わせ先] | AB28: [TM担当者.問い合わせ先]が空の場合は何も表示しない | AR28: 問い合わせ先：[TM担当者.問い合わせ先] | AX28: cTanto.GetbyID
D29: 19 | E29: 会社担当者E-mail | M29: 文字列 | P29: 半角 | S29: 41 | V29: 空
D30: 20 | E30: 仕訳名 | M30: 文字列 | P30: 全角 | S30: 縮小して全体表示 | V30: [[SQL31.仕分番号.仕分名称]
D31: 21 | E31: SEC | M31: 文字列 | P31: 半角 | S31: 4 | V31: [SQL31.仕分番号] | AB31: [SQL31.仕分番号]のデータ型をVARCHAR(2)に変換し、"0"と結合した後に末尾2文字を取得する
D32: 22 | E32: 品名 | M32: 文字列 | P32: 全角 | S32: 縮小して全体表示 | V32: [SQL31.見積区分],[SQL31.漢字名称] | AB32: [SQL31.見積区分]が"C"か"A"か"S"の場合は半角スペース2つ + [SQL31.漢字名称]、それ以外の場合は[SQL31.漢字名称]のみ表示 | AX32: 【合計】以外は左詰めで表示する
D33: 23 | E33: W | M33: 文字列 | P33: 半角 | S33: 9 | V33: [SQL31.W]
D34: 24 | E34: D | M34: 文字列 | P34: 半角 | S34: 9 | V34: [SQL31.D],[SQL31.D1],[SQL31.D2] | AB34: [SQL31.D]が0でない場合は[SQL31.D]を表示。 [SQL31.D]が0で[SQL31.D1]と[SQL31.D2]が0でない場合は[SQL31.D1] + "/" [SQL31.D2]を表示。すべて0の場合は何も表示しない。
D35: 25 | E35: H | M35: 文字列 | P35: 半角 | S35: 9 | V35: [SQL31.H],[SQL31.H1],[SQL31.H2] | AB35: [SQL31.H]が0でない場合は[SQL31.H]を表示。 [SQL31.H]が0で[SQL31.H1]と[SQL31.H2]が0でない場合は[SQL31.H1] + "/" [SQL31.H2]を表示。すべて0の場合は何も表示しない。
D36: 26 | E36: 数量_元 | M36: 数値 | P36: 半角 | S36: 6 | V36: [SQL31.数量]
D37: 27 | E37: 数量 | M37: 数値 | P37: 半角 | S37: 9 | V37: [33.数量_元] | AB37: [33.数量_元]が整数の場合は1の位まで表示、小数の場合は小数点第2位まで表示 | AR37: 9,999 or 9,999.99
D38: 28 | E38: 単位 | M38: 文字列 | P38: 全角 | S38: 3 | V38: [SQL31.単位名]
D39: 29 | E39: 単価_元 | M39: 数値 | P39: 半角 | S39: 6 | V39: [画面.書式区分],[SQL31.売上単価] | AB39: [画面.書式区分]が1以外の場合は[SQL31.売上単価]を表示、それ以外の場合は何も表示しない。
D40: 30 | E40: 単価 | M40: 数値 | P40: 半角 | S40: 12 | V40: [36.単価_元] | AB40: [32.単価_元]が整数の場合は1の位まで表示、小数の場合は小数点第2位まで表示 | AR40: 9,999 or 9,999.99
D41: 31 | E41: 金額 | M41: 数値 | P41: 半角 | S41: 12 | V41: [SQL31.売上端数],[SQL31.数量],[SQL31.売上単価][画面.書式区分],[SQL31.見積区分] | AB41: [SQL31.数量]と[SQL31.売上単価]をかけ、[SQL31.売上端数]が0の場合は四捨五入、1の場合は切り上げ、2の場合は切り捨てを行ったものを[売上金額]とする。 [画面.書式区分]が1以外かつ[SQL31.見積区分]が"A","C","S"のいずれにも該当しない場合は[売上金額]を表示。 [画面.書式区分]が1以外かつ[SQL31.見積区分]が"A","C","S"のいずれかに該当する場合は[売上金額]が0であれば何も表示しない、0でなければ[売上金額]を表示。 上記以外の場合は何も表示しない。 | AR41: 9999 | AX41: マイナスの値の場合は赤字で表示
D42: 32 | E42: 合計 | M42: 文字列 | P42: 全角 | S42: 縮小して全体表示 | V42: [[SQL31.仕分名称] | AB42: 17行目でまだデータが存在する場合、"次ページへ"を表示、 データ最終行の場合は"【合 計】"を表示、 最終行ではなくページの終わりの場合は"【" & [SQL31.名称] & "小計】"を表示。 | AR42: 1行空けて表示
D43: 33 | E43: 合計金額 | M43: 数値 | P43: 半角 | S43: 12 | V43: [38.金額] | AB43: [38.金額]の合計
D44: 34
D45: 35

Sheet 処理詳細_書き方
B2: システム名 | H2: 画面ID | L2: 業務分類 | R2: ドキュメント種別 | X2: ドキュメント名 | AK2: 帳票名 | AX2: 作成日 | BB2: 作成者 | BF2: 更新日 | BJ2: 更新者
B3: =変更履歴!B3 -> 受発注システム | H3: =変更履歴!H3 -> UN0200 | L3: =変更履歴!L3 -> 受発注 | R3: =変更履歴!R3 -> 帳票設計書 | X3: =変更履歴!X3 -> UN0200_納品書_帳票設計書 | AK3: =変更履歴!AK3 -> 納品書 | AX3: =変更履歴!AX3 -> 45581 | BB3: =変更履歴!BB3 -> 大谷 | BF3: =変更履歴!BF3 -> 45581 | BJ3: =変更履歴!BJ3 -> 大谷
B7: 1.タイトルを記載 | H7: select | J7: 項目名 | R7: 格納テーブル
J8: 仕入先CD | R8: VM支払予定情報.仕入先CD
J9: 仕入先名1 | R9: VM支払予定情報.仕入先名1
H10: from | J10: 使用するテーブル名を記載
J11: TD売上請求H
J12: TD見積
J13: TM納入先
H14: join | J14: 結合方式
K15: 結合テーブル名
M16: 結合条件
L17: and | M17: 結合条件
L18: or | M18: 結合条件
J19: INNER JOIN
K20: TM納入先
M21: [TD見積.納入得意先CD] = [TM納入先.得意先CD]
L22: and | M22: [TD見積.納入先CD] = [TM納入先.納入先CD]
H23: where | K23: 取得条件 | AK23: パラメータの意味が分かる場合は記載する
J24: and | K24: 取得条件
J25: or | K25: 取得条件
J26: ※可能な限り日本語化する
K27: [TD見積.得意先CD] = '8001' | AK27: 8001'はヤオコーの得意先CD
J28: and | K28: [TD売上請求H.請求日付]が[画面.請求期間From]以降
H32: order by | J32: ソート条件を記載
J33: [画面.iYK物件区分]が1の場合は[TD見積.納入得意先CD],[TD見積.納入先CD],[TD売上請求H.見積番号]を昇順でソート
H36: group byなどほかの条件がある場合は行を追加して記載

Sheet 処理詳細
B2: システム名 | H2: 画面ID | L2: システム分類 | R2: ドキュメント種別 | X2: ドキュメント名 | AK2: 帳票名 | AX2: 作成日 | BB2: 作成者 | BF2: 更新日 | BJ2: 更新者
B3: =[4]変更履歴!B3 -> XXXXXXXX | H3: =[4]変更履歴!H3 -> MH0400 | L3: =[4]変更履歴!L3 -> 運用自動化 | R3: =[4]変更履歴!R3 -> 帳票設計書 | X3: =[4]変更履歴!X3 -> MH0400_見積書_帳票設計書 | AK3: =[4]変更履歴!AK3 -> 見積書 | AX3: =[4]変更履歴!AX3 -> 0 | BB3: =[4]変更履歴!BB3 -> 0 | BF3: =[4]変更履歴!BF3 -> 0 | BJ3: =[4]変更履歴!BJ3 -> 0
B6: SQL1 | H6: select | J6: 見積番号 | R6: TD見積.見積番号
J7: 見積件名 | R7: TD見積.見積件名
J8: 得意先名1 | R8: TD見積.得意先名1
J9: 得意先名2 | R9: TD見積.得意先名2
J10: 現場名 | R10: TD見積.現場名
J11: 納期S | R11: TD見積.納期S
J12: 納期E | R12: TD見積.納期E
J13: 原価率 | R13: TD見積.原価率
J14: 担当者CD | R14: TD見積.担当者CD
H15: from | J15: From TD見積
H16: where | J16: WHERE 見積番号 = 画面.見積番号
B17: SQL2 | H17: select | J17: 見積番号 | R17: TD見積.見積番号
J18: 見積日付 | R18: TD見積.見積日付
J19: 物件種別 | R19: TD見積.物件種別
J20: 得意先CD | R20: TD見積.得意先CD
J21: 見積件名 | R21: TD見積.見積件名
J22: 合計金額 | R22: TD見積.合計金額 + TD見積.出精値引 AS 合計金額
J23: 見積書出力日 | R23: TD見積.見積書出力日
J24: 注文発行日 | R24: TD見積.注文発行日
H25: from | J25: FROM TD見積 AS MT
H26: where | J26: WHERE | AK26: WHERE句が存在するときのみ
K27: 得意先CD LIKE '画面.得意先CD%' | AK27: 画面.得意先CDが入力されている場合
K28: 納入先CD Like '画面.納入先CD%' | AK28: 画面.納入先CDが入力されている場合
K29: MT.見積番号 >= 画面.開始見積番号 And MT.見積番号 <= 画面.終了見積番号 | AK29: 画面.開始見積番号または画面.終了見積番号が入力されている場合
K30: 見積件名 Like '%画面.見積件名%' | AK30: 画面.見積件名が入力されている場合
K31: MT.合計金額 + MT.出精値引 >= 画面.開始見積金額 And MT.合計金額 + MT.出精値引 <= 画面.終了見積金額 | AK31: 画面.開始見積金額または画面.終了見積金額が入力されている場合
K32: MT見積日付 >= 開始見積日付 And MT見積日付 >= 終了見積日付
H33: order by | J33: ORDER BY MT.見積日付 DESC の降順でソート, MT.見積番号 DESC の降順でソート
B34: SQL3 | H34: select | J34: decimalPoint | R34: CASE WHEN COUNTRY_CODE = 'CN' THEN 2 ELSE 0 END | AK34: decimalPointは変数
H35: from | J35: FROM AppCountry
B36: SQL4 | H36: select | J36: 見積番号 | R36: #WK見積明細.見積番号 | AK36: SELECT * INTO #WK見積明細
J37: 仕分番号 | R37: #WK見積明細.仕分番号 | AK37: 附属部材以外で
J38: 仕分名称 | R38: #WK見積明細.仕分名称 | AK38: コメントでないもの
J39: 行番号 | R39: #WK見積明細.行番号
J40: SP区分 | R40: #WK見積明細.SP区分
J41: PC区分 | R41: #WK見積明細.PC区分
J42: 製品NO | R42: #WK見積明細.製品NO
J43: 仕様NO | R43: #WK見積明細.仕様NO
...

Sheet 確認事項
B2: 確認事項
B3: No. | C3: シート名 | D3: 概要 | E3: 確認済
B4: 1
B5: 2
B6: 3
B7: 4
B8: 5
B9: 6
B10: 7
B11: 8
B12: 9
B13: 10
B14: 11
B15: 12
... B54: 51

Sheet 別紙_テンプレート
E1: 納 品 書
A4: 株式会社〇〇 御中
A6: 下記の通り御納品いたします。
A9: 御納品金額 | D9: =M26+M37 -> 11310
A10: 消費税等(10%) | D10: =D9/10 -> 1131 | L10: 〒444-5555
A11: 合計 | D11: =SUM(D9,D10) -> 12441 | L11: 〇〇県〇〇市〇〇111-1
L12: TEL 111-222-3333
A13: 件 名 ： | L13: FAX 111-222-3333
A15: 納 期 ： | L15: コールセンター：111-222-3333
A16: 御支払条件 ： | L16: 問い合わせ先：〇〇 〇〇
L17: E-mail:xxxxx@sanwashouken.co.jp
A18: 備 考 ：
M19: (単位：円)
A20: SEC | B20: 品名 | E20: Ｗ | F20: Ｄ | G20: Ｈ | I20: 数量 | J20: 単位 | L20: 単価 | M20: 金額
B21: △△支店
A22: 1 | B22: ｷｯｸﾌﾟﾚｰﾄ | E22: 900 | F22: 0 | G22: 0 | I22: 5 | J22: 個 | L22: 1720 | M22: =I22*L22 -> 8600
A23: 2 | B23: 金具 | E23: 0 | F23: 0 | G23: 0 | I23: 10 | J23: 個 | L23: 100 | M23: =I23*L23 -> 1000
A24: 3 | B24: 棚 | E24: 900 | F24: 450 | G24: 0 | I24: 1 | J24: 枚 | L24: 940 | M24: =I24*L24 -> 940
B26: 【合 計】 | M26: =SUM(M22:M24) -> 10540
B28: □□支店
A31: SEC | B31: 品名 | E31: Ｗ | F31: Ｄ | G31: Ｈ | I31: 数量 | J31: 単位 | L31: 単価 | M31: 金額
A32: 1 | B32: カート | E32: 900 | F32: 0 | G32: 0 | I32: 5 | J32: 個 | L32: 8800 | M32: =I32*L32 -> 44000
A33: 2 | B33: ねじ | E33: 0 | F33: 0 | G33: 0 | I33: 10 | J33: 個 | L33: 500 | M33: =I33*L33 -> 5000
A34: 3 | B34: ボード | E34: 900 | F34: 450 | G34: 0 | I34: 1 | J34: 枚 | L34: 2000 | M34: =I34*L34 -> 2000
A35: 4 | B35: 部品1 | E35: 0 | F35: 0 | G35: 0 | I35: 3 | J35: 個 | L35: 600 | M35: =I35*L35 -> 1800
A36: 5 | B36: 部品2 | E36: 0 | F36: 0 | G36: 0 | I36: 5 | J36: 個 | L36: 800 | M36: =I36*L36 -> 4000
A37: 6 | B37: 部品3 | E37: 0 | F37: 0 | G37: 0 | I37: 7 | J37: 個 | L37: 110 | M37: =I37*L37 -> 770
A38: 7 | B38: 部品4 | E38: 0 | F38: 0 | G38: 0 | I38: 9 | J38: 個 | L38: 1200 | M38: =I38*L38 -> 10800
A39: 8 | B39: 部品5 | E39: 0 | F39: 0 | G39: 0 | I39: 10 | J39: 個 | L39: 170 | M39: =I39*L39 -> 1700
B41: 【合 計】 | M41: =SUM(M32:M39) -> 70070
B43: ××支店
A44: 1 | B44: カート | E44: 900 | F44: 0 | G44: 0 | I44: 5 | J44: 個 | L44: 8800 | M44: =I44*L44 -> 44000
A45: 2 | B45: ねじ | E45: 0 | F45: 0 | G45: 0 | I45: 10 | J45: 個 | L45: 500 | M45: =I45*L45 -> 5000
A46: 3 | B46: ボード | E46: 900 | F46: 450 | G46: 0 | I46: 1 | J46: 枚 | L46: 2000 | M46: =I46*L46 -> 2000
B48: 【合 計】 | M48: =SUM(M44:M46) -> 51000

Sheet 別紙_印刷レイアウト

Sheet 参照
A1: 数値
A2: ブール値
A3: 文字列
A4: 日付
A5: リスト
A6: 辞書配列
