Workbook

Sheet 変更履歴
B2: システム名 | H2: 画面ID | L2: システム分類 | R2: ドキュメント種別 | X2: ドキュメント名 | AK2: 帳票名 | AX2: 作成日 | BB2: 作成者 | BF2: 更新日 | BJ2: 更新者
B3: 受発注システム | H3: =LEFT($X$3,FIND("_",$X$3)-1) -> UN0300 | L3: 受発注 | R3: =MID($X$3,FIND("_",$X$3,FIND("_",$X$3)+1)+1,LEN($X$3)-FIND("_",$X$3,FIND("_",$X$3)+1)) -> 帳票設計書 | X3: =REPLACE(LEFT(CELL("filename",$B$2),FIND(".x",CELL("filename",$B$2))-1),1,FIND("[",CELL("filename",$B$2)),) -> UN0300_売上日計表_帳票設計書 | AK3: =MID($X$3,FIND("_",$X$3)+1,FIND("_",$X$3,FIND("_",$X$3)+1)-FIND("_",$X$3)-1) -> 売上日計表 | AX3: 45583 | BB3: 大谷 | BF3: 45583 | BJ3: 大谷
C7: 変更履歴
C8: 日付 | G8: 版数 | K8: 担当 | O8: 変更箇所 | Y8: 内容
C9: 45583 | G9: 1.0.0 | K9: 大谷 | O9: - | Y9: 新規作成

Sheet 概要
B2: システム名 | H2: 画面ID | L2: システム分類 | R2: ドキュメント種別 | X2: ドキュメント名 | AK2: 帳票名 | AX2: 作成日 | BB2: 作成者 | BF2: 更新日 | BJ2: 更新者
B3: =変更履歴!B3 -> 受発注システム | H3: =変更履歴!H3 -> UN0300 | L3: =変更履歴!L3 -> 受発注 | R3: =変更履歴!R3 -> 帳票設計書 | X3: =変更履歴!X3 -> UN0300_売上日計表_帳票設計書 | AK3: =変更履歴!AK3 -> 売上日計表 | AX3: =変更履歴!AX3 -> 45583 | BB3: =変更履歴!BB3 -> 大谷 | BF3: =変更履歴!BF3 -> 45583 | BJ3: =変更履歴!BJ3 -> 大谷
D7: 帳票の名称 | H7: =AK3 -> 売上日計表
D8: 帳票テンプレート名 | H8: -
D9: ファイル種類 | H9: PDF
D10: ファイル拡張子 | H10: pdf
D11: 文字コード | H11: -
D12: コーテーション | H12: -
D13: 固定長/可変長 | H13: -
D14: 区切り文字 | H14: -
D15: 用紙サイズ | H15: A3横
D16: 概要

Sheet 帳票レイアウト
B2: システム名 | H2: 画面ID | L2: システム分類 | R2: ドキュメント種別 | X2: ドキュメント名 | AK2: 帳票名 | AX2: 作成日 | BB2: 作成者 | BF2: 更新日 | BJ2: 更新者
B3: =変更履歴!B3 -> 受発注システム | H3: =変更履歴!H3 -> UN0300 | L3: =変更履歴!L3 -> 受発注 | R3: =変更履歴!R3 -> 帳票設計書 | X3: =変更履歴!X3 -> UN0300_売上日計表_帳票設計書 | AK3: =変更履歴!AK3 -> 売上日計表 | AX3: =変更履歴!AX3 -> 45583 | BB3: =変更履歴!BB3 -> 大谷 | BF3: =変更履歴!BF3 -> 45583 | BJ3: =変更履歴!BJ3 -> 大谷
B6: ページ１

Sheet 項目一覧
B2: システム名 | H2: 画面ID | L2: システム分類 | R2: ドキュメント種別 | X2: ドキュメント名 | AK2: 帳票名 | AX2: 作成日 | BB2: 作成者 | BF2: 更新日 | BJ2: 更新者
B3: =変更履歴!B3 -> 受発注システム | H3: =変更履歴!H3 -> UN0300 | L3: =変更履歴!L3 -> 受発注 | R3: =変更履歴!R3 -> 帳票設計書 | X3: =変更履歴!X3 -> UN0300_売上日計表_帳票設計書 | AK3: =変更履歴!AK3 -> 売上日計表 | AX3: =変更履歴!AX3 -> 45583 | BB3: =変更履歴!BB3 -> 大谷 | BF3: =変更履歴!BF3 -> 45583 | BJ3: =変更履歴!BJ3 -> 大谷
B7: 項目一覧
C9: 項目 | F9: フォントや文字サイズ、セル条件などは「別紙_テンプレート」準拠
D10: No. | E10: 項目名 | M10: データ型 | P10: 全角/半角 | S10: 文字数/桁数 | V10: データ取得元 | AB10: データ整形方法 | AR10: 整形後フォーマット | AX10: 区分1 | AZ10: 区分2 | BB10: 備考
D11: 1 | E11: 得意先CD開始 | M11: 数値 | P11: 半角 | V11: 画面.得意先開始CD | AB11: 画面からの引数が空の場合は「[最初]」を表示 | AR11: [9999]
D12: 2 | E12: 得意先CD終了 | M12: 数値 | P12: 半角 | V12: 画面.得意先終了CD | AB12: 画面からの引数が空の場合は「[最後]」を表示 | AR12: [9999]
D13: 3 | E13: 開始日付 | M13: 日付 | P13: 半角 | V13: 画面.売上開始日付,画面.請求開始日付 | AB13: 画面の入力によってどちらか決まる | AR13: yyyy年mm月dd日
D14: 4 | E14: 終了日付 | M14: 日付 | P14: 半角 | V14: 画面.売上終了日付,画面.請求終了日付 | AB14: 画面の入力によってどちらか決まる | AR14: yyyy年mm月dd日
D15: 5 | E15: 作成日 | M15: 日付 | P15: 半角 | V15: 現在日付 | AR15: yyyy年mm月dd日
D16: 6 | E16: 納入得意先CD | M16: 数値 | P16: 半角 | V16: SQL1.納入得意先CD
D17: 7 | E17: 納入先CD | M17: 数値 | P17: 半角 | V17: SQL1.納入先CD
D18: 8 | E18: 得意先名1 | M18: 文字列 | P18: 全角 | V18: SQL1.納入先名1
D19: 9 | E19: 得意先名2 | M19: 文字列 | P19: 全角 | V19: SQL1.納入先名2
D20: 10 | E20: 売上日付 | M20: 日付 | P20: 半角 | V20: SQL1.売上日付
D21: 11 | E21: 請求日付 | M21: 日付 | P21: 半角 | V21: SQL1.請求日付
D22: 12 | E22: 伝票番号 | M22: 数値 | P22: 半角 | V22: SQL1.見積番号,SQL1.売上明細行番号 | AB22: [SQL1.見積番号] + "-" + [SQL1.売上明細行番号]のゼロ埋め3桁表示 | AR22: 99999-001 | AX22: ○ | AZ22: ×
D23: 13 | E23: 製品NO | M23: 数値 | P23: 半角 | V23: SQL1.製品NO | AX23: ○ | AZ23: ×
D24: 14 | E24: 仕様NO | M24: 数値 | P24: 半角 | V24: SQL1.仕様NO | AX24: ○ | AZ24: ×
D25: 15 | E25: 製品名 | M25: 文字列 | P25: 全角 | V25: SQL1.漢字名称 | AX25: ○ | AZ25: ×
D26: 16 | E26: W | M26: 数値 | P26: 半角 | V26: SQL1.W | AX26: ○ | AZ26: ×
D27: 17 | E27: D | M27: 数値 | P27: 半角 | V27: SQL1.D,SQL1.D1,SQL1.D2 | AB27: [SQL1.D]が０でない場合、[SQL1.D]を表示 [SQL1.D]が０の場合、 [SQL1.D1],[SQL1.D2]がどちらも0の場合は""を表示 それ以外の場合は[SQL1.D1] + "/" + [SQL1.D2]を表示 | AX27: ○ | AZ27: ×
D28: 18 | E28: H | M28: 数値 | P28: 半角 | V28: SQL1.H,SQL1.H1,SQL1.H2 | AB28: [SQL1.H]が０でない場合、[SQL1.H]を表示 [SQL1.H]が０の場合、 [SQL1.H1],[SQL1.H2]がどちらも0の場合は""を表示 それ以外の場合は[SQL1.H1] + "/" + [SQL1.H2]を表示 | AX28: ○ | AZ28: ×
D29: 19 | E29: 数量 | M29: 数値 | P29: 半角 | V29: SQL1.売上数量 | AX29: ○ | AZ29: ×
D30: 20 | E30: 単位 | M30: 文字列 | P30: 全角 | V30: SQL1.単位名 | AX30: ○ | AZ30: ×
D31: 21 | E31: 売上単価 | M31: 数値 | P31: 半角 | V31: SQL1.売上単価 | AX31: ○ | AZ31: ×
D32: 22 | E32: 売上金額 | M32: 数値 | P32: 半角 | V32: SQL1.売上金額 | AX32: ○ | AZ32: ×
D33: 23 | E33: 伝区 | M33: 文字列 | P33: 全角 | V33: SQL1.伝票区分 | AX33: ○ | AZ33: ×
D34: 24 | E34: 消費税 | M34: 数値 | P34: 半角 | V34: SQL1.売上金額 | AX34: × | AZ34: ○ | BB34: 売上金額に外税額が入っている
D35: 25 | E35: 合計金額 | M35: 数値 | P35: 半角 | V35: SQL1.売上金額 | AB35: 売上番号ごとの[SQL1.売上金額]合計 | AX35: ○ | AZ35: ×

Sheet 確認事項
B2: 確認事項
B3: No. | C3: シート名 | D3: タイトル | E3: 概要 | F3: 回答 | G3: 確認済
B4: 1 | C4: 帳票レイアウト確認点 | D4: レイアウトサンプルに表示されていない項目について | E4: 「SECT」「締日」項目は出力後のレイアウトには表示されていないが必要な項目か | F4: 不要 | G4: 〇
B5: 2
B6: 3
B7: 4
B8: 5
B9: 6
B10: 7
B11: 8
B12: 9
B13: 10
B14: 11
B15: 12
B16: 13
... B54: 51

Sheet 処理詳細
B2: システム名 | H2: 画面ID | L2: システム分類 | R2: ドキュメント種別 | X2: ドキュメント名 | AK2: 帳票名 | AX2: 作成日 | BB2: 作成者 | BF2: 更新日 | BJ2: 更新者
B3: =変更履歴!B3 -> 受発注システム | H3: =変更履歴!H3 -> UN0300 | L3: =変更履歴!L3 -> 受発注 | R3: =変更履歴!R3 -> 帳票設計書 | X3: =変更履歴!X3 -> UN0300_売上日計表_帳票設計書 | AK3: =変更履歴!AK3 -> 売上日計表 | AX3: =変更履歴!AX3 -> 45583 | BB3: =変更履歴!BB3 -> 大谷 | BF3: =変更履歴!BF3 -> 45583 | BJ3: =変更履歴!BJ3 -> 大谷
B6: SQL1 | H6: select | J6: 区分 | R6: 1
J7: 見積番号 | R7: TD売上v2.見積番号
J8: 売上番号 | R8: TD売上v2.売上番号
J9: 売上日付 | R9: TD売上v2.売上日付
J10: .請求日付 | R10: TD売上請求H.請求日付
J11: 納入得意先CD | R11: TD見積.納入得意先CD
J12: 納入先CD | R12: TD見積.納入先CD
J13: 納入先名1 | R13: TD見積.納入先名1
J14: 納入先名2 | R14: TD見積.納入先名2
J15: 伝票区分 | R15: TD売上明細V2.伝票区分
J16: 売上明細行番号 | R16: TD売上明細V2.売上明細行番号
J17: 製品NO | R17: TD売上明細V2.製品NO
J18: 仕様NO | R18: TD売上明細V2.仕様NO
... J30: 売上金額 | R30: TD売上明細V2.売上金額
H31: from | J31: TD売上v2
J32: TD売上請求H
J33: TD見積
J34: TD売上明細V2
H35: join | J35: LEFT JOIN
K36: TD売上請求H
M37: TD売上v2.見積番号 = TD売上請求H.見積番号
J38: INNER JOIN
K39: TD見積
M40: TD売上v2.見積番号 = TD見積.見積番号
J41: INNER JOIN
K42: TD売上明細V2
M43: TD売上v2.売上番号 = TD売上明細V2.売上番号
H44: where | K44: TD売上v2.売上日付 >= COALESCE([画面.売上開始日付], TD売上v2.売上日付)
J45: AND | K45: TD売上v2.売上日付 <= COALESCE([画面.売上終了日付], TD売上v2.売上日付)
J46: AND | K46: (TD売上請求H.請求日付 >= COALESCE([画面.請求開始日付], TD売上請求H.請求日付) OR ([画面.請求開始日付]IS NULL))
J47: AND | K47: (TD売上請求H.請求日付 <= COALESCE([画面.請求終了日付], TD売上請求H.請求日付) OR ([画面.請求終了日付] IS NULL))
J48: AND | K48: TD見積.得意先CD >= COALESCE([画面.得意先開始CD], TD見積.得意先CD)
J49: AND | K49: TD見積.得意先CD <= COALESCE([画面.得意先終了CD], TD見積.得意先CD)
B50: SQL2 | H50: select | J50: 区分 | R50: 2
J51: 見積番号 | R51: TD売上v2.見積番号
J52: 売上番号 | R52: TD売上v2.売上番号
J53: 売上日付 | R53: TD売上v2.売上日付
J54: .請求日付 | R54: TD売上請求H.請求日付
...

Sheet 処理詳細_書き方
B2: システム名 | H2: 画面ID | L2: 業務分類 | R2: ドキュメント種別 | X2: ドキュメント名 | AK2: 帳票名 | AX2: 作成日 | BB2: 作成者 | BF2: 更新日 | BJ2: 更新者
B3: =変更履歴!B3 -> 受発注システム | H3: =変更履歴!H3 -> UN0300 | L3: =変更履歴!L3 -> 受発注 | R3: =変更履歴!R3 -> 帳票設計書 | X3: =変更履歴!X3 -> UN0300_売上日計表_帳票設計書 | AK3: =変更履歴!AK3 -> 売上日計表 | AX3: =変更履歴!AX3 -> 45583 | BB3: =変更履歴!BB3 -> 大谷 | BF3: =変更履歴!BF3 -> 45583 | BJ3: =変更履歴!BJ3 -> 大谷
B7: 1.タイトルを記載 | H7: select | J7: 項目名 | R7: 格納テーブル
J8: 仕入先CD | R8: VM支払予定情報.仕入先CD
J9: 仕入先名1 | R9: VM支払予定情報.仕入先名1
H10: from | J10: 使用するテーブル名を記載
J11: TD売上請求H
J12: TD見積
J13: TM納入先
H14: join | J14: 結合方式
K15: 結合テーブル名
M16: 結合条件
L17: and | M17: 結合条件
L18: or | M18: 結合条件
J19: INNER JOIN
K20: TM納入先
M21: [TD見積.納入得意先CD] = [TM納入先.得意先CD]
L22: and | M22: [TD見積.納入先CD] = [TM納入先.納入先CD]
H23: where | K23: 取得条件 | AK23: パラメータの意味が分かる場合は記載する
J24: and | K24: 取得条件
J25: or | K25: 取得条件
J26: ※可能な限り日本語化する
K27: [TD見積.得意先CD] = '8001' | AK27: 8001'はヤオコーの得意先CD
J28: and | K28: [TD売上請求H.請求日付]が[画面.請求期間From]以降
H32: order by | J32: ソート条件を記載
J33: [画面.iYK物件区分]が1の場合は[TD見積.納入得意先CD],[TD見積.納入先CD],[TD売上請求H.見積番号]を昇順でソート
H36: group byなどほかの条件がある場合は行を追加して記載

Sheet 帳票レイアウト確認点

Sheet 別紙_印刷レイアウト

Sheet 参照
A1: 数値
A2: ブール値
A3: 文字列
A4: 日付
A5: リスト
A6: 辞書配列
