Workbook

Sheet 変更履歴
B2: システム名 | H2: 画面ID | L2: システム分類 | R2: ドキュメント種別 | X2: ドキュメント名 | AK2: 帳票名 | AX2: 作成日 | BB2: 作成者 | BF2: 更新日 | BJ2: 更新者
B3: 受発注システム | H3: =LEFT($X$3,FIND("_",$X$3)-1) -> UN0700 | L3: 受発注 | R3: =MID($X$3,FIND("_",$X$3,FIND("_",$X$3)+1)+1,LEN($X$3)-FIND("_",$X$3,FIND("_",$X$3)+1)) -> 帳票設計書 | X3: =REPLACE(LEFT(CELL("filename",$B$2),FIND(".x",CELL("filename",$B$2))-1),1,FIND("[",CELL("filename",$B$2)),) -> UN0700_消込済一覧表_帳票設計書 | AK3: =MID($X$3,FIND("_",$X$3)+1,FIND("_",$X$3,FIND("_",$X$3)+1)-FIND("_",$X$3)-1) -> 消込済一覧表 | AX3: 45583 | BB3: 大谷 | BF3: 45583 | BJ3: 大谷
C7: 変更履歴
C8: 日付 | G8: 版数 | K8: 担当 | O8: 変更箇所 | Y8: 内容
C9: 45583 | G9: 1.0.0 | K9: 大谷 | O9: - | Y9: 新規作成

Sheet 概要
B2: システム名 | H2: 画面ID | L2: システム分類 | R2: ドキュメント種別 | X2: ドキュメント名 | AK2: 帳票名 | AX2: 作成日 | BB2: 作成者 | BF2: 更新日 | BJ2: 更新者
B3: =変更履歴!B3 -> 受発注システム | H3: =変更履歴!H3 -> UN0700 | L3: =変更履歴!L3 -> 受発注 | R3: =変更履歴!R3 -> 帳票設計書 | X3: =変更履歴!X3 -> UN0700_消込済一覧表_帳票設計書 | AK3: =変更履歴!AK3 -> 消込済一覧表 | AX3: =変更履歴!AX3 -> 45583 | BB3: =変更履歴!BB3 -> 大谷 | BF3: =変更履歴!BF3 -> 45583 | BJ3: =変更履歴!BJ3 -> 大谷
D7: 帳票の名称 | H7: =AK3 -> 消込済一覧表
D8: 帳票テンプレート名 | H8: -
D9: ファイル種類 | H9: PDF
D10: ファイル拡張子 | H10: pdf
D11: 文字コード | H11: -
D12: コーテーション | H12: -
D13: 固定長/可変長 | H13: -
D14: 区切り文字 | H14: -
D15: 用紙サイズ | H15: A3縦
D16: 概要

Sheet 帳票レイアウト
B2: システム名 | H2: 画面ID | L2: システム分類 | R2: ドキュメント種別 | X2: ドキュメント名 | AK2: 帳票名 | AX2: 作成日 | BB2: 作成者 | BF2: 更新日 | BJ2: 更新者
B3: =変更履歴!B3 -> 受発注システム | H3: =変更履歴!H3 -> UN0700 | L3: =変更履歴!L3 -> 受発注 | R3: =変更履歴!R3 -> 帳票設計書 | X3: =変更履歴!X3 -> UN0700_消込済一覧表_帳票設計書 | AK3: =変更履歴!AK3 -> 消込済一覧表 | AX3: =変更履歴!AX3 -> 45583 | BB3: =変更履歴!BB3 -> 大谷 | BF3: =変更履歴!BF3 -> 45583 | BJ3: =変更履歴!BJ3 -> 大谷
B6: ページ１

Sheet 項目一覧
B2: システム名 | H2: 画面ID | L2: システム分類 | R2: ドキュメント種別 | X2: ドキュメント名 | AK2: 帳票名 | AX2: 作成日 | BB2: 作成者 | BF2: 更新日 | BJ2: 更新者
B3: =変更履歴!B3 -> 受発注システム | H3: =変更履歴!H3 -> UN0700 | L3: =変更履歴!L3 -> 受発注 | R3: =変更履歴!R3 -> 帳票設計書 | X3: =変更履歴!X3 -> UN0700_消込済一覧表_帳票設計書 | AK3: =変更履歴!AK3 -> 消込済一覧表 | AX3: =変更履歴!AX3 -> 45583 | BB3: =変更履歴!BB3 -> 大谷 | BF3: =変更履歴!BF3 -> 45583 | BJ3: =変更履歴!BJ3 -> 大谷
B7: 項目一覧
C9: 項目 | F9: フォントや文字サイズ、セル条件などは「別紙_テンプレート」準拠
D10: No. | E10: 項目名 | M10: データ型 | P10: 全角/半角 | S10: 文字数/桁数 | V10: データ取得元 | AB10: データ整形方法 | AR10: 整形後フォーマット | AX10: 備考
D11: 1 | E11: 入金開始日付 | M11: 日付 | P11: 半角 | V11: 画面.開始日付 | AR11: yyyy年mm月dd日
D12: 2 | E12: 入金終了日付 | M12: 日付 | P12: 半角 | V12: 画面.終了日付 | AR12: yyyy年mm月dd日
D13: 3 | E13: 開始得意先CD | M13: 数値 | P13: 半角 | V13: 画面.開始得意先CD | AB13: 画面からの入力データが空の場合は"[最初]"を表示 | AR13: "[999999]"
D14: 4 | E14: 終了得意先CD | M14: 数値 | P14: 半角 | V14: 画面.終了得意先CD | AB14: 画面からの入力データが空の場合は"[最後]"を表示 | AR14: "[999999]"
D15: 5 | E15: 作成日 | M15: 日付 | P15: 半角 | V15: SQL1.現在日付 | AR15: yyyy年mm月dd日
D16: 6 | E16: 入金日付 | M16: 日付 | P16: 半角 | V16: SQL1.入金日付
D17: 7 | E17: 入金番号 | M17: 数値 | P17: 半角 | V17: SQL1.入金番号
D18: 8 | E18: 得意先CD | M18: 数値 | P18: 半角 | V18: SQL1.得意先CD
D19: 9 | E19: 得意先名1 | M19: 文字列 | P19: 全角 | V19: SQL1.得意先名1
D20: 10 | E20: 得意先名2 | M20: 文字列 | P20: 全角 | V20: SQL1.得意先名2
D21: 11 | E21: 入金金額 | M21: 数値 | P21: 半角 | V21: SQL1.入金金額 | AR21: 999999
D22: 12 | E22: 入金済金額 | M22: 数値 | P22: 半角 | V22: SQL1.入金済金額 | AR22: 999999
D23: 13 | E23: 売上日付 | M23: 日付 | P23: 半角 | V23: SQL1.売上日付
D24: 14 | E24: 請求日付 | M24: 日付 | P24: 半角 | V24: SQL1.請求日付
D25: 15 | E25: 売上番号 | M25: 数値 | P25: 半角 | V25: SQL1.見積番号
D26: 16 | E26: 売上金額 | M26: 数値 | P26: 半角 | V26: SQL1.税込金額 | AB26: [SQL1.税込金額]＞[SQL1.売上消込合計]の場合[SQL1.税込金額]を赤文字で表示 それ以外の場合は[SQL1.税込金額]を黒文字で表示 | AR26: 999999
D27: 17 | E27: 消込金額 | M27: 数値 | P27: 半角 | V27: SQL1.売上消込合計 | AB27: [SQL1.税込金額]＜[SQL1.売上消込合計]の場合[SQL1.売上消込合計]を赤文字で表示 それ以外の場合は[SQL1.売上消込合計]を黒文字で表示 | AR27: 999999
D28: 18
D29: 19
D30: 20

Sheet 処理詳細
B2: システム名 | H2: 画面ID | L2: システム分類 | R2: ドキュメント種別 | X2: ドキュメント名 | AK2: 帳票名 | AX2: 作成日 | BB2: 作成者 | BF2: 更新日 | BJ2: 更新者
B3: =変更履歴!B3 -> 受発注システム | H3: =変更履歴!H3 -> UN0700 | L3: =変更履歴!L3 -> 受発注 | R3: =変更履歴!R3 -> 帳票設計書 | X3: =変更履歴!X3 -> UN0700_消込済一覧表_帳票設計書 | AK3: =変更履歴!AK3 -> 消込済一覧表 | AX3: =変更履歴!AX3 -> 45583 | BB3: =変更履歴!BB3 -> 大谷 | BF3: =変更履歴!BF3 -> 45583 | BJ3: =変更履歴!BJ3 -> 大谷
B6: SQL1 | H6: select | J6: 入金番号 | R6: SQL2.入金番号
J7: 入金日付 | R7: SQL2.入金日付
J8: 得意先CD | R8: SQL2.得意先CD
J9: 得意先名1 | R9: SQL2.得意先名1
J10: 得意先名2 | R10: SQL2.得意先名2
J11: 入金金額 | R11: SQL2.入金金額
J12: 入金済金額 | R12: SQL4.入金消込合計
J13: 売上日付 | R13: SQL3.売上日付
J14: 請求日付 | R14: TD売上請求H.請求日付
J15: 見積番号 | R15: TD売上請求H.見積番号
J16: 税込金額 | R16: TD売上請求H.合計金額 + TD売上請求H.外税額
J17: 売上消込合計 | R17: SQL5.売上消込合計
H18: from | J18: SQL2
J19: TD入金消込
J20: TD売上請求H
J21: TD見積
J22: SQL3
J23: SQL4
J24: SQL5
H25: join | J25: INNER JOIN
K26: TD入金消込
M27: SQL2.入金番号 = KS.入金番号
J28: INNER JOIN
K29: TD売上請求H
M30: KS.売上番号 = TD売上請求H.見積番号
J31: INNER JOIN
K32: TD見積
M33: TD売上請求H.見積番号 = MH.見積番号
J34: INNER JOIN
K35: SQL3
M36: TD売上請求H.見積番号 = SQL3.見積番号
J37: INNER JOIN
K38: SQL4
M39: SQL2.入金番号 = SQL4.入金番号
J40: INNER JOIN
K41: SQL5
M42: TD売上請求H.見積番号 = SQL5.売上番号
L43: AND | M43: SQL2.入金番号 = SQL5.入金番号
...

Sheet 処理詳細_書き方
B2: システム名 | H2: 画面ID | L2: 業務分類 | R2: ドキュメント種別 | X2: ドキュメント名 | AK2: 帳票名 | AX2: 作成日 | BB2: 作成者 | BF2: 更新日 | BJ2: 更新者
B3: =変更履歴!B3 -> 受発注システム | H3: =変更履歴!H3 -> UN0700 | L3: =変更履歴!L3 -> 受発注 | R3: =変更履歴!R3 -> 帳票設計書 | X3: =変更履歴!X3 -> UN0700_消込済一覧表_帳票設計書 | AK3: =変更履歴!AK3 -> 消込済一覧表 | AX3: =変更履歴!AX3 -> 45583 | BB3: =変更履歴!BB3 -> 大谷 | BF3: =変更履歴!BF3 -> 45583 | BJ3: =変更履歴!BJ3 -> 大谷
B7: 1.タイトルを記載 | H7: select | J7: 項目名 | R7: 格納テーブル
J8: 仕入先CD | R8: VM支払予定情報.仕入先CD
J9: 仕入先名1 | R9: VM支払予定情報.仕入先名1
H10: from | J10: 使用するテーブル名を記載
J11: TD売上請求H
J12: TD見積
J13: TM納入先
H14: join | J14: 結合方式
K15: 結合テーブル名
M16: 結合条件
L17: and | M17: 結合条件
L18: or | M18: 結合条件
J19: INNER JOIN
K20: TM納入先
M21: [TD見積.納入得意先CD] = [TM納入先.得意先CD]
L22: and | M22: [TD見積.納入先CD] = [TM納入先.納入先CD]
H23: where | K23: 取得条件 | AK23: パラメータの意味が分かる場合は記載する
J24: and | K24: 取得条件
J25: or | K25: 取得条件
J26: ※可能な限り日本語化する
K27: [TD見積.得意先CD] = '8001' | AK27: 8001'はヤオコーの得意先CD
J28: and | K28: [TD売上請求H.請求日付]が[画面.請求期間From]以降
H32: order by | J32: ソート条件を記載
J33: [画面.iYK物件区分]が1の場合は[TD見積.納入得意先CD],[TD見積.納入先CD],[TD売上請求H.見積番号]を昇順でソート
H36: group byなどほかの条件がある場合は行を追加して記載

Sheet 確認事項
B2: 確認事項
B3: No. | C3: シート名 | D3: タイトル | E3: 概要 | F3: 確認済
B4: 1
B5: 2
B6: 3
B7: 4
B8: 5
B9: 6
B10: 7
B11: 8
B12: 9
B13: 10
B14: 11
B15: 12
... B54: 51

Sheet 別紙_印刷レイアウト

Sheet 参照
A1: 数値
A2: ブール値
A3: 文字列
A4: 日付
A5: リスト
A6: 辞書配列
